Workbook

Sheet Schedule
B3: September | M3: =RANDBETWEEN(1,31) -> 4 | N3: 30
B4: Sun | C4: Mon | D4: Tue | E4: Wed | F4: Thu | G4: Fri | H4: Sat | M4: =RANDBETWEEN(1,31) -> 13 | N4: 5
G5: =F5+1 -> 1 | H5: =G5+1 -> 2 | M5: =RANDBETWEEN(1,31) -> 11 | N5: 14
B6: =H5+1 -> 3 | C6: =B6+1 -> 4 | D6: =C6+1 -> 5 | E6: =D6+1 -> 6 | F6: =E6+1 -> 7 | G6: =F6+1 -> 8 | H6: =G6+1 -> 9 | M6: =RANDBETWEEN(1,31) -> 7 | N6: 26
B7: =H6+1 -> 10 | C7: =B7+1 -> 11 | D7: =C7+1 -> 12 | E7: =D7+1 -> 13 | F7: =E7+1 -> 14 | G7: =F7+1 -> 15 | H7: =G7+1 -> 16 | M7: =RANDBETWEEN(1,31) -> 8 | N7: 7
B8: =H7+1 -> 17 | C8: =B8+1 -> 18 | D8: =C8+1 -> 19 | E8: =D8+1 -> 20 | F8: =E8+1 -> 21 | G8: =F8+1 -> 22 | H8: =G8+1 -> 23 | M8: =RANDBETWEEN(1,31) -> 14 | N8: 3
B9: =H8+1 -> 24 | C9: =B9+1 -> 25 | D9: =C9+1 -> 26 | E9: =D9+1 -> 27 | F9: =E9+1 -> 28 | G9: =F9+1 -> 29 | H9: =G9+1 -> 30 | M9: =RANDBETWEEN(1,31) -> 28 | N9: 8
M10: =RANDBETWEEN(1,31) -> 29 | N10: 28
M11: =RANDBETWEEN(1,31) -> 1 | N11: 24
B12: October | M12: =RANDBETWEEN(1,31) -> 13 | N12: 17
B13: Sun | C13: Mon | D13: Tue | E13: Wed | F13: Thu | G13: Fri | H13: Sat | M13: =RANDBETWEEN(1,31) -> 6 | N13: 14
B14: 1 | C14: =B14+1 -> 2 | D14: =C14+1 -> 3 | E14: =D14+1 -> 4 | F14: =E14+1 -> 5 | G14: =F14+1 -> 6 | H14: =G14+1 -> 7 | M14: =RANDBETWEEN(1,31) -> 22 | N14: 25
B15: =H14+1 -> 8 | C15: =B15+1 -> 9 | D15: =C15+1 -> 10 | E15: =D15+1 -> 11 | F15: =E15+1 -> 12 | G15: =F15+1 -> 13 | H15: =G15+1 -> 14 | M15: =RANDBETWEEN(1,31) -> 20 | N15: 13
B16: =H15+1 -> 15 | C16: =B16+1 -> 16 | D16: =C16+1 -> 17 | E16: =D16+1 -> 18 | F16: =E16+1 -> 19 | G16: =F16+1 -> 20 | H16: =G16+1 -> 21 | M16: =RANDBETWEEN(1,31) -> 22 | N16: 20
B17: =H16+1 -> 22 | C17: =B17+1 -> 23 | D17: =C17+1 -> 24 | E17: =D17+1 -> 25 | F17: =E17+1 -> 26 | G17: =F17+1 -> 27 | H17: =G17+1 -> 28 | M17: =RANDBETWEEN(1,31) -> 22 | N17: 3
B18: =H17+1 -> 29 | C18: =B18+1 -> 30 | D18: =C18+1 -> 31 | E18: =D18+1 -> 32
B20: February
B21: Sun | C21: Mon | D21: Tue | E21: Wed | F21: Thu | G21: Fri | H21: Sat
F22: 1 | G22: =F22+1 -> 2 | H22: =G22+1 -> 3
B23: =H22+1 -> 4 | C23: =B23+1 -> 5 | D23: =C23+1 -> 6 | E23: =D23+1 -> 7 | F23: =E23+1 -> 8 | G23: =F23+1 -> 9 | H23: =G23+1 -> 10
B24: =H23+1 -> 11 | C24: =B24+1 -> 12 | D24: =C24+1 -> 13 | E24: =D24+1 -> 14 | F24: =E24+1 -> 15 | G24: =F24+1 -> 16 | H24: =G24+1 -> 17
B25: =H24+1 -> 18 | C25: =B25+1 -> 19 | D25: =C25+1 -> 20 | E25: =D25+1 -> 21 | F25: =E25+1 -> 22 | G25: =F25+1 -> 23 | H25: =G25+1 -> 24
B26: =H25+1 -> 25 | C26: =B26+1 -> 26 | D26: =C26+1 -> 27 | E26: =D26+1 -> 28 | F26: =E26+1 -> 29
B28: September
B29: Sun | C29: Mon | D29: Tue | E29: Wed | F29: Thu | G29: Fri | H29: Sat
G30: =F30+1 -> 1 | H30: =G30+1 -> 2
B31: =H30+1 -> 3 | C31: =B31+1 -> 4 | D31: =C31+1 -> 5 | E31: =D31+1 -> 6 | F31: =E31+1 -> 7 | G31: =F31+1 -> 8 | H31: =G31+1 -> 9
B32: =H31+1 -> 10 | C32: =B32+1 -> 11 | D32: =C32+1 -> 12 | E32: =D32+1 -> 13 | F32: =E32+1 -> 14 | G32: =F32+1 -> 15 | H32: =G32+1 -> 16
B33: =H32+1 -> 17 | C33: =B33+1 -> 18 | D33: =C33+1 -> 19 | E33: =D33+1 -> 20 | F33: =E33+1 -> 21 | G33: =F33+1 -> 22 | H33: =G33+1 -> 23
B34: =H33+1 -> 24 | C34: =B34+1 -> 25 | D34: =C34+1 -> 26 | E34: =D34+1 -> 27 | F34: =E34+1 -> 28 | G34: =F34+1 -> 29 | H34: =G34+1 -> 30

Sheet Boat Expansion
A1: 2024 McNary Reservoir Harvest Model
V2: ( D )
H4: Peak Hour Expansion | K4: Expansion converting trailer counts to daily peak trailer counts
H5: Area Expansion Factor | I5: 1.1 | K5: Expansion of the peak trailer count to the peak boat count for the river from McNary Dam to Hwy 395
D6: 1.285 | H6: Sept | I6: 1.285 | K6: Expansion of the peak boat count to the day's total boat trips
A7: ______________________________________________________________________________________________________________________________________________________________________________________________________________
D8: Trailers | F8: Peak hour | G8: % Salmon | H8: Boats (exp.) | I8: Boats (Total) | K8: Interviews
A9: Date | C9: Ramp | D9: counted | E9: Hour | F9: expansion | H9: (exp) | K9: Salmon | L9: Steelhead | M9: Sal/StHd | N9: Other | O9: Rec
C10: OR | F10: 1
C11: WA | F11: 1
F12: 1.2 | H12: =F12*D12 -> 0 | K12: Boats
C13: Boats | F13: 1.2 | H13: =F13*D13 -> 0 | K13: Salmon | L13: Steelhead | M13: Sal/StHd | N13: Other | O13: Rec
H14: =SUM(H10:H13) -> 0 | I14: =H14*I$6*I$5 -> 0 | K14: 0 | L14: 0 | M14: 0 | N14: 0 | O14: 0
A16: Monday | B16: 45516 | C16: OR | F16: 1
C17: WA | F17: 1
F18: 1.2 | H18: =F18*D18 -> 0 | K18: Boats
C19: Boats | F19: 1.2 | H19: =F19*D19 -> 0 | K19: Salmon | L19: Steelhead | M19: Sal/StHd | N19: Other | O19: Rec
H20: =SUM(H16:H19) -> 0 | I20: =H20*I$6*I$5 -> 0 | K20: =K16/SUM(K16:O16)*I20 -> #DIV/0! | L20: =L16/SUM(K16:O16)*$I20 -> #DIV/0! | M20: =M16/SUM(K16:O16)*$I20 -> #DIV/0! | N20: =N16/SUM(K16:O16)*$I20 -> #DIV/0! | O20: =O16/SUM(K16:O16)*$I20 -> #DIV/0!
A22: Tue | B22: =B16+1 -> 45517 | C22: OR | F22: 1
C23: WA | F23: 1
F24: 1.2 | H24: =F24*D24 -> 0 | K24: Boats
C25: Boats | F25: 1.2 | H25: =F25*D25 -> 0 | K25: Salmon | L25: Steelhead | M25: Sal/StHd | N25: Other | O25: Rec
H26: =SUM(H22:H25) -> 0 | I26: =H26*I$6*I$5 -> 0 | K26: =K22/SUM(K22:O22)*I26 -> #DIV/0! | L26: =L22/SUM(K22:O22)*$I26 -> #DIV/0! | M26: =M22/SUM(K22:O22)*$I26 -> #DIV/0! | N26: =N22/SUM(K22:O22)*$I26 -> #DIV/0! | O26: =O22/SUM(K22:O22)*$I26 -> #DIV/0!
A28: Wed | B28: =B22+1 -> 45518 | C28: OR | F28: 1 | K28: 0 | L28: 0 | M28: 0 | N28: 0 | O28: 0
C29: WA | F29: 1
F30: 1.2 | H30: =F30*D30 -> 0 | K30: Boats
C31: Boats | F31: 1.2 | H31: =F31*D31 -> 0 | K31: Salmon | L31: Steelhead | M31: Sal/StHd | N31: Other | O31: Rec
H32: =SUM(H28:H31) -> 0 | I32: =H32*I$6*I$5 -> 0 | K32: 0 | L32: 0 | M32: 0 | N32: 0 | O32: 0
A34: Thu | B34: =B28+1 -> 45519 | C34: OR | F34: 1 | K34: 0 | L34: 0 | M34: 0 | N34: 0 | O34: 0
C35: WA | F35: 1
F36: 1.2 | H36: =F36*D36 -> 0 | K36: Boats
C37: Boats | F37: 1.2 | H37: =F37*D37 -> 0 | K37: Salmon | L37: Steelhead | M37: Sal/StHd | N37: Other | O37: Rec
H38: =SUM(H34:H37) -> 0 | I38: =H38*I$6*I$5 -> 0 | K38: 0 | L38: 0 | M38: 0 | N38: 0 | O38: 0
A40: Fri | B40: =B34+1 -> 45520 | C40: OR | F40: 1 | H40: =F40*D40*G40 -> 0
C41: WA | F41: 1 | H41: =F41*D41 -> 0
F42: 1.2 | H42: =F42*D42 -> 0 | K42: Boats
C43: Boats | F43: 1 | G43: 100 | H43: =F43*D43 -> 0 | K43: Salmon | L43: Steelhead | M43: Sal/StHd | N43: Other | O43: Rec
H44: =SUM(H40:H43) -> 0 | I44: =H44*I$6*I$5 -> 0 | K44: =K40/SUM(K40:O40)*I44 -> #DIV/0! | L44: =L40/SUM(K40:O40)*$I44 -> #DIV/0! | M44: =M40/SUM(K40:O40)*$I44 -> #DIV/0! | N44: =N40/SUM(K40:O40)*$I44 -> #DIV/0! | O44: =O40/SUM(K40:O40)*$I44 -> #DIV/0!
A46: Sat | B46: =B40+1 -> 45521 | C46: OR | F46: 1 | H46: =D46*F46*G46 -> 0 | L46: 1
C47: WA | F47: 1 | H47: =D47*F47*G47 -> 0
...

Sheet Boat
K10: Sampled
K11: Steelhead | S11: Coho | W11: Chinook
D12: Sampled | K12: Harvest | O12: Catch & Release | W12: Harvest | AA12: C & R | AC12: White Sturgeon
D13: Target | E13: Boats | F13: Anglers | G13: Pole | H13: Estimated | I13: Sample | K13: AD | M13: Other | O13: AD | Q13: Wild | S13: Harvest | U13: C & R | W13: Adult | Y13: Jack | AD13: Legal | AH13: Walleye | AJ13: Trout | AL13: Bass | AN13: NPM | AP13: Sucker | AR13: C. Catfish | AT13: YP
C14: Date | E14: (#) | F14: (#) | G14: Hours | H14: Total boats | I14: Rate | K14: <78 | L14: ≥78 | M14: <78 | N14: ≥78 | O14: <78 | P14: ≥78 | Q14: <78 | R14: ≥78 | S14: NM | T14: AD | U14: NM | V14: AD | W14: NM | X14: AD | Y14: NM | Z14: AD | AA14: Adult | AB14: Jack | AC14: Sub | AD14: Rel | AE14: Kept | AF14: Over | AG14: Unk | AH14: Kept | AI14: Rel | AJ14: Kept | AK14: Rel | AL14: Kept | AM14: Rel | AN14: Kept | AO14: Rel | AP14: Kept | AQ14: Rel | AR14: Kept | AS14: Rel | AT14: Kept | AU14: Rel
H15: ='Boat Expansion'!I20 -> 0
C18: 45505
C19: =C18+1 -> 45506 | H19: ='Boat Expansion'!I44 -> 0
C20: =C19+1 -> 45507 | H20: ='Boat Expansion'!I50 -> 0
C21: =C20+1 -> 45508
C22: Total | E22: =SUM(E15:E21) -> 0 | F22: =SUM(F15:F21) -> 0 | G22: =SUM(G15:G21) -> 0 | H22: =SUM(H15:H21) -> 0 | I22: =E22/H22 -> #DIV/0! | K22: =SUM(K15:K21) -> 0 | L22: =SUM(L15:L21) -> 0 | M22: =SUM(M15:M21) -> 0 | N22: =SUM(N15:N21) -> 0 | O22: =SUM(O15:O21) -> 0 | P22: =SUM(P15:P21) -> 0 | Q22: =SUM(Q15:Q21) -> 0 | R22: =SUM(R15:R21) -> 0 | ... AO22: =SUM(AO15:AO21) -> 0 | AR22: =SUM(AR15:AR21) -> 0 | AS22: =SUM(AS15:AS21) -> 0 | AT22: =SUM(AT15:AT21) -> 0 | AU22: =SUM(AU15:AU21) -> 0
K23: =K22/$I22 -> #DIV/0! | L23: =L22/$I22 -> #DIV/0! | M23: =M22/$I22 -> #DIV/0! | N23: =N22/$I22 -> #DIV/0! | O23: =O22/$I22 -> #DIV/0! | P23: =P22/$I22 -> #DIV/0! | Q23: =Q22/$I22 -> #DIV/0! | R23: =R22/$I22 -> #DIV/0! | ... AO23: =AO22/$I22 -> #DIV/0! | AR23: =AR22/$I22 -> #DIV/0! | AS23: =AS22/$I22 -> #DIV/0! | AT23: =AT22/$I22 -> #DIV/0! | AU23: =AU22/$I22 -> #DIV/0!
C25: 45509 | H25: ='Boat Expansion'!I56 -> 1.4135
C26: =C25+1 -> 45510
C27: =C26+1 -> 45511
C28: =C27+1 -> 45512 | H28: ='Boat Expansion'!I74 -> 0
C29: =C28+1 -> 45513
C30: =C29+1 -> 45514 | H30: ='Boat Expansion'!I86 -> 0
C31: =C30+1 -> 45515 | H31: 0
C32: Total | E32: =SUM(E25:E31) -> 0 | F32: =SUM(F25:F31) -> 0 | G32: =SUM(G25:G31) -> 0 | H32: =SUM(H25:H31) -> 1.4135 | I32: 0 | K32: =SUM(K25:K31) -> 0 | L32: =SUM(L25:L31) -> 0 | M32: =SUM(M25:M31) -> 0 | N32: =SUM(N25:N31) -> 0 | O32: =SUM(O25:O31) -> 0 | P32: =SUM(P25:P31) -> 0 | Q32: =SUM(Q25:Q31) -> 0 | R32: =SUM(R25:R31) -> 0 | ... AO32: =SUM(AO25:AO31) -> 0 | AR32: =SUM(AR25:AR31) -> 0 | AS32: =SUM(AS25:AS31) -> 0 | AT32: =SUM(AT25:AT31) -> 0 | AU32: =SUM(AU25:AU31) -> 0
K33: 0 | L33: 0 | M33: 0 | N33: 0 | O33: 0 | P33: 0 | Q33: 0 | R33: 0 | S33: 0 | T33: 0 | U33: 0 | V33: 0 | W33: 0 | X33: 0 | Y33: 0 | Z33: 0 | AA33: 0 | AB33: 0 | AC33: 0 | AD33: 0 | AE33: 0 | AF33: 0 | AG33: 0 | AH33: 0 | AI33: 0 | AJ33: 0 | AK33: 0 | AL33: 0 | AM33: 0 | AN33: 0 | AO33: 0 | AP33: 0 | AQ33: 0 | AR33: 0 | AS33: 0 | AT33: 0 | AU33: 0
C35: =C31+1 -> 45516
C36: =C35+1 -> 45517
C37: =C36+1 -> 45518
C38: =C37+1 -> 45519 | H38: ='Boat Expansion'!I116 -> 0
C39: =C38+1 -> 45520
C40: =C39+1 -> 45521 | H40: ='Boat Expansion'!I128 -> 0
C41: =C40+1 -> 45522 | H41: ='Boat Expansion'!I134 -> 0
C42: Total | E42: =SUM(E35:E41) -> 0 | F42: =SUM(F35:F41) -> 0 | G42: =SUM(G35:G41) -> 0 | H42: =SUM(H35:H41) -> 0 | I42: =E42/H42 -> #DIV/0! | K42: =SUM(K35:K41) -> 0 | L42: =SUM(L35:L41) -> 0 | M42: =SUM(M35:M41) -> 0 | N42: =SUM(N35:N41) -> 0 | O42: =SUM(O35:O41) -> 0 | P42: =SUM(P35:P41) -> 0 | Q42: =SUM(Q35:Q41) -> 0 | R42: =SUM(R35:R41) -> 0 | ... AU42: =SUM(AU35:AU41) -> 0
K43: =K42/$I42 -> #DIV/0! | L43: =L42/$I42 -> #DIV/0! | M43: =M42/$I42 -> #DIV/0! | N43: =N42/$I42 -> #DIV/0! | O43: =O42/$I42 -> #DIV/0! | P43: =P42/$I42 -> #DIV/0! | Q43: =Q42/$I42 -> #DIV/0! | R43: =R42/$I42 -> #DIV/0! | ... AU43: =AU42/$I42 -> #DIV/0!
C45: =C41+1 -> 45523
C46: =C45+1 -> 45524
C47: =C46+1 -> 45525
C48: =C47+1 -> 45526
C49: =C48+1 -> 45527
C50: =C49+1 -> 45528
C51: =C50+1 -> 45529
C52: Total | E52: =SUM(E45:E51) -> 0 | F52: =SUM(F45:F51) -> 0 | G52: =SUM(G45:G51) -> 0 | H52: =SUM(H45:H51) -> 0 | I52: =E52/H52 -> #DIV/0! | K52: =SUM(K45:K51) -> 0 | L52: =SUM(L45:L51) -> 0 | M52: =SUM(M45:M51) -> 0 | N52: =SUM(N45:N51) -> 0 | O52: =SUM(O45:O51) -> 0 | P52: =SUM(P45:P51) -> 0 | Q52: =SUM(Q45:Q51) -> 0 | R52: =SUM(R45:R51) -> 0 | ... AU52: =SUM(AU45:AU51) -> 0
K53: =K52/$I52 -> #DIV/0! | L53: =L52/$I52 -> #DIV/0! | M53: =M52/$I52 -> #DIV/0! | N53: =N52/$I52 -> #DIV/0! | O53: =O52/$I52 -> #DIV/0! | P53: =P52/$I52 -> #DIV/0! | Q53: =Q52/$I52 -> #DIV/0! | R53: =R52/$I52 -> #DIV/0! | ... AU53: =AU52/$I52 -> #DIV/0!
C55: =C51+1 -> 45530
...

Sheet Bank
P1: 1 | Q1: 2 | R1: 3 | S1: 4 | T1: 5 | U1: 6 | V1: 7 | W1: 8 | X1: 9 | Y1: 10 | Z1: 11 | AA1: 12 | AB1: 13 | AC1: 14 | AD1: 15 | AE1: 16 | AF1: 17 | AG1: 18 | AH1: 19 | AI1: 20 | AJ1: 21 | AK1: 22 | AL1: 23 | AM1: 24 | AN1: 25 | AO1: 26 | AP1: 27 | BA1: 28 | BB1: 0 | BC1: 0 | BD1: 0 | BE1: 0 | BF1: 0 | BG1: 0 | BH1: 0 | BI1: 0 | BJ1: 0 | BK1: 0 | BL1: 0 | BM1: 0 | BN1: 0 | BO1: 0 | BP1: 0 | BQ1: 0 | BR1: 0 | BS1: 0 | BT1: 0 | BU1: 0 | BV1: 0 | BW1: 0 | BX1: 0 | BY1: 0 | BZ1: 0 | CA1: 0 | CB1: 0 | CC1: 0 | CD1: 0 | CE1: 0 | CF1: 0 | CG1: 0 | CH1: 0 | CI1: 0 | CJ1: 0
B2: Bank Angler Harvest Estimates
BB3: Catch & Harvest | DX3: CPUE
M4: Expansion | N4: 1.1 | P4: Sampled | BB4: CPUE | CN4: CPUE | DX4: CPUE
L5: +2 | P5: Steelhead | AB5: Chinook | AM5: =AM16+AM25+AM34+AM43+AM52+AM61+AM70+AM79+AM88+AM97+AM106+AM115+AM124+AM133+AM142+AM151+AM160+AM169+AM182+AM194+AM204+AM215 -> 0 | AN5: =AN16+AN25+AN34+AN43+AN52+AN61+AN70+AN79+AN88+AN97+AN106+AN115+AN124+AN133+AN142+AN151+AN160+AN169+AN182+AN194+AN204+AN215 -> 0 | AO5: =AO16+AO25+AO34+AO43+AO52+AO61+AO70+AO79+AO88+AO97+AO106+AO115+AO124+AO133+AO142+AO151+AO160+AO169+AO182+AO194+AO204+AO215 -> 0 | AP5: =AP16+AP25+AP34+AP43+AP52+AP61+AP70+AP79+AP88+AP97+AP106+AP115+AP124+AP133+AP142+AP151+AP160+AP169+AP182+AP194+AP204+AP215 -> 0 | AQ5: =AQ16+AQ25+AQ34+AQ43+AQ52+AQ61+AQ70+AQ79+AQ88+AQ97+AQ106+AQ115+AQ124+AQ133+AQ142+AQ151+AQ160+AQ169+AQ182+AQ194+AQ204+AQ215 -> 7 | AR5: =AR16+AR25+AR34+AR43+AR52+AR61+AR70+AR79+AR88+AR97+AR106+AR115+AR124+AR133+AR142+AR151+AR160+AR169+AR182+AR194+AR204+AR215 -> 3 | AS5: =AS16+AS25+AS34+AS43+AS52+AS61+AS70+AS79+AS88+AS97+AS106+AS115+AS124+AS133+AS142+AS151+AS160+AS169+AS182+AS194+AS204+AS215 -> 0 | AT5: =AT16+AT25+AT34+AT43+AT52+AT61+AT70+AT79+AT88+AT97+AT106+AT115+AT124+AT133+AT142+AT151+AT160+AT169+AT182+AT194+AT204+AT215 -> 0 | ... AZ5: =AZ16+AZ25+AZ34+AZ43+AZ52+AZ61+AZ70+AZ79+AZ88+AZ97+AZ106+AZ115+AZ124+AZ133+AZ142+AZ151+AZ160+AZ169+AZ182+AZ194+AZ204+AZ215 -> 13 | BB5: Steelhead | BN5: Chinook | CN5: Steelhead | CZ5: Chinook | DX5: Steelhead | EJ5: Chinook
H6: Effort | P6: Harvest | T6: Catch & Release | X6: Coho | AB6: Harvest | AF6: C & R | AH6: White Sturgeon | BB6: Harvest | BF6: Catch & Release | BJ6: Coho | BN6: Harvest | BR6: C & R | BT6: White Sturgeon | CN6: Harvest | CR6: Catch & Release | CV6: Coho | CZ6: Harvest | DD6: C & R | DF6: White Sturgeon | DX6: Harvest | EB6: Catch & Release | EF6: Coho | EJ6: Harvest | EN6: C & R | EP6: White Sturgeon
C7: Target | D7: Anglers | E7: Pole | F7: % | L7: Day | M7: Pole Hours | P7: AD | R7: Other | T7: AD | V7: Wild | X7: Harvest | Z7: C & R | AB7: Adult | AD7: Jack | AI7: Legal | AM7: NPM | AO7: Trout | AQ7: Bass | AS7: Shad | AU7: C. Catfish | AW7: Sucker | AY7: YP | BB7: AD | BD7: Other | BF7: AD | BH7: Wild | BJ7: Harvest | BL7: C & R | BN7: Adult | BP7: Jack | BU7: Legal | BY7: Walleye | CA7: Shad | CC7: Bass | CE7: NPM | CG7: C. Catfish | CI7: YP | CN7: AD | CP7: Other | CR7: AD | CT7: Wild | CV7: Harvest | CX7: C & R | CZ7: Adult | DB7: Jack | DG7: Legal | DK7: Walleye | DM7: Shad | DO7: Bass | DQ7: NPM | DS7: C. Catfish | DU7: YP | DX7: AD | DZ7: Other | EB7: AD | ED7: Wild | EF7: Harvest | EH7: C & R | EJ7: Adult | EL7: Jack | EQ7: Legal | EU7: Walleye | EW7: Shad | EY7: Bass | FA7: NPM | FC7: C. Catfish | FE7: YP
B8: Date | D8: (#) | E8: Hours | F8: Sampled | H8: Count | I8: Index | J8: % Sal | K8: %Oth | L8: Light | M8: Other | N8: Salmon | P8: <78 | Q8: ≥78 | R8: <78 | S8: ≥78 | T8: <78 | U8: ≥78 | V8: <78 | W8: ≥78 | X8: NM | Y8: AD | Z8: NM | AA8: AD | AB8: NM | AC8: AD | AD8: NM | AE8: AD | AF8: Adult | AG8: Jack | AH8: Sub | AI8: Rel | AJ8: Kept | AK8: Over | AL8: Unk | AM8: Kept | AN8: Rel | AO8: Kept | AP8: Rel | AQ8: Kept | AR8: Rel | AS8: Kept | AT8: Rel | AU8: Kept | AV8: Rel | AW8: Kept | AX8: Rel | AY8: Kept | AZ8: Rel | BB8: <79 | BC8: >78 | BD8: <79 | BE8: >78 | BF8: <79 | BG8: >78 | BH8: <79 | BI8: >78 | BJ8: NM | BK8: AD | BL8: NM | BM8: AD | BN8: NM | BO8: AD | BP8: NM | BQ8: AD | BR8: Adult | BS8: Jack | BT8: Sub | BU8: Rel | BV8: Kept | BW8: Over | BX8: Unk | BY8: Kept | BZ8: Rel | CA8: Kept | CB8: Rel | CC8: Kept | CD8: Rel | CE8: Kept | CF8: Rel | CG8: Kept | CH8: Rel | CI8: Kept | CJ8: Rel | CL8: Days | CN8: <79 | CO8: >78 | CP8: <79 | CQ8: >78 | CR8: <79 | CS8: >78 | CT8: <79 | CU8: >78 | CV8: NM | CW8: AD | CX8: NM | CY8: AD | CZ8: NM | DA8: AD | DB8: NM | DC8: AD | DD8: Adult | DE8: Jack | DF8: Sub | DG8: Rel | DH8: Kept | DI8: Over | DJ8: Unk | DK8: Kept | DL8: Rel | DM8: Kept | DN8: Rel | DO8: Kept | DP8: Rel | DQ8: Kept | DR8: Rel | DS8: Kept | DT8: Rel | DU8: Kept | DV8: Rel | DX8: <79 | DY8: >78 | DZ8: <79 | EA8: >78 | EB8: <79 | EC8: >78 | ED8: <79 | EE8: >78 | EF8: NM | EG8: AD | EH8: NM | EI8: AD | EJ8: NM | EK8: AD | EL8: NM | EM8: AD | EN8: Adult | EO8: Jack | EP8: Sub | EQ8: Rel | ER8: Kept | ES8: Over | ET8: Unk | EU8: Kept | EV8: Rel | EW8: Kept | EX8: Rel | EY8: Kept | EZ8: Rel | FA8: Kept | FB8: Rel | FC8: Kept | FD8: Rel | FE8: Kept | FF8: Rel
L9: 16 | M9: =H9/I9*K9*L9*1.5 -> #DIV/0! | N9: =H9/I9*J9*L9*N$4 -> #DIV/0! | BB9: =$N9*DX9 -> #DIV/0! | BC9: =$N9*DY9 -> #DIV/0! | BD9: =$N9*DZ9 -> #DIV/0! | BE9: =$N9*EA9 -> #DIV/0! | BF9: =$N9*EB9 -> #DIV/0! | BG9: =$N9*EC9 -> #DIV/0! | BH9: =$N9*ED9 -> #DIV/0! | BI9: =$N9*EE9 -> #DIV/0! | ... CJ9: =$N9*FF9 -> #DIV/0! | CL9: 5 | CN9: =AVERAGE(BB9:BB13)*$CL9 -> #DIV/0! | CO9: =AVERAGE(BC9:BC13)*$CL9 -> #DIV/0! | CP9: =AVERAGE(BD9:BD13)*$CL9 -> #DIV/0! | CQ9: =AVERAGE(BE9:BE13)*$CL9 -> #DIV/0! | CR9: =AVERAGE(BF9:BF13)*$CL9 -> #DIV/0! | CS9: =AVERAGE(BG9:BG13)*$CL9 -> #DIV/0! | CT9: =AVERAGE(BH9:BH13)*$CL9 -> #DIV/0! | CU9: =AVERAGE(BI9:BI13)*$CL9 -> #DIV/0! | ... DV9: =AVERAGE(CJ9:CJ13)*$CL9 -> #DIV/0! | DX9: =P9/$E9 -> #DIV/0! | DY9: =Q9/$E9 -> #DIV/0! | DZ9: =R9/$E9 -> #DIV/0! | EA9: =S9/$E9 -> #DIV/0! | EB9: =T9/$E9 -> #DIV/0! | EC9: =U9/$E9 -> #DIV/0! | ED9: =V9/$E9 -> #DIV/0! | EE9: =W9/$E9 -> #DIV/0! | ... FD9: =AV9/$E9 -> #DIV/0! | FE9: =AY9/$E9 -> #DIV/0! | FF9: =AZ9/$E9 -> #DIV/0!
M10: =H10/I10*K10*L10*1.5 -> #DIV/0! | N10: =H10/I10*J10*L10*N$4 -> #DIV/0! | BB10: =$N10*DX10 -> #DIV/0! | BC10: =$N10*DY10 -> #DIV/0! | BD10: =$N10*DZ10 -> #DIV/0! | BE10: =$N10*EA10 -> #DIV/0! | BF10: =$N10*EB10 -> #DIV/0! | BG10: =$N10*EC10 -> #DIV/0! | BH10: =$N10*ED10 -> #DIV/0! | BI10: =$N10*EE10 -> #DIV/0! | ... CJ10: =$N10*FF10 -> #DIV/0! | DX10: =P10/$E10 -> #DIV/0! | DY10: =Q10/$E10 -> #DIV/0! | DZ10: =R10/$E10 -> #DIV/0! | EA10: =S10/$E10 -> #DIV/0! | EB10: =T10/$E10 -> #DIV/0! | EC10: =U10/$E10 -> #DIV/0! | ED10: =V10/$E10 -> #DIV/0! | EE10: =W10/$E10 -> #DIV/0! | ... FD10: =AV10/$E10 -> #DIV/0! | FE10: =AY10/$E10 -> #DIV/0! | FF10: =AZ10/$E10 -> #DIV/0!
M11: =H11/I11*K11*L11*1.5 -> #DIV/0! | N11: =H11/I11*J11*L11*N$4 -> #DIV/0! | BB11: =$N11*DX11 -> #DIV/0! | BC11: =$N11*DY11 -> #DIV/0! | BD11: =$N11*DZ11 -> #DIV/0! | BE11: =$N11*EA11 -> #DIV/0! | BF11: =$N11*EB11 -> #DIV/0! | BG11: =$N11*EC11 -> #DIV/0! | BH11: =$N11*ED11 -> #DIV/0! | BI11: =$N11*EE11 -> #DIV/0! | ... CJ11: =$N11*FF11 -> #DIV/0! | DX11: =P11/$E11 -> #DIV/0! | DY11: =Q11/$E11 -> #DIV/0! | DZ11: =R11/$E11 -> #DIV/0! | EA11: =S11/$E11 -> #DIV/0! | EB11: =T11/$E11 -> #DIV/0! | EC11: =U11/$E11 -> #DIV/0! | ED11: =V11/$E11 -> #DIV/0! | EE11: =W11/$E11 -> #DIV/0! | ... FD11: =AV11/$E11 -> #DIV/0! | FE11: =AY11/$E11 -> #DIV/0! | FF11: =AZ11/$E11 -> #DIV/0!
B12: 45505 | M12: =H12/I12*K12*L12*1.5 -> #DIV/0! | N12: =H12/I12*J12*L12*N$4 -> #DIV/0! | BB12: =$N12*DX12 -> #DIV/0! | BC12: =$N12*DY12 -> #DIV/0! | BD12: =$N12*DZ12 -> #DIV/0! | BE12: =$N12*EA12 -> #DIV/0! | BF12: =$N12*EB12 -> #DIV/0! | BG12: =$N12*EC12 -> #DIV/0! | BH12: =$N12*ED12 -> #DIV/0! | BI12: =$N12*EE12 -> #DIV/0! | ... CJ12: =$N12*FF12 -> #DIV/0! | DX12: =P12/$E12 -> #DIV/0! | DY12: =Q12/$E12 -> #DIV/0! | DZ12: =R12/$E12 -> #DIV/0! | EA12: =S12/$E12 -> #DIV/0! | EB12: =T12/$E12 -> #DIV/0! | EC12: =U12/$E12 -> #DIV/0! | ED12: =V12/$E12 -> #DIV/0! | EE12: =W12/$E12 -> #DIV/0! | ... FD12: =AV12/$E12 -> #DIV/0! | FE12: =AY12/$E12 -> #DIV/0! | FF12: =AZ12/$E12 -> #DIV/0!
B13: =B12+1 -> 45506 | L13: 15.8 | M13: =H13/I13*K13*L13*1.5 -> #DIV/0! | N13: =H13/I13*J13*L13*N$4 -> #DIV/0! | BB13: =$N13*DX13 -> #DIV/0! | BC13: =$N13*DY13 -> #DIV/0! | BD13: =$N13*DZ13 -> #DIV/0! | BE13: =$N13*EA13 -> #DIV/0! | BF13: =$N13*EB13 -> #DIV/0! | BG13: =$N13*EC13 -> #DIV/0! | BH13: =$N13*ED13 -> #DIV/0! | BI13: =$N13*EE13 -> #DIV/0! | ... CJ13: =$N13*FF13 -> #DIV/0! | DX13: =P13/$E13 -> #DIV/0! | DY13: =Q13/$E13 -> #DIV/0! | DZ13: =R13/$E13 -> #DIV/0! | EA13: =S13/$E13 -> #DIV/0! | EB13: =T13/$E13 -> #DIV/0! | EC13: =U13/$E13 -> #DIV/0! | ED13: =V13/$E13 -> #DIV/0! | EE13: =W13/$E13 -> #DIV/0! | ... FD13: =AV13/$E13 -> #DIV/0! | FE13: =AY13/$E13 -> #DIV/0! | FF13: =AZ13/$E13 -> #DIV/0!
B14: =B13+1 -> 45507 | L14: 15.7 | M14: =H14/I14*K14*L14*1.5 -> #DIV/0! | N14: =H14/I14*J14*L14*N$4 -> #DIV/0! | BB14: =$N14*DX14 -> #DIV/0! | BC14: =$N14*DY14 -> #DIV/0! | BD14: =$N14*DZ14 -> #DIV/0! | BE14: =$N14*EA14 -> #DIV/0! | BF14: =$N14*EB14 -> #DIV/0! | BG14: =$N14*EC14 -> #DIV/0! | BH14: =$N14*ED14 -> #DIV/0! | BI14: =$N14*EE14 -> #DIV/0! | ... CJ14: =$N14*FF14 -> #DIV/0! | CL14: 2 | CN14: =AVERAGE(BB14:BB15)*$CL14 -> #DIV/0! | CO14: =AVERAGE(BC14:BC15)*$CL14 -> #DIV/0! | CP14: =AVERAGE(BD14:BD15)*$CL14 -> #DIV/0! | CQ14: =AVERAGE(BE14:BE15)*$CL14 -> #DIV/0! | CR14: =AVERAGE(BF14:BF15)*$CL14 -> #DIV/0! | CS14: =AVERAGE(BG14:BG15)*$CL14 -> #DIV/0! | CT14: =AVERAGE(BH14:BH15)*$CL14 -> #DIV/0! | CU14: =AVERAGE(BI14:BI15)*$CL14 -> #DIV/0! | ... DV14: =AVERAGE(CJ14:CJ15)*$CL14 -> #DIV/0! | DX14: =P14/$E14 -> #DIV/0! | DY14: =Q14/$E14 -> #DIV/0! | DZ14: =R14/$E14 -> #DIV/0! | EA14: =S14/$E14 -> #DIV/0! | EB14: =T14/$E14 -> #DIV/0! | EC14: =U14/$E14 -> #DIV/0! | ED14: =V14/$E14 -> #DIV/0! | EE14: =W14/$E14 -> #DIV/0! | ... FD14: =AV14/$E14 -> #DIV/0! | FE14: =AY14/$E14 -> #DIV/0! | FF14: =AZ14/$E14 -> #DIV/0!
B15: =B14+1 -> 45508 | M15: =H15/I15*K15*L15*1.5 -> #DIV/0! | N15: =H15/I15*J15*L15*N$4 -> #DIV/0! | BB15: =$N15*DX15 -> #DIV/0! | BC15: =$N15*DY15 -> #DIV/0! | BD15: =$N15*DZ15 -> #DIV/0! | BE15: =$N15*EA15 -> #DIV/0! | BF15: =$N15*EB15 -> #DIV/0! | BG15: =$N15*EC15 -> #DIV/0! | BH15: =$N15*ED15 -> #DIV/0! | BI15: =$N15*EE15 -> #DIV/0! | ... CJ15: =$N15*FF15 -> #DIV/0! | DX15: =P15/$E15 -> #DIV/0! | DY15: =Q15/$E15 -> #DIV/0! | DZ15: =R15/$E15 -> #DIV/0! | EA15: =S15/$E15 -> #DIV/0! | EB15: =T15/$E15 -> #DIV/0! | EC15: =U15/$E15 -> #DIV/0! | ED15: =V15/$E15 -> #DIV/0! | EE15: =W15/$E15 -> #DIV/0! | ... FD15: =AV15/$E15 -> #DIV/0! | FE15: =AY15/$E15 -> #DIV/0! | FF15: =AZ15/$E15 -> #DIV/0!
B16: Total | D16: =SUM(D9:D15) -> 0 | E16: =SUM(E9:E15) -> 0 | N16: =AVERAGE(N9:N13)*5+AVERAGE(N14:N15)*2 -> #DIV/0! | P16: =SUM(P9:P15) -> 0 | Q16: =SUM(Q9:Q15) -> 0 | R16: =SUM(R9:R15) -> 0 | S16: =SUM(S9:S15) -> 0 | T16: =SUM(T9:T15) -> 0 | U16: =SUM(U9:U15) -> 0 | V16: =SUM(V9:V15) -> 0 | W16: =SUM(W9:W15) -> 0 | ... AZ16: =SUM(AZ9:AZ15) -> 0 | BB16: =SUM(BB9:BB15) -> #DIV/0! | BC16: =SUM(BC9:BC15) -> #DIV/0! | BD16: =SUM(BD9:BD15) -> #DIV/0! | BE16: =SUM(BE9:BE15) -> #DIV/0! | BF16: =SUM(BF9:BF15) -> #DIV/0! | BG16: =SUM(BG9:BG15) -> #DIV/0! | BH16: =SUM(BH9:BH15) -> #DIV/0! | BI16: =SUM(BI9:BI15) -> #DIV/0! | ... CJ16: =SUM(CJ9:CJ15) -> #DIV/0! | CN16: =SUM(CN9:CN15) -> #DIV/0! | CO16: =SUM(CO9:CO15) -> #DIV/0! | CP16: =SUM(CP9:CP15) -> #DIV/0! | CQ16: =SUM(CQ9:CQ15) -> #DIV/0! | CR16: =SUM(CR9:CR15) -> #DIV/0! | CS16: =SUM(CS9:CS15) -> #DIV/0! | CT16: =SUM(CT9:CT15) -> #DIV/0! | CU16: =SUM(CU9:CU15) -> #DIV/0! | ... DV16: =SUM(DV9:DV15) -> #DIV/0! | DX16: =AVERAGE(DX9:DX15) -> #DIV/0! | DY16: =AVERAGE(DY9:DY15) -> #DIV/0! | DZ16: =AVERAGE(DZ9:DZ15) -> #DIV/0! | EA16: =AVERAGE(EA9:EA15) -> #DIV/0! | EB16: =AVERAGE(EB9:EB15) -> #DIV/0! | EC16: =AVERAGE(EC9:EC15) -> #DIV/0! | ED16: =AVERAGE(ED9:ED15) -> #DIV/0! | EE16: =AVERAGE(EE9:EE15) -> #DIV/0! | ... FF16: =AVERAGE(FF9:FF15) -> #DIV/0!
L17: +2
B18: 45509 | L18: 16.7 | M18: =H18/I18*K18*L18*1.5 -> #DIV/0! | N18: =H18/I18*J18*L18*N$4 -> #DIV/0! | BB18: =$N18*DX18 -> #DIV/0! | BC18: =$N18*DY18 -> #DIV/0! | BD18: =$N18*DZ18 -> #DIV/0! | BE18: =$N18*EA18 -> #DIV/0! | BF18: =$N18*EB18 -> #DIV/0! | BG18: =$N18*EC18 -> #DIV/0! | BH18: =$N18*ED18 -> #DIV/0! | BI18: =$N18*EE18 -> #DIV/0! | ... CJ18: =$N18*FF18 -> #DIV/0! | CL18: 5 | CN18: =AVERAGE(BB18:BB22)*$CL18 -> #DIV/0! | CO18: =AVERAGE(BC18:BC22)*$CL18 -> #DIV/0! | CP18: =AVERAGE(BD18:BD22)*$CL18 -> #DIV/0! | CQ18: =AVERAGE(BE18:BE22)*$CL18 -> #DIV/0! | CR18: =AVERAGE(BF18:BF22)*$CL18 -> #DIV/0! | CS18: =AVERAGE(BG18:BG22)*$CL18 -> #DIV/0! | CT18: =AVERAGE(BH18:BH22)*$CL18 -> #DIV/0! | CU18: =AVERAGE(BI18:BI22)*$CL18 -> #DIV/0! | ... DV18: =AVERAGE(CJ18:CJ22)*$CL18 -> #DIV/0! | DX18: =P18/$E18 -> #DIV/0! | DY18: =Q18/$E18 -> #DIV/0! | DZ18: =R18/$E18 -> #DIV/0! | EA18: =S18/$E18 -> #DIV/0! | EB18: =T18/$E18 -> #DIV/0! | EC18: =U18/$E18 -> #DIV/0! | ED18: =V18/$E18 -> #DIV/0! | EE18: =W18/$E18 -> #DIV/0! | ... FD18: =AV18/$E18 -> #DIV/0! | FE18: =AY18/$E18 -> #DIV/0! | FF18: =AZ18/$E18 -> #DIV/0!
B19: =B18+1 -> 45510 | M19: =H19/I19*K19*L19*1.5 -> #DIV/0! | N19: =H19/I19*J19*L19*N$4 -> #DIV/0! | BB19: =$N19*DX19 -> #DIV/0! | BC19: =$N19*DY19 -> #DIV/0! | BD19: =$N19*DZ19 -> #DIV/0! | BE19: =$N19*EA19 -> #DIV/0! | BF19: =$N19*EB19 -> #DIV/0! | BG19: =$N19*EC19 -> #DIV/0! | BH19: =$N19*ED19 -> #DIV/0! | BI19: =$N19*EE19 -> #DIV/0! | ... CJ19: =$N19*FF19 -> #DIV/0! | DX19: =P19/$E19 -> #DIV/0! | DY19: =Q19/$E19 -> #DIV/0! | DZ19: =R19/$E19 -> #DIV/0! | EA19: =S19/$E19 -> #DIV/0! | EB19: =T19/$E19 -> #DIV/0! | EC19: =U19/$E19 -> #DIV/0! | ED19: =V19/$E19 -> #DIV/0! | EE19: =W19/$E19 -> #DIV/0! | ... FD19: =AV19/$E19 -> #DIV/0! | FE19: =AY19/$E19 -> #DIV/0! | FF19: =AZ19/$E19 -> #DIV/0!
B20: =B19+1 -> 45511 | M20: =H20/I20*K20*L20*1.5 -> #DIV/0! | N20: =H20/I20*J20*L20*N$4 -> #DIV/0! | BB20: =$N20*DX20 -> #DIV/0! | BC20: =$N20*DY20 -> #DIV/0! | BD20: =$N20*DZ20 -> #DIV/0! | BE20: =$N20*EA20 -> #DIV/0! | BF20: =$N20*EB20 -> #DIV/0! | BG20: =$N20*EC20 -> #DIV/0! | BH20: =$N20*ED20 -> #DIV/0! | BI20: =$N20*EE20 -> #DIV/0! | ... CJ20: =$N20*FF20 -> #DIV/0! | DX20: =P20/$E20 -> #DIV/0! | DY20: =Q20/$E20 -> #DIV/0! | DZ20: =R20/$E20 -> #DIV/0! | EA20: =S20/$E20 -> #DIV/0! | EB20: =T20/$E20 -> #DIV/0! | EC20: =U20/$E20 -> #DIV/0! | ED20: =V20/$E20 -> #DIV/0! | EE20: =W20/$E20 -> #DIV/0! | ... FD20: =AV20/$E20 -> #DIV/0! | FE20: =AY20/$E20 -> #DIV/0! | FF20: =AZ20/$E20 -> #DIV/0!
B21: =B20+1 -> 45512 | L21: 16.5 | M21: =H21/I21*K21*L21*1.5 -> #DIV/0! | N21: =H21/I21*J21*L21*N$4 -> #DIV/0! | BB21: =$N21*DX21 -> #DIV/0! | BC21: =$N21*DY21 -> #DIV/0! | BD21: =$N21*DZ21 -> #DIV/0! | BE21: =$N21*EA21 -> #DIV/0! | BF21: =$N21*EB21 -> #DIV/0! | BG21: =$N21*EC21 -> #DIV/0! | BH21: =$N21*ED21 -> #DIV/0! | BI21: =$N21*EE21 -> #DIV/0! | ... CJ21: =$N21*FF21 -> #DIV/0! | DX21: =P21/$E21 -> #DIV/0! | DY21: =Q21/$E21 -> #DIV/0! | DZ21: =R21/$E21 -> #DIV/0! | EA21: =S21/$E21 -> #DIV/0! | EB21: =T21/$E21 -> #DIV/0! | EC21: =U21/$E21 -> #DIV/0! | ED21: =V21/$E21 -> #DIV/0! | EE21: =W21/$E21 -> #DIV/0! | ... FD21: =AV21/$E21 -> #DIV/0! | FE21: =AY21/$E21 -> #DIV/0! | FF21: =AZ21/$E21 -> #DIV/0!
B22: =B21+1 -> 45513 | M22: =H22/I22*K22*L22*1.5 -> #DIV/0! | N22: =H22/I22*J22*L22*N$4 -> #DIV/0! | BB22: =$N22*DX22 -> #DIV/0! | BC22: =$N22*DY22 -> #DIV/0! | BD22: =$N22*DZ22 -> #DIV/0! | BE22: =$N22*EA22 -> #DIV/0! | BF22: =$N22*EB22 -> #DIV/0! | BG22: =$N22*EC22 -> #DIV/0! | BH22: =$N22*ED22 -> #DIV/0! | BI22: =$N22*EE22 -> #DIV/0! | ... CJ22: =$N22*FF22 -> #DIV/0! | DX22: =P22/$E22 -> #DIV/0! | DY22: =Q22/$E22 -> #DIV/0! | DZ22: =R22/$E22 -> #DIV/0! | EA22: =S22/$E22 -> #DIV/0! | EB22: =T22/$E22 -> #DIV/0! | EC22: =U22/$E22 -> #DIV/0! | ED22: =V22/$E22 -> #DIV/0! | EE22: =W22/$E22 -> #DIV/0! | ... FD22: =AV22/$E22 -> #DIV/0! | FE22: =AY22/$E22 -> #DIV/0! | FF22: =AZ22/$E22 -> #DIV/0!
B23: =B22+1 -> 45514 | L23: 16.4 | M23: =H23/I23*K23*L23*1.5 -> #DIV/0! | N23: =H23/I23*J23*L23*N$4 -> #DIV/0! | BB23: =$N23*DX23 -> #DIV/0! | BC23: =$N23*DY23 -> #DIV/0! | BD23: =$N23*DZ23 -> #DIV/0! | BE23: =$N23*EA23 -> #DIV/0! | BF23: =$N23*EB23 -> #DIV/0! | BG23: =$N23*EC23 -> #DIV/0! | BH23: =$N23*ED23 -> #DIV/0! | BI23: =$N23*EE23 -> #DIV/0! | ... CJ23: =$N23*FF23 -> #DIV/0! | CL23: 2 | CN23: =AVERAGE(BB23:BB24)*$CL23 -> #DIV/0! | CO23: =AVERAGE(BC23:BC24)*$CL23 -> #DIV/0! | CP23: =AVERAGE(BD23:BD24)*$CL23 -> #DIV/0! | CQ23: =AVERAGE(BE23:BE24)*$CL23 -> #DIV/0! | CR23: =AVERAGE(BF23:BF24)*$CL23 -> #DIV/0! | CS23: =AVERAGE(BG23:BG24)*$CL23 -> #DIV/0! | CT23: =AVERAGE(BH23:BH24)*$CL23 -> #DIV/0! | CU23: =AVERAGE(BI23:BI24)*$CL23 -> #DIV/0! | ... DV23: =AVERAGE(CJ23:CJ24)*$CL23 -> #DIV/0! | DX23: =P23/$E23 -> #DIV/0! | DY23: =Q23/$E23 -> #DIV/0! | DZ23: =R23/$E23 -> #DIV/0! | EA23: =S23/$E23 -> #DIV/0! | EB23: =T23/$E23 -> #DIV/0! | EC23: =U23/$E23 -> #DIV/0! | ED23: =V23/$E23 -> #DIV/0! | EE23: =W23/$E23 -> #DIV/0! | ... FD23: =AV23/$E23 -> #DIV/0! | FE23: =AY23/$E23 -> #DIV/0! | FF23: =AZ23/$E23 -> #DIV/0!
B24: =B23+1 -> 45515 | L24: 16.4 | M24: =H24/I24*K24*L24*1.5 -> #DIV/0! | N24: =H24/I24*J24*L24*N$4 -> #DIV/0! | BB24: =$N24*DX24 -> #DIV/0! | BC24: =$N24*DY24 -> #DIV/0! | BD24: =$N24*DZ24 -> #DIV/0! | BE24: =$N24*EA24 -> #DIV/0! | BF24: =$N24*EB24 -> #DIV/0! | BG24: =$N24*EC24 -> #DIV/0! | BH24: =$N24*ED24 -> #DIV/0! | BI24: =$N24*EE24 -> #DIV/0! | ... CJ24: =$N24*FF24 -> #DIV/0! | DX24: =P24/$E24 -> #DIV/0! | DY24: =Q24/$E24 -> #DIV/0! | DZ24: =R24/$E24 -> #DIV/0! | EA24: =S24/$E24 -> #DIV/0! | EB24: =T24/$E24 -> #DIV/0! | EC24: =U24/$E24 -> #DIV/0! | ED24: =V24/$E24 -> #DIV/0! | EE24: =W24/$E24 -> #DIV/0! | ... FD24: =AV24/$E24 -> #DIV/0! | FE24: =AY24/$E24 -> #DIV/0! | FF24: =AZ24/$E24 -> #DIV/0!
D25: =SUM(D18:D24) -> 0 | E25: =SUM(E18:E24) -> 0 | N25: =AVERAGE(N18:N22)*5+AVERAGE(N23:N24)*2 -> #DIV/0! | P25: =SUM(P18:P24) -> 0 | Q25: =SUM(Q18:Q24) -> 0 | R25: =SUM(R18:R24) -> 0 | S25: =SUM(S18:S24) -> 0 | T25: =SUM(T18:T24) -> 0 | U25: =SUM(U18:U24) -> 0 | V25: =SUM(V18:V24) -> 0 | W25: =SUM(W18:W24) -> 0 | ... AZ25: =SUM(AZ18:AZ24) -> 0 | BB25: =SUM(BB18:BB24) -> #DIV/0! | BC25: =SUM(BC18:BC24) -> #DIV/0! | BD25: =SUM(BD18:BD24) -> #DIV/0! | BE25: =SUM(BE18:BE24) -> #DIV/0! | BF25: =SUM(BF18:BF24) -> #DIV/0! | BG25: =SUM(BG18:BG24) -> #DIV/0! | BH25: =SUM(BH18:BH24) -> #DIV/0! | BI25: =SUM(BI18:BI24) -> #DIV/0! | ... CJ25: =SUM(CJ18:CJ24) -> #DIV/0! | CN25: =SUM(CN18:CN24) -> #DIV/0! | CO25: =SUM(CO18:CO24) -> #DIV/0! | CP25: =SUM(CP18:CP24) -> #DIV/0! | CQ25: =SUM(CQ18:CQ24) -> #DIV/0! | CR25: =SUM(CR18:CR24) -> #DIV/0! | CS25: =SUM(CS18:CS24) -> #DIV/0! | CT25: =SUM(CT18:CT24) -> #DIV/0! | CU25: =SUM(CU18:CU24) -> #DIV/0! | ... DV25: =SUM(DV18:DV24) -> #DIV/0! | DX25: =AVERAGE(DX18:DX24) -> #DIV/0! | DY25: =AVERAGE(DY18:DY24) -> #DIV/0! | DZ25: =AVERAGE(DZ18:DZ24) -> #DIV/0! | EA25: =AVERAGE(EA18:EA24) -> #DIV/0! | EB25: =AVERAGE(EB18:EB24) -> #DIV/0! | EC25: =AVERAGE(EC18:EC24) -> #DIV/0! | ED25: =AVERAGE(ED18:ED24) -> #DIV/0! | EE25: =AVERAGE(EE18:EE24) -> #DIV/0! | ... FF25: =AVERAGE(FF18:FF24) -> #DIV/0!
L26: +2
B27: =B18+7 -> 45516 | M27: =H27/I27*K27*L27*1.5 -> #DIV/0! | N27: =H27/I27*J27*L27*N$4 -> #DIV/0! | BB27: =$N27*DX27 -> #DIV/0! | BC27: =$N27*DY27 -> #DIV/0! | BD27: =$N27*DZ27 -> #DIV/0! | BE27: =$N27*EA27 -> #DIV/0! | BF27: =$N27*EB27 -> #DIV/0! | BG27: =$N27*EC27 -> #DIV/0! | BH27: =$N27*ED27 -> #DIV/0! | BI27: =$N27*EE27 -> #DIV/0! | ... CJ27: =$N27*FF27 -> #DIV/0! | CL27: 5 | CN27: =AVERAGE(BB27:BB31)*$CL27 -> #DIV/0! | CO27: =AVERAGE(BC27:BC31)*$CL27 -> #DIV/0! | CP27: =AVERAGE(BD27:BD31)*$CL27 -> #DIV/0! | CQ27: =AVERAGE(BE27:BE31)*$CL27 -> #DIV/0! | CR27: =AVERAGE(BF27:BF31)*$CL27 -> #DIV/0! | CS27: =AVERAGE(BG27:BG31)*$CL27 -> #DIV/0! | CT27: =AVERAGE(BH27:BH31)*$CL27 -> #DIV/0! | CU27: =AVERAGE(BI27:BI31)*$CL27 -> #DIV/0! | ... DV27: =AVERAGE(CJ27:CJ31)*$CL27 -> #DIV/0! | DX27: =P27/$E27 -> #DIV/0! | DY27: =Q27/$E27 -> #DIV/0! | DZ27: =R27/$E27 -> #DIV/0! | EA27: =S27/$E27 -> #DIV/0! | EB27: =T27/$E27 -> #DIV/0! | EC27: =U27/$E27 -> #DIV/0! | ED27: =V27/$E27 -> #DIV/0! | EE27: =W27/$E27 -> #DIV/0! | ... FD27: =AV27/$E27 -> #DIV/0! | FE27: =AY27/$E27 -> #DIV/0! | FF27: =AZ27/$E27 -> #DIV/0!
B28: =B27+1 -> 45517 | M28: =H28/I28*K28*L28*1.5 -> #DIV/0! | N28: =H28/I28*J28*L28*N$4 -> #DIV/0! | BB28: =$N28*DX28 -> #DIV/0! | BC28: =$N28*DY28 -> #DIV/0! | BD28: =$N28*DZ28 -> #DIV/0! | BE28: =$N28*EA28 -> #DIV/0! | BF28: =$N28*EB28 -> #DIV/0! | BG28: =$N28*EC28 -> #DIV/0! | BH28: =$N28*ED28 -> #DIV/0! | BI28: =$N28*EE28 -> #DIV/0! | ... CJ28: =$N28*FF28 -> #DIV/0! | DX28: =P28/$E28 -> #DIV/0! | DY28: =Q28/$E28 -> #DIV/0! | DZ28: =R28/$E28 -> #DIV/0! | EA28: =S28/$E28 -> #DIV/0! | EB28: =T28/$E28 -> #DIV/0! | EC28: =U28/$E28 -> #DIV/0! | ED28: =V28/$E28 -> #DIV/0! | EE28: =W28/$E28 -> #DIV/0! | ... FD28: =AV28/$E28 -> #DIV/0! | FE28: =AY28/$E28 -> #DIV/0! | FF28: =AZ28/$E28 -> #DIV/0!
B29: =B28+1 -> 45518 | M29: =H29/I29*K29*L29*1.5 -> #DIV/0! | N29: =H29/I29*J29*L29*N$4 -> #DIV/0! | BB29: =$N29*DX29 -> #DIV/0! | BC29: =$N29*DY29 -> #DIV/0! | BD29: =$N29*DZ29 -> #DIV/0! | BE29: =$N29*EA29 -> #DIV/0! | BF29: =$N29*EB29 -> #DIV/0! | BG29: =$N29*EC29 -> #DIV/0! | BH29: =$N29*ED29 -> #DIV/0! | BI29: =$N29*EE29 -> #DIV/0! | ... CJ29: =$N29*FF29 -> #DIV/0! | DX29: =P29/$E29 -> #DIV/0! | DY29: =Q29/$E29 -> #DIV/0! | DZ29: =R29/$E29 -> #DIV/0! | EA29: =S29/$E29 -> #DIV/0! | EB29: =T29/$E29 -> #DIV/0! | EC29: =U29/$E29 -> #DIV/0! | ED29: =V29/$E29 -> #DIV/0! | EE29: =W29/$E29 -> #DIV/0! | ... FD29: =AV29/$E29 -> #DIV/0! | FE29: =AY29/$E29 -> #DIV/0! | FF29: =AZ29/$E29 -> #DIV/0!
B30: =B29+1 -> 45519 | L30: 16.2 | M30: =H30/I30*K30*L30*1.5 -> #DIV/0! | N30: =H30/I30*J30*L30*N$4 -> #DIV/0! | BB30: =$N30*DX30 -> #DIV/0! | BC30: =$N30*DY30 -> #DIV/0! | BD30: =$N30*DZ30 -> #DIV/0! | BE30: =$N30*EA30 -> #DIV/0! | BF30: =$N30*EB30 -> #DIV/0! | BG30: =$N30*EC30 -> #DIV/0! | BH30: =$N30*ED30 -> #DIV/0! | BI30: =$N30*EE30 -> #DIV/0! | ... CJ30: =$N30*FF30 -> #DIV/0! | DX30: =P30/$E30 -> #DIV/0! | DY30: =Q30/$E30 -> #DIV/0! | DZ30: =R30/$E30 -> #DIV/0! | EA30: =S30/$E30 -> #DIV/0! | EB30: =T30/$E30 -> #DIV/0! | EC30: =U30/$E30 -> #DIV/0! | ED30: =V30/$E30 -> #DIV/0! | EE30: =W30/$E30 -> #DIV/0! | ... FD30: =AV30/$E30 -> #DIV/0! | FE30: =AY30/$E30 -> #DIV/0! | FF30: =AZ30/$E30 -> #DIV/0!
B31: =B30+1 -> 45520 | M31: =H31/I31*K31*L31*1.5 -> #DIV/0! | N31: =H31/I31*J31*L31*N$4 -> #DIV/0! | BB31: =$N31*DX31 -> #DIV/0! | BC31: =$N31*DY31 -> #DIV/0! | BD31: =$N31*DZ31 -> #DIV/0! | BE31: =$N31*EA31 -> #DIV/0! | BF31: =$N31*EB31 -> #DIV/0! | BG31: =$N31*EC31 -> #DIV/0! | BH31: =$N31*ED31 -> #DIV/0! | BI31: =$N31*EE31 -> #DIV/0! | ... CJ31: =$N31*FF31 -> #DIV/0! | DX31: =P31/$E31 -> #DIV/0! | DY31: =Q31/$E31 -> #DIV/0! | DZ31: =R31/$E31 -> #DIV/0! | EA31: =S31/$E31 -> #DIV/0! | EB31: =T31/$E31 -> #DIV/0! | EC31: =U31/$E31 -> #DIV/0! | ED31: =V31/$E31 -> #DIV/0! | EE31: =W31/$E31 -> #DIV/0! | ... FD31: =AV31/$E31 -> #DIV/0! | FE31: =AY31/$E31 -> #DIV/0! | FF31: =AZ31/$E31 -> #DIV/0!
B32: =B31+1 -> 45521 | L32: 16.1 | M32: =H32/I32*K32*L32*1.5 -> #DIV/0! | N32: =H32/I32*J32*L32*N$4 -> #DIV/0! | BB32: =$N32*DX32 -> #DIV/0! | BC32: =$N32*DY32 -> #DIV/0! | BD32: =$N32*DZ32 -> #DIV/0! | BE32: =$N32*EA32 -> #DIV/0! | BF32: =$N32*EB32 -> #DIV/0! | BG32: =$N32*EC32 -> #DIV/0! | BH32: =$N32*ED32 -> #DIV/0! | BI32: =$N32*EE32 -> #DIV/0! | ... CJ32: =$N32*FF32 -> #DIV/0! | CL32: 2 | CN32: =AVERAGE(BB32:BB33)*$CL32 -> #DIV/0! | CO32: =AVERAGE(BC32:BC33)*$CL32 -> #DIV/0! | CP32: =AVERAGE(BD32:BD33)*$CL32 -> #DIV/0! | CQ32: =AVERAGE(BE32:BE33)*$CL32 -> #DIV/0! | CR32: =AVERAGE(BF32:BF33)*$CL32 -> #DIV/0! | CS32: =AVERAGE(BG32:BG33)*$CL32 -> #DIV/0! | CT32: =AVERAGE(BH32:BH33)*$CL32 -> #DIV/0! | CU32: =AVERAGE(BI32:BI33)*$CL32 -> #DIV/0! | ... DV32: =AVERAGE(CJ32:CJ33)*$CL32 -> #DIV/0! | DX32: =P32/$E32 -> #DIV/0! | DY32: =Q32/$E32 -> #DIV/0! | DZ32: =R32/$E32 -> #DIV/0! | EA32: =S32/$E32 -> #DIV/0! | EB32: =T32/$E32 -> #DIV/0! | EC32: =U32/$E32 -> #DIV/0! | ED32: =V32/$E32 -> #DIV/0! | EE32: =W32/$E32 -> #DIV/0! | ... FD32: =AV32/$E32 -> #DIV/0! | FE32: =AY32/$E32 -> #DIV/0! | FF32: =AZ32/$E32 -> #DIV/0!
B33: =B32+1 -> 45522 | L33: 16 | M33: =H33/I33*K33*L33*1.5 -> #DIV/0! | N33: =H33/I33*J33*L33*N$4 -> #DIV/0! | BB33: =$N33*DX33 -> #DIV/0! | BC33: =$N33*DY33 -> #DIV/0! | BD33: =$N33*DZ33 -> #DIV/0! | BE33: =$N33*EA33 -> #DIV/0! | BF33: =$N33*EB33 -> #DIV/0! | BG33: =$N33*EC33 -> #DIV/0! | BH33: =$N33*ED33 -> #DIV/0! | BI33: =$N33*EE33 -> #DIV/0! | ... CJ33: =$N33*FF33 -> #DIV/0! | DX33: =P33/$E33 -> #DIV/0! | DY33: =Q33/$E33 -> #DIV/0! | DZ33: =R33/$E33 -> #DIV/0! | EA33: =S33/$E33 -> #DIV/0! | EB33: =T33/$E33 -> #DIV/0! | EC33: =U33/$E33 -> #DIV/0! | ED33: =V33/$E33 -> #DIV/0! | EE33: =W33/$E33 -> #DIV/0! | ... FD33: =AV33/$E33 -> #DIV/0! | FE33: =AY33/$E33 -> #DIV/0! | FF33: =AZ33/$E33 -> #DIV/0!
D34: =SUM(D27:D33) -> 0 | E34: =SUM(E27:E33) -> 0 | N34: =AVERAGE(N27:N31)*5+AVERAGE(N32:N33)*2 -> #DIV/0! | P34: =SUM(P27:P33) -> 0 | Q34: =SUM(Q27:Q33) -> 0 | R34: =SUM(R27:R33) -> 0 | S34: =SUM(S27:S33) -> 0 | T34: =SUM(T27:T33) -> 0 | U34: =SUM(U27:U33) -> 0 | V34: =SUM(V27:V33) -> 0 | W34: =SUM(W27:W33) -> 0 | ... AZ34: =SUM(AZ27:AZ33) -> 0 | BB34: =SUM(BB27:BB33) -> #DIV/0! | BC34: =SUM(BC27:BC33) -> #DIV/0! | BD34: =SUM(BD27:BD33) -> #DIV/0! | BE34: =SUM(BE27:BE33) -> #DIV/0! | BF34: =SUM(BF27:BF33) -> #DIV/0! | BG34: =SUM(BG27:BG33) -> #DIV/0! | BH34: =SUM(BH27:BH33) -> #DIV/0! | BI34: =SUM(BI27:BI33) -> #DIV/0! | ... CJ34: =SUM(CJ27:CJ33) -> #DIV/0! | CN34: =SUM(CN27:CN33) -> #DIV/0! | CO34: =SUM(CO27:CO33) -> #DIV/0! | CP34: =SUM(CP27:CP33) -> #DIV/0! | CQ34: =SUM(CQ27:CQ33) -> #DIV/0! | CR34: =SUM(CR27:CR33) -> #DIV/0! | CS34: =SUM(CS27:CS33) -> #DIV/0! | CT34: =SUM(CT27:CT33) -> #DIV/0! | CU34: =SUM(CU27:CU33) -> #DIV/0! | ... DV34: =SUM(DV27:DV33) -> #DIV/0! | DX34: =AVERAGE(DX27:DX33) -> #DIV/0! | DY34: =AVERAGE(DY27:DY33) -> #DIV/0! | DZ34: =AVERAGE(DZ27:DZ33) -> #DIV/0! | EA34: =AVERAGE(EA27:EA33) -> #DIV/0! | EB34: =AVERAGE(EB27:EB33) -> #DIV/0! | EC34: =AVERAGE(EC27:EC33) -> #DIV/0! | ED34: =AVERAGE(ED27:ED33) -> #DIV/0! | EE34: =AVERAGE(EE27:EE33) -> #DIV/0! | ... FF34: =AVERAGE(FF27:FF33) -> #DIV/0!
L35: +2
B36: =B27+7 -> 45523 | L36: 16 | M36: =H36/I36*K36*L36*1.5 -> #DIV/0! | N36: =H36/I36*J36*L36*N$4 -> #DIV/0! | BB36: =$N36*DX36 -> #DIV/0! | BC36: =$N36*DY36 -> #DIV/0! | BD36: =$N36*DZ36 -> #DIV/0! | BE36: =$N36*EA36 -> #DIV/0! | BF36: =$N36*EB36 -> #DIV/0! | BG36: =$N36*EC36 -> #DIV/0! | BH36: =$N36*ED36 -> #DIV/0! | BI36: =$N36*EE36 -> #DIV/0! | ... CJ36: =$N36*FF36 -> #DIV/0! | CL36: 5 | CN36: =AVERAGE(BB36:BB40)*$CL36 -> #DIV/0! | CO36: =AVERAGE(BC36:BC40)*$CL36 -> #DIV/0! | CP36: =AVERAGE(BD36:BD40)*$CL36 -> #DIV/0! | CQ36: =AVERAGE(BE36:BE40)*$CL36 -> #DIV/0! | CR36: =AVERAGE(BF36:BF40)*$CL36 -> #DIV/0! | CS36: =AVERAGE(BG36:BG40)*$CL36 -> #DIV/0! | CT36: =AVERAGE(BH36:BH40)*$CL36 -> #DIV/0! | CU36: =AVERAGE(BI36:BI40)*$CL36 -> #DIV/0! | ... DV36: =AVERAGE(CJ36:CJ40)*$CL36 -> #DIV/0! | DX36: =P36/$E36 -> #DIV/0! | DY36: =Q36/$E36 -> #DIV/0! | DZ36: =R36/$E36 -> #DIV/0! | EA36: =S36/$E36 -> #DIV/0! | EB36: =T36/$E36 -> #DIV/0! | EC36: =U36/$E36 -> #DIV/0! | ED36: =V36/$E36 -> #DIV/0! | EE36: =W36/$E36 -> #DIV/0! | ... FD36: =AV36/$E36 -> #DIV/0! | FE36: =AY36/$E36 -> #DIV/0! | FF36: =AZ36/$E36 -> #DIV/0!
B37: =B36+1 -> 45524 | L37: 15.9 | M37: =H37/I37*K37*L37*1.5 -> #DIV/0! | N37: =H37/I37*J37*L37*N$4 -> #DIV/0! | BB37: =$N37*DX37 -> #DIV/0! | BC37: =$N37*DY37 -> #DIV/0! | BD37: =$N37*DZ37 -> #DIV/0! | BE37: =$N37*EA37 -> #DIV/0! | BF37: =$N37*EB37 -> #DIV/0! | BG37: =$N37*EC37 -> #DIV/0! | BH37: =$N37*ED37 -> #DIV/0! | BI37: =$N37*EE37 -> #DIV/0! | ... CJ37: =$N37*FF37 -> #DIV/0! | DX37: =P37/$E37 -> #DIV/0! | DY37: =Q37/$E37 -> #DIV/0! | DZ37: =R37/$E37 -> #DIV/0! | EA37: =S37/$E37 -> #DIV/0! | EB37: =T37/$E37 -> #DIV/0! | EC37: =U37/$E37 -> #DIV/0! | ED37: =V37/$E37 -> #DIV/0! | EE37: =W37/$E37 -> #DIV/0! | ... FD37: =AV37/$E37 -> #DIV/0! | FE37: =AY37/$E37 -> #DIV/0! | FF37: =AZ37/$E37 -> #DIV/0!
B38: =B37+1 -> 45525 | L38: 15.9 | M38: =H38/I38*K38*L38*1.5 -> #DIV/0! | N38: =H38/I38*J38*L38*N$4 -> #DIV/0! | BB38: =$N38*DX38 -> #DIV/0! | BC38: =$N38*DY38 -> #DIV/0! | BD38: =$N38*DZ38 -> #DIV/0! | BE38: =$N38*EA38 -> #DIV/0! | BF38: =$N38*EB38 -> #DIV/0! | BG38: =$N38*EC38 -> #DIV/0! | BH38: =$N38*ED38 -> #DIV/0! | BI38: =$N38*EE38 -> #DIV/0! | ... CJ38: =$N38*FF38 -> #DIV/0! | DX38: =P38/$E38 -> #DIV/0! | DY38: =Q38/$E38 -> #DIV/0! | DZ38: =R38/$E38 -> #DIV/0! | EA38: =S38/$E38 -> #DIV/0! | EB38: =T38/$E38 -> #DIV/0! | EC38: =U38/$E38 -> #DIV/0! | ED38: =V38/$E38 -> #DIV/0! | EE38: =W38/$E38 -> #DIV/0! | ... FD38: =AV38/$E38 -> #DIV/0! | FE38: =AY38/$E38 -> #DIV/0! | FF38: =AZ38/$E38 -> #DIV/0!
B39: =B38+1 -> 45526 | L39: 15.8 | M39: =H39/I39*K39*L39*1.5 -> #DIV/0! | N39: =H39/I39*J39*L39*N$4 -> #DIV/0! | BB39: =$N39*DX39 -> #DIV/0! | BC39: =$N39*DY39 -> #DIV/0! | BD39: =$N39*DZ39 -> #DIV/0! | BE39: =$N39*EA39 -> #DIV/0! | BF39: =$N39*EB39 -> #DIV/0! | BG39: =$N39*EC39 -> #DIV/0! | BH39: =$N39*ED39 -> #DIV/0! | BI39: =$N39*EE39 -> #DIV/0! | ... CJ39: =$N39*FF39 -> #DIV/0! | DX39: =P39/$E39 -> #DIV/0! | DY39: =Q39/$E39 -> #DIV/0! | DZ39: =R39/$E39 -> #DIV/0! | EA39: =S39/$E39 -> #DIV/0! | EB39: =T39/$E39 -> #DIV/0! | EC39: =U39/$E39 -> #DIV/0! | ED39: =V39/$E39 -> #DIV/0! | EE39: =W39/$E39 -> #DIV/0! | ... FD39: =AV39/$E39 -> #DIV/0! | FE39: =AY39/$E39 -> #DIV/0! | FF39: =AZ39/$E39 -> #DIV/0!
B40: =B39+1 -> 45527 | L40: 15.8 | M40: =H40/I40*K40*L40*1.5 -> #DIV/0! | N40: =H40/I40*J40*L40*N$4 -> #DIV/0! | BB40: =$N40*DX40 -> #DIV/0! | BC40: =$N40*DY40 -> #DIV/0! | BD40: =$N40*DZ40 -> #DIV/0! | BE40: =$N40*EA40 -> #DIV/0! | BF40: =$N40*EB40 -> #DIV/0! | BG40: =$N40*EC40 -> #DIV/0! | BH40: =$N40*ED40 -> #DIV/0! | BI40: =$N40*EE40 -> #DIV/0! | ... CJ40: =$N40*FF40 -> #DIV/0! | DX40: =P40/$E40 -> #DIV/0! | DY40: =Q40/$E40 -> #DIV/0! | DZ40: =R40/$E40 -> #DIV/0! | EA40: =S40/$E40 -> #DIV/0! | EB40: =T40/$E40 -> #DIV/0! | EC40: =U40/$E40 -> #DIV/0! | ED40: =V40/$E40 -> #DIV/0! | EE40: =W40/$E40 -> #DIV/0! | ... FD40: =AV40/$E40 -> #DIV/0! | FE40: =AY40/$E40 -> #DIV/0! | FF40: =AZ40/$E40 -> #DIV/0!
...

Sheet Summary
A3: Estimated Steelhead Harvest in the McNary Reservoir, September 1 - Oct 31, 2024
K5: Catch & Harvest | AS5: Sampled
K6: Steelhead | Q6: Coho | U6: Chinook | AA6: White Sturgeon | AS6: Steelhead | BA6: Coho | BE6: Chinook | BK6: White Sturgeon
A7: Bank & Boat Combined | K7: Harvest | M7: Catch & Release | U7: Harvest | Y7: C & R | AS7: Harvest | AW7: Catch & Release | BE7: Harvest | BI7: C & R
B8: Sampled | F8: Estimated | I8: Anglers | K8: AD | M8: AD | O8: Wild | Q8: Harvest | S8: C & R | U8: Adult | W8: Jack | AB8: Legal | AF8: Walleye | AH8: Trout | AJ8: Bass | AL8: NPM | AN8: C. Catfish | AP8: YP | AS8: AD | AU8: Other | AW8: AD | AY8: Wild | BA8: Harvest | BC8: C & R | BE8: Adult | BG8: Jack | BL8: Legal | BP8: Walleye | BR8: Trout | BT8: Bass | BV8: Shad | BX8: C. Catfish | BZ8: YP
A9: Date | B9: Boats | C9: Anglers | D9: Hours | F9: Boat | G9: Anglers | H9: Hours | I9: Sampled | K9: <78 | L9: ≥78 | M9: <78 | N9: ≥78 | O9: <78 | P9: ≥78 | Q9: NM | R9: AD | S9: NM | T9: AD | U9: NM | V9: AD | W9: NM | X9: AD | Y9: Adult | Z9: Jack | AA9: Sub | AB9: Rel | AC9: Kept | AD9: Over | AE9: Unk | AF9: Kept | AG9: Rel | AH9: Kept | AI9: Rel | AJ9: Kept | AK9: Rel | AL9: Kept | AM9: Rel | AN9: Kept | AO9: Rel | AP9: Kept | AQ9: Rel | AS9: <79 | AT9: >78 | AU9: <79 | AV9: >78 | AW9: <79 | AX9: >78 | AY9: <79 | AZ9: >78 | BA9: NM | BB9: AD | BC9: NM | BD9: AD | BE9: NM | BF9: AD | BG9: NM | BH9: AD | BI9: Adult | BJ9: Jack | BK9: Sub | BL9: Rel | BM9: Kept | BN9: Over | BO9: Unk | BP9: Kept | BQ9: Rel | BR9: Kept | BS9: Rel | BT9: Kept | BU9: Rel | BV9: Kept | BW9: Rel | BX9: Kept | BY9: Rel | BZ9: Kept | CA9: Rel | CF9: Hatch | CG9: Wild | CH9: % Hatch
A10: Aug 1-4 | B10: =B39 -> 0 | C10: =C39+C68 -> 0 | D10: =D39+D68 -> 0 | F10: =F39 -> 0 | G10: =G39+G68 -> #DIV/0! | H10: =H39+H68 -> #DIV/0! | I10: =C10/G10 -> #DIV/0! | K10: =K39+K68 -> #DIV/0! | L10: =L39+L68 -> #DIV/0! | M10: =M39+M68 -> #DIV/0! | N10: =N39+N68 -> #DIV/0! | O10: =O39+O68 -> #DIV/0! | P10: =P39+P68 -> #DIV/0! | Q10: =Q39+Q68 -> #DIV/0! | R10: =R39+R68 -> #DIV/0! | ... AQ10: =AQ39+AQ68 -> #DIV/0! | AS10: =AS39+AS68 -> #DIV/0! | AT10: =AT39+AT68 -> #DIV/0! | AU10: =AU39+AU68 -> #DIV/0! | AV10: =AV39+AV68 -> #DIV/0! | AW10: =AW39+AW68 -> #DIV/0! | AX10: =AX39+AX68 -> #DIV/0! | AY10: =AY39+AY68 -> #DIV/0! | AZ10: =AZ39+AZ68 -> #DIV/0! | ... CA10: =CA39+CA68 -> 0
A11: Aug 5-11 | B11: =B40 -> 0 | C11: =C40+C69 -> 0 | D11: =D40+D69 -> 0 | F11: =F40 -> 1.4135 | G11: =G40+G69 -> #DIV/0! | H11: =H40+H69 -> #DIV/0! | I11: =C11/G11 -> #DIV/0! | K11: =K40+K69 -> #DIV/0! | L11: =L40+L69 -> #DIV/0! | M11: =M40+M69 -> #DIV/0! | N11: =N40+N69 -> #DIV/0! | O11: =O40+O69 -> #DIV/0! | P11: =P40+P69 -> #DIV/0! | Q11: =Q40+Q69 -> #DIV/0! | R11: =R40+R69 -> #DIV/0! | ... AQ11: =AQ40+AQ69 -> #DIV/0! | AS11: =AS40+AS69 -> 0 | AT11: =AT40+AT69 -> 0 | AU11: =AU40+AU69 -> 0 | AV11: =AV40+AV69 -> 0 | AW11: =AW40+AW69 -> 0 | AX11: =AX40+AX69 -> 0 | AY11: =AY40+AY69 -> 0 | AZ11: =AZ40+AZ69 -> 0 | ... CA11: =CA40+CA69 -> 0
A12: Aug 12-18 | B12: =B41 -> 0 | C12: =C41+C70 -> 0 | D12: =D41+D70 -> 0 | F12: =F41 -> 0 | G12: =G41+G70 -> #DIV/0! | H12: =H41+H70 -> #DIV/0! | I12: =C12/G12 -> #DIV/0! | K12: =K41+K70 -> #DIV/0! | L12: =L41+L70 -> #DIV/0! | M12: =M41+M70 -> #DIV/0! | N12: =N41+N70 -> #DIV/0! | O12: =O41+O70 -> #DIV/0! | P12: =P41+P70 -> #DIV/0! | Q12: =Q41+Q70 -> #DIV/0! | R12: =R41+R70 -> #DIV/0! | ... AQ12: =AQ41+AQ70 -> #DIV/0! | AS12: =AS41+AS70 -> 0 | AT12: =AT41+AT70 -> 0 | AU12: =AU41+AU70 -> 0 | AV12: =AV41+AV70 -> 0 | AW12: =AW41+AW70 -> 0 | AX12: =AX41+AX70 -> 0 | AY12: =AY41+AY70 -> 0 | AZ12: =AZ41+AZ70 -> 0 | ... CA12: =CA41+CA70 -> 0
A13: Aug 19-25 | B13: =B42 -> 0 | C13: =C42+C71 -> 0 | D13: =D42+D71 -> 0 | F13: =F42 -> 0 | G13: =G42+G71 -> #DIV/0! | H13: =H42+H71 -> #DIV/0! | I13: =C13/G13 -> #DIV/0! | K13: =K42+K71 -> #DIV/0! | L13: =L42+L71 -> #DIV/0! | M13: =M42+M71 -> #DIV/0! | N13: =N42+N71 -> #DIV/0! | O13: =O42+O71 -> #DIV/0! | P13: =P42+P71 -> #DIV/0! | Q13: =Q42+Q71 -> #DIV/0! | R13: =R42+R71 -> #DIV/0! | ... AQ13: =AQ42+AQ71 -> #DIV/0! | AS13: =AS42+AS71 -> 0 | AT13: =AT42+AT71 -> 0 | AU13: =AU42+AU71 -> 0 | AV13: =AV42+AV71 -> 0 | AW13: =AW42+AW71 -> 0 | AX13: =AX42+AX71 -> 0 | AY13: =AY42+AY71 -> 0 | AZ13: =AZ42+AZ71 -> 0 | ... CA13: =CA42+CA71 -> 0
A14: Aug 26-Sept 1 | B14: =B43 -> 0 | C14: =C43+C72 -> 0 | D14: =D43+D72 -> 0 | F14: =F43 -> 46.6455 | G14: =G43+G72 -> #DIV/0! | H14: =H43+H72 -> #DIV/0! | I14: =C14/G14 -> #DIV/0! | K14: =K43+K72 -> #DIV/0! | L14: =L43+L72 -> #DIV/0! | M14: =M43+M72 -> #DIV/0! | N14: =N43+N72 -> #DIV/0! | O14: =O43+O72 -> #DIV/0! | P14: =P43+P72 -> #DIV/0! | Q14: =Q43+Q72 -> #DIV/0! | R14: =R43+R72 -> #DIV/0! | ... AQ14: =AQ43+AQ72 -> #DIV/0! | AS14: =AS43+AS72 -> 0 | AT14: =AT43+AT72 -> 0 | AU14: =AU43+AU72 -> 0 | AV14: =AV43+AV72 -> 0 | AW14: =AW43+AW72 -> 0 | AX14: =AX43+AX72 -> 0 | AY14: =AY43+AY72 -> 0 | AZ14: =AZ43+AZ72 -> 0 | ... CA14: =CA43+CA72 -> 0
A15: Sept 2-8 | B15: =B44 -> 33 | C15: =C44+C73 -> 102 | D15: =D44+D73 -> 351.69 | F15: =F44 -> 58.2227 | G15: =G44+G73 -> 352.76784 | H15: =H44+H73 -> 743.86236 | I15: =C15/G15 -> 0.289142 | K15: =K44+K73 -> 0 | L15: =L44+L73 -> 0 | M15: =M44+M73 -> 7.2377947 | N15: =N44+N73 -> 0 | O15: =O44+O73 -> 9.0021189 | P15: =P44+P73 -> 0 | Q15: =Q44+Q73 -> 0 | R15: =R44+R73 -> 0 | ... AQ15: =AQ44+AQ73 -> 0 | AS15: =AS44+AS73 -> 0 | AT15: =AT44+AT73 -> 0 | AU15: =AU44+AU73 -> 0 | AV15: =AV44+AV73 -> 0 | AW15: =AW44+AW73 -> 2 | AX15: =AX44+AX73 -> 0 | AY15: =AY44+AY73 -> 3 | AZ15: =AZ44+AZ73 -> 0 | ... CA15: =CA44+CA73 -> 0
A16: Sept 9-15 | B16: =B45 -> 34 | C16: =C45+C74 -> 105 | D16: =D45+D74 -> 340.66 | F16: =F45 -> 86.2235 | G16: =G45+G74 -> 281.63322 | H16: =H45+H74 -> 894.34318 | I16: =C16/G16 -> 0.37282533 | K16: =K45+K74 -> 0 | L16: =L45+L74 -> 0 | M16: =M45+M74 -> 0 | N16: =N45+N74 -> 0 | O16: =O45+O74 -> 0 | P16: =P45+P74 -> 0 | Q16: =Q45+Q74 -> 0 | R16: =R45+R74 -> 0 | ... AQ16: =AQ45+AQ74 -> 24.666 | AS16: =AS45+AS74 -> 0 | AT16: =AT45+AT74 -> 0 | AU16: =AU45+AU74 -> 0 | AV16: =AV45+AV74 -> 0 | AW16: =AW45+AW74 -> 0 | AX16: =AX45+AX74 -> 0 | AY16: =AY45+AY74 -> 0 | AZ16: =AZ45+AZ74 -> 0 | ... CA16: =CA45+CA74 -> 11
A17: Sept 16-22 | B17: =B46 -> 29 | C17: =C46+C75 -> 58 | D17: =D46+D75 -> 256.52 | F17: =F46 -> 59.1265 | G17: =G46+G75 -> 161.1426 | H17: =H46+H75 -> 621.22166 | I17: =C17/G17 -> 0.35992965 | K17: =K46+K75 -> 0 | L17: =L46+L75 -> 0 | M17: =M46+M75 -> 0 | N17: =N46+N75 -> 0 | O17: =O46+O75 -> 2.0388448 | P17: =P46+P75 -> 0 | Q17: =Q46+Q75 -> 0 | R17: =R46+R75 -> 0 | ... AQ17: =AQ46+AQ75 -> 0 | AS17: =AS46+AS75 -> 0 | AT17: =AT46+AT75 -> 0 | AU17: =AU46+AU75 -> 0 | AV17: =AV46+AV75 -> 0 | AW17: =AW46+AW75 -> 0 | AX17: =AX46+AX75 -> 0 | AY17: =AY46+AY75 -> 1 | AZ17: =AZ46+AZ75 -> 0 | ... CA17: =CA46+CA75 -> 0 | CF17: =SUM(AS17:AX17) -> 0 | CG17: =SUM(AY17:AZ17) -> 1 | CH17: =CF17/(CG17+CF17) -> 0
A18: Sept 23-29 | B18: =B47 -> 29 | C18: =C47+C76 -> 76 | D18: =D47+D76 -> 289.31 | F18: =F47 -> 57.9535 | G18: =G47+G76 -> 177.77078 | H18: =H47+H76 -> 628.42481 | I18: =C18/G18 -> 0.42751684 | K18: =K47+K76 -> 0 | L18: =L47+L76 -> 0 | M18: =M47+M76 -> 0 | N18: =N47+N76 -> 0 | O18: =O47+O76 -> 0 | P18: =P47+P76 -> 0 | Q18: =Q47+Q76 -> 0 | R18: =R47+R76 -> 0 | ... AQ18: =AQ47+AQ76 -> 0 | AS18: =AS47+AS76 -> 0 | AT18: =AT47+AT76 -> 0 | AU18: =AU47+AU76 -> 0 | AV18: =AV47+AV76 -> 0 | AW18: =AW47+AW76 -> 0 | AX18: =AX47+AX76 -> 0 | AY18: =AY47+AY76 -> 0 | AZ18: =AZ47+AZ76 -> 0 | ... CA18: =CA47+CA76 -> 0 | CF18: =SUM(AS18:AX18) -> 0 | CG18: =SUM(AY18:AZ18) -> 0 | CH18: =CF18/(CG18+CF18) -> #DIV/0!
A19: Sept 30-Oct 6 | B19: =B48 -> 17 | C19: =C48+C77 -> 43 | D19: =D48+D77 -> 177.01 | F19: =F48 -> 43.8185 | G19: =G48+G77 -> 122.30281 | H19: =H48+H77 -> 491.33467 | I19: =C19/G19 -> 0.35158637 | K19: =K48+K77 -> 0 | L19: =L48+L77 -> 0 | M19: =M48+M77 -> 0 | N19: =N48+N77 -> 0 | O19: =O48+O77 -> 5.1551176 | P19: =P48+P77 -> 0 | Q19: =Q48+Q77 -> 0 | R19: =R48+R77 -> 0 | ... AQ19: =AQ48+AQ77 -> 2.5775588 | AS19: =AS48+AS77 -> 0 | AT19: =AT48+AT77 -> 0 | AU19: =AU48+AU77 -> 0 | AV19: =AV48+AV77 -> 0 | AW19: =AW48+AW77 -> 0 | AX19: =AX48+AX77 -> 0 | AY19: =AY48+AY77 -> 2 | AZ19: =AZ48+AZ77 -> 0 | ... CA19: =CA48+CA77 -> 0 | CF19: =SUM(AS19:AX19) -> 0 | CG19: =SUM(AY19:AZ19) -> 2 | CH19: =CF19/(CG19+CF19) -> 0
A20: Oct 7-13 | B20: =B49 -> 26 | C20: =C49+C78 -> 95 | D20: =D49+D78 -> 364.02 | F20: =F49 -> 37.5991 | G20: =G49+G78 -> 187.19569 | H20: =H49+H78 -> 605.23797 | I20: =C20/G20 -> 0.50749032 | K20: =K49+K78 -> 1.4461192 | L20: =L49+L78 -> 0 | M20: =M49+M78 -> 0 | N20: =N49+N78 -> 0 | O20: =O49+O78 -> 11.699241 | P20: =P49+P78 -> 0 | Q20: =Q49+Q78 -> 1.4461192 | R20: =R49+R78 -> 1.4461192 | ... AQ20: =AQ49+AQ78 -> 4.3383577 | AS20: =AS49+AS78 -> 1 | AT20: =AT49+AT78 -> 0 | AU20: =AU49+AU78 -> 0 | AV20: =AV49+AV78 -> 0 | AW20: =AW49+AW78 -> 0 | AX20: =AX49+AX78 -> 0 | AY20: =AY49+AY78 -> 5 | AZ20: =AZ49+AZ78 -> 0 | ... CA20: =CA49+CA78 -> 0 | CF20: =SUM(AS20:AX20) -> 1 | CG20: =SUM(AY20:AZ20) -> 5 | CH20: =CF20/(CG20+CF20) -> 0.16666667
A21: Oct 14-20 | B21: =B50 -> 14 | C21: =C50+C79 -> 48 | D21: =D50+D79 -> 148.23 | F21: =F50 -> 42.405 | G21: =G50+G79 -> 143.99912 | H21: =H50+H79 -> 446.07897 | I21: =C21/G21 -> 0.33333536 | K21: =K50+K79 -> 0 | L21: =L50+L79 -> 0 | M21: =M50+M79 -> 12.666754 | N21: =N50+N79 -> 0 | O21: =O50+O79 -> 18.940599 | P21: =P50+P79 -> 0 | Q21: =Q50+Q79 -> 7.4047959 | R21: =R50+R79 -> 3.0289286 | ... AQ21: =AQ50+AQ79 -> 3.0289286 | AS21: =AS50+AS79 -> 0 | AT21: =AT50+AT79 -> 0 | AU21: =AU50+AU79 -> 0 | AV21: =AV50+AV79 -> 0 | AW21: =AW50+AW79 -> 3 | AX21: =AX50+AX79 -> 0 | AY21: =AY50+AY79 -> 5 | AZ21: =AZ50+AZ79 -> 0 | ... CA21: =CA50+CA79 -> 0 | CF21: =SUM(AS21:AX21) -> 3 | CG21: =SUM(AY21:AZ21) -> 5 | CH21: =CF21/(CG21+CF21) -> 0.375
A22: Oct 21-27 | B22: =B51 -> 4 | C22: =C51+C80 -> 28 | D22: =D51+D80 -> 72.01 | F22: =F51 -> 14.8945 | G22: =G51+G80 -> 123.78278 | H22: =H51+H80 -> 312.98839 | I22: =C22/G22 -> 0.2262027 | K22: =K51+K80 -> 0 | L22: =L51+L80 -> 0 | M22: =M51+M80 -> 0 | N22: =N51+N80 -> 19.06519 | O22: =O51+O80 -> 5.8499815 | P22: =P51+P80 -> 19.396557 | Q22: =Q51+Q80 -> 7.44725 | R22: =R51+R80 -> 3.723625 | ... AQ22: =AQ51+AQ80 -> 0 | AS22: =AS51+AS80 -> 0 | AT22: =AT51+AT80 -> 0 | AU22: =AU51+AU80 -> 0 | AV22: =AV51+AV80 -> 0 | AW22: =AW51+AW80 -> 0 | AX22: =AX51+AX80 -> 5 | AY22: =AY51+AY80 -> 1 | AZ22: =AZ51+AZ80 -> 5 | ... CA22: =CA51+CA80 -> 0
A23: Oct 28-Nov 3 | B23: =B52 -> 10 | C23: =C52+C81 -> 61 | D23: =D52+D81 -> 95.5 | F23: =F52 -> 24.158286 | G23: =G52+G81 -> 173.97226 | H23: =H52+H81 -> 236.21241 | I23: =C23/G23 -> 0.35063061 | K23: =K52+K81 -> 16.9108 | L23: =L52+L81 -> 12.079143 | M23: =M52+M81 -> 0 | N23: =N52+N81 -> 0 | O23: =O52+O81 -> 127.69954 | P23: =P52+P81 -> 0 | Q23: =Q52+Q81 -> 4.8316571 | R23: =R52+R81 -> 0 | ... AQ23: =AQ52+AQ81 -> 2.4158286 | AS23: =AS52+AS81 -> 10 | AT23: =AT52+AT81 -> 5 | AU23: =AU52+AU81 -> 0 | AV23: =AV52+AV81 -> 0 | AW23: =AW52+AW81 -> 0 | AX23: =AX52+AX81 -> 0 | AY23: =AY52+AY81 -> 63 | AZ23: =AZ52+AZ81 -> 0 | ... CA23: =CA52+CA81 -> 2
A24: Nov 4-10 | B24: =B53 -> 26 | C24: =C53+C82 -> 76 | D24: =D53+D82 -> 267.57 | F24: =F53 -> 183.426 | G24: =G53+G82 -> 483.45878 | H24: =H53+H82 -> 1756.533 | I24: =C24/G24 -> 0.15720058 | K24: =K44+K73 -> 0 | L24: =L44+L73 -> 0 | M24: =M44+M73 -> 7.2377947 | N24: =N44+N73 -> 0 | O24: =O44+O73 -> 9.0021189 | P24: =P44+P73 -> 0 | Q24: =Q53+Q82 -> 0 | R24: =R53+R82 -> 0 | S24: =S53+S82 -> 0 | T24: =T53+T82 -> 0 | U24: =U44+U73 -> 3.5286485 | V24: =V44+V73 -> 3.5286485 | W24: =W44+W73 -> 0 | X24: =X44+X73 -> 0 | Y24: =Y44+Y73 -> 0 | Z24: =Z44+Z73 -> 0 | AA24: =AA44+AA73 -> 0 | AB24: =AB44+AB73 -> 0 | ... AQ24: =AQ44+AQ73 -> 0 | AS24: =AS53+AS82 -> 4 | AT24: =AT53+AT82 -> 1 | AU24: =AU53+AU82 -> 0 | AV24: =AV53+AV82 -> 0 | AW24: =AW53+AW82 -> 0 | AX24: =AX53+AX82 -> 0 | AY24: =AY53+AY82 -> 16 | AZ24: =AZ53+AZ82 -> 0 | ... CA24: =CA53+CA82 -> 0 | CC24: =SUM(AS24:AZ24) -> 21 | CD24: =D24/CC24 -> 12.741429 | CE24: =CC24/B24 -> 0.80769231 | CF24: =SUM(AS24:AX24) -> 5 | CG24: =SUM(AY24:AZ24) -> 16 | CH24: =CF24/(CG24+CF24) -> 0.23809524
A25: Nov 11-17 | B25: =B54 -> 4 | C25: =C54+C83 -> 20 | D25: =D54+D83 -> 70.45 | F25: =F54 -> 52.3755 | G25: =G54+G83 -> 111.0477 | H25: =H54+H83 -> 452.57838 | I25: =C25/G25 -> 0.18010279 | K25: =K45+K74 -> 0 | L25: =L45+L74 -> 0 | M25: =M45+M74 -> 0 | N25: =N45+N74 -> 0 | O25: =O45+O74 -> 0 | P25: =P45+P74 -> 0 | Q25: =Q54+Q83 -> 1.8075941 | R25: =R54+R83 -> 0 | S25: =S54+S83 -> 0 | T25: =T54+T83 -> 0 | U25: =U45+U74 -> 0 | V25: =V45+V74 -> 0 | W25: =W45+W74 -> 0 | X25: =X45+X74 -> 0 | Y25: =Y45+Y74 -> 0 | Z25: =Z45+Z74 -> 0 | AA25: =AA45+AA74 -> 0 | AB25: =AB45+AB74 -> 0 | ... AQ25: =AQ45+AQ74 -> 24.666 | AS25: =AS54+AS83 -> 2 | AT25: =AT54+AT83 -> 0 | AU25: =AU54+AU83 -> 0 | AV25: =AV54+AV83 -> 0 | AW25: =AW54+AW83 -> 0 | AX25: =AX54+AX83 -> 0 | AY25: =AY54+AY83 -> 7 | AZ25: =AZ54+AZ83 -> 0 | ... CA25: =CA54+CA83 -> 1 | CC25: =SUM(AS25:AZ25) -> 9 | CD25: =D25/CC25 -> 7.8277778 | CE25: =CC25/B25 -> 2.25 | CF25: =SUM(AS25:AX25) -> 2 | CG25: =SUM(AY25:AZ25) -> 7 | CH25: =CF25/(CG25+CF25) -> 0.22222222
A26: Nov 18-24 | B26: =B55 -> 15 | C26: =C55+C84 -> 63 | D26: =D55+D84 -> 213.39 | F26: =F55 -> 62.405 | G26: =G55+G84 -> 218.44411 | H26: =H55+H84 -> 758.66402 | I26: =C26/G26 -> 0.28840329 | K26: =K46+K75 -> 0 | L26: =L46+L75 -> 0 | M26: =M46+M75 -> 0 | N26: =N46+N75 -> 0 | O26: =O46+O75 -> 2.0388448 | P26: =P46+P75 -> 0 | Q26: =Q55+Q84 -> 49.924 | R26: =R55+R84 -> 0 | S26: =S55+S84 -> 0 | T26: =T55+T84 -> 0 | U26: =U46+U75 -> 0 | V26: =V46+V75 -> 4.0776897 | W26: =W46+W75 -> 0 | X26: =X46+X75 -> 2.0388448 | Y26: =Y46+Y75 -> 0 | Z26: =Z46+Z75 -> 0 | AA26: =AA46+AA75 -> 0 | AB26: =AB46+AB75 -> 0 | ... AQ26: =AQ46+AQ75 -> 0 | AS26: =AS55+AS84 -> 0 | AT26: =AT55+AT84 -> 0 | AU26: =AU55+AU84 -> 0 | AV26: =AV55+AV84 -> 0 | AW26: =AW55+AW84 -> 0 | AX26: =AX55+AX84 -> 0 | AY26: =AY55+AY84 -> 0 | AZ26: =AZ55+AZ84 -> 0 | ... CA26: =CA55+CA84 -> 0 | CC26: =SUM(AS26:AZ26) -> 0 | CD26: =D26/CC26 -> #DIV/0! | CE26: =CC26/B26 -> 0 | CF26: =SUM(AS26:AX26) -> 0 | CG26: =SUM(AY26:AZ26) -> 0 | CH26: =CF26/(CG26+CF26) -> #DIV/0!
A27: Nov 25-Dec 1 | B27: =B56 -> 19 | C27: =C56+C85 -> 57 | D27: =D56+D85 -> 287.3 | F27: =F56 -> 95.9915 | G27: =G56+G85 -> 229.66272 | H27: =H56+H85 -> 1193.1714 | I27: =C27/G27 -> 0.24819004 | K27: =K56+K85 -> 6.8203669 | L27: =L56+L85 -> 15.156553 | M27: =M56+M85 -> 0 | N27: =N56+N85 -> 0 | O27: =O56+O85 -> 37.525243 | P27: =P56+P85 -> 40.417474 | Q27: =Q56+Q85 -> 0 | R27: =R56+R85 -> 0 | ... AQ27: =AQ56+AQ85 -> 0 | AS27: =AS56+AS85 -> 1 | AT27: =AT56+AT85 -> 0 | AU27: =AU56+AU85 -> 0 | AV27: =AV56+AV85 -> 0 | AW27: =AW56+AW85 -> 0 | AX27: =AX56+AX85 -> 0 | AY27: =AY56+AY85 -> 4 | AZ27: =AZ56+AZ85 -> 0 | ... CA27: =CA56+CA85 -> 0 | CC27: =SUM(AS27:AZ27) -> 5 | CD27: =D27/CC27 -> 57.46 | CE27: =CC27/B27 -> 0.26315789 | CF27: =SUM(AS27:AX27) -> 1 | CG27: =SUM(AY27:AZ27) -> 4 | CH27: =CF27/(CG27+CF27) -> 0.2
A28: Dec 2-31 | B28: =B57 -> 0 | C28: =C57+C86 -> 0 | D28: =D57+D86 -> 0 | F28: =F57 -> 0 | G28: =G57+G86 -> #DIV/0! | H28: =H57+H86 -> #DIV/0! | I28: =C28/G28 -> #DIV/0! | K28: =K57+K86 -> #DIV/0! | L28: =L57+L86 -> #DIV/0! | M28: =M57+M86 -> #DIV/0! | N28: =N57+N86 -> #DIV/0! | O28: =O57+O86 -> #DIV/0! | P28: =P57+P86 -> #DIV/0! | Q28: =Q57+Q86 -> #DIV/0! | R28: =R57+R86 -> #DIV/0! | ... AQ28: =AQ57+AQ86 -> #DIV/0! | AS28: =AS57+AS86 -> 0 | AT28: =AT57+AT86 -> 0 | AU28: =AU57+AU86 -> 0 | AV28: =AV57+AV86 -> 0 | AW28: =AW57+AW86 -> 0 | AX28: =AX57+AX86 -> 0 | AY28: =AY57+AY86 -> 0 | AZ28: =AZ57+AZ86 -> 0 | ... CA28: =CA57+CA86 -> 0 | CC28: =SUM(AS28:AZ28) -> 0 | CD28: =D28/CC28 -> #DIV/0! | CE28: =CC28/B28 -> #DIV/0! | CF28: =SUM(AS28:AX28) -> 0 | CG28: =SUM(AY28:AZ28) -> 0 | CH28: =CF28/(CG28+CF28) -> #DIV/0!
A29: January | B29: =B58 -> 0 | C29: =C58+C87 -> 0 | D29: =D58+D87 -> 0 | F29: =F58 -> 0 | G29: =G58+G87 -> #DIV/0! | H29: =H58+H87 -> #DIV/0! | I29: =C29/G29 -> #DIV/0! | K29: =K58+K87 -> #DIV/0! | L29: =L58+L87 -> #DIV/0! | M29: =M58+M87 -> #DIV/0! | N29: =N58+N87 -> #DIV/0! | O29: =O58+O87 -> #DIV/0! | P29: =P58+P87 -> #DIV/0! | Q29: =Q58+Q87 -> #DIV/0! | R29: =R58+R87 -> #DIV/0! | ... AQ29: =AQ58+AQ87 -> #DIV/0! | AS29: =AS58+AS87 -> 0 | AT29: =AT58+AT87 -> 0 | AU29: =AU58+AU87 -> 0 | AV29: =AV58+AV87 -> 0 | AW29: =AW58+AW87 -> 0 | AX29: =AX58+AX87 -> 0 | AY29: =AY58+AY87 -> 0 | AZ29: =AZ58+AZ87 -> 0 | ... CA29: =CA58+CA87 -> 0 | CC29: =SUM(AS29:AZ29) -> 0 | CD29: =D29/CC29 -> #DIV/0! | CE29: =CC29/B29 -> #DIV/0!
A30: February | B30: =B59 -> 0 | C30: =C59+C88 -> 0 | D30: =D59+D88 -> 0 | F30: =F59 -> 0 | G30: =G59+G88 -> #DIV/0! | H30: =H59+H88 -> #DIV/0! | I30: =C30/G30 -> #DIV/0! | K30: =K59+K88 -> #DIV/0! | L30: =L59+L88 -> #DIV/0! | M30: =M59+M88 -> #DIV/0! | N30: =N59+N88 -> #DIV/0! | O30: =O59+O88 -> #DIV/0! | P30: =P59+P88 -> #DIV/0! | Q30: =Q59+Q88 -> #DIV/0! | R30: =R59+R88 -> #DIV/0! | ... AQ30: =AQ59+AQ88 -> #DIV/0! | AS30: =AS59+AS88 -> #DIV/0! | AT30: =AT59+AT88 -> #DIV/0! | AU30: =AU59+AU88 -> #DIV/0! | AV30: =AV59+AV88 -> #DIV/0! | AW30: =AW59+AW88 -> #DIV/0! | AX30: =AX59+AX88 -> #DIV/0! | AY30: =AY59+AY88 -> #DIV/0! | AZ30: =AZ59+AZ88 -> #DIV/0! | ... CA30: =CA59+CA88 -> 0 | CC30: =SUM(AS30:AZ30) -> #DIV/0! | CD30: =D30/CC30 -> #DIV/0! | CE30: =CC30/B30 -> #DIV/0!
A31: March | B31: =B60 -> 0 | C31: =C60+C89 -> 0 | D31: =D60+D89 -> 0 | F31: =F60 -> 0 | G31: =G60+G89 -> #DIV/0! | H31: =H60+H89 -> #DIV/0! | I31: =C31/G31 -> #DIV/0! | K31: =K60+K89 -> #DIV/0! | L31: =L60+L89 -> #DIV/0! | M31: =M60+M89 -> #DIV/0! | N31: =N60+N89 -> #DIV/0! | O31: =O60+O89 -> #DIV/0! | P31: =P60+P89 -> #DIV/0! | Q31: =Q60+Q89 -> #DIV/0! | R31: =R60+R89 -> #DIV/0! | ... AQ31: =AQ60+AQ89 -> #DIV/0! | AS31: =AS60+AS89 -> 0 | AT31: =AT60+AT89 -> 0 | AU31: =AU60+AU89 -> 0 | AV31: =AV60+AV89 -> 0 | AW31: =AW60+AW89 -> 0 | AX31: =AX60+AX89 -> 0 | AY31: =AY60+AY89 -> 0 | AZ31: =AZ60+AZ89 -> 0 | ... CA31: =CA60+CA89 -> 0 | CC31: =SUM(AS31:AZ31) -> 0 | CD31: =D31/CC31 -> #DIV/0! | CE31: =CC31/B31 -> #DIV/0!
