Workbook

Sheet Factors
A5: Table 1. Expansion factors converting trailer counts to estimates of total boat angling effort (boat trips)
A6: for the fall chinook sport fishery on the Hanford Reach of the Columbia River. The expansion factors
A7: are based on 1994 dawn-to-dusk trailer count and aerial boat count data.
A8: ______________________________________________________________________________________________________________________________________________________________________________________________________
A10: ( B ) | C10: Expansion converting trailer counts
C11: to daily peak trailer counts
A12: ____________________________________________________________________________________________________________
D13: Vernita ramps
A14: Month | D14: ___________________________________________________________________ | H14: Ringold &
B15: Hour | D15: Weekday | F15: Weekend | H15: Wahluke | N15: ( A ) Expansion for missing counts
A16: ____________________________________________________________________________________________________________ | N16: __________________________________
A17: September | N17: Bridge | P17: 3.0059701 | Q17: x rough count
B18: 7 am | D18: 1.1989437 | F18: 1.2308917 | H18: 1.3238434 | N18: Rough | P18: 1.4985119 | Q18: x bridge count
B19: 8 am | D19: 1.0673981 | F19: 1.0980114 | H19: 1.1104478 | N19: Wahluke | P19: 1.6151762 | Q19: x Ringold count
B20: 9 am | D20: 1.0118871 | F20: 1.0348059 | H20: 1.0247934 | N20: Ringold | P20: 2.6255507 | Q20: x Wahluke count
B21: 10am | D21: 1 | F21: 1.0104575 | H21: 1 | N21: _____________________________________________________________________________________________________________________________________
B22: 11am | D22: 1.0333839 | F22: 1 | H22: 1.0276243
B23: noon | D23: 1.2634508 | F23: 1.1367647 | H23: 1.2277228
B24: 1 pm | D24: 1.4041237 | F24: 1.2308917 | H24: 1.3932584
A25: October
B26: 7 am | D26: 1.3450065 | F26: 1.2643573 | H26: 1.2094595
B27: 8 am | D27: 1.0904311 | F27: 1.0491679 | H27: 1.0376812
B28: 9 am | D28: 1.0287698 | F28: 1.0028923 | H28: 0.99721448
B29: 10am | D29: 1 | F29: 1 | H29: 1
B30: 11am | D30: 1.0443102 | F30: 1.0483749 | H30: 1.1737705
B31: noon | D31: 1.2185664 | F31: 1.2124126 | H31: 1.5105485
B32: 1 pm | D32: 1.3900804 | F32: 1.4010101 | H32: 1.6807512
A33: ____________________________________________________________________________________________________________
A35: ( C ) | C35: Expansion of the peak trailer count | K35: ( D ) | M35: Expansion of the peak
C36: to the peak boat count for the river | M36: boat count to the day's
C37: from RM342 to Priest Rapids Dam | M37: total boat trips
A38: _______________________________________________________________________________________________________________________________________ | K38: _______________________________________________________________________________________________________________________________________
F39: Ramps | N39: Ramps
D40: ___________________________________________________________________ | N40: ___________________________________________________________________ | S40: _______________________________________________________________________________________________________________________________________
D41: Vernita | F41: Wahluke, | H41: Ringold | N41: Vernita | P41: Ringold | S41: Number of
D42: bridge & | F42: Vernita | H42: Wahluke, | N42: bridge & | P42: Wahluke, | S42: sampler | U42: Sample
A43: Week | D43: rough | F43: B&R | H43: Vern B&R | K43: Week | N43: rough | P43: Vern B&R | S43: days/week | U43: rate
A44: _______________________________________________________________________________________________________________________________________ | K44: _______________________________________________________________________________________________________________________________________ | S44: _______________________________________________________________________________________________________________________________________
B46: 36 | D46: 2.64 | F46: 2.13 | H46: 1.84 | L46: 36 | N46: 1.246526 | P46: 1.468658 | S46: 4 | U46: 0.069297078
B47: 37 | D47: 2.64 | F47: 2.13 | H47: 1.84 | L47: 37 | N47: 1.4203241 | P47: 1.2014592 | S47: 5 | U47: 0.11853871
...

Sheet Harvest
G2: Aug | H2: =H31+H34+H35+H36 -> 0 | I2: =I31+I34+I35+I36 -> 0 | J2: =J31+J34+J35+J36 -> 0 | K2: =K31+K34+K35+K36 -> 0 | L2: =L31+L34+L35+L36 -> 0 | M2: =M31+M34+M35+M36 -> 0
G3: Sept | H3: =H37+H38+H39+H40+H51+H61+H71+SUM(H74:H78) -> 411 | I3: =I37+I38+I39+I40+I51+I61+I71+SUM(I74:I78) -> 282 | J3: =J37+J38+J39+J40+J51+J61+J71+SUM(J74:J78) -> 129 | K3: =K37+K38+K39+K40+K51+K61+K71+SUM(K74:K78) -> 26 | L3: =L37+L38+L39+L40+L51+L61+L71+SUM(L74:L78) -> 16 | M3: =M37+M38+M39+M40+M51+M61+M71+SUM(M74:M78) -> 10
G4: Oct | H4: =H79+H80+H91+H101+H111+H121 -> 1607 | I4: =I79+I80+I91+I101+I111+I121 -> 1031 | J4: =J79+J80+J91+J101+J111+J121 -> 576 | K4: =K79+K80+K91+K101+K111+K121 -> 68 | L4: =L79+L80+L91+L101+L111+L121 -> 36 | M4: =M79+M80+M91+M101+M111+M121 -> 32
B6: Sampled | D6: =D22+D32+D42+D52+D62+D72+D82+D92+D102+D112+D122+D132 -> 1755 | E6: =E22+E32+E42+E52+E62+E72+E82+E92+E102+E112+E122+E132 -> 4794 | F6: =F22+F32+F42+F52+F62+F72+F82+F92+F102+F112+F122+F132 -> 29853.46 | H6: =H21+H31+H41+H51+H61+H71+H81+H91+H101+H111+H121+H131 -> 2038 | I6: =I21+I31+I41+I51+I61+I71+I81+I91+I101+I111+I121+I131 -> 1320 | J6: =J21+J31+J41+J51+J61+J71+J81+J91+J101+J111+J121+J131 -> 718 | K6: =K21+K31+K41+K51+K61+K71+K81+K91+K101+K111+K121+K131 -> 94 | L6: =L21+L31+L41+L51+L61+L71+L81+L91+L101+L111+L121+L131 -> 52 | M6: =M21+M31+M41+M51+M61+M71+M81+M91+M101+M111+M121+M131 -> 42 | N6: =N21+N31+N41+N51+N61+N71+N81+N91+N101+N111+N121+N131 -> 17 | O6: =O21+O31+O41+O51+O61+O71+O81+O91+O101+O111+O121+O131 -> 4 | ... V6: =V21+V31+V41+V51+V61+V71+V81+V91+V101+V111+V121+V131 -> 0 | X6: =X21+X31+X41+X51+X61+X71+X81+X91+X101+X111+X121+X131 -> 0 | Y6: =Y21+Y31+Y41+Y51+Y61+Y71+Y81+Y91+Y101+Y111+Y121+Y131 -> 0 | Z6: =Z21+Z31+Z41+Z51+Z61+Z71+Z81+Z91+Z101+Z111+Z121+Z131 -> 25 | AA6: =AA21+AA31+AA41+AA51+AA61+AA71+AA81+AA91+AA101+AA111+AA121+AA131 -> 6 | AB6: =AB21+AB31+AB41+AB51+AB61+AB71+AB81+AB91+AB101+AB111+AB121+AB131 -> 0 | AC6: =AC21+AC31+AC41+AC51+AC61+AC71+AC81+AC91+AC101+AC111+AC121+AC131 -> 0 | AD6: =AD21+AD31+AD41+AD51+AD61+AD71+AD81+AD91+AD101+AD111+AD121+AD131 -> 9 | AE6: =AE21+AE31+AE41+AE51+AE61+AE71+AE81+AE91+AE101+AE111+AE121+AE131 -> 22 | ... CQ6: =CQ21+CQ31+CQ41+CQ51+CQ61+CQ71+CQ81+CQ91+CQ101+CQ111+CQ121+CQ131 -> 0
B7: Expanded | C7: =+C32+C42+C52+C62+C72+C82+C92+C102+C112 -> 6165.9308 | H7: =+H32+H42+H52+H62+H72+H82+H92+H102+H112 -> 7136.8062 | I7: =I22+I32+I42+I52+I62+I72+I82+I92+I102+I112+I122+I132 -> 4764.6906 | J7: =J22+J32+J42+J52+J62+J72+J82+J92+J102+J112+J122+J132 -> 2550.8202 | K7: =K22+K32+K42+K52+K62+K72+K82+K92+K102+K112+K122+K132 -> 332.58779 | L7: =L22+L32+L42+L52+L62+L72+L82+L92+L102+L112+L122+L132 -> 186.74188 | M7: =M22+M32+M42+M52+M62+M72+M82+M92+M102+M112+M122+M132 -> 145.84591 | N7: =N22+N32+N42+N52+N62+N72+N82+N92+N102+N112+N122+N132 -> 59.178591 | O7: =O22+O32+O42+O52+O62+O72+O82+O92+O102+O112+O122+O132 -> 12.803271 | P7: =P22+P32+P42+P52+P62+P72+P82+P92+P102+P112+P122+P132 -> 46.37532 | ... V7: =V22+V32+V42+V52+V62+V72+V82+V92+V102+V112+V122+V132 -> 0 | X7: =X22+X32+X42+X52+X62+X72+X82+X92+X102+X112+X122+X132 -> 0 | Y7: =Y22+Y32+Y42+Y52+Y62+Y72+Y82+Y92+Y102+Y112+Y122+Y132 -> 0 | Z7: =Z22+Z32+Z42+Z52+Z62+Z72+Z82+Z92+Z102+Z112+Z122+Z132 -> 89.431446 | AA7: =AA22+AA32+AA42+AA52+AA62+AA72+AA82+AA92+AA102+AA112+AA122+AA132 -> 24.064632 | AB7: =AB22+AB32+AB42+AB52+AB62+AB72+AB82+AB92+AB102+AB112+AB122+AB132 -> 0 | AC7: =AC22+AC32+AC42+AC52+AC62+AC72+AC82+AC92+AC102+AC112+AC122+AC132 -> 0 | AD7: =AD22+AD32+AD42+AD52+AD62+AD72+AD82+AD92+AD102+AD112+AD122+AD132 -> 31.907017 | AE7: =AE22+AE32+AE42+AE52+AE62+AE72+AE82+AE92+AE102+AE112+AE122+AE132 -> 83.47181 | ... CQ7: =CQ22+CQ32+CQ42+CQ52+CQ62+CQ72+CQ82+CQ92+CQ102+CQ112+CQ122+CQ132 -> 0
B8: From Summary
AW10: Salmon Anglers Only | BE10: Salmon Anglers Only (Hanford - PRD) | BM10: Salmon Anglers Only (Hwy 395 - Hanford) | BU10: Salmon/Steelhead Anglers | CC10: Salmon/Steelhead Anglers (Hanford - PRD) | CK10: Salmon/Steelhead Anglers (Hwy 395 - Hanford)
H11: Harvest (Sampled) | T11: Catch & Release | AD11: Catch and Harvest (Sampled) | AW11: Steelhead | BE11: Steelhead | BM11: Steelhead | BU11: Steelhead | CC11: Steelhead | CK11: Steelhead
A12: Day | B12: Date | C12: Boats | G12: Sample (%) | H12: Chinook | N12: Coho | T12: Chinook | W12: Coho | Z12: Sturgeon | AD12: Walleye | AF12: SMB | AH12: NPM | AJ12: Carp | AL12: C. Catfish | AN12: Sucker | AP12: Shad | AR12: Trout | AT12: Whitefish | AW12: Catch | BA12: Harvest | BE12: Catch | BI12: Harvest | BM12: Catch | BQ12: Harvest | BU12: Catch | BY12: Harvest | CC12: Catch | CG12: Harvest | CK12: Catch | CO12: Harvest
C13: Total | D13: Sampled | E13: Anglers | F13: Hours | H13: Adult | I13: NM | J13: AD | K13: Jacks | L13: NM | M13: AD | N13: Adult | O13: NM | P13: AD | Q13: Jack | R13: NM | S13: AD | T13: Adult | U13: Jacks | V13: Sockeye | W13: Adult | X13: Jacks | Z13: <43" | AA13: 43"-54" | AB13: >54" | AC13: Unk | AD13: Catch | AE13: Harvest | AF13: Catch | AG13: Harvest | AH13: Catch | AI13: Harvest | AJ13: Catch | AK13: Harvest | AL13: Catch | AM13: Harvest | AN13: Catch | AO13: Harvest | AP13: Catch | AQ13: Harvest | AR13: Catch | AS13: Harvest | AT13: Catch | AU13: Harvest | AW13: AdRv | AX13: Ad Only | AY13: Wild | AZ13: Unk | BA13: AdRv | BB13: Ad Only | BC13: Wild | BE13: AdRv | BF13: Ad Only | BG13: Wild | BH13: Unk | BI13: AdRv | BJ13: Ad Only | BK13: Wild | BM13: AdRv | BN13: Ad Only | BO13: Wild | BP13: Unk | BQ13: AdRv | BR13: Ad Only | BS13: Wild | BU13: AdRv | BV13: Ad Only | BW13: Wild | BX13: Unk | BY13: AdRv | BZ13: Ad Only | CA13: Wild | CC13: AdRv | CD13: Ad Only | CE13: Wild | CF13: Unk | CG13: AdRv | CH13: Ad Only | CI13: Wild | CK13: AdRv | CL13: Ad Only | CM13: Wild | CN13: Unk | CO13: AdRv | CP13: Ad Only | CQ13: Wild
A14: Mon | B14: 45880 | C14: =Boats!J50 -> 0 | H14: =SUM(I14:J14) -> 0 | K14: =SUM(L14:M14) -> 0 | N14: =SUM(O14:P14) -> 0 | Q14: =SUM(R14:S14) -> 0
A15: Tue | B15: =B14+1 -> 45881 | C15: =Boats!J57 -> 0 | H15: =SUM(I15:J15) -> 0 | K15: =SUM(L15:M15) -> 0 | N15: =SUM(O15:P15) -> 0 | Q15: =SUM(R15:S15) -> 0
A16: Wed | B16: =B15+1 -> 45882 | C16: =Boats!J64 -> 0 | H16: =SUM(I16:J16) -> 0 | K16: =SUM(L16:M16) -> 0 | N16: =SUM(O16:P16) -> 0 | Q16: =SUM(R16:S16) -> 0
A17: Thu | B17: =B16+1 -> 45883 | C17: =Boats!J71 -> 0 | H17: =SUM(I17:J17) -> 0 | K17: =SUM(L17:M17) -> 0 | N17: =SUM(O17:P17) -> 0 | Q17: =SUM(R17:S17) -> 0
A18: Fri | B18: =B17+1 -> 45884 | C18: =Boats!J78 -> 0 | H18: =SUM(I18:J18) -> 0 | K18: =SUM(L18:M18) -> 0 | N18: =SUM(O18:P18) -> 0 | Q18: =SUM(R18:S18) -> 0
A19: Sat | B19: =B18+1 -> 45885 | C19: =Boats!J85 -> 20.034567 | D19: 4 | E19: 8 | F19: 53.67 | H19: =SUM(I19:J19) -> 0 | K19: =SUM(L19:M19) -> 0 | N19: =SUM(O19:P19) -> 0 | Q19: =SUM(R19:S19) -> 0 | AA19: 2 | AZ19: 2 | BH19: 2
A20: Sun | B20: =B19+1 -> 45886 | C20: =Boats!J92 -> 11.125554 | D20: 5 | E20: 8 | F20: 69.7 | H20: =SUM(I20:J20) -> 0 | K20: =SUM(L20:M20) -> 0 | N20: =SUM(O20:P20) -> 0 | Q20: =SUM(R20:S20) -> 0
A21: Sampled | H21: =SUM(H14:H20) -> 0 | I21: =SUM(I14:I20) -> 0 | J21: =SUM(J14:J20) -> 0 | K21: =SUM(K14:K20) -> 0 | L21: =SUM(L14:L20) -> 0 | M21: =SUM(M14:M20) -> 0 | N21: =SUM(N14:N20) -> 0 | O21: =SUM(O14:O20) -> 0 | ... X21: =SUM(X14:X20) -> 0 | Z21: =SUM(Z14:Z20) -> 0 | AA21: =SUM(AA14:AA20) -> 2 | AB21: =SUM(AB14:AB20) -> 0 | AC21: =SUM(AC14:AC20) -> 0 | AD21: =SUM(AD14:AD20) -> 0 | AE21: =SUM(AE14:AE20) -> 0 | AF21: =SUM(AF14:AF20) -> 0 | AG21: =SUM(AG14:AG20) -> 0 | ... AU21: =SUM(AU14:AU20) -> 0 | AW21: =SUM(AW14:AW20) -> 0 | AX21: =SUM(AX14:AX20) -> 0 | AY21: =SUM(AY14:AY20) -> 0 | AZ21: =SUM(AZ14:AZ20) -> 2 | BA21: =SUM(BA14:BA20) -> 0 | BB21: =SUM(BB14:BB20) -> 0 | BC21: =SUM(BC14:BC20) -> 0 | BE21: =SUM(BE14:BE20) -> 0 | BF21: =SUM(BF14:BF20) -> 0 | BG21: =SUM(BG14:BG20) -> 0 | BH21: =SUM(BH14:BH20) -> 2 | BI21: =SUM(BI14:BI20) -> 0 | BJ21: =SUM(BJ14:BJ20) -> 0 | BK21: =SUM(BK14:BK20) -> 0 | BM21: =SUM(BM14:BM20) -> 0 | BN21: =SUM(BN14:BN20) -> 0 | BO21: =SUM(BO14:BO20) -> 0 | BP21: =SUM(BP14:BP20) -> 0 | BQ21: =SUM(BQ14:BQ20) -> 0 | BR21: =SUM(BR14:BR20) -> 0 | BS21: =SUM(BS14:BS20) -> 0 | BU21: =SUM(BU14:BU20) -> 0 | BV21: =SUM(BV14:BV20) -> 0 | BW21: =SUM(BW14:BW20) -> 0 | BX21: =SUM(BX14:BX20) -> 0 | BY21: =SUM(BY14:BY20) -> 0 | BZ21: =SUM(BZ14:BZ20) -> 0 | CA21: =SUM(CA14:CA20) -> 0 | CC21: =SUM(CC14:CC20) -> 0 | CD21: =SUM(CD14:CD20) -> 0 | CE21: =SUM(CE14:CE20) -> 0 | CF21: =SUM(CF14:CF20) -> 0 | CG21: =SUM(CG14:CG20) -> 0 | CH21: =SUM(CH14:CH20) -> 0 | CI21: =SUM(CI14:CI20) -> 0 | CK21: =SUM(CK14:CK20) -> 0 | CL21: =SUM(CL14:CL20) -> 0 | CM21: =SUM(CM14:CM20) -> 0 | CN21: =SUM(CN14:CN20) -> 0 | CO21: =SUM(CO14:CO20) -> 0 | CP21: =SUM(CP14:CP20) -> 0 | CQ21: =SUM(CQ14:CQ20) -> 0
A22: Expanded | C22: =SUM(C14:C20) -> 31.160121 | D22: =SUM(D14:D20) -> 9 | E22: =SUM(E14:E20) -> 16 | F22: =SUM(F14:F20) -> 123.37 | G22: =D22/C22 -> 0.28883071 | H22: =H21/$G22 -> 0 | I22: =I21/$G22 -> 0 | J22: =J21/$G22 -> 0 | K22: =K21/$G22 -> 0 | L22: =L21/$G22 -> 0 | M22: =M21/$G22 -> 0 | N22: =N21/$G22 -> 0 | O22: =O21/$G22 -> 0 | ... X22: =X21/$G22 -> 0 | Z22: =Z21/$G22 -> 0 | AA22: =AA21/$G22 -> 6.9244714 | AB22: =AB21/$G22 -> 0 | AC22: =AC21/$G22 -> 0 | AD22: =AD21/$G22 -> 0 | AE22: =AE21/$G22 -> 0 | AF22: =AF21/$G22 -> 0 | AG22: =AG21/$G22 -> 0 | ... AU22: =AU21/$G22 -> 0 | AW22: =AW21/$G22 -> 0 | AX22: =AX21/$G22 -> 0 | AY22: =AY21/$G22 -> 0 | AZ22: =AZ21/$G22 -> 6.9244714 | BA22: =BA21/$G22 -> 0 | BB22: =BB21/$G22 -> 0 | BC22: =BC21/$G22 -> 0 | BE22: =BE21/$G22 -> 0 | BF22: =BF21/$G22 -> 0 | BG22: =BG21/$G22 -> 0 | BH22: =BH21/$G22 -> 6.9244714 | BI22: =BI21/$G22 -> 0 | BJ22: =BJ21/$G22 -> 0 | BK22: =BK21/$G22 -> 0 | BM22: =BM21/$G22 -> 0 | BN22: =BN21/$G22 -> 0 | BO22: =BO21/$G22 -> 0 | BP22: =BP21/$G22 -> 0 | BQ22: =BQ21/$G22 -> 0 | BR22: =BR21/$G22 -> 0 | BS22: =BS21/$G22 -> 0 | BU22: =BU21/$G22 -> 0 | BV22: =BV21/$G22 -> 0 | BW22: =BW21/$G22 -> 0 | BX22: =BX21/$G22 -> 0 | BY22: =BY21/$G22 -> 0 | BZ22: =BZ21/$G22 -> 0 | CA22: =CA21/$G22 -> 0 | CC22: =CC21/$G22 -> 0 | CD22: =CD21/$G22 -> 0 | CE22: =CE21/$G22 -> 0 | CF22: =CF21/$G22 -> 0 | CG22: =CG21/$G22 -> 0 | CH22: =CH21/$G22 -> 0 | CI22: =CI21/$G22 -> 0 | CK22: =CK21/$G22 -> 0 | CL22: =CL21/$G22 -> 0 | CM22: =CM21/$G22 -> 0 | CN22: =CN21/$G22 -> 0 | CO22: =CO21/$G22 -> 0 | CP22: =CP21/$G22 -> 0 | CQ22: =CQ21/$G22 -> 0
A24: Mon | B24: =B20+1 -> 45887 | C24: =Boats!J99 -> 0 | H24: =SUM(I24:J24) -> 0 | K24: =SUM(L24:M24) -> 0 | N24: =SUM(O24:P24) -> 0 | Q24: =SUM(R24:S24) -> 0
A25: Tue | B25: =B24+1 -> 45888 | C25: =Boats!J106 -> 3.8036065 | D25: 1 | E25: 1 | F25: 11 | H25: =SUM(I25:J25) -> 0 | K25: =SUM(L25:M25) -> 0 | N25: =SUM(O25:P25) -> 0 | Q25: =SUM(R25:S25) -> 0
A26: Wed | B26: =B25+1 -> 45889 | C26: =Boats!J113 -> 4.9552818 | D26: 2 | E26: 4 | F26: 28.83 | H26: =SUM(I26:J26) -> 0 | K26: =SUM(L26:M26) -> 0 | N26: =SUM(O26:P26) -> 0 | Q26: =SUM(R26:S26) -> 0 | AF26: 1
A27: Thu | B27: =B26+1 -> 45890 | C27: =Boats!J120 -> 0 | D27: 0 | E27: 0 | F27: 0 | H27: =SUM(I27:J27) -> 0 | K27: =SUM(L27:M27) -> 0 | N27: =SUM(O27:P27) -> 0 | Q27: =SUM(R27:S27) -> 0
A28: Fri | B28: =B27+1 -> 45891 | C28: =Boats!J127 -> 11.847452 | D28: 5 | E28: 10 | F28: 54.8 | H28: =SUM(I28:J28) -> 0 | K28: =SUM(L28:M28) -> 0 | N28: =SUM(O28:P28) -> 0 | Q28: =SUM(R28:S28) -> 0
A29: Sat | B29: =B28+1 -> 45892 | C29: =Boats!J134 -> 5.5495778 | D29: 2 | E29: 3 | F29: 7.93 | H29: =SUM(I29:J29) -> 0 | K29: =SUM(L29:M29) -> 0 | N29: =SUM(O29:P29) -> 0 | Q29: =SUM(R29:S29) -> 0 | AF29: 1
A30: Sun | B30: =B29+1 -> 45893 | C30: =Boats!J141 -> 21.309077 | D30: 7 | E30: 14 | F30: 67.53 | H30: =SUM(I30:J30) -> 0 | K30: =SUM(L30:M30) -> 0 | N30: =SUM(O30:P30) -> 0 | Q30: =SUM(R30:S30) -> 0 | Z30: 2 | AE30: 1
A31: Sampled | H31: =SUM(H24:H30) -> 0 | I31: =SUM(I24:I30) -> 0 | J31: =SUM(J24:J30) -> 0 | K31: =SUM(K24:K30) -> 0 | L31: =SUM(L24:L30) -> 0 | M31: =SUM(M24:M30) -> 0 | N31: =SUM(N24:N30) -> 0 | O31: =SUM(O24:O30) -> 0 | ... X31: =SUM(X24:X30) -> 0 | Z31: =SUM(Z24:Z30) -> 2 | AA31: =SUM(AA24:AA30) -> 0 | AB31: =SUM(AB24:AB30) -> 0 | AC31: =SUM(AC24:AC30) -> 0 | AD31: =SUM(AD24:AD30) -> 0 | AE31: =SUM(AE24:AE30) -> 1 | AF31: =SUM(AF24:AF30) -> 2 | AG31: =SUM(AG24:AG30) -> 0 | ... AU31: =SUM(AU24:AU30) -> 0 | AW31: =SUM(AW24:AW30) -> 0 | AX31: =SUM(AX24:AX30) -> 0 | AY31: =SUM(AY24:AY30) -> 0 | AZ31: =SUM(AZ24:AZ30) -> 0 | BA31: =SUM(BA24:BA30) -> 0 | BB31: =SUM(BB24:BB30) -> 0 | BC31: =SUM(BC24:BC30) -> 0 | BE31: =SUM(BE24:BE30) -> 0 | BF31: =SUM(BF24:BF30) -> 0 | BG31: =SUM(BG24:BG30) -> 0 | BH31: =SUM(BH24:BH30) -> 0 | BI31: =SUM(BI24:BI30) -> 0 | BJ31: =SUM(BJ24:BJ30) -> 0 | BK31: =SUM(BK24:BK30) -> 0 | BM31: =SUM(BM24:BM30) -> 0 | BN31: =SUM(BN24:BN30) -> 0 | BO31: =SUM(BO24:BO30) -> 0 | BP31: =SUM(BP24:BP30) -> 0 | BQ31: =SUM(BQ24:BQ30) -> 0 | BR31: =SUM(BR24:BR30) -> 0 | BS31: =SUM(BS24:BS30) -> 0 | BU31: =SUM(BU24:BU30) -> 0 | BV31: =SUM(BV24:BV30) -> 0 | BW31: =SUM(BW24:BW30) -> 0 | BX31: =SUM(BX24:BX30) -> 0 | BY31: =SUM(BY24:BY30) -> 0 | BZ31: =SUM(BZ24:BZ30) -> 0 | CA31: =SUM(CA24:CA30) -> 0 | CC31: =SUM(CC24:CC30) -> 0 | CD31: =SUM(CD24:CD30) -> 0 | CE31: =SUM(CE24:CE30) -> 0 | CF31: =SUM(CF24:CF30) -> 0 | CG31: =SUM(CG24:CG30) -> 0 | CH31: =SUM(CH24:CH30) -> 0 | CI31: =SUM(CI24:CI30) -> 0 | CK31: =SUM(CK24:CK30) -> 0 | CL31: =SUM(CL24:CL30) -> 0 | CM31: =SUM(CM24:CM30) -> 0 | CN31: =SUM(CN24:CN30) -> 0 | CO31: =SUM(CO24:CO30) -> 0 | CP31: =SUM(CP24:CP30) -> 0 | CQ31: =SUM(CQ24:CQ30) -> 0
A32: Expanded | C32: =SUM(C24:C30) -> 47.464995 | D32: =SUM(D24:D30) -> 17 | E32: =SUM(E24:E30) -> 32 | F32: =SUM(F24:F30) -> 170.09 | G32: =D32/C32 -> 0.35815868 | H32: =H31/$G32 -> 0 | I32: =I31/$G32 -> 0 | J32: =J31/$G32 -> 0 | K32: =K31/$G32 -> 0 | L32: =L31/$G32 -> 0 | M32: =M31/$G32 -> 0 | N32: =N31/$G32 -> 0 | O32: =O31/$G32 -> 0 | ... X32: =X31/$G32 -> 0 | Z32: =Z31/$G32 -> 5.584117 | AA32: =AA31/$G32 -> 0 | AB32: =AB31/$G32 -> 0 | AC32: =AC31/$G32 -> 0 | AD32: =AD31/$G32 -> 0 | AE32: =AE31/$G32 -> 2.7920585 | AF32: =AF31/$G32 -> 5.584117 | AG32: =AG31/$G32 -> 0 | ... AU32: =AU31/$G32 -> 0 | AW32: =AW31/$G32 -> 0 | AX32: =AX31/$G32 -> 0 | AY32: =AY31/$G32 -> 0 | AZ32: =AZ31/$G32 -> 0 | BA32: =BA31/$G32 -> 0 | BB32: =BB31/$G32 -> 0 | BC32: =BC31/$G32 -> 0 | BE32: =BE31/$G32 -> 0 | BF32: =BF31/$G32 -> 0 | BG32: =BG31/$G32 -> 0 | BH32: =BH31/$G32 -> 0 | BI32: =BI31/$G32 -> 0 | BJ32: =BJ31/$G32 -> 0 | BK32: =BK31/$G32 -> 0 | BM32: =BM31/$G32 -> 0 | BN32: =BN31/$G32 -> 0 | BO32: =BO31/$G32 -> 0 | BP32: =BP31/$G32 -> 0 | BQ32: =BQ31/$G32 -> 0 | BR32: =BR31/$G32 -> 0 | BS32: =BS31/$G32 -> 0 | BU32: =BU31/$G32 -> 0 | BV32: =BV31/$G32 -> 0 | BW32: =BW31/$G32 -> 0 | BX32: =BX31/$G32 -> 0 | BY32: =BY31/$G32 -> 0 | BZ32: =BZ31/$G32 -> 0 | CA32: =CA31/$G32 -> 0 | CC32: =CC31/$G32 -> 0 | CD32: =CD31/$G32 -> 0 | CE32: =CE31/$G32 -> 0 | CF32: =CF31/$G32 -> 0 | CG32: =CG31/$G32 -> 0 | CH32: =CH31/$G32 -> 0 | CI32: =CI31/$G32 -> 0 | CK32: =CK31/$G32 -> 0 | CL32: =CL31/$G32 -> 0 | CM32: =CM31/$G32 -> 0 | CN32: =CN31/$G32 -> 0 | CO32: =CO31/$G32 -> 0 | CP32: =CP31/$G32 -> 0 | CQ32: =CQ31/$G32 -> 0
A34: Mon | B34: =B30+1 -> 45894 | C34: =Boats!J148 -> 2.0231674 | D34: 0 | E34: 0 | F34: 0 | H34: =SUM(I34:J34) -> 0 | K34: =SUM(L34:M34) -> 0 | N34: =SUM(O34:P34) -> 0 | Q34: =SUM(R34:S34) -> 0
A35: Tue | B35: =B34+1 -> 45895 | C35: =Boats!J155 -> 3.072894 | D35: 1 | E35: 2 | F35: 15.07 | H35: =SUM(I35:J35) -> 0 | K35: =SUM(L35:M35) -> 0 | N35: =SUM(O35:P35) -> 0 | Q35: =SUM(R35:S35) -> 0
A36: Wed | B36: =B35+1 -> 45896 | C36: =Boats!J162 -> 2.4472044 | D36: 1 | E36: 2 | F36: 9.2 | H36: =SUM(I36:J36) -> 0 | K36: =SUM(L36:M36) -> 0 | N36: =SUM(O36:P36) -> 0 | Q36: =SUM(R36:S36) -> 0
A37: Thu | B37: =B36+1 -> 45897 | C37: =Boats!J169 -> 12.098011 | D37: 3 | E37: 5 | F37: 33.63 | H37: =SUM(I37:J37) -> 1 | J37: 1 | K37: =SUM(L37:M37) -> 0 | N37: =SUM(O37:P37) -> 0 | Q37: =SUM(R37:S37) -> 0
A38: Fri | B38: =B37+1 -> 45898 | C38: =Boats!J176 -> 16.224786 | D38: 11 | E38: 19 | F38: 110.43 | H38: =SUM(I38:J38) -> 0 | K38: =SUM(L38:M38) -> 0 | N38: =SUM(O38:P38) -> 0 | Q38: =SUM(R38:S38) -> 0 | AD38: 3 | AF38: 6
A39: Sat | B39: =B38+1 -> 45899 | C39: =Boats!J183 -> 33.182445 | D39: 10 | E39: 25 | F39: 178.27 | H39: =SUM(I39:J39) -> 3 | I39: 3 | K39: =SUM(L39:M39) -> 0 | N39: =SUM(O39:P39) -> 0 | Q39: =SUM(R39:S39) -> 0
A40: Sun | B40: =B39+1 -> 45900 | C40: =Boats!J190 -> 32.032917 | D40: 8 | E40: 16 | F40: 78.48 | H40: =SUM(I40:J40) -> 4 | I40: 4 | K40: =SUM(L40:M40) -> 0 | N40: =SUM(O40:P40) -> 0 | Q40: =SUM(R40:S40) -> 0 | AD40: 1
A41: Sampled | H41: =SUM(H34:H40) -> 8 | I41: =SUM(I34:I40) -> 7 | J41: =SUM(J34:J40) -> 1 | K41: =SUM(K34:K40) -> 0 | L41: =SUM(L34:L40) -> 0 | M41: =SUM(M34:M40) -> 0 | N41: =SUM(N34:N40) -> 0 | O41: =SUM(O34:O40) -> 0 | ... X41: =SUM(X34:X40) -> 0 | Z41: =SUM(Z34:Z40) -> 0 | AA41: =SUM(AA34:AA40) -> 0 | AB41: =SUM(AB34:AB40) -> 0 | AC41: =SUM(AC34:AC40) -> 0 | AD41: =SUM(AD34:AD40) -> 4 | AE41: =SUM(AE34:AE40) -> 0 | AF41: =SUM(AF34:AF40) -> 6 | AG41: =SUM(AG34:AG40) -> 0 | ... AU41: =SUM(AU34:AU40) -> 0 | AW41: =SUM(AW34:AW40) -> 0 | AX41: =SUM(AX34:AX40) -> 0 | AY41: =SUM(AY34:AY40) -> 0 | AZ41: =SUM(AZ34:AZ40) -> 0 | BA41: =SUM(BA34:BA40) -> 0 | BB41: =SUM(BB34:BB40) -> 0 | BC41: =SUM(BC34:BC40) -> 0 | BE41: =SUM(BE34:BE40) -> 0 | BF41: =SUM(BF34:BF40) -> 0 | BG41: =SUM(BG34:BG40) -> 0 | BH41: =SUM(BH34:BH40) -> 0 | BI41: =SUM(BI34:BI40) -> 0 | BJ41: =SUM(BJ34:BJ40) -> 0 | BK41: =SUM(BK34:BK40) -> 0 | BM41: =SUM(BM34:BM40) -> 0 | BN41: =SUM(BN34:BN40) -> 0 | BO41: =SUM(BO34:BO40) -> 0 | BP41: =SUM(BP34:BP40) -> 0 | BQ41: =SUM(BQ34:BQ40) -> 0 | BR41: =SUM(BR34:BR40) -> 0 | BS41: =SUM(BS34:BS40) -> 0 | BU41: =SUM(BU34:BU40) -> 0 | BV41: =SUM(BV34:BV40) -> 0 | BW41: =SUM(BW34:BW40) -> 0 | BX41: =SUM(BX34:BX40) -> 0 | BY41: =SUM(BY34:BY40) -> 0 | BZ41: =SUM(BZ34:BZ40) -> 0 | CA41: =SUM(CA34:CA40) -> 0 | CC41: =SUM(CC34:CC40) -> 0 | CD41: =SUM(CD34:CD40) -> 0 | CE41: =SUM(CE34:CE40) -> 0 | CF41: =SUM(CF34:CF40) -> 0 | CG41: =SUM(CG34:CG40) -> 0 | CH41: =SUM(CH34:CH40) -> 0 | CI41: =SUM(CI34:CI40) -> 0 | CK41: =SUM(CK34:CK40) -> 0 | CL41: =SUM(CL34:CL40) -> 0 | CM41: =SUM(CM34:CM40) -> 0 | CN41: =SUM(CN34:CN40) -> 0 | CO41: =SUM(CO34:CO40) -> 0 | CP41: =SUM(CP34:CP40) -> 0 | CQ41: =SUM(CQ34:CQ40) -> 0
A42: Expanded | C42: =SUM(C34:C40) -> 101.08143 | D42: =SUM(D34:D40) -> 34 | E42: =SUM(E34:E40) -> 69 | F42: =SUM(F34:F40) -> 425.08 | G42: =D42/C42 -> 0.33636249 | H42: =H41/$G42 -> 23.783865 | I42: =I41/$G42 -> 20.810882 | J42: =J41/$G42 -> 2.9729831 | K42: =K41/$G42 -> 0 | L42: =L41/$G42 -> 0 | M42: =M41/$G42 -> 0 | N42: =N41/$G42 -> 0 | O42: =O41/$G42 -> 0 | ... X42: =X41/$G42 -> 0 | Z42: =Z41/$G42 -> 0 | AA42: =AA41/$G42 -> 0 | AB42: =AB41/$G42 -> 0 | AC42: =AC41/$G42 -> 0 | AD42: =AD41/$G42 -> 11.891932 | AE42: =AE41/$G42 -> 0 | AF42: =AF41/$G42 -> 17.837899 | AG42: =AG41/$G42 -> 0 | ... AU42: =AU41/$G42 -> 0 | AW42: =AW41/$G42 -> 0 | AX42: =AX41/$G42 -> 0 | AY42: =AY41/$G42 -> 0 | AZ42: =AZ41/$G42 -> 0 | BA42: =BA41/$G42 -> 0 | BB42: =BB41/$G42 -> 0 | BC42: =BC41/$G42 -> 0 | BE42: =BE41/$G42 -> 0 | BF42: =BF41/$G42 -> 0 | BG42: =BG41/$G42 -> 0 | BH42: =BH41/$G42 -> 0 | BI42: =BI41/$G42 -> 0 | BJ42: =BJ41/$G42 -> 0 | BK42: =BK41/$G42 -> 0 | BM42: =BM41/$G42 -> 0 | BN42: =BN41/$G42 -> 0 | BO42: =BO41/$G42 -> 0 | BP42: =BP41/$G42 -> 0 | BQ42: =BQ41/$G42 -> 0 | BR42: =BR41/$G42 -> 0 | BS42: =BS41/$G42 -> 0 | BU42: =BU41/$G42 -> 0 | BV42: =BV41/$G42 -> 0 | BW42: =BW41/$G42 -> 0 | BX42: =BX41/$G42 -> 0 | BY42: =BY41/$G42 -> 0 | BZ42: =BZ41/$G42 -> 0 | CA42: =CA41/$G42 -> 0 | CC42: =CC41/$G42 -> 0 | CD42: =CD41/$G42 -> 0 | CE42: =CE41/$G42 -> 0 | CF42: =CF41/$G42 -> 0 | CG42: =CG41/$G42 -> 0 | CH42: =CH41/$G42 -> 0 | CI42: =CI41/$G42 -> 0 | CK42: =CK41/$G42 -> 0 | CL42: =CL41/$G42 -> 0 | CM42: =CM41/$G42 -> 0 | CN42: =CN41/$G42 -> 0 | CO42: =CO41/$G42 -> 0 | CP42: =CP41/$G42 -> 0 | CQ42: =CQ41/$G42 -> 0
A44: Mon | B44: =B40+1 -> 45901 | C44: =Boats!J197 -> 0 | D44: 0 | E44: 0 | F44: 0 | H44: =SUM(I44:J44) -> 0 | K44: =SUM(L44:M44) -> 0 | N44: =SUM(O44:P44) -> 0 | Q44: =SUM(R44:S44) -> 0
A45: Tue | B45: =B44+1 -> 45902 | C45: =Boats!J204 -> 8.2267357 | D45: 2 | E45: 2 | F45: 28.83 | H45: =SUM(I45:J45) -> 1 | J45: 1 | K45: =SUM(L45:M45) -> 0 | N45: =SUM(O45:P45) -> 0 | Q45: =SUM(R45:S45) -> 0
A46: Wed | B46: =B45+1 -> 45903 | C46: =Boats!J211 -> 14.656206 | D46: 5 | E46: 8 | F46: 54.83 | H46: =SUM(I46:J46) -> 0 | K46: =SUM(L46:M46) -> 0 | N46: =SUM(O46:P46) -> 0 | Q46: =SUM(R46:S46) -> 0
...

Sheet Boats
O1: -9.15 | P1: 2.2038323
A2: 2024 Hanford Reach Fall Chinook Counts and Expansions | O2: 9/16-30 | P2: 1.6911804 | AA2: August | AC2: 15.52 | AD2: 1.128 | AE2: 1.22 | AG2: 1.1
G3: Vernita | H3: Vernita | I3: Vernita | M3: Vernita | W3: Waluke
D4: Vernita | E4: Vernita | F4: Vernita | G4: & Waluke | H4: & Waluke | I4: & Waluke | K4: Vernita | L4: Vernita | M4: & Ringold | O4: Vernita | U4: Waluke | V4: Waluke | W4: & Ringold | X4: Waluke | AB4: Ringold
C5: Vernita | D5: & Waluke | E5: & Waluke | F5: & Waluke | G5: & Ringold | H5: & Ringold | I5: & Snyder | J5: Vernita | K5: & Ringold | L5: & Ringold | M5: & Snyder | N5: Vernita | O5: & Snyder | P5: Vernita | R5: Waluke | S5: Waluke | T5: Waluke | U5: & Ringold | V5: & Ringold | W5: & Snyder | X5: & Snyder | Z5: Ringold | AA5: Ringold | AB5: & Snyder | AD5: Snyder
B6: Vernita | C6: & Waluke | D6: & Ringold | E6: & Snyder | F6: & Bateman | G6: & Snyder | H6: & Bateman | I6: & Bateman | J6: & Ringold | K6: & Snyder | L6: & Bateman | M6: & Bateman | N6: & Snyder | O6: & Bateman | P6: & Bateman | Q6: Waluke | R6: & Ringold | S6: & Snyder | T6: & Bateman | U6: & Bateman | V6: & Snyder | W6: & Bateman | X6: & Bateman | Y6: Ringold | Z6: & Snyder | AA6: & Bateman | AB6: & Bateman | AC6: Snyder | AD6: & Bateman | AE6: Bateman | AG6: All
A7: August | B7: 19.444444 | C7: 19.444444 | D7: 14.942529 | E7: 6.9567583 | F7: 1.2623251 | G7: 6.2798442 | H7: 1.2381088 | I7: 1.1305752 | J7: 14.942529 | K7: 6.2798442 | L7: 1.2381088 | M7: 1.1111111 | N7: 6.9567583 | O7: 1.1305752 | P7: 1.2623251 | R7: 64.539007 | S7: 10.832295 | T7: 1.3499642 | U7: 1.3223055 | V7: 9.2754873 | W7: 1.1784512 | X7: 1.2003693 | Y7: 64.539007 | Z7: 9.2754873 | AA7: 1.3223055 | AB7: 1.1784512 | AC7: 10.832295 | AD7: 1.2003693 | AE7: 1.3499642 | AG7: 1.1111111
A8: Sept 1-15 | B8: 3.0563603 | C8: 2.6131249 | D8: 2.0659799 | E8: 1.874991 | F8: 1.5432111 | G8: 1.575587 | H8: 1.334494 | I8: 1.2521102 | J8: 2.3335329 | K8: 1.7265579 | L8: 1.4412323 | M8: 1.1841285 | N8: 2.0927558 | O8: 1.3456148 | P8: 1.6877568 | Q8: 18.019 | R8: 6.3757107 | S8: 4.8508524 | T8: 3.1170814 | U8: 2.3687637 | V8: 3.2520583 | W8: 1.7457691 | X8: 2.1210472 | Y8: 9.8669713 | Z8: 3.9682458 | AA8: 2.7272917 | AB8: 1.9330529 | AC8: 6.6378012 | AD8: 2.40403 | AE8: 3.769092 | AG8: 1.1111111
A9: Sept 16-30 | B9: 2.4087999 | C9: 1.984154 | D9: 1.5053217 | E9: 1.5534738 | F9: 1.6667837 | G9: 1.2437265 | H9: 1.3153143 | I9: 1.3519299 | J9: 1.7377367 | K9: 1.3982365 | L9: 1.4893677 | M9: 1.2328156 | N9: 1.8022241 | O9: 1.5364885 | P9: 1.956529 | Q9: 11.255 | R9: 4.0133994 | S9: 4.3749486 | T9: 5.4108636 | U9: 2.8974584 | V9: 2.571416 | W9: 2.0624701 | X9: 3.0812953 | Y9: 6.2376542 | Z9: 3.3328652 | AA9: 3.9019608 | AB9: 2.5252087 | AC9: 7.1568918 | AD9: 4.242858 | AE9: 10.420495 | AG9: 1.1111111
A10: Oct 1-15 | B10: 2.3563383 | C10: 1.8989219 | D10: 1.4484418 | E10: 1.4404741 | F10: 1.7586553 | G10: 1.1655034 | H10: 1.3653765 | I10: 1.3582942 | J10: 1.7001895 | K10: 1.3231521 | L10: 1.5868699 | M10: 1.2534899 | N10: 1.6892219 | O10: 1.5773114 | P10: 2.1441332 | Q10: 9.7821201 | R10: 3.75926 | S10: 3.7060563 | T10: 6.9334194 | U10: 3.2466326 | V10: 2.3062142 | W10: 2.102551 | X10: 3.2068729 | Y10: 6.1056595 | Z10: 3.0176495 | AA10: 4.8594614 | AB10: 2.6781979 | AC10: 5.9665417 | AD10: 4.7709258 | AE10: 23.808589 | AG10: 1.1111111
A11: Oct 16-31 | D11: 1.6236323 | E11: 3.5199247 | G11: 1.1111111 | H11: 1.6236323 | I11: 3.5199247 | J11: 1.6236323 | K11: 1.1111111 | L11: 1.6236323 | M11: 1.1111111 | N11: 3.5199247 | O11: 3.5199247 | R11: 1.6236323 | S11: 3.5199247 | U11: 1.6236323 | V11: 1.1111111 | W11: 1.1111111 | X11: 3.5199247 | Y11: 1.6236323 | Z11: 1.1111111 | AA11: 1.6236323 | AB11: 1.1111111 | AC11: 3.5199247 | AD11: 3.5199247 | AG11: 1.1111111
A13: ______________________________________________________________________________________________________________________________________________________________________________________________________________ | J13: 1.285
A14: Day | B14: Date | C14: Ramp | D14: Trailers | E14: Hour | F14: Salmon (%) | G14: Peak Hour Expansion | H14: Boats (expanded) | I14: Area Expansion | J14: Total Boats | K14: Evening Fishery | M14: Trailers | N14: Hour | O14: Salmon (%)
C15: Ramp | D15: counted | E15: Hour | F15: % Sal | G15: Expansion | H15: (exp) | J15: Boats | M15: counted | N15: Hour | O15: % Sal
A17: Thur | C17: Vernita | G17: =IF(E17<8,Factors!F$18,IF(E17<9,Factors!F$19,IF(E17<10,Factors!F$20,IF(E17<11,Factors!F$21,IF(E17<12,Factors!F$22,IF(E17<13,Factors!F$23)))))) -> 1.2308917 | H17: =D17*F17*G17 -> 0
C18: W. Bluffs | G18: =IF(E18<8,Factors!H$18,IF(E18<9,Factors!H$19,IF(E18<10,Factors!H$20,IF(E18<11,Factors!H$21,IF(E18<12,Factors!H$22,IF(E18<13,Factors!H$23)))))) -> 1.3238434 | H18: =D18*F18*G18 -> 0
A19: Tues | C19: Ringold | G19: =IF(E19<8,Factors!H$18,IF(E19<9,Factors!H$19,IF(E19<10,Factors!H$20,IF(E19<11,Factors!H$21,IF(E19<12,Factors!H$22,IF(E19<13,Factors!H$23)))))) -> 1.3238434 | H19: =D19*F19*G19 -> 0
C20: Bateman | G20: =IF(E20<8,Factors!H$18,IF(E20<9,Factors!H$19,IF(E20<10,Factors!H$20,IF(E20<11,Factors!H$21,IF(E20<12,Factors!H$22,IF(E20<13,Factors!H$23)))))) -> 1.3238434 | H20: =D20*F20*G20 -> 0
C21: Snyder | G21: =IF(E21<8,Factors!H$18,IF(E21<9,Factors!H$19,IF(E21<10,Factors!H$20,IF(E21<11,Factors!H$21,IF(E21<12,Factors!H$22,IF(E21<13,Factors!H$23)))))) -> 1.3238434 | H21: =D21*F21*G21 -> 0
H22: =SUM(H17:H21) -> 0 | I22: =$AG$8 -> 1.1111111 | J22: =H22*I22*J$13+K22 -> 0 | K22: =K21+K20 -> 0
A24: Fri | C24: Vernita | G24: =IF(E24<8,Factors!F$18,IF(E24<9,Factors!F$19,IF(E24<10,Factors!F$20,IF(E24<11,Factors!F$21,IF(E24<12,Factors!F$22,IF(E24<13,Factors!F$23)))))) -> 1.2308917 | H24: =D24*F24*G24 -> 0
C25: W. Bluffs | G25: =IF(E25<8,Factors!H$18,IF(E25<9,Factors!H$19,IF(E25<10,Factors!H$20,IF(E25<11,Factors!H$21,IF(E25<12,Factors!H$22,IF(E25<13,Factors!H$23)))))) -> 1.3238434 | H25: =D25*F25*G25 -> 0
A26: Tues | C26: Ringold | G26: =IF(E26<8,Factors!H$18,IF(E26<9,Factors!H$19,IF(E26<10,Factors!H$20,IF(E26<11,Factors!H$21,IF(E26<12,Factors!H$22,IF(E26<13,Factors!H$23)))))) -> 1.3238434 | H26: =D26*F26*G26 -> 0
C27: Bateman | G27: =IF(E27<8,Factors!H$18,IF(E27<9,Factors!H$19,IF(E27<10,Factors!H$20,IF(E27<11,Factors!H$21,IF(E27<12,Factors!H$22,IF(E27<13,Factors!H$23)))))) -> 1.3238434 | H27: =D27*F27*G27 -> 0
C28: Snyder | G28: =IF(E28<8,Factors!H$18,IF(E28<9,Factors!H$19,IF(E28<10,Factors!H$20,IF(E28<11,Factors!H$21,IF(E28<12,Factors!H$22,IF(E28<13,Factors!H$23)))))) -> 1.3238434 | H28: =D28*F28*G28 -> 0
H29: =SUM(H24:H28) -> 0 | I29: =$AG$8 -> 1.1111111 | J29: =H29*I29*J$13+K29 -> 0 | K29: =K28+K27 -> 0
A31: Sat | C31: Vernita | G31: =IF(E31<8,Factors!F$18,IF(E31<9,Factors!F$19,IF(E31<10,Factors!F$20,IF(E31<11,Factors!F$21,IF(E31<12,Factors!F$22,IF(E31<13,Factors!F$23)))))) -> 1.2308917 | H31: =D31*F31*G31 -> 0
C32: W. Bluffs | G32: =IF(E32<8,Factors!H$18,IF(E32<9,Factors!H$19,IF(E32<10,Factors!H$20,IF(E32<11,Factors!H$21,IF(E32<12,Factors!H$22,IF(E32<13,Factors!H$23)))))) -> 1.3238434 | H32: =D32*F32*G32 -> 0
A33: Tues | C33: Ringold | G33: =IF(E33<8,Factors!H$18,IF(E33<9,Factors!H$19,IF(E33<10,Factors!H$20,IF(E33<11,Factors!H$21,IF(E33<12,Factors!H$22,IF(E33<13,Factors!H$23)))))) -> 1.3238434 | H33: =D33*F33*G33 -> 0
C34: Bateman | G34: =IF(E34<8,Factors!H$18,IF(E34<9,Factors!H$19,IF(E34<10,Factors!H$20,IF(E34<11,Factors!H$21,IF(E34<12,Factors!H$22,IF(E34<13,Factors!H$23)))))) -> 1.3238434 | H34: =D34*F34*G34 -> 0
C35: Snyder | G35: =IF(E35<8,Factors!H$18,IF(E35<9,Factors!H$19,IF(E35<10,Factors!H$20,IF(E35<11,Factors!H$21,IF(E35<12,Factors!H$22,IF(E35<13,Factors!H$23)))))) -> 1.3238434 | H35: =D35*F35*G35 -> 0
H36: =SUM(H31:H35) -> 0 | I36: =$AG$8 -> 1.1111111 | J36: =H36*I36*J$13+K36 -> 0 | K36: =K35+K34 -> 0
A38: Sun | C38: Vernita | G38: =IF(E38<8,Factors!F$18,IF(E38<9,Factors!F$19,IF(E38<10,Factors!F$20,IF(E38<11,Factors!F$21,IF(E38<12,Factors!F$22,IF(E38<13,Factors!F$23)))))) -> 1.2308917 | H38: =D38*F38*G38 -> 0
C39: W. Bluffs | G39: =IF(E39<8,Factors!H$18,IF(E39<9,Factors!H$19,IF(E39<10,Factors!H$20,IF(E39<11,Factors!H$21,IF(E39<12,Factors!H$22,IF(E39<13,Factors!H$23)))))) -> 1.3238434 | H39: =D39*F39*G39 -> 0
A40: Tues | C40: Ringold | G40: =IF(E40<8,Factors!H$18,IF(E40<9,Factors!H$19,IF(E40<10,Factors!H$20,IF(E40<11,Factors!H$21,IF(E40<12,Factors!H$22,IF(E40<13,Factors!H$23)))))) -> 1.3238434 | H40: =D40*F40*G40 -> 0
C41: Bateman | G41: =IF(E41<8,Factors!H$18,IF(E41<9,Factors!H$19,IF(E41<10,Factors!H$20,IF(E41<11,Factors!H$21,IF(E41<12,Factors!H$22,IF(E41<13,Factors!H$23)))))) -> 1.3238434 | H41: =D41*F41*G41 -> 0
C42: Snyder | G42: =IF(E42<8,Factors!H$18,IF(E42<9,Factors!H$19,IF(E42<10,Factors!H$20,IF(E42<11,Factors!H$21,IF(E42<12,Factors!H$22,IF(E42<13,Factors!H$23)))))) -> 1.3238434 | H42: =D42*F42*G42 -> 0
H43: =SUM(H38:H42) -> 0 | I43: =AD7 -> 1.2003693 | J43: =H43*I43*J$13+K43 -> 0 | K43: =K42+K41 -> 0
A45: Mon | B45: 45880 | C45: Vernita | G45: =IF(E45<8,Factors!F$18,IF(E45<9,Factors!F$19,IF(E45<10,Factors!F$20,IF(E45<11,Factors!F$21,IF(E45<12,Factors!F$22,IF(E45<13,Factors!F$23)))))) -> 1.2308917 | H45: =D45*F45*G45 -> 0
C46: W. Bluffs | G46: =IF(E46<8,Factors!H$18,IF(E46<9,Factors!H$19,IF(E46<10,Factors!H$20,IF(E46<11,Factors!H$21,IF(E46<12,Factors!H$22,IF(E46<13,Factors!H$23)))))) -> 1.3238434 | H46: =D46*F46*G46 -> 0
...

Sheet Bank
CX1: From steelhead sport summary | DH1: 108 | DI1: 121
DQ2: Aug | DS2: =#REF!+#REF!+#REF!+#REF! -> #REF! | DT2: =#REF!+#REF!+#REF!+#REF! -> #REF! | DU2: =#REF!+#REF!+#REF!+#REF! -> #REF! | DV2: =#REF!+#REF!+#REF!+#REF! -> #REF! | DW2: =#REF!+#REF!+#REF!+#REF! -> #REF! | DX2: =#REF!+#REF!+#REF!+#REF! -> #REF! | DY2: =#REF!+#REF!+#REF!+#REF! -> #REF! | DZ2: =#REF!+#REF!+#REF!+#REF! -> #REF! | ... EE2: =#REF!+#REF!+#REF!+#REF! -> #REF!
H3: =#REF!+H36+H45+H54+H63+H72+H81+H90+H99 -> #REF! | I3: =#REF!+I36+I45+I54+I63+I72+I81+I90+I99 -> #REF! | J3: =#REF!+J36+J45+J54+J63+J72+J81+J90+J99 -> #REF! | K3: =#REF!+K36+K45+K54+K63+K72+K81+K90+K99 -> #REF! | L3: =#REF!+L36+L45+L54+L63+L72+L81+L90+L99 -> #REF! | M3: =#REF!+M36+M45+M54+M63+M72+M81+M90+M99 -> #REF! | N3: =#REF!+N36+N45+N54+N63+N72+N81+N90+N99 -> #REF! | O3: =#REF!+O36+O45+O54+O63+O72+O81+O90+O99 -> #REF! | ... AA3: =#REF!+AA36+AA45+AA54+AA63+AA72+AA81+AA90+AA99 -> #REF! | AH3: =#REF!+AH36+AH45+AH54+AH63+AH72+AH81+AH90+AH99 -> #REF! | CZ3: =#REF!+CZ72+CZ81+CZ90+CZ99+#REF!+#REF!+#REF!+#REF!+#REF! -> #REF! | DA3: =#REF!+DA72+DA81+DA90+DA99+#REF!+#REF!+#REF!+#REF!+#REF! -> #REF! | DB3: =#REF!+DB72+DB81+DB90+DB99+#REF!+#REF!+#REF!+#REF!+#REF! -> #REF! | DC3: =#REF!+DC72+DC81+DC90+DC99+#REF!+#REF!+#REF!+#REF!+#REF! -> #REF! | DD3: =#REF!+DD72+DD81+DD90+DD99+#REF!+#REF!+#REF!+#REF!+#REF! -> #REF! | DE3: =#REF!+DE72+DE81+DE90+DE99+#REF!+#REF!+#REF!+#REF!+#REF! -> #REF! | DF3: =#REF!+DF72+DF81+DF90+DF99+#REF!+#REF!+#REF!+#REF!+#REF! -> #REF! | DG3: =#REF!+DG72+DG81+DG90+DG99+#REF!+#REF!+#REF!+#REF!+#REF! -> #REF! | ... DK3: =#REF!+DK72+DK81+DK90+DK99+#REF!+#REF!+#REF!+#REF!+#REF! -> #REF! | DQ3: Sept | DS3: =#REF!+#REF!+#REF!+#REF! -> #REF! | DT3: =#REF!+#REF!+#REF!+#REF! -> #REF! | DU3: =#REF!+#REF!+#REF!+#REF! -> #REF! | DV3: =#REF!+#REF!+#REF!+#REF! -> #REF! | DW3: =#REF!+#REF!+#REF!+#REF! -> #REF! | DX3: =#REF!+#REF!+#REF!+#REF! -> #REF! | DY3: =#REF!+#REF!+#REF!+#REF! -> #REF! | DZ3: =#REF!+#REF!+#REF!+#REF! -> #REF! | ... EE3: =#REF!+#REF!+#REF!+#REF! -> #REF!
R4: Aug | S4: =#REF!+S36 -> #REF! | T4: =#REF!+T36 -> #REF! | U4: =#REF!+U36 -> #REF! | V4: =#REF!+V36 -> #REF! | W4: =#REF!+W36 -> #REF! | X4: =#REF!+X36 -> #REF! | AU4: =6500/286170 -> 0.022713772 | DQ4: Oct | DS4: =#REF!+#REF!+#REF!+#REF!+#REF! -> #REF! | DT4: =#REF!+#REF!+#REF!+#REF!+#REF! -> #REF! | DU4: =#REF!+#REF!+#REF!+#REF!+#REF! -> #REF! | DV4: =#REF!+#REF!+#REF!+#REF!+#REF! -> #REF! | DW4: =#REF!+#REF!+#REF!+#REF!+#REF! -> #REF! | DX4: =#REF!+#REF!+#REF!+#REF!+#REF! -> #REF! | DY4: =#REF!+#REF!+#REF!+#REF!+#REF! -> #REF! | DZ4: =#REF!+#REF!+#REF!+#REF!+#REF! -> #REF! | ... EE4: =#REF!+#REF!+#REF!+#REF!+#REF! -> #REF!
A5: =COUNT(A18:A35) -> 15 | R5: Sept | S5: =S45+S54+S63+S72 -> 74 | T5: =T45+T54+T63+T72 -> 20 | U5: =U45+U54+U63+U72 -> 54 | V5: =V45+V54+V63+V72 -> 10 | W5: =W45+W54+W63+W72 -> 1 | X5: =X45+X54+X63+X72 -> 9 | AU5: =3547/286170 -> 0.01239473 | DS5: =DS4+DS3 -> #REF! | DT5: =DT4+DT3 -> #REF! | DU5: =DU4+DU3 -> #REF! | DV5: =DV4+DV3 -> #REF! | DW5: =DW4+DW3 -> #REF! | DX5: =DX4+DX3 -> #REF! | DY5: =DY4+DY3 -> #REF! | DZ5: =DZ4+DZ3 -> #REF! | ... EE5: =EE4+EE3 -> #REF!
L6: Unknown | R6: Oct | S6: =S81+S90+S99 -> 78 | T6: =T81+T90+T99 -> 18 | U6: =U81+U90+U99 -> 60 | V6: =V81+V90+V99 -> 10 | W6: =W81+W90+W99 -> 1 | X6: =X81+X90+X99 -> 9
A7: Bank
A8: Weekday | S8: Chinook | AA8: Coho
H9: Steelhead | S9: Harvest | Y9: C&R | AA9: Harvest | AG9: C&R | AJ9: Chinook (not wanded for CWT) | AQ9: Effort | BG9: Harvest | BK9: C&R | BX9: Chinook | BZ9: Coho | CB9: C&R | CG9: Total | CI9: ADRV | CK9: AD | CM9: Wild | CO9: Chinook | CQ9: Coho | CS9: C&R | DH9: Chinook | DJ9: Coho | DL9: C&R
A10: Date | B10: Day | D10: Anglers | F10: Hours | H10: Total | K10: ADRV | M10: AD | O10: Unknown | Q10: Wild | S10: Adult | V10: Jacks | AA10: Adult | AD10: Jacks | AJ10: Adult | AL10: Jack | AN10: Total | AQ10: Pole Count | AR10: Index | AU10: Salmon | AV10: Pole | AW10: Peak Angler | AY10: Total | BA10: ADRV | BC10: AD | BE10: Wild | BG10: Chinook | BI10: Coho | BK10: Chinook | BM10: Coho | BP10: Total | BR10: ADRV | BT10: AD | BV10: Wild | BX10: Kept | BZ10: Kept | CB10: Chinook | CD10: Coho | CO10: Harvest | CQ10: Harvest | CS10: Chinook | CU10: Coho | CZ10: Total | DB10: ADRV | DD10: AD | DF10: Non-Clipped/Wild | DH10: Harvest | DJ10: Harvest | DL10: Chinook | DN10: Coho | DQ10: PIT | DS10: Trout | DU10: Smallmouth | DW10: Sucker | DY10: Whitefish | EA10: Pikeminnow | EC10: Sturgeon | EF10: Walleye | EH10: Bass
D11: Anglers | E11: Poles | F11: Anglers | G11: Poles | H11: Total | I11: Kept | J11: Rel | K11: Kept | L11: Rel | M11: Kept | N11: Rel | O11: Kept | P11: Rel | Q11: Kept | R11: Rel | S11: Tot | T11: NM | U11: AD | V11: Tot | W11: NM | X11: AD | Y11: Adult | Z11: Jack | AA11: Tot | AB11: NM | AC11: AD | AD11: Tot | AE11: NM | AF11: AD | AG11: Adult | AH11: Jack | AJ11: NM | AK11: AD | AL11: NM | AM11: AD | AN11: Adult | AO11: Jack | AQ11: (total) | AR11: (#) | AS11: Avg | AT11: Daylight | AU11: % | AV11: Hrs | AW11: Count | AY11: Catch | AZ11: Harvest | BA11: Catch | BB11: Harvest | BC11: Catch | BD11: Harvest | BE11: Catch | BF11: Harvest | BG11: Adult | BH11: Jack | BI11: Adult | BJ11: Jack | BK11: Adult | BL11: Jack | BM11: Adult | BN11: Jack | BP11: Catch | BQ11: Harvest | BR11: Catch | BS11: Harvest | BT11: Catch | BU11: Harvest | BV11: Catch | BW11: Harvest | BX11: Adult | BY11: Jack | BZ11: Adult | CA11: Jack | CB11: Adult | CC11: Jack | CD11: Adult | CE11: Jack | CG11: Catch | CH11: Harvest | CI11: Catch | CJ11: Harvest | CK11: Catch | CL11: Harvest | CM11: Catch | CN11: Harvest | CO11: Adult | CP11: Jack | CQ11: Adult | CR11: Jack | CS11: Adult | CT11: Jack | CU11: Adult | CV11: Jack | CZ11: Catch | DA11: Harvest | DB11: Catch | DC11: Harvest | DD11: Catch | DE11: Harvest | DF11: Catch | DG11: Harvest | DH11: Adult | DI11: Jack | DJ11: Adult | DK11: Jack | DL11: Adult | DM11: Jack | DN11: Adult | DO11: Jack | DQ11: AdRv | DR11: Harvest | DS11: Catch | DT11: Harvest | DU11: Catch | DV11: Harvest | DW11: Catch | DX11: Harvest | DY11: Catch | DZ11: Harvest | EA11: Catch | EB11: Harvest | EC11: Legal Rel | ED11: Over | EE11: Under | EF11: Catch | EG11: Harvest | EH11: Catch | EI11: Harvest
A12: 45880 | B12: Mon | H12: =I12+J12 -> 0 | I12: =K12+M12+Q12 -> 0 | J12: =L12+N12+R12 -> 0 | S12: =SUM(T12:U12) -> 0 | V12: =SUM(W12:X12) -> 0 | CG12: =AVERAGE(BP12:BP26) -> 0 | CH12: =AVERAGE(BQ12:BQ26) -> 0 | CI12: =AVERAGE(BR12:BR26) -> 0 | CJ12: =AVERAGE(BS12:BS26) -> 0 | CK12: =AVERAGE(BT12:BT26) -> 0 | CL12: =AVERAGE(BU12:BU26) -> 0 | CM12: =AVERAGE(BV12:BV26) -> 0 | CN12: =AVERAGE(BW12:BW26) -> 0 | ... CV12: =AVERAGE(CE12:CE26) -> 0 | CX12: 5 | CZ12: =CG12*$CX12 -> 0 | DA12: =CH12*$CX12 -> 0 | DB12: =CI12*$CX12 -> 0 | DC12: =CJ12*$CX12 -> 0 | DD12: =CK12*$CX12 -> 0 | DE12: =CL12*$CX12 -> 0 | DF12: =CM12*$CX12 -> 0 | DG12: =CN12*$CX12 -> 0 | ... DK12: =CR12*$CX12 -> 0 | DO12: =CR12*$CX12 -> 0
A13: =A12+1 -> 45881 | B13: Tues | H13: =I13+J13 -> 0 | I13: =K13+M13+Q13 -> 0 | J13: =L13+N13+R13 -> 0 | S13: =SUM(T13:U13) -> 0 | V13: =SUM(W13:X13) -> 0
A14: =A13+1 -> 45882 | B14: Wed | H14: =I14+J14 -> 0 | I14: =K14+M14+Q14 -> 0 | J14: =L14+N14+R14 -> 0 | S14: =SUM(T14:U14) -> 0 | V14: =SUM(W14:X14) -> 0 | BP14: =AY14*$AV14 -> 0 | BQ14: =AZ14*$AV14 -> 0 | BR14: =BA14*$AV14 -> 0 | BS14: =BB14*$AV14 -> 0 | BT14: =BC14*$AV14 -> 0 | BU14: =BD14*$AV14 -> 0 | BV14: =BE14*$AV14 -> 0 | BW14: =BF14*$AV14 -> 0 | ... CE14: =BN14*$AV14 -> 0
A15: =A14+1 -> 45883 | B15: Thur | H15: =I15+J15 -> 0 | I15: =K15+M15+Q15 -> 0 | J15: =L15+N15+R15 -> 0 | S15: =SUM(T15:U15) -> 0 | V15: =SUM(W15:X15) -> 0 | BP15: =AY15*$AV15 -> 0 | BQ15: =AZ15*$AV15 -> 0 | BR15: =BA15*$AV15 -> 0 | BS15: =BB15*$AV15 -> 0 | BT15: =BC15*$AV15 -> 0 | BU15: =BD15*$AV15 -> 0 | BV15: =BE15*$AV15 -> 0 | BW15: =BF15*$AV15 -> 0 | ... CE15: =BN15*$AV15 -> 0
A16: =A15+1 -> 45884 | B16: Fri | H16: =I16+J16 -> 0 | I16: =K16+M16+Q16 -> 0 | J16: =L16+N16+R16 -> 0 | S16: =SUM(T16:U16) -> 0 | V16: =SUM(W16:X16) -> 0 | BP16: =AY16*$AV16 -> 0 | BQ16: =AZ16*$AV16 -> 0 | BR16: =BA16*$AV16 -> 0 | BS16: =BB16*$AV16 -> 0 | BT16: =BC16*$AV16 -> 0 | BU16: =BD16*$AV16 -> 0 | BV16: =BE16*$AV16 -> 0 | BW16: =BF16*$AV16 -> 0 | ... CE16: =BN16*$AV16 -> 0
A17: =A16+1 -> 45885 | B17: Sat | D17: 8 | E17: 8 | F17: 33.27 | G17: 33.27 | H17: =I17+J17 -> 0 | I17: =K17+M17+Q17 -> 0 | J17: =L17+N17+R17 -> 0 | S17: =SUM(T17:U17) -> 0 | V17: =SUM(W17:X17) -> 0 | AQ17: 5 | AR17: 3 | AS17: =AQ17/AR17 -> 1.6666667 | AT17: 14.2 | AU17: 1 | AV17: =AT17*AS17*AU17 -> 23.666667 | AY17: =H17/G17 -> 0 | AZ17: =I17/G17 -> 0 | BA17: =(K17+L17)/$G17 -> 0 | BB17: =K17/$G17 -> 0 | BC17: =(M17+N17)/$G17 -> 0 | BD17: =M17/$G17 -> 0 | BE17: =(Q17+R17)/$G17 -> 0 | BF17: =Q17/$G17 -> 0 | BG17: =S17/$G17 -> 0 | BH17: =V17/$G17 -> 0 | BI17: =AA17/$G17 -> 0 | BJ17: =AH17/$G17 -> 0 | BP17: =AY17*$AV17 -> 0 | BQ17: =AZ17*$AV17 -> 0 | BR17: =BA17*$AV17 -> 0 | BS17: =BB17*$AV17 -> 0 | BT17: =BC17*$AV17 -> 0 | BU17: =BD17*$AV17 -> 0 | BV17: =BE17*$AV17 -> 0 | BW17: =BF17*$AV17 -> 0 | ... CE17: =BN17*$AV17 -> 0 | CX17: 2 | CZ17: =CG17*$CX17 -> 0 | DA17: =CH17*$CX17 -> 0 | DB17: =CI17*$CX17 -> 0 | DC17: =CJ17*$CX17 -> 0 | DD17: =CK17*$CX17 -> 0 | DE17: =CL17*$CX17 -> 0 | DF17: =CM17*$CX17 -> 0 | DG17: =CN17*$CX17 -> 0 | ... DO17: =CV17*$CX17 -> 0
A18: =A17+1 -> 45886 | B18: Sun | D18: 0 | E18: 0 | F18: 0 | G18: 0 | H18: =I18+J18 -> 0 | I18: =K18+M18+Q18 -> 0 | J18: =L18+N18+R18 -> 0 | S18: =SUM(T18:U18) -> 0 | V18: =SUM(W18:X18) -> 0 | AQ18: 0 | AR18: 3 | AS18: =AQ18/AR18 -> 0 | AT18: 14.2 | AU18: 1 | AV18: =AT18*AS18*AU18 -> 0 | BP18: =AY18*$AV18 -> 0 | BQ18: =AZ18*$AV18 -> 0 | BR18: =BA18*$AV18 -> 0 | BS18: =BB18*$AV18 -> 0 | BT18: =BC18*$AV18 -> 0 | BU18: =BD18*$AV18 -> 0 | BV18: =BE18*$AV18 -> 0 | BW18: =BF18*$AV18 -> 0 | ... CE18: =BN18*$AV18 -> 0
D19: =SUM(D12:D18) -> 8 | E19: =SUM(E12:E18) -> 8 | F19: =SUM(F12:F18) -> 33.27 | G19: =SUM(G12:G18) -> 33.27 | H19: =SUM(H4:H18) -> 0 | I19: =SUM(I4:I18) -> 0 | J19: =SUM(J4:J18) -> 0 | K19: =SUM(K4:K18) -> 0 | L19: =SUM(L4:L18) -> 0 | M19: =SUM(M4:M18) -> 0 | N19: =SUM(N4:N18) -> 0 | O19: =SUM(O4:O18) -> 0 | ... R19: =SUM(R4:R18) -> 0 | S19: =SUM(S12:S18) -> 0 | T19: =SUM(T12:T18) -> 0 | U19: =SUM(U4:U18) -> #REF! | V19: =SUM(V4:V18) -> #REF! | W19: =SUM(W4:W18) -> #REF! | X19: =SUM(X4:X18) -> #REF! | Y19: =SUM(Y4:Y18) -> 0 | Z19: =SUM(Z4:Z18) -> 0 | AA19: =SUM(AA4:AA18) -> 0 | AB19: =SUM(AB4:AB18) -> 0 | ... AH19: =SUM(AH4:AH18) -> 0 | AV19: =+AVERAGE(AV17:AV18)*2 -> 23.666667
A20: =A18+1 -> 45887 | B20: Mon | H20: =I20+J20 -> 0 | I20: =K20+M20+Q20 -> 0 | J20: =L20+N20+R20 -> 0 | S20: =SUM(T20:U20) -> 0 | V20: =SUM(W20:X20) -> 0 | AQ20: 0 | AR20: 3 | AS20: =AQ20/AR20 -> 0 | AT20: 14.1 | AU20: 1 | AV20: =AT20*AS20*AU20 -> 0 | CX20: 5 | CZ20: =CG20*$CX20 -> 0 | DA20: =CH20*$CX20 -> 0 | DB20: =CI20*$CX20 -> 0 | DC20: =CJ20*$CX20 -> 0 | DD20: =CK20*$CX20 -> 0 | DE20: =CL20*$CX20 -> 0 | DF20: =CM20*$CX20 -> 0 | DG20: =CN20*$CX20 -> 0 | ... DO20: =CV20*$CX20 -> 0
A21: =A20+1 -> 45888 | B21: Tues | D21: 0 | E21: 0 | F21: 0 | G21: 0 | H21: =I21+J21 -> 0 | I21: =K21+M21+Q21 -> 0 | J21: =L21+N21+R21 -> 0 | S21: =SUM(T21:U21) -> 0 | V21: =SUM(W21:X21) -> 0 | AQ21: 0 | AR21: 3 | AS21: =AQ21/AR21 -> 0 | AT21: 14.1 | AU21: 1 | AV21: =AT21*AS21*AU21 -> 0 | BP21: =AY21*$AV21 -> 0 | BQ21: =AZ21*$AV21 -> 0 | BR21: =BA21*$AV21 -> 0 | BS21: =BB21*$AV21 -> 0 | BT21: =BC21*$AV21 -> 0 | BU21: =BD21*$AV21 -> 0 | BV21: =BE21*$AV21 -> 0 | BW21: =BF21*$AV21 -> 0 | ... CE21: =BN21*$AV21 -> 0
A22: =A21+1 -> 45889 | B22: Wed | D22: 0 | E22: 0 | F22: 0 | G22: 0 | H22: =I22+J22 -> 0 | I22: =K22+M22+Q22 -> 0 | J22: =L22+N22+R22 -> 0 | S22: =SUM(T22:U22) -> 0 | V22: =SUM(W22:X22) -> 0 | AQ22: 0 | AR22: 3 | AS22: =AQ22/AR22 -> 0 | AT22: 14 | AU22: 1 | AV22: =AT22*AS22*AU22 -> 0 | AW22: 4 | BP22: =AY22*$AV22 -> 0 | BQ22: =AZ22*$AV22 -> 0 | BR22: =BA22*$AV22 -> 0 | BS22: =BB22*$AV22 -> 0 | BT22: =BC22*$AV22 -> 0 | BU22: =BD22*$AV22 -> 0 | BV22: =BE22*$AV22 -> 0 | BW22: =BF22*$AV22 -> 0 | ... CE22: =BN22*$AV22 -> 0
A23: =A22+1 -> 45890 | B23: Thur | D23: 0 | E23: 0 | F23: 0 | G23: 0 | H23: =I23+J23 -> 0 | I23: =K23+M23+Q23 -> 0 | J23: =L23+N23+R23 -> 0 | S23: =SUM(T23:U23) -> 0 | V23: =SUM(W23:X23) -> 0 | AQ23: 0 | AR23: 3 | AS23: =AQ23/AR23 -> 0 | AT23: 14 | AU23: 1 | AV23: =AT23*AS23*AU23 -> 0
A24: =A23+1 -> 45891 | B24: Fri | D24: 1 | E24: 2 | F24: 3.52 | G24: 7.03 | H24: =I24+J24 -> 0 | I24: =K24+M24+Q24 -> 0 | J24: =L24+N24+R24 -> 0 | P24: 1 | S24: =SUM(T24:U24) -> 0 | V24: =SUM(W24:X24) -> 0 | AQ24: 2 | AR24: 3 | AS24: =AQ24/AR24 -> 0.66666667 | AT24: 13.9 | AU24: 1 | AV24: =AT24*AS24*AU24 -> 9.2666667 | AY24: =H24/G24 -> 0 | AZ24: =I24/G24 -> 0 | BA24: =(K24+L24)/$G24 -> 0 | BB24: =K24/$G24 -> 0 | BC24: =(M24+N24)/$G24 -> 0 | BD24: =M24/$G24 -> 0 | BE24: =(Q24+R24)/$G24 -> 0 | BF24: =Q24/$G24 -> 0 | BG24: =S24/$G24 -> 0 | BH24: =V24/$G24 -> 0 | BI24: =AA24/$G24 -> 0 | BJ24: =AH24/$G24 -> 0 | BP24: =AY24*$AV24 -> 0 | BQ24: =AZ24*$AV24 -> 0 | BR24: =BA24*$AV24 -> 0 | BS24: =BB24*$AV24 -> 0 | BT24: =BC24*$AV24 -> 0 | BU24: =BD24*$AV24 -> 0 | BV24: =BE24*$AV24 -> 0 | BW24: =BF24*$AV24 -> 0 | ... CE24: =BN24*$AV24 -> 0
A25: =A24+1 -> 45892 | B25: Sat | D25: 9 | E25: 9 | F25: 17.57 | G25: 17.57 | H25: =I25+J25 -> 0 | I25: =K25+M25+Q25 -> 0 | J25: =L25+N25+R25 -> 0 | S25: =SUM(T25:U25) -> 0 | V25: =SUM(W25:X25) -> 0 | AQ25: 9 | AR25: 3 | AS25: =AQ25/AR25 -> 3 | AT25: 13.9 | AU25: 1 | AV25: =AT25*AS25*AU25 -> 41.7 | AW25: 8 | AY25: =H25/G25 -> 0 | AZ25: =I25/G25 -> 0 | BA25: =(K25+L25)/$G25 -> 0 | BB25: =K25/$G25 -> 0 | BC25: =(M25+N25)/$G25 -> 0 | BD25: =M25/$G25 -> 0 | BE25: =(Q25+R25)/$G25 -> 0 | BF25: =Q25/$G25 -> 0 | BG25: =S25/$G25 -> 0 | BH25: =V25/$G25 -> 0 | BI25: =AA25/$G25 -> 0 | BJ25: =AH25/$G25 -> 0 | BP25: =AY25*$AV25 -> 0 | BQ25: =AZ25*$AV25 -> 0 | BR25: =BA25*$AV25 -> 0 | BS25: =BB25*$AV25 -> 0 | BT25: =BC25*$AV25 -> 0 | BU25: =BD25*$AV25 -> 0 | BV25: =BE25*$AV25 -> 0 | BW25: =BF25*$AV25 -> 0 | ... CE25: =BN25*$AV25 -> 0 | CX25: 2
A26: =A25+1 -> 45893 | B26: Sun | D26: 4 | E26: 4 | F26: 8.9 | G26: 8.9 | H26: =I26+J26 -> 0 | I26: =K26+M26+Q26 -> 0 | J26: =L26+N26+R26 -> 0 | S26: =SUM(T26:U26) -> 0 | V26: =SUM(W26:X26) -> 0 | AQ26: 4 | AR26: 3 | AS26: =AQ26/AR26 -> 1.3333333 | AT26: 13.8 | AU26: 1 | AV26: =AT26*AS26*AU26 -> 18.4 | AW26: 9 | AY26: =H26/G26 -> 0 | AZ26: =I26/G26 -> 0 | BA26: =(K26+L26)/$G26 -> 0 | BB26: =K26/$G26 -> 0 | BC26: =(M26+N26)/$G26 -> 0 | BD26: =M26/$G26 -> 0 | BE26: =(Q26+R26)/$G26 -> 0 | BF26: =Q26/$G26 -> 0 | BG26: =S26/$G26 -> 0 | BH26: =V26/$G26 -> 0 | BI26: =AA26/$G26 -> 0 | BJ26: =AH26/$G26 -> 0 | BP26: =AY26*$AV26 -> 0 | BQ26: =AZ26*$AV26 -> 0 | BR26: =BA26*$AV26 -> 0 | BS26: =BB26*$AV26 -> 0 | BT26: =BC26*$AV26 -> 0 | BU26: =BD26*$AV26 -> 0 | BV26: =BE26*$AV26 -> 0 | BW26: =BF26*$AV26 -> 0 | ... CE26: =BN26*$AV26 -> 0
D27: =SUM(D20:D26) -> 14 | E27: =SUM(E20:E26) -> 15 | F27: =SUM(F20:F26) -> 29.99 | G27: =SUM(G20:G26) -> 33.5 | H27: =SUM(H12:H26) -> 0 | I27: =SUM(I12:I26) -> 0 | J27: =SUM(J12:J26) -> 0 | K27: =SUM(K12:K26) -> 0 | L27: =SUM(L12:L26) -> 0 | M27: =SUM(M12:M26) -> 0 | N27: =SUM(N12:N26) -> 0 | O27: =SUM(O12:O26) -> 0 | ... AH27: =SUM(AH12:AH26) -> 0 | AV27: =AVERAGE(AV20:AV24)*5+AVERAGE(AV25:AV26)*2 -> 69.366667 | CZ27: =CZ12 -> 0 | DA27: =DA12 -> 0 | DB27: =DB12 -> 0 | DC27: =DC12 -> 0 | DD27: =DD12 -> 0 | DE27: =DE12 -> 0 | DF27: =DF12 -> 0 | DG27: =DG12 -> 0 | ... DO27: =DO12 -> 0
A29: 45894 | B29: Mon | D29: 1 | E29: 2 | F29: 4 | G29: 8 | H29: =I29+J29 -> 0 | I29: =K29+M29+Q29 -> 0 | J29: =L29+N29+R29 -> 0 | S29: =T29+U29 -> 0 | V29: =W29+X29 -> 0 | AA29: =AB29+AC29 -> 0 | AD29: =AE29+AF29 -> 0 | AQ29: 0 | AR29: 1 | AS29: =AQ29/AR29 -> 0 | AT29: 13.7 | AU29: 1 | AV29: =AT29*AS29*AU29 -> 0 | AW29: 2 | AY29: =H29/G29 -> 0 | AZ29: =I29/G29 -> 0 | BA29: =(K29+L29)/$G29 -> 0 | BB29: =K29/$G29 -> 0 | BC29: =(M29+N29)/$G29 -> 0 | BD29: =M29/$G29 -> 0 | BE29: =(Q29+R29)/$G29 -> 0 | BF29: =Q29/$G29 -> 0 | BG29: =S29/$G29 -> 0 | BH29: =V29/$G29 -> 0 | BI29: =AA29/$G29 -> 0 | BJ29: =AH29/$G29 -> 0 | BP29: =AY29*$AV29 -> 0 | BQ29: =AZ29*$AV29 -> 0 | BR29: =BA29*$AV29 -> 0 | BS29: =BB29*$AV29 -> 0 | BT29: =BC29*$AV29 -> 0 | BU29: =BD29*$AV29 -> 0 | BV29: =BE29*$AV29 -> 0 | BW29: =BF29*$AV29 -> 0 | ... CE29: =BN29*$AV29 -> 0 | CG29: =AVERAGE(BP29:BP33) -> 0 | CH29: =AVERAGE(BQ29:BQ33) -> 0 | CI29: =AVERAGE(BR29:BR33) -> 0 | CJ29: =AVERAGE(BS29:BS33) -> 0 | CK29: =AVERAGE(BT29:BT33) -> 0 | CL29: =AVERAGE(BU29:BU33) -> 0 | CM29: =AVERAGE(BV29:BV33) -> 0 | CN29: =AVERAGE(BW29:BW33) -> 0 | ... CV29: =AVERAGE(CE29:CE33) -> 0 | CX29: 5 | CZ29: =CG29*$CX29 -> 0 | DA29: =CH29*$CX29 -> 0 | DB29: =CI29*$CX29 -> 0 | DC29: =CJ29*$CX29 -> 0 | DD29: =CK29*$CX29 -> 0 | DE29: =CL29*$CX29 -> 0 | DF29: =CM29*$CX29 -> 0 | DG29: =CN29*$CX29 -> 0 | ... DO29: =CV29*$CX29 -> 0
A30: =A29+1 -> 45895 | B30: Tues | D30: 3 | E30: 5 | F30: 7.25 | G30: 12.92 | H30: =I30+J30 -> 0 | I30: =K30+M30+Q30 -> 0 | J30: =L30+N30+R30 -> 0 | S30: =T30+U30 -> 0 | V30: =W30+X30 -> 0 | AA30: =AB30+AC30 -> 0 | AD30: =AE30+AF30 -> 0 | AQ30: 3 | AR30: 3 | AS30: =AQ30/AR30 -> 1 | AT30: 13.6 | AU30: 1 | AV30: =AT30*AS30*AU30 -> 13.6 | AW30: 2 | AY30: =H30/G30 -> 0 | AZ30: =I30/G30 -> 0 | BA30: =(K30+L30)/$G30 -> 0 | BB30: =K30/$G30 -> 0 | BC30: =(M30+N30)/$G30 -> 0 | BD30: =M30/$G30 -> 0 | BE30: =(Q30+R30)/$G30 -> 0 | BF30: =Q30/$G30 -> 0 | BG30: =S30/$G30 -> 0 | BH30: =V30/$G30 -> 0 | BI30: =AA30/$G30 -> 0 | BJ30: =AH30/$G30 -> 0 | BP30: =AY30*$AV30 -> 0 | BQ30: =AZ30*$AV30 -> 0 | BR30: =BA30*$AV30 -> 0 | BS30: =BB30*$AV30 -> 0 | BT30: =BC30*$AV30 -> 0 | BU30: =BD30*$AV30 -> 0 | BV30: =BE30*$AV30 -> 0 | BW30: =BF30*$AV30 -> 0 | ... CE30: =BN30*$AV30 -> 0
A31: =A30+1 -> 45896 | B31: Wed | D31: 3 | E31: 5 | F31: 5.08 | G31: 8.75 | H31: =I31+J31 -> 0 | I31: =K31+M31+Q31 -> 0 | J31: =L31+N31+R31 -> 0 | S31: =T31+U31 -> 0 | V31: =W31+X31 -> 0 | AA31: =AB31+AC31 -> 0 | AD31: =AE31+AF31 -> 0 | AQ31: 3 | AR31: 3 | AS31: =AQ31/AR31 -> 1 | AT31: 13.6 | AU31: 1 | AV31: =AT31*AS31*AU31 -> 13.6 | AW31: 8 | AY31: =H31/G31 -> 0 | AZ31: =I31/G31 -> 0 | BA31: =(K31+L31)/$G31 -> 0 | BB31: =K31/$G31 -> 0 | BC31: =(M31+N31)/$G31 -> 0 | BD31: =M31/$G31 -> 0 | BE31: =(Q31+R31)/$G31 -> 0 | BF31: =Q31/$G31 -> 0 | BG31: =S31/$G31 -> 0 | BH31: =V31/$G31 -> 0 | BI31: =AA31/$G31 -> 0 | BJ31: =AH31/$G31 -> 0 | BP31: =AY31*$AV31 -> 0 | BQ31: =AZ31*$AV31 -> 0 | BR31: =BA31*$AV31 -> 0 | BS31: =BB31*$AV31 -> 0 | BT31: =BC31*$AV31 -> 0 | BU31: =BD31*$AV31 -> 0 | BV31: =BE31*$AV31 -> 0 | BW31: =BF31*$AV31 -> 0 | ... CE31: =BN31*$AV31 -> 0
A32: =A31+1 -> 45897 | B32: Thur | D32: 0 | E32: 0 | F32: 0 | G32: 0 | H32: =I32+J32 -> 0 | I32: =K32+M32+Q32 -> 0 | J32: =L32+N32+R32 -> 0 | S32: =T32+U32 -> 0 | V32: =W32+X32 -> 0 | AA32: =AB32+AC32 -> 0 | AD32: =AE32+AF32 -> 0 | AQ32: 0 | AR32: 3 | AS32: =AQ32/AR32 -> 0 | AT32: 13.5 | AU32: 1 | AV32: =AT32*AS32*AU32 -> 0 | BP32: =AY32*$AV32 -> 0 | BQ32: =AZ32*$AV32 -> 0 | BR32: =BA32*$AV32 -> 0 | BS32: =BB32*$AV32 -> 0 | BT32: =BC32*$AV32 -> 0 | BU32: =BD32*$AV32 -> 0 | BV32: =BE32*$AV32 -> 0 | BW32: =BF32*$AV32 -> 0 | ... CE32: =BN32*$AV32 -> 0
A33: =A32+1 -> 45898 | B33: Fri | D33: 3 | E33: 3 | F33: 9.25 | G33: 9.25 | H33: =I33+J33 -> 0 | I33: =K33+M33+Q33 -> 0 | J33: =L33+N33+R33 -> 0 | S33: =T33+U33 -> 0 | V33: =W33+X33 -> 0 | AA33: =AB33+AC33 -> 0 | AD33: =AE33+AF33 -> 0 | AQ33: 3 | AR33: 3 | AS33: =AQ33/AR33 -> 1 | AT33: 13.4 | AU33: 1 | AV33: =AT33*AS33*AU33 -> 13.4 | AW33: 14 | AY33: =H33/G33 -> 0 | AZ33: =I33/G33 -> 0 | BA33: =(K33+L33)/$G33 -> 0 | BB33: =K33/$G33 -> 0 | BC33: =(M33+N33)/$G33 -> 0 | BD33: =M33/$G33 -> 0 | BE33: =(Q33+R33)/$G33 -> 0 | BF33: =Q33/$G33 -> 0 | BG33: =S33/$G33 -> 0 | BH33: =V33/$G33 -> 0 | BI33: =AA33/$G33 -> 0 | BJ33: =AH33/$G33 -> 0
A34: =A33+1 -> 45899 | B34: Sat | D34: 5 | E34: 5 | F34: 4.68 | G34: 4.68 | H34: =I34+J34 -> 0 | I34: =K34+M34+Q34 -> 0 | J34: =L34+N34+R34 -> 0 | S34: =T34+U34 -> 0 | V34: =W34+X34 -> 0 | AA34: =AB34+AC34 -> 0 | AD34: =AE34+AF34 -> 0 | AQ34: 5 | AR34: 2 | AS34: =AQ34/AR34 -> 2.5 | AT34: 13.3 | AU34: 1 | AV34: =AT34*AS34*AU34 -> 33.25 | AW34: 11 | AY34: =H34/G34 -> 0 | AZ34: =I34/G34 -> 0 | BA34: =(K34+L34)/$G34 -> 0 | BB34: =K34/$G34 -> 0 | BC34: =(M34+N34)/$G34 -> 0 | BD34: =M34/$G34 -> 0 | BE34: =(Q34+R34)/$G34 -> 0 | BF34: =Q34/$G34 -> 0 | BG34: =S34/$G34 -> 0 | BH34: =V34/$G34 -> 0 | BI34: =AA34/$G34 -> 0 | BJ34: =AH34/$G34 -> 0 | BP34: =AY34*$AV34 -> 0 | BQ34: =AZ34*$AV34 -> 0 | BR34: =BA34*$AV34 -> 0 | BS34: =BB34*$AV34 -> 0 | BT34: =BC34*$AV34 -> 0 | BU34: =BD34*$AV34 -> 0 | BV34: =BE34*$AV34 -> 0 | BW34: =BF34*$AV34 -> 0 | ... CE34: =BN34*$AV34 -> 0 | CG34: =AVERAGE(BP34:BP35) -> 0 | CH34: =AVERAGE(BQ34:BQ35) -> 0 | CI34: =AVERAGE(BR34:BR35) -> 0 | CJ34: =AVERAGE(BS34:BS35) -> 0 | CK34: =AVERAGE(BT34:BT35) -> 0 | CL34: =AVERAGE(BU34:BU35) -> 0 | CM34: =AVERAGE(BV34:BV35) -> 0 | CN34: =AVERAGE(BW34:BW35) -> 0 | ... CV34: =AVERAGE(CE34:CE35) -> 0 | CX34: 2 | CZ34: =CG34*$CX34 -> 0 | DA34: =CH34*$CX34 -> 0 | DB34: =CI34*$CX34 -> 0 | DC34: =CJ34*$CX34 -> 0 | DD34: =CK34*$CX34 -> 0 | DE34: =CL34*$CX34 -> 0 | DF34: =CM34*$CX34 -> 0 | DG34: =CN34*$CX34 -> 0 | ... DO34: =CV34*$CX34 -> 0
A35: =A34+1 -> 45900 | B35: Sun | D35: 2 | E35: 2 | F35: 2.83 | G35: 2.83 | H35: =I35+J35 -> 0 | I35: =K35+M35+Q35 -> 0 | J35: =L35+N35+R35 -> 0 | S35: =T35+U35 -> 0 | V35: =W35+X35 -> 0 | AA35: =AB35+AC35 -> 0 | AD35: =AE35+AF35 -> 0 | AQ35: 2 | AR35: 2 | AS35: =AQ35/AR35 -> 1 | AT35: 13.3 | AU35: 1 | AV35: =AT35*AS35*AU35 -> 13.3 | AW35: 17 | AY35: =H35/G35 -> 0 | AZ35: =I35/G35 -> 0 | BA35: =(K35+L35)/$G35 -> 0 | BB35: =K35/$G35 -> 0 | BC35: =(M35+N35)/$G35 -> 0 | BD35: =M35/$G35 -> 0 | BE35: =(Q35+R35)/$G35 -> 0 | BF35: =Q35/$G35 -> 0 | BG35: =S35/$G35 -> 0 | BH35: =V35/$G35 -> 0 | BI35: =AA35/$G35 -> 0 | BJ35: =AH35/$G35 -> 0 | BP35: =AY35*$AV35 -> 0 | BQ35: =AZ35*$AV35 -> 0 | BR35: =BA35*$AV35 -> 0 | BS35: =BB35*$AV35 -> 0 | BT35: =BC35*$AV35 -> 0 | BU35: =BD35*$AV35 -> 0 | BV35: =BE35*$AV35 -> 0 | BW35: =BF35*$AV35 -> 0 | ... CE35: =BN35*$AV35 -> 0
D36: =SUM(D29:D35) -> 17 | E36: =SUM(E29:E35) -> 22 | F36: =SUM(F29:F35) -> 33.09 | G36: =SUM(G29:G35) -> 46.43 | H36: =SUM(H29:H35) -> 0 | I36: =SUM(I29:I35) -> 0 | J36: =SUM(J29:J35) -> 0 | K36: =SUM(K29:K35) -> 0 | ... AH36: =SUM(AH29:AH35) -> 0 | AV36: =AVERAGE(AV29:AV33)*5+AVERAGE(AV34:AV35)*2 -> 87.15 | CZ36: =CZ34+CZ29 -> 0 | DA36: =DA34+DA29 -> 0 | DB36: =DB34+DB29 -> 0 | DC36: =DC34+DC29 -> 0 | DD36: =DD34+DD29 -> 0 | DE36: =DE34+DE29 -> 0 | DF36: =DF34+DF29 -> 0 | DG36: =DG34+DG29 -> 0 | ... DO36: =DO34+DO29 -> 0
A38: =A29+7 -> 45901 | B38: Mon | H38: =I38+J38 -> 0 | I38: =K38+M38+Q38 -> 0 | J38: =L38+N38+R38 -> 0 | S38: =T38+U38 -> 0 | V38: =W38+X38 -> 0 | AA38: =AB38+AC38 -> 0 | AD38: =AE38+AF38 -> 0 | CG38: =AVERAGE(BP38:BP42) -> 0 | CH38: =AVERAGE(BQ38:BQ42) -> 0 | CI38: =AVERAGE(BR38:BR42) -> 0 | CJ38: =AVERAGE(BS38:BS42) -> 0 | CK38: =AVERAGE(BT38:BT42) -> 0 | CL38: =AVERAGE(BU38:BU42) -> 0 | CM38: =AVERAGE(BV38:BV42) -> 0 | CN38: =AVERAGE(BW38:BW42) -> 0 | ... CV38: =AVERAGE(CE38:CE42) -> 0 | CX38: 5
A39: =A38+1 -> 45902 | B39: Tues | D39: 1 | E39: 1 | F39: 2.25 | G39: 2.25 | H39: =I39+J39 -> 0 | I39: =K39+M39+Q39 -> 0 | J39: =L39+N39+R39 -> 0 | S39: =T39+U39 -> 0 | V39: =W39+X39 -> 0 | AA39: =AB39+AC39 -> 0 | AD39: =AE39+AF39 -> 0 | AQ39: 1 | AR39: 3 | AS39: =AQ39/AR39 -> 0.33333333 | AT39: 13.3 | AU39: 1 | AV39: =AT39*AS39*AU39 -> 4.4333333 | AW39: 2 | AY39: =H39/G39 -> 0 | AZ39: =I39/G39 -> 0 | BA39: =(K39+L39)/$G39 -> 0 | BB39: =K39/$G39 -> 0 | BC39: =(M39+N39)/$G39 -> 0 | BD39: =M39/$G39 -> 0 | BE39: =(Q39+R39)/$G39 -> 0 | BF39: =Q39/$G39 -> 0 | BG39: =S39/$G39 -> 0 | BH39: =V39/$G39 -> 0 | BI39: =AA39/$G39 -> 0 | BJ39: =AH39/$G39 -> 0 | BP39: =AY39*$AV39 -> 0 | BQ39: =AZ39*$AV39 -> 0 | BR39: =BA39*$AV39 -> 0 | BS39: =BB39*$AV39 -> 0 | BT39: =BC39*$AV39 -> 0 | BU39: =BD39*$AV39 -> 0 | BV39: =BE39*$AV39 -> 0 | BW39: =BF39*$AV39 -> 0 | ... CE39: =BN39*$AV39 -> 0 | CZ39: =CG39*$CX39 -> 0 | DA39: =CH39*$CX39 -> 0 | DB39: =CI39*$CX39 -> 0 | DC39: =CJ39*$CX39 -> 0 | DD39: =CK39*$CX39 -> 0 | DE39: =CL39*$CX39 -> 0 | DF39: =CM39*$CX39 -> 0 | DG39: =CN39*$CX39 -> 0 | ... DO39: =CV39*$CX39 -> 0
A40: =A39+1 -> 45903 | B40: Wed | D40: 2 | E40: 4 | F40: 11.05 | G40: 16.7 | H40: =I40+J40 -> 0 | I40: =K40+M40+Q40 -> 0 | J40: =L40+N40+R40 -> 0 | S40: =T40+U40 -> 0 | V40: =W40+X40 -> 0 | AA40: =AB40+AC40 -> 0 | AD40: =AE40+AF40 -> 0 | AQ40: 4 | AR40: 3 | AS40: =AQ40/AR40 -> 1.3333333 | AT40: 13.2 | AU40: 1 | AV40: =AT40*AS40*AU40 -> 17.6 | AW40: 4 | AY40: =H40/G40 -> 0 | AZ40: =I40/G40 -> 0 | BA40: =(K40+L40)/$G40 -> 0 | BB40: =K40/$G40 -> 0 | BC40: =(M40+N40)/$G40 -> 0 | BD40: =M40/$G40 -> 0 | BE40: =(Q40+R40)/$G40 -> 0 | BF40: =Q40/$G40 -> 0 | BG40: =S40/$G40 -> 0 | BH40: =V40/$G40 -> 0 | BI40: =AA40/$G40 -> 0 | BJ40: =AH40/$G40 -> 0 | BP40: =AY40*$AV40 -> 0 | BQ40: =AZ40*$AV40 -> 0 | BR40: =BA40*$AV40 -> 0 | BS40: =BB40*$AV40 -> 0 | BT40: =BC40*$AV40 -> 0 | BU40: =BD40*$AV40 -> 0 | BV40: =BE40*$AV40 -> 0 | BW40: =BF40*$AV40 -> 0 | ... CE40: =BN40*$AV40 -> 0
