Workbook

Sheet Prosser
C2: 2025 Yakima River Fall Salmon Creel Survey (Sept 15 - October 31) | L2: No Boats=FIX FORMULA
AB3: hours/fish
E4: Sampled | AC4: Effort | AG4: Expanded Catch & Harvest
H5: Chinook | N5: Coho | T5: Steelhead | V5: Incidental Catch | AG5: Chinook | AM5: Coho | AS5: Steelhead | AU5: Incidental Catch
E6: Sampled | H6: Adults | J6: Jacks | L6: Released | N6: Adults | P6: Jacks | R6: Released | T6: (Released) | V6: NPM | X6: SK | Z6: SMB | AC6: Angler | AD6: Effort | AE6: Sampled | AG6: Adults | AI6: Jacks | AK6: Released | AM6: Adults | AO6: Jacks | AQ6: Released | AS6: (Released) | AU6: NPM | AW6: SK | AY6: SMB
C7: Combined | E7: Boats | F7: Anglers | G7: Hours | H7: NM | I7: AD | J7: NM | K7: AD | L7: Adult | M7: Jacks | N7: NM | O7: AD | P7: NM | Q7: AD | R7: Adult | S7: Jacks | T7: Hatch | U7: Wild | V7: Catch | W7: Rel | X7: Catch | Y7: Rel | Z7: Catch | AA7: Rel | AC7: Trips | AD7: Pole Hrs | AE7: % | AG7: NM | AH7: AD | AI7: NM | AJ7: AD | AK7: Adult | AL7: Jacks | AM7: NM | AN7: AD | AO7: NM | AP7: AD | AQ7: Adult | AR7: Jacks | AS7: Hatch | AT7: Wild | AU7: Catch | AV7: Rel | AW7: Catch | AX7: Rel | AY7: Catch | AZ7: Rel
C8: 0 | E8: =E22+E36 -> 0 | F8: =F22+F36 -> 0 | G8: =G22+G36 -> 0 | H8: =H22+H36 -> 0 | I8: =I22+I36 -> 0 | J8: =J22+J36 -> 0 | K8: =K22+K36 -> 0 | L8: =L22+L36 -> 0 | ... AA8: =AA22+AA36 -> 0
C9: Sept 15-21 | E9: =E23+E37 -> 0 | F9: =F23+F37 -> 56 | G9: =G23+G37 -> 120.88 | H9: =H23+H37 -> 0 | I9: =I23+I37 -> 0 | J9: =J23+J37 -> 0 | K9: =K23+K37 -> 0 | L9: =L23+L37 -> 0 | ... AA9: =AA23+AA37 -> 0 | AB9: 0 | AC9: =AC23+AC37 -> 219.73705 | AD9: =AD23+AD37 -> 436.36842 | AE9: =G9/AD9 -> 0.27701363 | AG9: =AG23 -> 0 | AH9: =AH23 -> 0 | AI9: =AI23 -> 0 | AJ9: =AJ23 -> 0 | AK9: =AK23 -> 0 | AL9: =AL23 -> 0 | AM9: =AM23 -> 0 | AN9: =AN23 -> 0 | ... AZ9: =AZ23 -> 0
C10: Sept 21-28 | E10: =E24+E38 -> 0 | F10: =F24+F38 -> 78 | G10: =G24+G38 -> 161.47 | H10: =H24+H38 -> 4 | I10: =I24+I38 -> 3 | J10: =J24+J38 -> 1 | K10: =K24+K38 -> 0 | L10: =L24+L38 -> 1 | ... AA10: =AA24+AA38 -> 0 | AB10: =SUM(G10)/SUM(H10:M10) -> 17.941111 | AC10: =AC24+AC38 -> 378.40155 | AD10: =AD24+AD38 -> 698.84211 | AE10: =G10/AD10 -> 0.23105362 | AG10: =AG24 -> 29.391418 | AH10: =AH24 -> 12.770654 | AI10: =AI24 -> 7.3478545 | AJ10: =AJ24 -> 0 | AK10: =AK24 -> 2.7113996 | AL10: =AL24 -> 0 | AM10: =AM24 -> 0 | AN10: =AN24 -> 0 | ... AZ10: =AZ24 -> 0
C11: Sept 29-Oct 5 | E11: =E25+E39 -> 1 | F11: =F25+F39 -> 98 | G11: =G25+G39 -> 163.55 | H11: =H25+H39 -> 3 | I11: =I25+I39 -> 10 | J11: =J25+J39 -> 1 | K11: =K25+K39 -> 0 | L11: =L25+L39 -> 0 | ... AA11: =AA25+AA39 -> 0 | AB11: =SUM(G11)/SUM(H11:M11) -> 11.682143 | AC11: =AC25+AC39 -> 886.35987 | AD11: =AD25+AD39 -> 798.94737 | AE11: =G11/AD11 -> 0.20470685 | AG11: =AG25 -> 5.8263741 | AH11: =AH25 -> 20.392309 | AI11: =AI25 -> 2.913187 | AJ11: =AJ25 -> 0 | AK11: =AK25 -> 0 | AL11: =AL25 -> 0 | AM11: =AM25 -> 0 | AN11: =AN25 -> 0 | ... AZ11: =AZ25 -> 0
C12: Oct 6-Oct 12 | E12: =E26+E40 -> 0 | F12: =F26+F40 -> 169 | G12: =G26+G40 -> 385.46 | H12: =H26+H40 -> 12 | I12: =I26+I40 -> 22 | J12: =J26+J40 -> 1 | K12: =K26+K40 -> 1 | L12: =L26+L40 -> 0 | ... AA12: =AA26+AA40 -> 1 | AB12: =SUM(G12)/SUM(H12:M12) -> 10.707222 | AC12: =AC26+AC40 -> 608.38443 | AD12: =AD26+AD40 -> 1387.3684 | AE12: =G12/AD12 -> 0.27783536 | AG12: =AG26 -> 43.39829 | AH12: =AH26 -> 81.215386 | AI12: =AI26 -> 4.7728224 | AJ12: =AJ26 -> 4.7728224 | AK12: =AK26 -> 0 | AL12: =AL26 -> 0 | AM12: =AM26 -> 2.7905968 | AN12: =AN26 -> 0 | ... AZ12: =AZ26 -> 4.7728224
C13: Oct 13-19 | E13: =E27+E41 -> 0 | F13: =F27+F41 -> 149 | G13: =G27+G41 -> 341.13 | H13: =H27+H41 -> 12 | I13: =I27+I41 -> 14 | J13: =J27+J41 -> 1 | K13: =K27+K41 -> 0 | L13: =L27+L41 -> 0 | ... AA13: =AA27+AA41 -> 0 | AB13: =SUM(G13)/SUM(H13:M13) -> 12.634444 | AC13: =AC27+AC41 -> 710.32091 | AD13: =AD27+AD41 -> 1204.3333 | AE13: =G13/AD13 -> 0.28325215 | AG13: =AG27 -> 36.118671 | AH13: =AH27 -> 46.27833 | AI13: =AI27 -> 8.1847392 | AJ13: =AJ27 -> 0 | AK13: =AK27 -> 0 | AL13: =AL27 -> 0 | AM13: =AM27 -> 3.9498386 | AN13: =AN27 -> 0 | ... AZ13: =AZ27 -> 0
C14: Oct 20-26 | E14: =E28+E42 -> 0 | F14: =F28+F42 -> 128 | G14: =G28+G42 -> 383.7 | H14: =H28+H42 -> 4 | I14: =I28+I42 -> 10 | J14: =J28+J42 -> 0 | K14: =K28+K42 -> 0 | L14: =L28+L42 -> 1 | ... AA14: =AA28+AA42 -> 0 | AB14: =SUM(G14)/SUM(H14:M14) -> 25.58 | AC14: =AC28+AC42 -> 353.28058 | AD14: =AD28+AD42 -> 985.35088 | AE14: =G14/AD14 -> 0.38940443 | AG14: =AG28 -> 16.761406 | AH14: =AH28 -> 41.903516 | AI14: =AI28 -> 0 | AJ14: =AJ28 -> 0 | AK14: =AK28 -> 4.1903516 | AL14: =AL28 -> 0 | AM14: =AM28 -> 4.1903516 | AN14: =AN28 -> 0 | ... AZ14: =AZ28 -> 0
C15: Oct 27-Nov 2 | E15: =E29+E43 -> 0 | F15: =F29+F43 -> 111 | G15: =G29+G43 -> 210.16 | H15: =H29+H43 -> 3 | I15: =I29+I43 -> 12 | J15: =J29+J43 -> 0 | K15: =K29+K43 -> 0 | L15: =L29+L43 -> 8 | ... AA15: =AA29+AA43 -> 0 | AB15: =SUM(G15)/SUM(H15:M15) -> 9.1373913 | AC15: =AC29+AC43 -> 518.82392 | AD15: =AD29+AD43 -> 917.01754 | AE15: =G15/AD15 -> 0.22917773 | AG15: =AG29 -> 11.042334 | AH15: =AH29 -> 61.952814 | AI15: =AI29 -> 0 | AJ15: =AJ29 -> 0 | AK15: =AK29 -> 37.74518 | AL15: =AL29 -> 0 | AM15: =AM29 -> 0 | AN15: =AN29 -> 35.622214 | ... AZ15: =AZ29 -> 0
C16: Nov 3-9 | E16: =E30+E44 -> 0 | F16: =F30+F44 -> 0 | G16: =G30+G44 -> 0 | H16: =H30+H44 -> 0 | I16: =I30+I44 -> 0 | J16: =J30+J44 -> 0 | K16: =K30+K44 -> 0 | L16: =L30+L44 -> 0 | ... AA16: =AA30+AA44 -> 0
C17: Nov 10-16 | E17: =E31+E45 -> 0 | F17: =F31+F45 -> 0 | G17: =G31+G45 -> 0 | H17: =H31+H45 -> 0 | I17: =I31+I45 -> 0 | J17: =J31+J45 -> 0 | K17: =K31+K45 -> 0 | L17: =L31+L45 -> 0 | ... AA17: =AA31+AA45 -> 0
E18: =SUM(E8:E17) -> 1 | F18: =SUM(F8:F17) -> 789 | G18: =SUM(G8:G17) -> 1766.35 | H18: =SUM(H8:H17) -> 38 | I18: =SUM(I8:I17) -> 71 | J18: =SUM(J8:J17) -> 4 | K18: =SUM(K8:K17) -> 1 | L18: =SUM(L8:L17) -> 10 | ... AA18: =SUM(AA8:AA17) -> 1 | AB18: =SUM(G18)/SUM(H18:M18) -> 14.244758 | AC18: =SUM(AC8:AC17) -> 3675.3083 | AD18: =SUM(AD8:AD17) -> 6428.2281 | AE18: =G18/AD18 -> 0.27478023 | AG18: =SUM(AG8:AG17) -> 142.53849 | AH18: =SUM(AH8:AH17) -> 264.51301 | AI18: =SUM(AI8:AI17) -> 23.218603 | AJ18: =SUM(AJ8:AJ17) -> 4.7728224 | AK18: =SUM(AK8:AK17) -> 44.646931 | AL18: =SUM(AL8:AL17) -> 0 | AM18: =SUM(AM8:AM17) -> 10.930787 | AN18: =SUM(AN8:AN17) -> 35.622214 | ... AZ18: =SUM(AZ8:AZ17) -> 4.7728224
AG19: =SUM(AG18:AL18) -> 479.68986 | AH19: Total Salmon Caught
C21: Bank Summary | E21: Sampled | AC21: Effort | AG21: Expanded Catch & Harvest
C22: =C8 -> 0 | F22: =SUM(F52:F56) -> 0 | G22: =SUM(G52:G56) -> 0 | H22: =SUM(H52:H56) -> 0 | I22: =SUM(I52:I56) -> 0 | J22: =SUM(J52:J56) -> 0 | K22: =SUM(K52:K56) -> 0 | L22: =SUM(L52:L56) -> 0 | M22: =SUM(M52:M56) -> 0 | ... AA22: =SUM(AA52:AA56) -> 0 | AC22: =AK52+AK36 -> #DIV/0! | AD22: =AJ52+AJ55 -> 0 | AE22: =G22/AD22 -> #DIV/0! | AG22: =BG52+BG55 -> #DIV/0! | AH22: =BH52+BH55 -> #DIV/0! | AI22: =BI52+BI55 -> #DIV/0! | AJ22: =BJ52+BJ55 -> #DIV/0! | AK22: =BK52+BK55 -> #DIV/0! | AL22: =BL52+BL55 -> #DIV/0! | AM22: =BM52+BM55 -> #DIV/0! | AN22: =BN52+BN55 -> #DIV/0! | ... AZ22: =BZ52+BZ55 -> #DIV/0!
C23: =C9 -> Sept 15-21 | F23: =SUM(F57:F61) -> 56 | G23: =SUM(G57:G61) -> 120.88 | H23: =SUM(H57:H61) -> 0 | I23: =SUM(I57:I61) -> 0 | J23: =SUM(J57:J61) -> 0 | K23: =SUM(K57:K61) -> 0 | L23: =SUM(L57:L61) -> 0 | M23: =SUM(M57:M61) -> 0 | ... AA23: =SUM(AA57:AA61) -> 0 | AB23: 0 | AC23: =AK57+AK60 -> 219.73705 | AD23: =AJ57+AJ60 -> 436.36842 | AE23: =G23/AD23 -> 0.27701363 | AG23: =BG57+BG60 -> 0 | AH23: =BH57+BH60 -> 0 | AI23: =BI57+BI60 -> 0 | AJ23: =BJ57+BJ60 -> 0 | AK23: =BK57+BK60 -> 0 | AL23: =BL57+BL60 -> 0 | AM23: =BM57+BM60 -> 0 | AN23: =BN57+BN60 -> 0 | ... AZ23: =BZ57+BZ60 -> 0
C24: =C10 -> Sept 21-28 | F24: =SUM(F62:F66) -> 78 | G24: =SUM(G62:G66) -> 161.47 | H24: =SUM(H62:H66) -> 4 | I24: =SUM(I62:I66) -> 3 | J24: =SUM(J62:J66) -> 1 | K24: =SUM(K62:K66) -> 0 | L24: =SUM(L62:L66) -> 1 | M24: =SUM(M62:M66) -> 0 | ... AA24: =SUM(AA62:AA66) -> 0 | AB24: =SUM(G24)/SUM(H24:M24) -> 17.941111 | AC24: =AK62+AK65 -> 378.40155 | AD24: =AJ62+AJ65 -> 698.84211 | AE24: =G24/AD24 -> 0.23105362 | AG24: =BG62+BG65 -> 29.391418 | AH24: =BH62+BH65 -> 12.770654 | AI24: =BI62+BI65 -> 7.3478545 | AJ24: =BJ62+BJ65 -> 0 | AK24: =BK62+BK65 -> 2.7113996 | AL24: =BL62+BL65 -> 0 | AM24: =BM62+BM65 -> 0 | AN24: =BN62+BN65 -> 0 | ... AZ24: =BZ62+BZ65 -> 0
C25: =C11 -> Sept 29-Oct 5 | F25: =SUM(F67:F71) -> 96 | G25: =SUM(G67:G71) -> 155.95 | H25: =SUM(H67:H71) -> 2 | I25: =SUM(I67:I71) -> 7 | J25: =SUM(J67:J71) -> 1 | K25: =SUM(K67:K71) -> 0 | L25: =SUM(L67:L71) -> 0 | M25: =SUM(M67:M71) -> 0 | ... AA25: =SUM(AA67:AA71) -> 0 | AB25: =SUM(G25)/SUM(H25:M25) -> 15.595 | AC25: =AK67+AK70 -> 886.35987 | AD25: =AJ67+AJ70 -> 798.94737 | AE25: =G25/AD25 -> 0.19519433 | AG25: =BG67+BG70 -> 5.8263741 | AH25: =BH67+BH70 -> 20.392309 | AI25: =BI67+BI70 -> 2.913187 | AJ25: =BJ67+BJ70 -> 0 | AK25: =BK67+BK70 -> 0 | AL25: =BL67+BL70 -> 0 | AM25: =BM67+BM70 -> 0 | AN25: =BN67+BN70 -> 0 | ... AZ25: =BZ67+BZ70 -> 0
C26: =C12 -> Oct 6-Oct 12 | F26: =SUM(F72:F76) -> 169 | G26: =SUM(G72:G76) -> 385.46 | H26: =SUM(H72:H76) -> 12 | I26: =SUM(I72:I76) -> 22 | J26: =SUM(J72:J76) -> 1 | K26: =SUM(K72:K76) -> 1 | L26: =SUM(L72:L76) -> 0 | M26: =SUM(M72:M76) -> 0 | ... AA26: =SUM(AA72:AA76) -> 1 | AB26: =SUM(G26)/SUM(H26:M26) -> 10.707222 | AC26: =AK72+AK75 -> 608.38443 | AD26: =AJ72+AJ75 -> 1387.3684 | AE26: =G26/AD26 -> 0.27783536 | AG26: =BG72+BG75 -> 43.39829 | AH26: =BH72+BH75 -> 81.215386 | AI26: =BI72+BI75 -> 4.7728224 | AJ26: =BJ72+BJ75 -> 4.7728224 | AK26: =BK72+BK75 -> 0 | AL26: =BL72+BL75 -> 0 | AM26: =BM72+BM75 -> 2.7905968 | AN26: =BN72+BN75 -> 0 | ... AZ26: =BZ72+BZ75 -> 4.7728224
C27: =C13 -> Oct 13-19 | F27: =SUM(F77:F81) -> 149 | G27: =SUM(G77:G81) -> 341.13 | H27: =SUM(H77:H81) -> 12 | I27: =SUM(I77:I81) -> 14 | J27: =SUM(J77:J81) -> 1 | K27: =SUM(K77:K81) -> 0 | L27: =SUM(L77:L81) -> 0 | M27: =SUM(M77:M81) -> 0 | ... AA27: =SUM(AA77:AA81) -> 0 | AB27: =SUM(G27)/SUM(H27:M27) -> 12.634444 | AC27: =AK77+AK80 -> 710.32091 | AD27: =AJ77+AJ80 -> 1204.3333 | AE27: =G27/AD27 -> 0.28325215 | AG27: =BG77+BG80 -> 36.118671 | AH27: =BH77+BH80 -> 46.27833 | AI27: =BI77+BI80 -> 8.1847392 | AJ27: =BJ77+BJ80 -> 0 | AK27: =BK77+BK80 -> 0 | AL27: =BL77+BL80 -> 0 | AM27: =BM77+BM80 -> 3.9498386 | AN27: =BN77+BN80 -> 0 | ... AZ27: =BZ77+BZ80 -> 0
C28: =C14 -> Oct 20-26 | F28: =SUM(F82:F86) -> 128 | G28: =SUM(G82:G86) -> 383.7 | H28: =SUM(H82:H86) -> 4 | I28: =SUM(I82:I86) -> 10 | J28: =SUM(J82:J86) -> 0 | K28: =SUM(K82:K86) -> 0 | L28: =SUM(L82:L86) -> 1 | M28: =SUM(M82:M86) -> 0 | ... AA28: =SUM(AA82:AA86) -> 0 | AB28: =SUM(G28)/SUM(H28:M28) -> 25.58 | AC28: =AK82+AK85 -> 353.28058 | AD28: =AJ82+AJ85 -> 985.35088 | AE28: =G28/AD28 -> 0.38940443 | AG28: =BG82+BG85 -> 16.761406 | AH28: =BH82+BH85 -> 41.903516 | AI28: =BI82+BI85 -> 0 | AJ28: =BJ82+BJ85 -> 0 | AK28: =BK82+BK85 -> 4.1903516 | AL28: =BL82+BL85 -> 0 | AM28: =BM82+BM85 -> 4.1903516 | AN28: =BN82+BN85 -> 0 | ... AZ28: =BZ82+BZ85 -> 0
C29: =C15 -> Oct 27-Nov 2 | F29: =SUM(F87:F91) -> 111 | G29: =SUM(G87:G91) -> 210.16 | H29: =SUM(H87:H91) -> 3 | I29: =SUM(I87:I91) -> 12 | J29: =SUM(J87:J91) -> 0 | K29: =SUM(K87:K91) -> 0 | L29: =SUM(L87:L91) -> 8 | M29: =SUM(M87:M91) -> 0 | ... AA29: =SUM(AA87:AA91) -> 0 | AB29: =SUM(G29)/SUM(H29:M29) -> 9.1373913 | AC29: =AK87+AK90 -> 518.82392 | AD29: =AJ87+AJ90 -> 917.01754 | AE29: =G29/AD29 -> 0.22917773 | AG29: =BG87+BG90 -> 11.042334 | AH29: =BH87+BH90 -> 61.952814 | AI29: =BI87+BI90 -> 0 | AJ29: =BJ87+BJ90 -> 0 | AK29: =BK87+BK90 -> 37.74518 | AL29: =BL87+BL90 -> 0 | AM29: =BM87+BM90 -> 0 | AN29: =BN87+BN90 -> 35.622214 | ... AZ29: =BZ87+BZ90 -> 0
C30: =C16 -> Nov 3-9 | F30: =SUM(F92:F96) -> 0 | G30: =SUM(G92:G96) -> 0 | H30: =SUM(H92:H96) -> 0 | I30: =SUM(I92:I96) -> 0 | J30: =SUM(J92:J96) -> 0 | K30: =SUM(K92:K96) -> 0 | L30: =SUM(L92:L96) -> 0 | M30: =SUM(M92:M96) -> 0 | ... AA30: =SUM(AA92:AA96) -> 0 | AC30: =AK97+AK100 -> #DIV/0! | AD30: =AJ97+AJ100 -> 0 | AE30: =G30/AD30 -> #DIV/0! | AG30: =BG92+BG95 -> #DIV/0! | AH30: =BH92+BH95 -> #DIV/0! | AI30: =BI92+BI95 -> #DIV/0! | AJ30: =BJ92+BJ95 -> #DIV/0! | AK30: =BK92+BK95 -> #DIV/0! | AL30: =BL92+BL95 -> #DIV/0! | AM30: =BM92+BM95 -> #DIV/0! | AN30: =BN92+BN95 -> #DIV/0! | ... AZ30: =BZ92+BZ95 -> #DIV/0!
C31: =C17 -> Nov 10-16 | F31: =SUM(F97:F101) -> 0 | G31: =SUM(G97:G101) -> 0 | H31: =SUM(H97:H101) -> 0 | I31: =SUM(I97:I101) -> 0 | J31: =SUM(J97:J101) -> 0 | K31: =SUM(K97:K101) -> 0 | L31: =SUM(L97:L101) -> 0 | M31: =SUM(M97:M101) -> 0 | ... AA31: =SUM(AA97:AA101) -> 0 | AC31: =AK98+AK101 -> 0 | AD31: =AJ98+AJ101 -> 0 | AE31: 0 | AG31: =BG97 -> #DIV/0! | AH31: =BH97 -> #DIV/0! | AI31: =BI97 -> #DIV/0! | AJ31: =BJ97 -> #DIV/0! | AK31: =BK97 -> #DIV/0! | AL31: =BL97 -> #DIV/0! | AM31: =BM97 -> #DIV/0! | AN31: =BN97 -> #DIV/0! | ... AZ31: =BZ97 -> #DIV/0!
F32: =SUM(F22:F31) -> 787 | G32: =SUM(G22:G31) -> 1758.75 | H32: =SUM(H22:H31) -> 37 | I32: =SUM(I22:I31) -> 68 | J32: =SUM(J22:J31) -> 4 | K32: =SUM(K22:K31) -> 1 | L32: =SUM(L22:L31) -> 10 | M32: =SUM(M22:M31) -> 0 | ... AA32: =SUM(AA22:AA31) -> 1 | AB32: =SUM(G32)/SUM(H32:M32) -> 14.65625 | AC32: =SUM(AC22:AC31) -> #DIV/0! | AD32: =SUM(AD22:AD31) -> 6428.2281 | AE32: =G32/AD32 -> 0.27359795 | AG32: =SUM(AG22:AG31) -> #DIV/0! | AH32: =SUM(AH22:AH31) -> #DIV/0! | AI32: =SUM(AI22:AI31) -> #DIV/0! | AJ32: =SUM(AJ22:AJ31) -> #DIV/0! | AK32: =SUM(AK22:AK31) -> #DIV/0! | AL32: =SUM(AL22:AL31) -> #DIV/0! | AM32: =SUM(AM22:AM31) -> #DIV/0! | AN32: =SUM(AN22:AN31) -> #DIV/0! | ... AZ32: =SUM(AZ22:AZ31) -> #DIV/0!
C35: Boat Summary | E35: Sampled | AC35: Effort | AG35: Expanded Catch & Harvest
C36: =C8 -> 0 | E36: =SUM(E109:E113) -> 0 | F36: =SUM(F109:F113) -> 0 | G36: =SUM(G109:G113) -> 0 | H36: =SUM(H109:H113) -> 0 | I36: =SUM(I109:I113) -> 0 | J36: =SUM(J109:J113) -> 0 | K36: =SUM(K109:K113) -> 0 | L36: =SUM(L109:L113) -> 0 | ... AA36: =SUM(AA109:AA113) -> 0 | AC36: =AK109+AK112 -> 0 | AD36: =AJ109+AJ112 -> #DIV/0! | AE36: =G36/AD36 -> #DIV/0! | AG36: =BG109+BG112 -> 0 | AH36: =BH109+BH112 -> #DIV/0! | AI36: =BI109+BI112 -> #DIV/0! | AJ36: =BJ109+BJ112 -> #DIV/0! | AK36: =BK109+BK112 -> #DIV/0! | AL36: =BL109+BL112 -> #DIV/0! | AM36: =BM109+BM112 -> #DIV/0! | AN36: =BN109+BN112 -> #DIV/0! | ... AZ36: =BZ109+BZ112 -> #DIV/0!
C37: =C9 -> Sept 15-21 | E37: =SUM(E114:E118) -> 0 | F37: =SUM(F114:F118) -> 0 | G37: =SUM(G114:G118) -> 0 | H37: =SUM(H114:H118) -> 0 | I37: =SUM(I114:I118) -> 0 | J37: =SUM(J114:J118) -> 0 | K37: =SUM(K114:K118) -> 0 | L37: =SUM(L114:L118) -> 0 | ... AA37: =SUM(AA114:AA118) -> 0 | AC37: 0 | AD37: 0 | AE37: =G37/AD37 -> #DIV/0! | AG37: =BG114+BG117 -> #DIV/0! | AH37: =BH114+BH117 -> #DIV/0! | AI37: =BI114+BI117 -> #DIV/0! | AJ37: =BJ114+BJ117 -> #DIV/0! | AK37: =BK114+BK117 -> #DIV/0! | AL37: =BL114+BL117 -> #DIV/0! | AM37: =BM114+BM117 -> #DIV/0! | AN37: =BN114+BN117 -> #DIV/0! | ... AZ37: =BZ114+BZ117 -> #DIV/0!
C38: =C10 -> Sept 21-28 | E38: =SUM(E119:E123) -> 0 | F38: =SUM(F119:F123) -> 0 | G38: =SUM(G119:G123) -> 0 | H38: =SUM(H119:H123) -> 0 | I38: =SUM(I119:I123) -> 0 | J38: =SUM(J119:J123) -> 0 | K38: =SUM(K119:K123) -> 0 | L38: =SUM(L119:L123) -> 0 | ... AA38: =SUM(AA119:AA123) -> 0 | AC38: 0 | AD38: 0 | AE38: =G38/AD38 -> #DIV/0! | AG38: =BG119+BG122 -> #DIV/0! | AH38: =BH119+BH122 -> #DIV/0! | AI38: =BI119+BI122 -> #DIV/0! | AJ38: =BJ119+BJ122 -> #DIV/0! | AK38: =BK119+BK122 -> #DIV/0! | AL38: =BL119+BL122 -> #DIV/0! | AM38: =BM119+BM122 -> #DIV/0! | AN38: =BN119+BN122 -> #DIV/0! | ... AZ38: =BZ119+BZ122 -> #DIV/0!
C39: =C11 -> Sept 29-Oct 5 | E39: =SUM(E124:E128) -> 1 | F39: =SUM(F124:F128) -> 2 | G39: =SUM(G124:G128) -> 7.6 | H39: =SUM(H124:H128) -> 1 | I39: =SUM(I124:I128) -> 3 | J39: =SUM(J124:J128) -> 0 | K39: =SUM(K124:K128) -> 0 | L39: =SUM(L124:L128) -> 0 | ... AA39: =SUM(AA124:AA128) -> 0 | AB39: =SUM(G39)/SUM(H39:M39) -> 1.9 | AC39: 0 | AD39: 0 | AE39: =G39/AD39 -> #DIV/0! | AG39: =BG124+BG127 -> #DIV/0! | AH39: =BH124+BH127 -> #DIV/0! | AI39: =BI124+BI127 -> #DIV/0! | AJ39: =BJ124+BJ127 -> #DIV/0! | AK39: =BK124+BK127 -> #DIV/0! | AL39: =BL124+BL127 -> #DIV/0! | AM39: =BM124+BM127 -> #DIV/0! | AN39: =BN124+BN127 -> #DIV/0! | ... AZ39: =BZ124+BZ127 -> #DIV/0!
C40: =C12 -> Oct 6-Oct 12 | E40: =SUM(E129:E133) -> 0 | F40: =SUM(F129:F133) -> 0 | G40: =SUM(G129:G133) -> 0 | H40: =SUM(H129:H133) -> 0 | I40: =SUM(I129:I133) -> 0 | J40: =SUM(J129:J133) -> 0 | K40: =SUM(K129:K133) -> 0 | L40: =SUM(L129:L133) -> 0 | ... AA40: =SUM(AA129:AA133) -> 0 | AC40: 0 | AD40: 0 | AE40: =G40/AD40 -> #DIV/0! | AG40: =BG129+BG132 -> #DIV/0! | AH40: =BH129+BH132 -> #DIV/0! | AI40: =BI129+BI132 -> #DIV/0! | AJ40: =BJ129+BJ132 -> #DIV/0! | AK40: =BK129+BK132 -> #DIV/0! | AL40: =BL129+BL132 -> #DIV/0! | AM40: =BM129+BM132 -> #DIV/0! | AN40: =BN129+BN132 -> #DIV/0! | ... AZ40: =BZ129+BZ132 -> #DIV/0!
C41: =C13 -> Oct 13-19 | E41: =SUM(E134:E138) -> 0 | F41: =SUM(F134:F138) -> 0 | G41: =SUM(G134:G138) -> 0 | H41: =SUM(H134:H138) -> 0 | I41: =SUM(I134:I138) -> 0 | J41: =SUM(J134:J138) -> 0 | K41: =SUM(K134:K138) -> 0 | L41: =SUM(L134:L138) -> 0 | ... AA41: =SUM(AA134:AA138) -> 0 | AC41: 0 | AD41: 0 | AE41: =G41/AD41 -> #DIV/0! | AG41: =BG134+BG137 -> #DIV/0! | AH41: =BH134+BH137 -> #DIV/0! | AI41: =BI134+BI137 -> #DIV/0! | AJ41: =BJ134+BJ137 -> #DIV/0! | AK41: =BK134+BK137 -> #DIV/0! | AL41: =BL134+BL137 -> #DIV/0! | AM41: =BM134+BM137 -> #DIV/0! | AN41: =BN134+BN137 -> #DIV/0! | ... AZ41: =BZ134+BZ137 -> #DIV/0!
C42: =C14 -> Oct 20-26 | E42: =SUM(E139:E143) -> 0 | F42: =SUM(F139:F143) -> 0 | G42: =SUM(G139:G143) -> 0 | H42: =SUM(H139:H143) -> 0 | I42: =SUM(I139:I143) -> 0 | J42: =SUM(J139:J143) -> 0 | K42: =SUM(K139:K143) -> 0 | L42: =SUM(L139:L143) -> 0 | ... AA42: =SUM(AA139:AA143) -> 0 | AC42: 0 | AD42: 0 | AE42: =G42/AD42 -> #DIV/0! | AG42: =BG139+BG142 -> #DIV/0! | AH42: =BH139+BH142 -> #DIV/0! | AI42: =BI139+BI142 -> #DIV/0! | AJ42: =BJ139+BJ142 -> #DIV/0! | AK42: =BK139+BK142 -> #DIV/0! | AL42: =BL139+BL142 -> #DIV/0! | AM42: =BM139+BM142 -> #DIV/0! | AN42: =BN139+BN142 -> #DIV/0! | ... AZ42: =BZ139+BZ142 -> #DIV/0!
C43: =C15 -> Oct 27-Nov 2 | E43: =SUM(E144:E148) -> 0 | F43: =SUM(F144:F148) -> 0 | G43: =SUM(G144:G148) -> 0 | H43: =SUM(H144:H148) -> 0 | I43: =SUM(I144:I148) -> 0 | J43: =SUM(J144:J148) -> 0 | K43: =SUM(K144:K148) -> 0 | L43: =SUM(L144:L148) -> 0 | ... AA43: =SUM(AA144:AA148) -> 0 | AC43: 0 | AD43: 0 | AE43: =G43/AD43 -> #DIV/0! | AG43: =BG144+BG147 -> #DIV/0! | AH43: =BH144+BH147 -> #DIV/0! | AI43: =BI144+BI147 -> #DIV/0! | AJ43: =BJ144+BJ147 -> #DIV/0! | AK43: =BK144+BK147 -> #DIV/0! | AL43: =BL144+BL147 -> #DIV/0! | AM43: =BM144+BM147 -> #DIV/0! | AN43: =BN144+BN147 -> #DIV/0! | ... AZ43: =BZ144+BZ147 -> #DIV/0!
C44: =C16 -> Nov 3-9 | E44: =SUM(E149:E153) -> 0 | F44: =SUM(F149:F153) -> 0 | G44: =SUM(G149:G153) -> 0 | H44: =SUM(H149:H153) -> 0 | I44: =SUM(I149:I153) -> 0 | J44: =SUM(J149:J153) -> 0 | K44: =SUM(K149:K153) -> 0 | L44: =SUM(L149:L153) -> 0 | ... AA44: =SUM(AA149:AA153) -> 0 | AC44: 0 | AD44: 0 | AE44: =G44/AD44 -> #DIV/0! | AG44: =BG149+BG152 -> #DIV/0! | AH44: =BH149+BH152 -> #DIV/0! | AI44: =BI149+BI152 -> #DIV/0! | AJ44: =BJ149+BJ152 -> #DIV/0! | AK44: =BK149+BK152 -> #DIV/0! | AL44: =BL149+BL152 -> #DIV/0! | AM44: =BM149+BM152 -> #DIV/0! | AN44: =BN149+BN152 -> #DIV/0! | ... AZ44: =BZ149+BZ152 -> #DIV/0!
...

Sheet Horn Rapids
C2: =Prosser!C2 -> 2025 Yakima River Fall Salmon Creel Survey (Sept 15 - October 31)
AB3: hours/fish
E4: Sampled | AC4: Effort | AG4: Expanded Catch & Harvest
H5: Chinook | N5: Coho | T5: Steelhead | V5: Incidental Catch | AG5: Chinook | AM5: Coho | AS5: Steelhead | AU5: Incidental Catch
E6: Sampled | H6: Adults | J6: Jacks | L6: Released | N6: Adults | P6: Jacks | R6: Released | T6: (Released) | V6: NPM | X6: SK | AC6: Angler | AD6: Effort | AE6: Sampled | AG6: Adults | AI6: Jacks | AK6: Released | AM6: Adults | AO6: Jacks | AQ6: Released | AS6: (Released) | AU6: NPM | AW6: SK
C7: Combined | E7: Boats | F7: Anglers | G7: Hours | H7: NM | I7: AD | J7: NM | K7: AD | L7: Adult | M7: Jacks | N7: NM | O7: AD | P7: NM | Q7: AD | R7: Adult | S7: Jacks | T7: Hatch | U7: Wild | V7: Catch | W7: Rel | X7: Catch | Y7: Rel | Z7: Catch | AA7: Rel | AC7: Trips | AD7: Pole Hrs | AE7: % | AG7: NM | AH7: AD | AI7: NM | AJ7: AD | AK7: Adult | AL7: Jacks | AM7: NM | AN7: AD | AO7: NM | AP7: AD | AQ7: Adult | AR7: Jacks | AS7: Hatch | AT7: Wild | AU7: Catch | AV7: Rel | AW7: Catch | AX7: Rel | AY7: Catch | AZ7: Rel
C8: =Prosser!C8 -> 0 | E8: =E22+E36 -> 0 | F8: =F22+F36 -> 0 | G8: =G22+G36 -> 0 | H8: =H22+H36 -> 0 | I8: =I22+I36 -> 0 | J8: =J22+J36 -> 0 | K8: =K22+K36 -> 0 | L8: =L22+L36 -> 0 | ... AA8: =AA22+AA36 -> 0 | AB8: =SUM(G8)/SUM(H8:M8) -> #DIV/0! | AC8: =AC22+AC36 -> #DIV/0! | AD8: =AD22+AD36 -> #DIV/0! | AE8: =G8/AD8 -> #DIV/0! | AG8: =AG22+AG36 -> #DIV/0! | AH8: =AH22+AH36 -> #DIV/0! | AI8: =AI22+AI36 -> #DIV/0! | AJ8: =AJ22+AJ36 -> #DIV/0! | AK8: =AK22+AK36 -> #DIV/0! | AL8: =AL22+AL36 -> #DIV/0! | AM8: =AM22+AM36 -> #DIV/0! | AN8: =AN22+AN36 -> #DIV/0! | ... AZ8: =AZ22+AZ36 -> #DIV/0!
C9: =Prosser!C9 -> Sept 15-21 | E9: =E23+E37 -> 0 | F9: =F23+F37 -> 0 | G9: =G23+G37 -> 0 | H9: =H23+H37 -> 0 | I9: =I23+I37 -> 0 | J9: =J23+J37 -> 0 | K9: =K23+K37 -> 0 | L9: =L23+L37 -> 0 | ... AA9: =AA23+AA37 -> 0 | AB9: =SUM(G9)/SUM(H9:M9) -> #DIV/0! | AC9: =AC23+AC37 -> #DIV/0! | AD9: =AD23+AD37 -> #DIV/0! | AE9: =G9/AD9 -> #DIV/0! | AG9: =AG23+AG37 -> #DIV/0! | AH9: =AH23+AH37 -> #DIV/0! | AI9: =AI23+AI37 -> #DIV/0! | AJ9: =AJ23+AJ37 -> #DIV/0! | AK9: =AK23+AK37 -> #DIV/0! | AL9: =AL23+AL37 -> #DIV/0! | AM9: =AM23+AM37 -> #DIV/0! | AN9: =AN23+AN37 -> #DIV/0! | ... AZ9: =AZ23+AZ37 -> #DIV/0!
C10: =Prosser!C10 -> Sept 21-28 | E10: =E24+E38 -> 0 | F10: =F24+F38 -> 0 | G10: =G24+G38 -> 0 | H10: =H24+H38 -> 0 | I10: =I24+I38 -> 0 | J10: =J24+J38 -> 0 | K10: =K24+K38 -> 0 | L10: =L24+L38 -> 0 | ... AA10: =AA24+AA38 -> 0 | AB10: =SUM(G10)/SUM(H10:M10) -> #DIV/0! | AC10: =AC24+AC38 -> #DIV/0! | AD10: =AD24+AD38 -> #DIV/0! | AE10: =G10/AD10 -> #DIV/0! | AG10: =AG24+AG38 -> #DIV/0! | AH10: =AH24+AH38 -> #DIV/0! | AI10: =AI24+AI38 -> #DIV/0! | AJ10: =AJ24+AJ38 -> #DIV/0! | AK10: =AK24+AK38 -> #DIV/0! | AL10: =AL24+AL38 -> #DIV/0! | AM10: =AM24+AM38 -> #DIV/0! | AN10: =AN24+AN38 -> #DIV/0! | ... AZ10: =AZ24+AZ38 -> #DIV/0!
C11: =Prosser!C11 -> Sept 29-Oct 5 | E11: =E25+E39 -> 0 | F11: =F25+F39 -> 0 | G11: =G25+G39 -> 0 | H11: =H25+H39 -> 0 | I11: =I25+I39 -> 0 | J11: =J25+J39 -> 0 | K11: =K25+K39 -> 0 | L11: =L25+L39 -> 0 | ... AA11: =AA25+AA39 -> 0 | AB11: =SUM(G11)/SUM(H11:M11) -> #DIV/0! | AC11: =AC25+AC39 -> #DIV/0! | AD11: =AD25+AD39 -> #DIV/0! | AE11: =G11/AD11 -> #DIV/0! | AG11: =AG25+AG39 -> #DIV/0! | AH11: =AH25+AH39 -> #DIV/0! | AI11: =AI25+AI39 -> #DIV/0! | AJ11: =AJ25+AJ39 -> #DIV/0! | AK11: =AK25+AK39 -> #DIV/0! | AL11: =AL25+AL39 -> #DIV/0! | AM11: =AM25+AM39 -> #DIV/0! | AN11: =AN25+AN39 -> #DIV/0! | ... AZ11: =AZ25+AZ39 -> #DIV/0!
C12: =Prosser!C12 -> Oct 6-Oct 12 | E12: =E26+E40 -> 0 | F12: =F26+F40 -> 0 | G12: =G26+G40 -> 0 | H12: =H26+H40 -> 0 | I12: =I26+I40 -> 0 | J12: =J26+J40 -> 0 | K12: =K26+K40 -> 0 | L12: =L26+L40 -> 0 | ... AA12: =AA26+AA40 -> 0 | AB12: =SUM(G12)/SUM(H12:M12) -> #DIV/0! | AC12: =AC26+AC40 -> #DIV/0! | AD12: =AD26+AD40 -> #DIV/0! | AE12: =G12/AD12 -> #DIV/0! | AG12: =AG26+AG40 -> #DIV/0! | AH12: =AH26+AH40 -> #DIV/0! | AI12: =AI26+AI40 -> #DIV/0! | AJ12: =AJ26+AJ40 -> #DIV/0! | AK12: =AK26+AK40 -> #DIV/0! | AL12: =AL26+AL40 -> #DIV/0! | AM12: =AM26+AM40 -> #DIV/0! | AN12: =AN26+AN40 -> #DIV/0! | ... AZ12: =AZ26+AZ40 -> #DIV/0!
C13: =Prosser!C13 -> Oct 13-19 | E13: =E27+E41 -> 0 | F13: =F27+F41 -> 0 | G13: =G27+G41 -> 0 | H13: =H27+H41 -> 0 | I13: =I27+I41 -> 0 | J13: =J27+J41 -> 0 | K13: =K27+K41 -> 0 | L13: =L27+L41 -> 0 | ... AA13: =AA27+AA41 -> 0 | AB13: =SUM(G13)/SUM(H13:M13) -> #DIV/0! | AC13: =AC27+AC41 -> #DIV/0! | AD13: =AD27+AD41 -> #DIV/0! | AE13: =G13/AD13 -> #DIV/0! | AG13: =AG27+AG41 -> #DIV/0! | AH13: =AH27+AH41 -> #DIV/0! | AI13: =AI27+AI41 -> #DIV/0! | AJ13: =AJ27+AJ41 -> #DIV/0! | AK13: =AK27+AK41 -> #DIV/0! | AL13: =AL27+AL41 -> #DIV/0! | AM13: =AM27+AM41 -> #DIV/0! | AN13: =AN27+AN41 -> #DIV/0! | ... AZ13: =AZ27+AZ41 -> #DIV/0!
C14: =Prosser!C14 -> Oct 20-26 | E14: =E28+E42 -> 0 | F14: =F28+F42 -> 0 | G14: =G28+G42 -> 0 | H14: =H28+H42 -> 0 | I14: =I28+I42 -> 0 | J14: =J28+J42 -> 0 | K14: =K28+K42 -> 0 | L14: =L28+L42 -> 0 | ... AA14: =AA28+AA42 -> 0 | AB14: =SUM(G14)/SUM(H14:M14) -> #DIV/0! | AC14: =AC28+AC42 -> #DIV/0! | AD14: =AD28+AD42 -> #DIV/0! | AE14: =G14/AD14 -> #DIV/0! | AG14: =AG28+AG42 -> #DIV/0! | AH14: =AH28+AH42 -> #DIV/0! | AI14: =AI28+AI42 -> #DIV/0! | AJ14: =AJ28+AJ42 -> #DIV/0! | AK14: =AK28+AK42 -> #DIV/0! | AL14: =AL28+AL42 -> #DIV/0! | AM14: =AM28+AM42 -> #DIV/0! | AN14: =AN28+AN42 -> #DIV/0! | ... AZ14: =AZ28+AZ42 -> #DIV/0!
C15: =Prosser!C15 -> Oct 27-Nov 2 | E15: =E29+E43 -> 0 | F15: =F29+F43 -> 0 | G15: =G29+G43 -> 0 | H15: =H29+H43 -> 0 | I15: =I29+I43 -> 0 | J15: =J29+J43 -> 0 | K15: =K29+K43 -> 0 | L15: =L29+L43 -> 0 | ... AA15: =AA29+AA43 -> 0 | AB15: =SUM(G15)/SUM(H15:M15) -> #DIV/0! | AC15: =AC29+AC43 -> #DIV/0! | AD15: =AD29+AD43 -> #DIV/0! | AE15: =G15/AD15 -> #DIV/0! | AG15: =AG29+AG43 -> #DIV/0! | AH15: =AH29+AH43 -> #DIV/0! | AI15: =AI29+AI43 -> #DIV/0! | AJ15: =AJ29+AJ43 -> #DIV/0! | AK15: =AK29+AK43 -> #DIV/0! | AL15: =AL29+AL43 -> #DIV/0! | AM15: =AM29+AM43 -> #DIV/0! | AN15: =AN29+AN43 -> #DIV/0! | ... AZ15: =AZ29+AZ43 -> #DIV/0!
C16: =Prosser!C16 -> Nov 3-9 | E16: =E30+E44 -> 0 | F16: =F30+F44 -> 0 | G16: =G30+G44 -> 0 | H16: =H30+H44 -> 0 | I16: =I30+I44 -> 0 | J16: =J30+J44 -> 0 | K16: =K30+K44 -> 0 | L16: =L30+L44 -> 0 | ... AA16: =AA30+AA44 -> 0 | AB16: =SUM(G16)/SUM(H16:M16) -> #DIV/0! | AC16: =AC30+AC44 -> #DIV/0! | AD16: =AD30+AD44 -> #DIV/0! | AE16: =G16/AD16 -> #DIV/0! | AG16: =AG30+AG44 -> #DIV/0! | AH16: =AH30+AH44 -> #DIV/0! | AI16: =AI30+AI44 -> #DIV/0! | AJ16: =AJ30+AJ44 -> #DIV/0! | AK16: =AK30+AK44 -> #DIV/0! | AL16: =AL30+AL44 -> #DIV/0! | AM16: =AM30+AM44 -> #DIV/0! | AN16: =AN30+AN44 -> #DIV/0! | ... AZ16: =AZ30+AZ44 -> #DIV/0!
C17: =Prosser!C17 -> Nov 10-16
E18: =SUM(E8:E17) -> 0 | F18: =SUM(F8:F17) -> 0 | G18: =SUM(G8:G17) -> 0 | H18: =SUM(H8:H17) -> 0 | I18: =SUM(I8:I17) -> 0 | J18: =SUM(J8:J17) -> 0 | K18: =SUM(K8:K17) -> 0 | L18: =SUM(L8:L17) -> 0 | ... AA18: =SUM(AA8:AA17) -> 0 | AB18: =SUM(G18)/SUM(H18:M18) -> #DIV/0! | AC18: =SUM(AC8:AC17) -> #DIV/0! | AD18: =SUM(AD8:AD17) -> #DIV/0! | AE18: =G18/AD18 -> #DIV/0! | AG18: =SUM(AG8:AG17) -> #DIV/0! | AH18: =SUM(AH8:AH17) -> #DIV/0! | AI18: =SUM(AI8:AI17) -> #DIV/0! | AJ18: =SUM(AJ8:AJ17) -> #DIV/0! | AK18: =SUM(AK8:AK17) -> #DIV/0! | AL18: =SUM(AL8:AL17) -> #DIV/0! | AM18: =SUM(AM8:AM17) -> #DIV/0! | AN18: =SUM(AN8:AN17) -> #DIV/0! | ... AZ18: =SUM(AZ8:AZ17) -> #DIV/0!
AG19: =SUM(AG18:AL18) -> #DIV/0! | AH19: Total Salmon Caught
C21: Bank Summary | E21: Sampled | AC21: Effort | AG21: Expanded Catch & Harvest
C22: =C8 -> 0 | F22: =SUM(F52:F56) -> 0 | G22: =SUM(G52:G56) -> 0 | H22: =SUM(H52:H56) -> 0 | I22: =SUM(I52:I56) -> 0 | J22: =SUM(J52:J56) -> 0 | K22: =SUM(K52:K56) -> 0 | L22: =SUM(L52:L56) -> 0 | M22: =SUM(M52:M56) -> 0 | ... AA22: =SUM(AA52:AA56) -> 0 | AB22: =SUM(G22)/SUM(H22:M22) -> #DIV/0! | AC22: =AK52+AK55 -> #DIV/0! | AD22: =AJ52+AJ55 -> #DIV/0! | AE22: =G22/AD22 -> #DIV/0! | AG22: =BG52+BG55 -> #DIV/0! | AH22: =BH52+BH55 -> #DIV/0! | AI22: =BI52+BI55 -> #DIV/0! | AJ22: =BJ52+BJ55 -> #DIV/0! | AK22: =BK52+BK55 -> #DIV/0! | AL22: =BL52+BL55 -> #DIV/0! | AM22: =BM52+BM55 -> #DIV/0! | AN22: =BN52+BN55 -> #DIV/0! | ... AZ22: =BZ52+BZ55 -> #DIV/0!
C23: =C9 -> Sept 15-21 | F23: =SUM(F57:F61) -> 0 | G23: =SUM(G57:G61) -> 0 | H23: =SUM(H57:H61) -> 0 | I23: =SUM(I57:I61) -> 0 | J23: =SUM(J57:J61) -> 0 | K23: =SUM(K57:K61) -> 0 | L23: =SUM(L57:L61) -> 0 | M23: =SUM(M57:M61) -> 0 | ... AA23: =SUM(AA57:AA61) -> 0 | AB23: =SUM(G23)/SUM(H23:M23) -> #DIV/0! | AC23: =AK57+AK60 -> #DIV/0! | AD23: =AJ57+AJ60 -> #DIV/0! | AE23: =G23/AD23 -> #DIV/0! | AG23: =BG57+BG60 -> #DIV/0! | AH23: =BH57+BH60 -> #DIV/0! | AI23: =BI57+BI60 -> #DIV/0! | AJ23: =BJ57+BJ60 -> #DIV/0! | AK23: =BK57+BK60 -> #DIV/0! | AL23: =BL57+BL60 -> #DIV/0! | AM23: =BM57+BM60 -> #DIV/0! | AN23: =BN57+BN60 -> #DIV/0! | ... AZ23: =BZ57+BZ60 -> #DIV/0!
C24: =C10 -> Sept 21-28 | F24: =SUM(F62:F66) -> 0 | G24: =SUM(G62:G66) -> 0 | H24: =SUM(H62:H66) -> 0 | I24: =SUM(I62:I66) -> 0 | J24: =SUM(J62:J66) -> 0 | K24: =SUM(K62:K66) -> 0 | L24: =SUM(L62:L66) -> 0 | M24: =SUM(M62:M66) -> 0 | ... AA24: =SUM(AA62:AA66) -> 0 | AB24: =SUM(G24)/SUM(H24:M24) -> #DIV/0! | AC24: =AK62+AK65 -> #DIV/0! | AD24: =AJ62+AJ65 -> #DIV/0! | AE24: =G24/AD24 -> #DIV/0! | AG24: =BG62+BG65 -> #DIV/0! | AH24: =BH62+BH65 -> #DIV/0! | AI24: =BI62+BI65 -> #DIV/0! | AJ24: =BJ62+BJ65 -> #DIV/0! | AK24: =BK62+BK65 -> #DIV/0! | AL24: =BL62+BL65 -> #DIV/0! | AM24: =BM62+BM65 -> #DIV/0! | AN24: =BN62+BN65 -> #DIV/0! | ... AZ24: =BZ62+BZ65 -> #DIV/0!
C25: =C11 -> Sept 29-Oct 5 | F25: =SUM(F67:F71) -> 0 | G25: =SUM(G67:G71) -> 0 | H25: =SUM(H67:H71) -> 0 | I25: =SUM(I67:I71) -> 0 | J25: =SUM(J67:J71) -> 0 | K25: =SUM(K67:K71) -> 0 | L25: =SUM(L67:L71) -> 0 | M25: =SUM(M67:M71) -> 0 | ... AA25: =SUM(AA67:AA71) -> 0 | AB25: =SUM(G25)/SUM(H25:M25) -> #DIV/0! | AC25: =AK67+AK70 -> #DIV/0! | AD25: =AJ67+AJ70 -> #DIV/0! | AE25: =G25/AD25 -> #DIV/0! | AG25: =BG67+BG70 -> #DIV/0! | AH25: =BH67+BH70 -> #DIV/0! | AI25: =BI67+BI70 -> #DIV/0! | AJ25: =BJ67+BJ70 -> #DIV/0! | AK25: =BK67+BK70 -> #DIV/0! | AL25: =BL67+BL70 -> #DIV/0! | AM25: =BM67+BM70 -> #DIV/0! | AN25: =BN67+BN70 -> #DIV/0! | ... AZ25: =BZ67+BZ70 -> #DIV/0!
C26: =C12 -> Oct 6-Oct 12 | F26: =SUM(F72:F76) -> 0 | G26: =SUM(G72:G76) -> 0 | H26: =SUM(H72:H76) -> 0 | I26: =SUM(I72:I76) -> 0 | J26: =SUM(J72:J76) -> 0 | K26: =SUM(K72:K76) -> 0 | L26: =SUM(L72:L76) -> 0 | M26: =SUM(M72:M76) -> 0 | ... AA26: =SUM(AA72:AA76) -> 0 | AB26: =SUM(G26)/SUM(H26:M26) -> #DIV/0! | AC26: =AK72+AK75 -> #DIV/0! | AD26: =AJ72+AJ75 -> #DIV/0! | AE26: =G26/AD26 -> #DIV/0! | AG26: =BG72+BG75 -> #DIV/0! | AH26: =BH72+BH75 -> #DIV/0! | AI26: =BI72+BI75 -> #DIV/0! | AJ26: =BJ72+BJ75 -> #DIV/0! | AK26: =BK72+BK75 -> #DIV/0! | AL26: =BL72+BL75 -> #DIV/0! | AM26: =BM72+BM75 -> #DIV/0! | AN26: =BN72+BN75 -> #DIV/0! | ... AZ26: =BZ72+BZ75 -> #DIV/0!
C27: =C13 -> Oct 13-19 | F27: =SUM(F77:F81) -> 0 | G27: =SUM(G77:G81) -> 0 | H27: =SUM(H77:H81) -> 0 | I27: =SUM(I77:I81) -> 0 | J27: =SUM(J77:J81) -> 0 | K27: =SUM(K77:K81) -> 0 | L27: =SUM(L77:L81) -> 0 | M27: =SUM(M77:M81) -> 0 | ... AA27: =SUM(AA77:AA81) -> 0 | AB27: =SUM(G27)/SUM(H27:M27) -> #DIV/0! | AC27: =AK77+AK80 -> #DIV/0! | AD27: =AJ77+AJ80 -> #DIV/0! | AE27: =G27/AD27 -> #DIV/0! | AG27: =BG77+BG80 -> #DIV/0! | AH27: =BH77+BH80 -> #DIV/0! | AI27: =BI77+BI80 -> #DIV/0! | AJ27: =BJ77+BJ80 -> #DIV/0! | AK27: =BK77+BK80 -> #DIV/0! | AL27: =BL77+BL80 -> #DIV/0! | AM27: =BM77+BM80 -> #DIV/0! | AN27: =BN77+BN80 -> #DIV/0! | ... AZ27: =BZ77+BZ80 -> #DIV/0!
C28: =C14 -> Oct 20-26 | F28: =SUM(F82:F86) -> 0 | G28: =SUM(G82:G86) -> 0 | H28: =SUM(H82:H86) -> 0 | I28: =SUM(I82:I86) -> 0 | J28: =SUM(J82:J86) -> 0 | K28: =SUM(K82:K86) -> 0 | L28: =SUM(L82:L86) -> 0 | M28: =SUM(M82:M86) -> 0 | ... AA28: =SUM(AA82:AA86) -> 0 | AB28: =SUM(G28)/SUM(H28:M28) -> #DIV/0! | AC28: =AK82+AK85 -> #DIV/0! | AD28: =AJ82+AJ85 -> #DIV/0! | AE28: =G28/AD28 -> #DIV/0! | AG28: =BG82+BG85 -> #DIV/0! | AH28: =BH82+BH85 -> #DIV/0! | AI28: =BI82+BI85 -> #DIV/0! | AJ28: =BJ82+BJ85 -> #DIV/0! | AK28: =BK82+BK85 -> #DIV/0! | AL28: =BL82+BL85 -> #DIV/0! | AM28: =BM82+BM85 -> #DIV/0! | AN28: =BN82+BN85 -> #DIV/0! | ... AZ28: =BZ82+BZ85 -> #DIV/0!
C29: =C15 -> Oct 27-Nov 2 | F29: =SUM(F87:F91) -> 0 | G29: =SUM(G87:G91) -> 0 | H29: =SUM(H87:H91) -> 0 | I29: =SUM(I87:I91) -> 0 | J29: =SUM(J87:J91) -> 0 | K29: =SUM(K87:K91) -> 0 | L29: =SUM(L87:L91) -> 0 | M29: =SUM(M87:M91) -> 0 | ... AA29: =SUM(AA87:AA91) -> 0 | AB29: =SUM(G29)/SUM(H29:M29) -> #DIV/0! | AC29: =AK87+AK90 -> #DIV/0! | AD29: =AJ87+AJ90 -> #DIV/0! | AE29: =G29/AD29 -> #DIV/0! | AG29: =BG87+BG90 -> #DIV/0! | AH29: =BH87+BH90 -> #DIV/0! | AI29: =BI87+BI90 -> #DIV/0! | AJ29: =BJ87+BJ90 -> #DIV/0! | AK29: =BK87+BK90 -> #DIV/0! | AL29: =BL87+BL90 -> #DIV/0! | AM29: =BM87+BM90 -> #DIV/0! | AN29: =BN87+BN90 -> #DIV/0! | ... AZ29: =BZ87+BZ90 -> #DIV/0!
C30: =C16 -> Nov 3-9 | F30: =SUM(F92:F96) -> 0 | G30: =SUM(G92:G96) -> 0 | H30: =SUM(H92:H96) -> 0 | I30: =SUM(I92:I96) -> 0 | J30: =SUM(J92:J96) -> 0 | K30: =SUM(K92:K96) -> 0 | L30: =SUM(L92:L96) -> 0 | M30: =SUM(M92:M96) -> 0 | ... AA30: =SUM(AA92:AA96) -> 0 | AB30: =SUM(G30)/SUM(H30:M30) -> #DIV/0! | AC30: =AK92+AK95 -> #DIV/0! | AD30: =AL92+AL95 -> #DIV/0! | AE30: =G30/AD30 -> #DIV/0! | AG30: =BG92+BG95 -> #DIV/0! | AH30: =BH92+BH95 -> #DIV/0! | AI30: =BI92+BI95 -> #DIV/0! | AJ30: =BJ92+BJ95 -> #DIV/0! | AK30: =BK92+BK95 -> #DIV/0! | AL30: =BL92+BL95 -> #DIV/0! | AM30: =BM92+BM95 -> #DIV/0! | AN30: =BN92+BN95 -> #DIV/0! | ... AZ30: =BZ92+BZ95 -> #DIV/0!
C31: =C17 -> Nov 10-16
F32: =SUM(F22:F31) -> 0 | G32: =SUM(G22:G31) -> 0 | H32: =SUM(H22:H31) -> 0 | I32: =SUM(I22:I31) -> 0 | J32: =SUM(J22:J31) -> 0 | K32: =SUM(K22:K31) -> 0 | L32: =SUM(L22:L31) -> 0 | M32: =SUM(M22:M31) -> 0 | ... AA32: =SUM(AA22:AA31) -> 0 | AB32: =SUM(G32)/SUM(H32:M32) -> #DIV/0! | AC32: =SUM(AC22:AC31) -> #DIV/0! | AD32: =SUM(AD22:AD31) -> #DIV/0! | AE32: =G32/AD32 -> #DIV/0! | AG32: =SUM(AG22:AG31) -> #DIV/0! | AH32: =SUM(AH22:AH31) -> #DIV/0! | AI32: =SUM(AI22:AI31) -> #DIV/0! | AJ32: =SUM(AJ22:AJ31) -> #DIV/0! | AK32: =SUM(AK22:AK31) -> #DIV/0! | AL32: =SUM(AL22:AL31) -> #DIV/0! | AM32: =SUM(AM22:AM31) -> #DIV/0! | AN32: =SUM(AN22:AN31) -> #DIV/0! | ... AZ32: =SUM(AZ22:AZ31) -> #DIV/0!
C35: Boat Summary | E35: Sampled | AC35: Effort | AG35: Expanded Catch & Harvest
C36: =C8 -> 0 | E36: =SUM(E104:E108) -> 0 | F36: =SUM(F104:F108) -> 0 | G36: =SUM(G104:G108) -> 0 | H36: =SUM(H104:H108) -> 0 | I36: =SUM(I104:I108) -> 0 | J36: =SUM(J104:J108) -> 0 | K36: =SUM(K104:K108) -> 0 | L36: =SUM(L104:L108) -> 0 | ... AA36: =SUM(AA104:AA108) -> 0 | AB36: =SUM(G36)/SUM(H36:M36) -> #DIV/0! | AC36: =AK104+AK107 -> 0 | AD36: =AJ104+AJ107 -> 0 | AE36: =G36/AD36 -> #DIV/0! | AG36: =BG104+BG107 -> 0 | AH36: =BH104+BH107 -> 0 | AI36: =BI104+BI107 -> 0 | AJ36: =BJ104+BJ107 -> 0 | AK36: =BK104+BK107 -> 0 | AL36: =BL104+BL107 -> 0 | AM36: =BM104+BM107 -> 0 | AN36: =BN104+BN107 -> 0 | ... AZ36: =BZ104+BZ107 -> 0
C37: =C9 -> Sept 15-21 | E37: =SUM(E109:E113) -> 0 | F37: =SUM(F109:F113) -> 0 | G37: =SUM(G109:G113) -> 0 | H37: =SUM(H109:H113) -> 0 | I37: =SUM(I109:I113) -> 0 | J37: =SUM(J109:J113) -> 0 | K37: =SUM(K109:K113) -> 0 | L37: =SUM(L109:L113) -> 0 | ... AA37: =SUM(AA109:AA113) -> 0 | AB37: =SUM(G37)/SUM(H37:M37) -> #DIV/0! | AC37: =AK109+AK112 -> #DIV/0! | AD37: =AJ109+AJ112 -> #DIV/0! | AE37: =G37/AD37 -> #DIV/0! | AG37: =BG109+BG112 -> #DIV/0! | AH37: =BH109+BH112 -> #DIV/0! | AI37: =BI109+BI112 -> #DIV/0! | AJ37: =BJ109+BJ112 -> #DIV/0! | AK37: =BK109+BK112 -> #DIV/0! | AL37: =BL109+BL112 -> #DIV/0! | AM37: =BM109+BM112 -> #DIV/0! | AN37: =BN109+BN112 -> #DIV/0! | ... AZ37: =BZ109+BZ112 -> #DIV/0!
C38: =C10 -> Sept 21-28 | E38: =SUM(E114:E118) -> 0 | F38: =SUM(F114:F118) -> 0 | G38: =SUM(G114:G118) -> 0 | H38: =SUM(H114:H118) -> 0 | I38: =SUM(I114:I118) -> 0 | J38: =SUM(J114:J118) -> 0 | K38: =SUM(K114:K118) -> 0 | L38: =SUM(L114:L118) -> 0 | ... AA38: =SUM(AA114:AA118) -> 0 | AB38: =SUM(G38)/SUM(H38:M38) -> #DIV/0! | AC38: =AK114+AK117 -> #DIV/0! | AD38: =AJ114+AJ117 -> #DIV/0! | AE38: =G38/AD38 -> #DIV/0! | AG38: =BG114+BG117 -> #DIV/0! | AH38: =BH114+BH117 -> #DIV/0! | AI38: =BI114+BI117 -> #DIV/0! | AJ38: =BJ114+BJ117 -> #DIV/0! | AK38: =BK114+BK117 -> #DIV/0! | AL38: =BL114+BL117 -> #DIV/0! | AM38: =BM114+BM117 -> #DIV/0! | AN38: =BN114+BN117 -> #DIV/0! | ... AZ38: =BZ114+BZ117 -> #DIV/0!
C39: =C11 -> Sept 29-Oct 5 | E39: =SUM(E119:E123) -> 0 | F39: =SUM(F119:F123) -> 0 | G39: =SUM(G119:G123) -> 0 | H39: =SUM(H119:H123) -> 0 | I39: =SUM(I119:I123) -> 0 | J39: =SUM(J119:J123) -> 0 | K39: =SUM(K119:K123) -> 0 | L39: =SUM(L119:L123) -> 0 | ... AA39: =SUM(AA119:AA123) -> 0 | AB39: =SUM(G39)/SUM(H39:M39) -> #DIV/0! | AC39: =AK119+AK122 -> #DIV/0! | AD39: =AJ119+AJ122 -> #DIV/0! | AE39: =G39/AD39 -> #DIV/0! | AG39: =BG119+BG122 -> #DIV/0! | AH39: =BH119+BH122 -> #DIV/0! | AI39: =BI119+BI122 -> #DIV/0! | AJ39: =BJ119+BJ122 -> #DIV/0! | AK39: =BK119+BK122 -> #DIV/0! | AL39: =BL119+BL122 -> #DIV/0! | AM39: =BM119+BM122 -> #DIV/0! | AN39: =BN119+BN122 -> #DIV/0! | ... AZ39: =BZ119+BZ122 -> #DIV/0!
C40: =C12 -> Oct 6-Oct 12 | E40: =SUM(E124:E128) -> 0 | F40: =SUM(F124:F128) -> 0 | G40: =SUM(G124:G128) -> 0 | H40: =SUM(H124:H128) -> 0 | I40: =SUM(I124:I128) -> 0 | J40: =SUM(J124:J128) -> 0 | K40: =SUM(K124:K128) -> 0 | L40: =SUM(L124:L128) -> 0 | ... AA40: =SUM(AA124:AA128) -> 0 | AB40: =SUM(G40)/SUM(H40:M40) -> #DIV/0! | AC40: =AK124+AK127 -> #DIV/0! | AD40: =AJ124+AJ127 -> #DIV/0! | AE40: =G40/AD40 -> #DIV/0! | AG40: =BG124+BG127 -> #DIV/0! | AH40: =BH124+BH127 -> #DIV/0! | AI40: =BI124+BI127 -> #DIV/0! | AJ40: =BJ124+BJ127 -> #DIV/0! | AK40: =BK124+BK127 -> #DIV/0! | AL40: =BL124+BL127 -> #DIV/0! | AM40: =BM124+BM127 -> #DIV/0! | AN40: =BN124+BN127 -> #DIV/0! | ... AZ40: =BZ124+BZ127 -> #DIV/0!
C41: =C13 -> Oct 13-19 | E41: =SUM(E129:E133) -> 0 | F41: =SUM(F129:F133) -> 0 | G41: =SUM(G129:G133) -> 0 | H41: =SUM(H129:H133) -> 0 | I41: =SUM(I129:I133) -> 0 | J41: =SUM(J129:J133) -> 0 | K41: =SUM(K129:K133) -> 0 | L41: =SUM(L129:L133) -> 0 | ... AA41: =SUM(AA129:AA133) -> 0 | AB41: =SUM(G41)/SUM(H41:M41) -> #DIV/0! | AC41: =AK129+AK132 -> #DIV/0! | AD41: =AJ129+AJ132 -> #DIV/0! | AE41: =G41/AD41 -> #DIV/0! | AG41: =BG129+BG132 -> #DIV/0! | AH41: =BH129+BH132 -> #DIV/0! | AI41: =BI129+BI132 -> #DIV/0! | AJ41: =BJ129+BJ132 -> #DIV/0! | AK41: =BK129+BK132 -> #DIV/0! | AL41: =BL129+BL132 -> #DIV/0! | AM41: =BM129+BM132 -> #DIV/0! | AN41: =BN129+BN132 -> #DIV/0! | ... AZ41: =BZ129+BZ132 -> #DIV/0!
C42: =C14 -> Oct 20-26 | E42: =SUM(E134:E138) -> 0 | F42: =SUM(F134:F138) -> 0 | G42: =SUM(G134:G138) -> 0 | H42: =SUM(H134:H138) -> 0 | I42: =SUM(I134:I138) -> 0 | J42: =SUM(J134:J138) -> 0 | K42: =SUM(K134:K138) -> 0 | L42: =SUM(L134:L138) -> 0 | ... AA42: =SUM(AA134:AA138) -> 0 | AB42: =SUM(G42)/SUM(H42:M42) -> #DIV/0! | AC42: =AK134+AK137 -> #DIV/0! | AD42: =AJ134+AJ137 -> #DIV/0! | AE42: =G42/AD42 -> #DIV/0! | AG42: =BG134+BG137 -> #DIV/0! | AH42: =BH134+BH137 -> #DIV/0! | AI42: =BI134+BI137 -> #DIV/0! | AJ42: =BJ134+BJ137 -> #DIV/0! | AK42: =BK134+BK137 -> #DIV/0! | AL42: =BL134+BL137 -> #DIV/0! | AM42: =BM134+BM137 -> #DIV/0! | AN42: =BN134+BN137 -> #DIV/0! | ... AZ42: =BZ134+BZ137 -> #DIV/0!
C43: =C15 -> Oct 27-Nov 2 | E43: =SUM(E139:E143) -> 0 | F43: =SUM(F139:F143) -> 0 | G43: =SUM(G139:G143) -> 0 | H43: =SUM(H139:H143) -> 0 | I43: =SUM(I139:I143) -> 0 | J43: =SUM(J139:J143) -> 0 | K43: =SUM(K139:K143) -> 0 | L43: =SUM(L139:L143) -> 0 | ... AA43: =SUM(AA139:AA143) -> 0 | AB43: =SUM(G43)/SUM(H43:M43) -> #DIV/0! | AC43: =AK139+AK142 -> #DIV/0! | AD43: =AJ139+AJ142 -> #DIV/0! | AE43: =G43/AD43 -> #DIV/0! | AG43: =BG139+BG142 -> #DIV/0! | AH43: =BH139+BH142 -> #DIV/0! | AI43: =BI139+BI142 -> #DIV/0! | AJ43: =BJ139+BJ142 -> #DIV/0! | AK43: =BK139+BK142 -> #DIV/0! | AL43: =BL139+BL142 -> #DIV/0! | AM43: =BM139+BM142 -> #DIV/0! | AN43: =BN139+BN142 -> #DIV/0! | ... AZ43: =BZ139+BZ142 -> #DIV/0!
C44: =C16 -> Nov 3-9 | E44: =SUM(E144:E148) -> 0 | F44: =SUM(F144:F148) -> 0 | G44: =SUM(G144:G148) -> 0 | H44: =SUM(H144:H148) -> 0 | I44: =SUM(I144:I148) -> 0 | J44: =SUM(J144:J148) -> 0 | K44: =SUM(K144:K148) -> 0 | L44: =SUM(L144:L148) -> 0 | ... AA44: =SUM(AA144:AA148) -> 0 | AB44: =SUM(G44)/SUM(H44:M44) -> #DIV/0! | AC44: =AK144+AK147 -> #DIV/0! | AD44: =AJ144+AJ147 -> #DIV/0! | AE44: =G44/AD44 -> #DIV/0! | AG44: =BG144+BG147 -> #DIV/0! | AH44: =BH144+BH147 -> #DIV/0! | AI44: =BI144+BI147 -> #DIV/0! | AJ44: =BJ144+BJ147 -> #DIV/0! | AK44: =BK144+BK147 -> #DIV/0! | AL44: =BL144+BL147 -> #DIV/0! | AM44: =BM144+BM147 -> #DIV/0! | AN44: =BN144+BN147 -> #DIV/0! | ... AZ44: =BZ144+BZ147 -> #DIV/0!
...

Sheet Summary
C2: =Prosser!C2 -> 2025 Yakima River Fall Salmon Creel Survey (Sept 15 - October 31)
AB3: hours/fish
E4: Sampled | AC4: Effort | AG4: Expanded Catch & Harvest
H5: Chinook | N5: Coho | T5: Steelhead | V5: Incidental Catch | AG5: Chinook | AM5: Coho | AS5: Steelhead | AU5: Incidental Catch
E6: Sampled | H6: Adults | J6: Jacks | L6: Released | N6: Adults | P6: Jacks | R6: Released | T6: (Released) | V6: NPM | X6: SK | Z6: Bass | AC6: Angler | AD6: Effort | AE6: Sampled | AG6: Adults | AI6: Jacks | AK6: Released | AM6: Adults | AO6: Jacks | AQ6: Released | AS6: (Released) | AU6: NPM | AW6: SK
C7: Combined | E7: Boats | F7: Anglers | G7: Hours | H7: NM | I7: AD | J7: NM | K7: AD | L7: Adult | M7: Jacks | N7: NM | O7: AD | P7: NM | Q7: AD | R7: Adult | S7: Jacks | T7: Hatch | U7: Wild | V7: Catch | W7: Rel | X7: Catch | Y7: Rel | Z7: Catch | AA7: Rel | AC7: Trips | AD7: Pole Hrs | AE7: % | AG7: NM | AH7: AD | AI7: NM | AJ7: AD | AK7: Adult | AL7: Jacks | AM7: NM | AN7: AD | AO7: NM | AP7: AD | AQ7: Adult | AR7: Jacks | AS7: Hatch | AT7: Wild | AU7: Catch | AV7: Rel | AW7: Catch | AX7: Rel | AY7: Catch | AZ7: Rel
C8: =Prosser!C8 -> 0 | E8: =E22+E36 -> 0 | F8: =F22+F36 -> 0 | G8: =G22+G36 -> 0 | H8: =H22+H36 -> 0 | I8: =I22+I36 -> 0 | J8: =J22+J36 -> 0 | K8: =K22+K36 -> 0 | L8: =L22+L36 -> 0 | ... AA8: =AA22+AA36 -> 0 | AB8: =SUM(G8)/SUM(H8:M8) -> #DIV/0! | AC8: =AC22+AC36 -> 0 | AD8: =AD22+AD36 -> 0 | AE8: =G8/AD8 -> #DIV/0! | AG8: =AG22+AG36 -> 0 | AH8: =AH22+AH36 -> 0 | AI8: =AI22+AI36 -> 0 | AJ8: =AJ22+AJ36 -> 0 | AK8: =AK22+AK36 -> 0 | AL8: =AL22+AL36 -> 0 | AM8: =AM22+AM36 -> 0 | AN8: =AN22+AN36 -> 0 | ... AZ8: =AZ22+AZ36 -> 0
C9: =Prosser!C9 -> Sept 15-21 | E9: =E23+E37 -> 0 | F9: =F23+F37 -> 56 | G9: =G23+G37 -> 120.88 | H9: =H23+H37 -> 0 | I9: =I23+I37 -> 0 | J9: =J23+J37 -> 0 | K9: =K23+K37 -> 0 | L9: =L23+L37 -> 0 | ... AA9: =AA23+AA37 -> 0 | AB9: =SUM(G9)/SUM(H9:M9) -> #DIV/0! | AC9: =AC23+AC37 -> 0 | AD9: =AD23+AD37 -> 0 | AE9: =G9/AD9 -> #DIV/0! | AG9: =AG23+AG37 -> 0 | AH9: =AH23+AH37 -> 0 | AI9: =AI23+AI37 -> 0 | AJ9: =AJ23+AJ37 -> 0 | AK9: =AK23+AK37 -> 0 | AL9: =AL23+AL37 -> 0 | AM9: =AM23+AM37 -> 0 | AN9: =AN23+AN37 -> 0 | ... AZ9: =AZ23+AZ37 -> 0
C10: =Prosser!C10 -> Sept 21-28 | E10: =E24+E38 -> 0 | F10: =F24+F38 -> 78 | G10: =G24+G38 -> 161.47 | H10: =H24+H38 -> 4 | I10: =I24+I38 -> 3 | J10: =J24+J38 -> 1 | K10: =K24+K38 -> 0 | L10: =L24+L38 -> 1 | ... AA10: =AA24+AA38 -> 0 | AB10: =SUM(G10)/SUM(H10:M10) -> 17.941111 | AC10: =AC24+AC38 -> 0 | AD10: =AD24+AD38 -> 0 | AE10: =G10/AD10 -> #DIV/0! | AG10: =AG24+AG38 -> 0 | AH10: =AH24+AH38 -> 0 | AI10: =AI24+AI38 -> 0 | AJ10: =AJ24+AJ38 -> 0 | AK10: =AK24+AK38 -> 0 | AL10: =AL24+AL38 -> 0 | AM10: =AM24+AM38 -> 0 | AN10: =AN24+AN38 -> 0 | ... AZ10: =AZ24+AZ38 -> 0
C11: =Prosser!C11 -> Sept 29-Oct 5 | E11: =E25+E39 -> 1 | F11: =F25+F39 -> 98 | G11: =G25+G39 -> 163.55 | H11: =H25+H39 -> 3 | I11: =I25+I39 -> 10 | J11: =J25+J39 -> 1 | K11: =K25+K39 -> 0 | L11: =L25+L39 -> 0 | ... AA11: =AA25+AA39 -> 0 | AB11: =SUM(G11)/SUM(H11:M11) -> 11.682143 | AC11: =AC25+AC39 -> 0 | AD11: =AD25+AD39 -> 0 | AE11: =G11/AD11 -> #DIV/0! | AG11: =AG25+AG39 -> 0 | AH11: =AH25+AH39 -> 0 | AI11: =AI25+AI39 -> 0 | AJ11: =AJ25+AJ39 -> 0 | AK11: =AK25+AK39 -> 0 | AL11: =AL25+AL39 -> 0 | AM11: =AM25+AM39 -> 0 | AN11: =AN25+AN39 -> 0 | ... AZ11: =AZ25+AZ39 -> 0
C12: =Prosser!C12 -> Oct 6-Oct 12 | E12: =E26+E40 -> 0 | F12: =F26+F40 -> 169 | G12: =G26+G40 -> 385.46 | H12: =H26+H40 -> 12 | I12: =I26+I40 -> 22 | J12: =J26+J40 -> 1 | K12: =K26+K40 -> 1 | L12: =L26+L40 -> 0 | ... AA12: =AA26+AA40 -> 1 | AB12: =SUM(G12)/SUM(H12:M12) -> 10.707222 | AC12: =AC26+AC40 -> 0 | AD12: =AD26+AD40 -> 0 | AE12: =G12/AD12 -> #DIV/0! | AG12: =AG26+AG40 -> 0 | AH12: =AH26+AH40 -> 0 | AI12: =AI26+AI40 -> 0 | AJ12: =AJ26+AJ40 -> 0 | AK12: =AK26+AK40 -> 0 | AL12: =AL26+AL40 -> 0 | AM12: =AM26+AM40 -> 0 | AN12: =AN26+AN40 -> 0 | ... AZ12: =AZ26+AZ40 -> 0
C13: =Prosser!C13 -> Oct 13-19 | E13: =E27+E41 -> 0 | F13: =F27+F41 -> 149 | G13: =G27+G41 -> 341.13 | H13: =H27+H41 -> 12 | I13: =I27+I41 -> 14 | J13: =J27+J41 -> 1 | K13: =K27+K41 -> 0 | L13: =L27+L41 -> 0 | ... AA13: =AA27+AA41 -> 0 | AB13: =SUM(G13)/SUM(H13:M13) -> 12.634444 | AC13: =AC27+AC41 -> 0 | AD13: =AD27+AD41 -> 0 | AE13: =G13/AD13 -> #DIV/0! | AG13: =AG27+AG41 -> 0 | AH13: =AH27+AH41 -> 0 | AI13: =AI27+AI41 -> 0 | AJ13: =AJ27+AJ41 -> 0 | AK13: =AK27+AK41 -> 0 | AL13: =AL27+AL41 -> 0 | AM13: =AM27+AM41 -> 0 | AN13: =AN27+AN41 -> 0 | ... AZ13: =AZ27+AZ41 -> 0
C14: =Prosser!C14 -> Oct 20-26 | E14: =E28+E42 -> 0 | F14: =F28+F42 -> 128 | G14: =G28+G42 -> 383.7 | H14: =H28+H42 -> 4 | I14: =I28+I42 -> 10 | J14: =J28+J42 -> 0 | K14: =K28+K42 -> 0 | L14: =L28+L42 -> 1 | ... AA14: =AA28+AA42 -> 0 | AB14: =SUM(G14)/SUM(H14:M14) -> 25.58 | AC14: =AC28+AC42 -> 0 | AD14: =AD28+AD42 -> 0 | AE14: =G14/AD14 -> #DIV/0! | AG14: =AG28+AG42 -> 0 | AH14: =AH28+AH42 -> 0 | AI14: =AI28+AI42 -> 0 | AJ14: =AJ28+AJ42 -> 0 | AK14: =AK28+AK42 -> 0 | AL14: =AL28+AL42 -> 0 | AM14: =AM28+AM42 -> 0 | AN14: =AN28+AN42 -> 0 | ... AZ14: =AZ28+AZ42 -> 0
C15: =Prosser!C15 -> Oct 27-Nov 2 | E15: =E29+E43 -> 0 | F15: =F29+F43 -> 111 | G15: =G29+G43 -> 210.16 | H15: =H29+H43 -> 3 | I15: =I29+I43 -> 12 | J15: =J29+J43 -> 0 | K15: =K29+K43 -> 0 | L15: =L29+L43 -> 8 | ... AA15: =AA29+AA43 -> 0 | AB15: =SUM(G15)/SUM(H15:M15) -> 9.1373913 | AC15: =AC29+AC43 -> 0 | AD15: =AD29+AD43 -> 0 | AE15: =G15/AD15 -> #DIV/0! | AG15: =AG29+AG43 -> 0 | AH15: =AH29+AH43 -> 0 | AI15: =AI29+AI43 -> 0 | AJ15: =AJ29+AJ43 -> 0 | AK15: =AK29+AK43 -> 0 | AL15: =AL29+AL43 -> 0 | AM15: =AM29+AM43 -> 0 | AN15: =AN29+AN43 -> 0 | ... AZ15: =AZ29+AZ43 -> 0
C16: =Prosser!C16 -> Nov 3-9 | E16: =E30+E44 -> 0 | F16: =F30+F44 -> 0 | G16: =G30+G44 -> 0 | H16: =H30+H44 -> 0 | I16: =I30+I44 -> 0 | J16: =J30+J44 -> 0 | K16: =K30+K44 -> 0 | L16: =L30+L44 -> 0 | ... AA16: =AA30+AA44 -> 0 | AB16: =SUM(G16)/SUM(H16:M16) -> #DIV/0! | AC16: =AC30+AC44 -> 0 | AD16: =AD30+AD44 -> 0 | AE16: =G16/AD16 -> #DIV/0! | AG16: =AG30+AG44 -> 0 | AH16: =AH30+AH44 -> 0 | AI16: =AI30+AI44 -> 0 | AJ16: =AJ30+AJ44 -> 0 | AK16: =AK30+AK44 -> 0 | AL16: =AL30+AL44 -> 0 | AM16: =AM30+AM44 -> 0 | AN16: =AN30+AN44 -> 0 | ... AZ16: =AZ30+AZ44 -> 0
C17: =Prosser!C17 -> Nov 10-16 | E17: =E31+E45 -> 0 | F17: =F31+F45 -> 0 | G17: =G31+G45 -> 0 | H17: =H31+H45 -> 0 | I17: =I31+I45 -> 0 | J17: =J31+J45 -> 0 | K17: =K31+K45 -> 0 | L17: =L31+L45 -> 0 | ... AA17: =AA31+AA45 -> 0 | AB17: 0
E18: =SUM(E8:E17) -> 1 | F18: =SUM(F8:F17) -> 789 | G18: =SUM(G8:G17) -> 1766.35 | H18: =SUM(H8:H17) -> 38 | I18: =SUM(I8:I17) -> 71 | J18: =SUM(J8:J17) -> 4 | K18: =SUM(K8:K17) -> 1 | L18: =SUM(L8:L17) -> 10 | ... AA18: =SUM(AA8:AA17) -> 1 | AB18: =SUM(G18)/SUM(H18:M18) -> 14.244758 | AC18: =SUM(AC8:AC17) -> 0 | AD18: =SUM(AD8:AD17) -> 0 | AE18: =G18/AD18 -> #DIV/0! | AG18: =SUM(AG8:AG17) -> 0 | AH18: =SUM(AH8:AH17) -> 0 | AI18: =SUM(AI8:AI17) -> 0 | AJ18: =SUM(AJ8:AJ17) -> 0 | AK18: =SUM(AK8:AK17) -> 0 | AL18: =SUM(AL8:AL17) -> 0 | AM18: =SUM(AM8:AM17) -> 0 | AN18: =SUM(AN8:AN17) -> 0 | ... AZ18: =SUM(AZ8:AZ17) -> 0
AG19: =SUM(AG18:AL18) -> 0 | AH19: Total Salmon Caught
C21: Bank Summary | E21: Sampled | AC21: Effort | AG21: Expanded Catch & Harvest
C22: =C8 -> 0 | F22: =Prosser!F22+'Horn Rapids'!F22 -> 0 | G22: =Prosser!G22+'Horn Rapids'!G22 -> 0 | H22: =Prosser!H22+'Horn Rapids'!H22 -> 0 | I22: =Prosser!I22+'Horn Rapids'!I22 -> 0 | J22: =Prosser!J22+'Horn Rapids'!J22 -> 0 | K22: =Prosser!K22+'Horn Rapids'!K22 -> 0 | L22: =Prosser!L22+'Horn Rapids'!L22 -> 0 | M22: =Prosser!M22+'Horn Rapids'!M22 -> 0 | ... AA22: =Prosser!AA22+'Horn Rapids'!AA22 -> 0 | AB22: =SUM(G22)/SUM(H22:M22) -> #DIV/0!
C23: =C9 -> Sept 15-21 | F23: =Prosser!F23+'Horn Rapids'!F23 -> 56 | G23: =Prosser!G23+'Horn Rapids'!G23 -> 120.88 | H23: =Prosser!H23+'Horn Rapids'!H23 -> 0 | I23: =Prosser!I23+'Horn Rapids'!I23 -> 0 | J23: =Prosser!J23+'Horn Rapids'!J23 -> 0 | K23: =Prosser!K23+'Horn Rapids'!K23 -> 0 | L23: =Prosser!L23+'Horn Rapids'!L23 -> 0 | M23: =Prosser!M23+'Horn Rapids'!M23 -> 0 | ... AA23: =Prosser!AA23+'Horn Rapids'!AA23 -> 0 | AB23: =SUM(G23)/SUM(H23:M23) -> #DIV/0!
C24: =C10 -> Sept 21-28 | F24: =Prosser!F24+'Horn Rapids'!F24 -> 78 | G24: =Prosser!G24+'Horn Rapids'!G24 -> 161.47 | H24: =Prosser!H24+'Horn Rapids'!H24 -> 4 | I24: =Prosser!I24+'Horn Rapids'!I24 -> 3 | J24: =Prosser!J24+'Horn Rapids'!J24 -> 1 | K24: =Prosser!K24+'Horn Rapids'!K24 -> 0 | L24: =Prosser!L24+'Horn Rapids'!L24 -> 1 | M24: =Prosser!M24+'Horn Rapids'!M24 -> 0 | ... AA24: =Prosser!AA24+'Horn Rapids'!AA24 -> 0 | AB24: =SUM(G24)/SUM(H24:M24) -> 17.941111
C25: =C11 -> Sept 29-Oct 5 | F25: =Prosser!F25+'Horn Rapids'!F25 -> 96 | G25: =Prosser!G25+'Horn Rapids'!G25 -> 155.95 | H25: =Prosser!H25+'Horn Rapids'!H25 -> 2 | I25: =Prosser!I25+'Horn Rapids'!I25 -> 7 | J25: =Prosser!J25+'Horn Rapids'!J25 -> 1 | K25: =Prosser!K25+'Horn Rapids'!K25 -> 0 | L25: =Prosser!L25+'Horn Rapids'!L25 -> 0 | M25: =Prosser!M25+'Horn Rapids'!M25 -> 0 | ... AA25: =Prosser!AA25+'Horn Rapids'!AA25 -> 0 | AB25: =SUM(G25)/SUM(H25:M25) -> 15.595
C26: =C12 -> Oct 6-Oct 12 | F26: =Prosser!F26+'Horn Rapids'!F26 -> 169 | G26: =Prosser!G26+'Horn Rapids'!G26 -> 385.46 | H26: =Prosser!H26+'Horn Rapids'!H26 -> 12 | I26: =Prosser!I26+'Horn Rapids'!I26 -> 22 | J26: =Prosser!J26+'Horn Rapids'!J26 -> 1 | K26: =Prosser!K26+'Horn Rapids'!K26 -> 1 | L26: =Prosser!L26+'Horn Rapids'!L26 -> 0 | M26: =Prosser!M26+'Horn Rapids'!M26 -> 0 | ... AA26: =Prosser!AA26+'Horn Rapids'!AA26 -> 1 | AB26: =SUM(G26)/SUM(H26:M26) -> 10.707222
C27: =C13 -> Oct 13-19 | F27: =Prosser!F27+'Horn Rapids'!F27 -> 149 | G27: =Prosser!G27+'Horn Rapids'!G27 -> 341.13 | H27: =Prosser!H27+'Horn Rapids'!H27 -> 12 | I27: =Prosser!I27+'Horn Rapids'!I27 -> 14 | J27: =Prosser!J27+'Horn Rapids'!J27 -> 1 | K27: =Prosser!K27+'Horn Rapids'!K27 -> 0 | L27: =Prosser!L27+'Horn Rapids'!L27 -> 0 | M27: =Prosser!M27+'Horn Rapids'!M27 -> 0 | ... AA27: =Prosser!AA27+'Horn Rapids'!AA27 -> 0 | AB27: =SUM(G27)/SUM(H27:M27) -> 12.634444
C28: =C14 -> Oct 20-26 | F28: =Prosser!F28+'Horn Rapids'!F28 -> 128 | G28: =Prosser!G28+'Horn Rapids'!G28 -> 383.7 | H28: =Prosser!H28+'Horn Rapids'!H28 -> 4 | I28: =Prosser!I28+'Horn Rapids'!I28 -> 10 | J28: =Prosser!J28+'Horn Rapids'!J28 -> 0 | K28: =Prosser!K28+'Horn Rapids'!K28 -> 0 | L28: =Prosser!L28+'Horn Rapids'!L28 -> 1 | M28: =Prosser!M28+'Horn Rapids'!M28 -> 0 | ... AA28: =Prosser!AA28+'Horn Rapids'!AA28 -> 0 | AB28: =SUM(G28)/SUM(H28:M28) -> 25.58
C29: =C15 -> Oct 27-Nov 2 | F29: =Prosser!F29+'Horn Rapids'!F29 -> 111 | G29: =Prosser!G29+'Horn Rapids'!G29 -> 210.16 | H29: =Prosser!H29+'Horn Rapids'!H29 -> 3 | I29: =Prosser!I29+'Horn Rapids'!I29 -> 12 | J29: =Prosser!J29+'Horn Rapids'!J29 -> 0 | K29: =Prosser!K29+'Horn Rapids'!K29 -> 0 | L29: =Prosser!L29+'Horn Rapids'!L29 -> 8 | M29: =Prosser!M29+'Horn Rapids'!M29 -> 0 | ... AA29: =Prosser!AA29+'Horn Rapids'!AA29 -> 0 | AB29: =SUM(G29)/SUM(H29:M29) -> 9.1373913
C30: =C16 -> Nov 3-9 | F30: =Prosser!F30+'Horn Rapids'!F30 -> 0 | G30: =Prosser!G30+'Horn Rapids'!G30 -> 0 | H30: =Prosser!H30+'Horn Rapids'!H30 -> 0 | I30: =Prosser!I30+'Horn Rapids'!I30 -> 0 | J30: =Prosser!J30+'Horn Rapids'!J30 -> 0 | K30: =Prosser!K30+'Horn Rapids'!K30 -> 0 | L30: =Prosser!L30+'Horn Rapids'!L30 -> 0 | M30: =Prosser!M30+'Horn Rapids'!M30 -> 0 | ... AA30: =Prosser!AA30+'Horn Rapids'!AA30 -> 0 | AB30: =SUM(G30)/SUM(H30:M30) -> #DIV/0!
C31: =C17 -> Nov 10-16 | F31: =Prosser!F31+'Horn Rapids'!F31 -> 0 | G31: =Prosser!G31+'Horn Rapids'!G31 -> 0 | H31: =Prosser!H31+'Horn Rapids'!H31 -> 0 | I31: =Prosser!I31+'Horn Rapids'!I31 -> 0 | J31: =Prosser!J31+'Horn Rapids'!J31 -> 0 | K31: =Prosser!K31+'Horn Rapids'!K31 -> 0 | L31: =Prosser!L31+'Horn Rapids'!L31 -> 0 | M31: =Prosser!M31+'Horn Rapids'!M31 -> 0 | ... AA31: =Prosser!AA31+'Horn Rapids'!AA31 -> 0 | AB31: 0
F32: =SUM(F22:F31) -> 787 | G32: =SUM(G22:G31) -> 1758.75 | H32: =SUM(H22:H31) -> 37 | I32: =SUM(I22:I31) -> 68 | J32: =SUM(J22:J31) -> 4 | K32: =SUM(K22:K31) -> 1 | L32: =SUM(L22:L31) -> 10 | M32: =SUM(M22:M31) -> 0 | ... AA32: =SUM(AA22:AA31) -> 1 | AB32: =SUM(G32)/SUM(H32:M32) -> 14.65625 | AC32: =SUM(AC22:AC31) -> 0 | AD32: =SUM(AD22:AD31) -> 0 | AE32: =G32/AD32 -> #DIV/0! | AG32: =SUM(AG22:AG31) -> 0 | AH32: =SUM(AH22:AH31) -> 0 | AI32: =SUM(AI22:AI31) -> 0 | AJ32: =SUM(AJ22:AJ31) -> 0 | AK32: =SUM(AK22:AK31) -> 0 | AL32: =SUM(AL22:AL31) -> 0 | AM32: =SUM(AM22:AM31) -> 0 | AN32: =SUM(AN22:AN31) -> 0 | ... AZ32: =SUM(AZ22:AZ31) -> 0
C35: Boat Summary | E35: Sampled | AC35: Effort | AG35: Expanded Catch & Harvest
C36: =C8 -> 0 | E36: =Prosser!E36+'Horn Rapids'!E36 -> 0 | F36: =Prosser!F36+'Horn Rapids'!F36 -> 0 | G36: =Prosser!G36+'Horn Rapids'!G36 -> 0 | H36: =Prosser!H36+'Horn Rapids'!H36 -> 0 | I36: =Prosser!I36+'Horn Rapids'!I36 -> 0 | J36: =Prosser!J36+'Horn Rapids'!J36 -> 0 | K36: =Prosser!K36+'Horn Rapids'!K36 -> 0 | L36: =Prosser!L36+'Horn Rapids'!L36 -> 0 | ... AA36: =Prosser!AA36+'Horn Rapids'!AA36 -> 0 | AB36: 0
C37: =C9 -> Sept 15-21 | E37: =Prosser!E37+'Horn Rapids'!E37 -> 0 | F37: =Prosser!F37+'Horn Rapids'!F37 -> 0 | G37: =Prosser!G37+'Horn Rapids'!G37 -> 0 | H37: =Prosser!H37+'Horn Rapids'!H37 -> 0 | I37: =Prosser!I37+'Horn Rapids'!I37 -> 0 | J37: =Prosser!J37+'Horn Rapids'!J37 -> 0 | K37: =Prosser!K37+'Horn Rapids'!K37 -> 0 | L37: =Prosser!L37+'Horn Rapids'!L37 -> 0 | ... AA37: =Prosser!AA37+'Horn Rapids'!AA37 -> 0 | AB37: =SUM(G37)/SUM(H37:M37) -> #DIV/0!
C38: =C10 -> Sept 21-28 | E38: =Prosser!E38+'Horn Rapids'!E38 -> 0 | F38: =Prosser!F38+'Horn Rapids'!F38 -> 0 | G38: =Prosser!G38+'Horn Rapids'!G38 -> 0 | H38: =Prosser!H38+'Horn Rapids'!H38 -> 0 | I38: =Prosser!I38+'Horn Rapids'!I38 -> 0 | J38: =Prosser!J38+'Horn Rapids'!J38 -> 0 | K38: =Prosser!K38+'Horn Rapids'!K38 -> 0 | L38: =Prosser!L38+'Horn Rapids'!L38 -> 0 | ... AA38: =Prosser!AA38+'Horn Rapids'!AA38 -> 0 | AB38: =SUM(G38)/SUM(H38:M38) -> #DIV/0!
C39: =C11 -> Sept 29-Oct 5 | E39: =Prosser!E39+'Horn Rapids'!E39 -> 1 | F39: =Prosser!F39+'Horn Rapids'!F39 -> 2 | G39: =Prosser!G39+'Horn Rapids'!G39 -> 7.6 | H39: =Prosser!H39+'Horn Rapids'!H39 -> 1 | I39: =Prosser!I39+'Horn Rapids'!I39 -> 3 | J39: =Prosser!J39+'Horn Rapids'!J39 -> 0 | K39: =Prosser!K39+'Horn Rapids'!K39 -> 0 | L39: =Prosser!L39+'Horn Rapids'!L39 -> 0 | ... AA39: =Prosser!AA39+'Horn Rapids'!AA39 -> 0 | AB39: =SUM(G39)/SUM(H39:M39) -> 1.9
C40: =C12 -> Oct 6-Oct 12 | E40: =Prosser!E40+'Horn Rapids'!E40 -> 0 | F40: =Prosser!F40+'Horn Rapids'!F40 -> 0 | G40: =Prosser!G40+'Horn Rapids'!G40 -> 0 | H40: =Prosser!H40+'Horn Rapids'!H40 -> 0 | I40: =Prosser!I40+'Horn Rapids'!I40 -> 0 | J40: =Prosser!J40+'Horn Rapids'!J40 -> 0 | K40: =Prosser!K40+'Horn Rapids'!K40 -> 0 | L40: =Prosser!L40+'Horn Rapids'!L40 -> 0 | ... AA40: =Prosser!AA40+'Horn Rapids'!AA40 -> 0 | AB40: =SUM(G40)/SUM(H40:M40) -> #DIV/0!
C41: =C13 -> Oct 13-19 | E41: =Prosser!E41+'Horn Rapids'!E41 -> 0 | F41: =Prosser!F41+'Horn Rapids'!F41 -> 0 | G41: =Prosser!G41+'Horn Rapids'!G41 -> 0 | H41: =Prosser!H41+'Horn Rapids'!H41 -> 0 | I41: =Prosser!I41+'Horn Rapids'!I41 -> 0 | J41: =Prosser!J41+'Horn Rapids'!J41 -> 0 | K41: =Prosser!K41+'Horn Rapids'!K41 -> 0 | L41: =Prosser!L41+'Horn Rapids'!L41 -> 0 | ... AA41: =Prosser!AA41+'Horn Rapids'!AA41 -> 0 | AB41: =SUM(G41)/SUM(H41:M41) -> #DIV/0!
C42: =C14 -> Oct 20-26 | E42: =Prosser!E42+'Horn Rapids'!E42 -> 0 | F42: =Prosser!F42+'Horn Rapids'!F42 -> 0 | G42: =Prosser!G42+'Horn Rapids'!G42 -> 0 | H42: =Prosser!H42+'Horn Rapids'!H42 -> 0 | I42: =Prosser!I42+'Horn Rapids'!I42 -> 0 | J42: =Prosser!J42+'Horn Rapids'!J42 -> 0 | K42: =Prosser!K42+'Horn Rapids'!K42 -> 0 | L42: =Prosser!L42+'Horn Rapids'!L42 -> 0 | ... AA42: =Prosser!AA42+'Horn Rapids'!AA42 -> 0 | AB42: =SUM(G42)/SUM(H42:M42) -> #DIV/0!
C43: =C15 -> Oct 27-Nov 2 | E43: =Prosser!E43+'Horn Rapids'!E43 -> 0 | F43: =Prosser!F43+'Horn Rapids'!F43 -> 0 | G43: =Prosser!G43+'Horn Rapids'!G43 -> 0 | H43: =Prosser!H43+'Horn Rapids'!H43 -> 0 | I43: =Prosser!I43+'Horn Rapids'!I43 -> 0 | J43: =Prosser!J43+'Horn Rapids'!J43 -> 0 | K43: =Prosser!K43+'Horn Rapids'!K43 -> 0 | L43: =Prosser!L43+'Horn Rapids'!L43 -> 0 | ... AA43: =Prosser!AA43+'Horn Rapids'!AA43 -> 0 | AB43: =SUM(G43)/SUM(H43:M43) -> #DIV/0!
C44: =C16 -> Nov 3-9 | E44: =Prosser!E44+'Horn Rapids'!E44 -> 0 | F44: =Prosser!F44+'Horn Rapids'!F44 -> 0 | G44: =Prosser!G44+'Horn Rapids'!G44 -> 0 | H44: =Prosser!H44+'Horn Rapids'!H44 -> 0 | I44: =Prosser!I44+'Horn Rapids'!I44 -> 0 | J44: =Prosser!J44+'Horn Rapids'!J44 -> 0 | K44: =Prosser!K44+'Horn Rapids'!K44 -> 0 | L44: =Prosser!L44+'Horn Rapids'!L44 -> 0 | ... AA44: =Prosser!AA44+'Horn Rapids'!AA44 -> 0 | AB44: =SUM(G44)/SUM(H44:M44) -> #DIV/0!
...

Sheet Other
C3: =Prosser!C8 -> 0 | E3: =SUM(E16:E25) -> 0 | F3: =SUM(F16:F25) -> 0 | G3: =SUM(G16:G25) -> 0 | H3: =SUM(H16:H25) -> 0 | I3: =SUM(I16:I25) -> 0 | J3: =SUM(J16:J25) -> 0 | K3: =SUM(K16:K25) -> 0 | L3: =SUM(L16:L25) -> 0 | ... W3: =SUM(W16:W25) -> 0 | AG3: =SUM(AG16:AG25) -> #DIV/0! | CA3: May 2-3 | CC3: =SUM(CC16:CC25) -> #DIV/0! | CD3: =SUM(CD16:CD25) -> #DIV/0! | CE3: =SUM(CE16:CE25) -> #DIV/0! | CF3: =SUM(CF16:CF25) -> #DIV/0! | CG3: =SUM(CG16:CG25) -> #DIV/0! | CH3: =SUM(CH16:CH25) -> #DIV/0! | CI3: =SUM(CI16:CI25) -> #DIV/0! | CJ3: =SUM(CJ16:CJ25) -> #DIV/0! | ... CT3: =SUM(CT16:CT25) -> 0
C4: =Prosser!C9 -> Sept 15-21 | E4: =SUM(E26:E35) -> 0 | F4: =SUM(F26:F35) -> 0 | G4: =SUM(G26:G35) -> 0 | H4: =SUM(H26:H35) -> 0 | I4: =SUM(I26:I35) -> 0 | J4: =SUM(J26:J35) -> 0 | K4: =SUM(K26:K35) -> 0 | L4: =SUM(L26:L35) -> 0 | ... W4: =SUM(W26:W35) -> 0 | AG4: =AVERAGE(AG26:AG35)*7 -> #DIV/0! | CA4: May 4-10 | CC4: =SUM(CC26:CC35) -> #DIV/0! | CD4: =SUM(CD26:CD35) -> #DIV/0! | CE4: =SUM(CE26:CE35) -> #DIV/0! | CF4: =SUM(CF26:CF35) -> #DIV/0! | CG4: =SUM(CG26:CG35) -> #DIV/0! | CH4: =SUM(CH26:CH35) -> #DIV/0! | CI4: =SUM(CI26:CI35) -> #DIV/0! | CJ4: =SUM(CJ26:CJ35) -> #DIV/0! | ... CT4: =SUM(CT26:CT35) -> 0
C5: =Prosser!C10 -> Sept 21-28 | E5: =SUM(E36:E45) -> 0 | F5: =SUM(F36:F45) -> 0 | G5: =SUM(G36:G45) -> 0 | H5: =SUM(H36:H45) -> 0 | I5: =SUM(I36:I45) -> 0 | J5: =SUM(J36:J45) -> 0 | K5: =SUM(K36:K45) -> 0 | L5: =SUM(L36:L45) -> 0 | ... W5: =SUM(W36:W45) -> 0 | AG5: =AVERAGE(AG36:AG41)*5+AG42+AG44 -> #DIV/0! | CA5: May 11-17 | CC5: =SUM(CC36:CC45) -> #DIV/0! | CD5: =SUM(CD36:CD45) -> #DIV/0! | CE5: =SUM(CE36:CE45) -> #DIV/0! | CF5: =SUM(CF36:CF45) -> #DIV/0! | CG5: =SUM(CG36:CG45) -> #DIV/0! | CH5: =SUM(CH36:CH45) -> #DIV/0! | CI5: =SUM(CI36:CI45) -> #DIV/0! | CJ5: =SUM(CJ36:CJ45) -> #DIV/0! | ... CT5: =SUM(CT36:CT45) -> 0
C6: =Prosser!C11 -> Sept 29-Oct 5 | E6: =SUM(E46:E55) -> 0 | F6: =SUM(F46:F55) -> 0 | G6: =SUM(G46:G55) -> 0 | H6: =SUM(H46:H55) -> 0 | I6: =SUM(I46:I55) -> 0 | J6: =SUM(J46:J55) -> 0 | K6: =SUM(K46:K55) -> 0 | L6: =SUM(L46:L55) -> 0 | ... W6: =SUM(W46:W55) -> 0 | AG6: =AVERAGE(AG46:AG51)*5+AG52+AG54 -> #DIV/0! | CA6: May 18-24 | CC6: =SUM(CC46:CC55) -> #DIV/0! | CD6: =SUM(CD46:CD55) -> #DIV/0! | CE6: =SUM(CE46:CE55) -> #DIV/0! | CF6: =SUM(CF46:CF55) -> #DIV/0! | CG6: =SUM(CG46:CG55) -> #DIV/0! | CH6: =SUM(CH46:CH55) -> #DIV/0! | CI6: =SUM(CI46:CI55) -> #DIV/0! | CJ6: =SUM(CJ46:CJ55) -> #DIV/0! | ... CT6: =SUM(CT46:CT55) -> 0
C7: =Prosser!C12 -> Oct 6-Oct 12 | E7: =SUM(E56:E63) -> 0 | F7: =SUM(F56:F63) -> 0 | G7: =SUM(G56:G63) -> 0 | H7: =SUM(H56:H63) -> 0 | I7: =SUM(I56:I63) -> 0 | J7: =SUM(J56:J63) -> 0 | K7: =SUM(K56:K63) -> 0 | L7: =SUM(L56:L63) -> 0 | ... W7: =SUM(W56:W63) -> 0 | AG7: =AVERAGE(AG56:AG59)*5+AG60+AG62 -> #DIV/0! | CA7: May 26-Jun 1 | CC7: =SUM(CC47:CC56) -> #DIV/0! | CD7: =SUM(CD47:CD56) -> #DIV/0! | CE7: =SUM(CE47:CE56) -> #DIV/0! | CF7: =SUM(CF47:CF56) -> #DIV/0! | CG7: =SUM(CG47:CG56) -> #DIV/0! | CH7: =SUM(CH47:CH56) -> #DIV/0! | CI7: =SUM(CI47:CI56) -> #DIV/0! | CJ7: =SUM(CJ47:CJ56) -> #DIV/0! | ... CT7: =SUM(CT47:CT56) -> 0
