Workbook

Sheet Readme
A2: From: Jonathan Carey - NOAA Federal <jonathan.carey@noaa.gov>
A3: Date: Fri, Aug 18, 2023 at 5:17 PM
A4: Subject: Rec data for EIS
A5: To: James Dixon <james.dixon@noaa.gov>
A8: Here you go, I've gone through the rec data that Eric sent and 4 files are attached here:
A10: 1. "Recreational Effort for RMP EIS.xlsx" - this is the file from 2018 which you probably already have.
A11: 2. "Rec_raw_catch_effort__raw_2010-2021.csv" - this is the raw data in the same format as what was in the 'Data' tab of the 2018 file, updated with what Eric sent through 2021.
A12: 3. "Rec_pivot_trips_by_subregion_year.csv" - this is an updated version of the pivot table in cells A3:I9 of the 'Pivot' tab of the 2018 file, updated with what Eric sent through 2021.
A13: 4. "Rec_pivot_trips_proportion_subregion_year.csv" - this is an updated version of the pivot table in cells K3:O32 of the 'Pivot' tab of the 2018 file, updated with what Eric sent through 2021.
A15: Hope that's what you were looking for? Note that I used the same values as we did in 2018 to convert steelhead and freshwater salmon catches into trips, let me know if you know of better numbers to use for that and I can easily update.
A17: --
A18: Jon Carey
... A34: Angler Trips/Fish Caught
A35: Species | B35: Even Year | C35: Odd Year
A36: Salmon | B36: 8.65 | C36: 3.44
A37: Steelhead | B37: 8.54 | C37: 18.55
A39: Lookups: | B39: Salmon | C39: Steelhead
A40: 2010 | B40: =B36 -> 8.65 | C40: =B37 -> 8.54
A41: 2011 | B41: =C36 -> 3.44 | C41: =C37 -> 18.55
A42: 2012 | B42: =B$40 -> 8.65 | C42: =C$40 -> 8.54
A43: 2013 | B43: =B$41 -> 3.44 | C43: =C$41 -> 18.55
A44: 2014 | B44: =B$40 -> 8.65 | C44: =C$40 -> 8.54
A45: 2015 | B45: =B$41 -> 3.44 | C45: =C$41 -> 18.55
A46: 2016 | B46: =B$40 -> 8.65 | C46: =C$40 -> 8.54
A47: 2017 | B47: =B$41 -> 3.44 | C47: =C$41 -> 18.55
A48: 2018 | B48: =B$40 -> 8.65 | C48: =C$40 -> 8.54
A49: 2019 | B49: =B$41 -> 3.44 | C49: =C$41 -> 18.55
A50: 2020 | B50: =B$40 -> 8.65 | C50: =C$40 -> 8.54
A51: 2021 | B51: =B$41 -> 3.44 | C51: =C$41 -> 18.55
A52: 2022 | B52: =B$40 -> 8.65 | C52: =C$40 -> 8.54
A54: Updated May 10, 2024 from: <Updated FW trips-per-fish estimates including steelhead for PS RMP EIS_05-10-2024_ecw.xlsx>
A55: (Based on re-examination of 2006 and 2011 FW angler data plus incorporation of 2022 FW angler data)
A56: Use the following angler success rate estimates to calculate est. number of angler trips associated with FW Salmon and FW Steelhead recreational catch during each odd and even year in the 2010-2019 Existing Conditions baseline period
B57: Odd Years | C57: Even Years
A58: PS Salmon FW angler success rates (for 2011 and 2022, respectively) | B58: ='[1]Updated Puget Sound effort'!$B$30 -> 3.5390404 | C58: ='[1]Updated Puget Sound effort'!$C$30 -> 4.8195549
A59: PS Steelhead FW angler success rates (straight avg of 2011 and 2022 FW steelhead angler success rates - assumes no difference between odd- vs even-years) | B59: ='[1]Updated Puget Sound effort'!$B$31:$C$31 -> 20.927237
A61: Updated FW Angler Success Rate Lookups: | B61: Salmon | C61: Steelhead
A62: 2010 | B62: =C$58 -> 4.8195549 | C62: =B$59 -> 20.927237
A63: 2011 | B63: =B$58 -> 3.5390404 | C63: =B$59 -> 20.927237
A64: 2012 | B64: =C$58 -> 4.8195549 | C64: =B$59 -> 20.927237
...

Sheet LUTs
A1: Catch Area | B1: County_CatchArea | C1: Subregion_CatchArea | E1: County of Res | F1: Subregion of Res | G1: County_N-S_Order | H1: Subregion_N-S_Order
A2: Area 5: W Juan de Fuca | B2: NA | C2: 0Strait of Juan de Fuca | E2: Island | F2: North Puget Sound | G2: 04Island | H2: =CONCATENATE("01",F2) -> 01North Puget Sound
A3: Area 6: E Juan de Fuca | B3: NA | C3: 0Strait of Juan de Fuca | E3: San Juan | F3: North Puget Sound | G3: 05San Juan | H3: =CONCATENATE("01",F3) -> 01North Puget Sound
A4: Clallam River | B4: Clallam | C4: 0Strait of Juan de Fuca | E4: Skagit | F4: North Puget Sound | G4: 02Skagit | H4: =CONCATENATE("01",F4) -> 01North Puget Sound
A5: Deep Creek (Clallam Co.) | B5: Clallam | C5: 0Strait of Juan de Fuca | E5: Snohomish | F5: North Puget Sound | G5: 03Snohomish | H5: =CONCATENATE("01",F5) -> 01North Puget Sound
A6: Dungeness River | B6: Clallam | C6: 0Strait of Juan de Fuca | E6: Whatcom | F6: North Puget Sound | G6: 01Whatcom | H6: =CONCATENATE("01",F6) -> 01North Puget Sound
A7: Elwha River | B7: Clallam | C7: 0Strait of Juan de Fuca | E7: King | F7: South Puget Sound | G7: 06King | H7: =CONCATENATE("02",F7) -> 02South Puget Sound
A8: Hoko River | B8: Clallam | C8: 0Strait of Juan de Fuca | E8: Kitsap | F8: South Puget Sound | G8: 10Kitsap | H8: =CONCATENATE("02",F8) -> 02South Puget Sound
A9: Lyre River | B9: Clallam | C9: 0Strait of Juan de Fuca | E9: Mason | F9: South Puget Sound | G9: 09Mason | H9: =CONCATENATE("02",F9) -> 02South Puget Sound
A10: Morse Creek (Clallam Co.) | B10: Clallam | C10: 0Strait of Juan de Fuca | E10: Pierce | F10: South Puget Sound | G10: 07Pierce | H10: =CONCATENATE("02",F10) -> 02South Puget Sound
A11: Pysht River | B11: Clallam | C11: 0Strait of Juan de Fuca | E11: Thurston | F11: South Puget Sound | G11: 08Thurston | H11: =CONCATENATE("02",F11) -> 02South Puget Sound
A12: Salt Creek (Clallam Co.) | B12: Clallam | C12: 0Strait of Juan de Fuca | E12: Clallam | F12: Strait of Juan de Fuca | G12: 11Clallam | H12: =CONCATENATE("03",F12) -> 03Strait of Juan de Fuca
A13: Sekiu River | B13: Clallam | C13: 0Strait of Juan de Fuca | E13: Jefferson | F13: Strait of Juan de Fuca | G13: 12Jefferson | H13: =CONCATENATE("03",F13) -> 03Strait of Juan de Fuca
A14: Area 7: San Juan Islands | B14: NA | C14: 1North Puget Sound | E14: Other | F14: Non Puget Sound | G14: 20Other | H14: =CONCATENATE("07",F14) -> 07Non Puget Sound
A15: Baker Lake | B15: Whatcom | C15: 1North Puget Sound
A16: Baker River | B16: Skagit/Whatcom | C16: 1North Puget Sound
A17: California Creek | B17: Whatcom | C17: 1North Puget Sound
A18: Cascade River | B18: Skagit | C18: 1North Puget Sound
A19: Dakota Creek (Whatcom Co) | B19: Whatcom | C19: 1North Puget Sound
A20: Nooksack River | B20: Whatcom | C20: 1North Puget Sound
A21: Nooksack River, below North Fork | B21: Whatcom | C21: 1North Puget Sound
A22: Nooksack River, No. Fork | B22: Whatcom | C22: 1North Puget Sound
A23: Nooksack River, So. Fork | B23: Whatcom | C23: 1North Puget Sound
A24: Samish River | B24: Skagit | C24: 1North Puget Sound
A25: Whatcom Creek | B25: Whatcom | C25: 1North Puget Sound
A26: Area 8-1: Skagit Bay-Saratoga Psg. | B26: NA | C26: 2Central Puget Sound | D26: Skagit Bay in Central but the rest of Skagit River in North Puget Sound?
A27: Area 8-2: Port Susan-Port Gardner | B27: NA | C27: 2Central Puget Sound
A28: Area 9: Admiralty Inlet | B28: NA | C28: 2Central Puget Sound
A29: Canyon Creek | B29: Snohomish | C29: 2Central Puget Sound
A30: Lake Sammamish | B30: King | C30: 2Central Puget Sound
A31: Lake Washington | B31: King | C31: 2Central Puget Sound
A32: Pilchuck Creek (Stillaguamish System) | B32: Skagit/Snohomish | C32: 2Central Puget Sound
A33: Pilchuck River (Snohomish System) | B33: Snohomish | C33: 2Central Puget Sound
A34: Raging River | B34: King | C34: 2Central Puget Sound
A35: Sauk River | B35: Skagit/Snohomish | C35: 2Central Puget Sound
A36: Skagit River | B36: Skagit/Whatcom | C36: 2Central Puget Sound | D36: Skagit Bay in Central but the rest of Skagit River in North Puget Sound?
A37: Skykomish River | B37: Snohomish | C37: 2Central Puget Sound
A38: Skykomish River, No. Fork | B38: Snohomish | C38: 2Central Puget Sound
A39: Skykomish River, So. Fork | B39: Snohomish/King | C39: 2Central Puget Sound
A40: Snohomish River | B40: Snohomish | C40: 2Central Puget Sound
...

Sheet Rec_raw_catch_effort_2010-2021
A1: Row | B1: Year | C1: Water_Type | D1: Water_Type2 | E1: Species | F1: CatchAreaCode | G1: CatchArea | H1: CatchArea2 | I1: County_CatchArea | J1: Subregion_CatchArea | K1: County_of_Residence | L1: County_of_Res_N-S_Order | M1: Subregion_County_of_Residence | N1: Subregion_Co_of_Res_N-S_Order | O1: Catch | P1: Trips | Q1: Catch2 | R1: Trips2 | S1: 2010-2019? | T1: Trips/Catch | U1: Trips2/Catch2
A2: 3120 | B2: 2010 | C2: Marine | D2: 1Marine | E2: Salmon | F2: 5 | G2: Area 5: W Juan de Fuca | H2: =G2 -> Area 5: W Juan de Fuca | I2: =IFERROR(VLOOKUP(H2,LUTs!$A$1:$C$73,2,FALSE),"NA") -> NA | J2: =IFERROR(VLOOKUP(H2,LUTs!$A$1:$C$73,3,FALSE),"NA") -> 0Strait of Juan de Fuca | K2: Clallam | L2: =VLOOKUP(K2,LUTs!E$2:G$14,3,) -> 11Clallam | M2: =VLOOKUP($K2,LUTs!$E$2:$H$14,2,) -> Strait of Juan de Fuca | N2: =VLOOKUP($K2,LUTs!$E$2:$H$14,4,) -> 03Strait of Juan de Fuca | O2: 2398.9335 | P2: 4507.4475 | Q2: =O2 -> 2398.9335 | R2: =P2 -> 4507.4475 | S2: =IF(B2<=2019,"Y","N") -> Y | T2: =IFERROR(P2/O2,"NA") -> 1.878938 | U2: =IFERROR(R2/Q2,"NA") -> 1.878938
A3: 3004 | B3: 2010 | C3: Marine | D3: 1Marine | E3: Salmon | F3: 5 | G3: Area 5: W Juan de Fuca | H3: =G3 -> Area 5: W Juan de Fuca | I3: =IFERROR(VLOOKUP(H3,LUTs!$A$1:$C$73,2,FALSE),"NA") -> NA | J3: =IFERROR(VLOOKUP(H3,LUTs!$A$1:$C$73,3,FALSE),"NA") -> 0Strait of Juan de Fuca | K3: Island | L3: =VLOOKUP(K3,LUTs!E$2:G$14,3,) -> 04Island | M3: =VLOOKUP($K3,LUTs!$E$2:$H$14,2,) -> North Puget Sound | N3: =VLOOKUP($K3,LUTs!$E$2:$H$14,4,) -> 01North Puget Sound | O3: 164.11215 | P3: 308.35657 | Q3: =O3 -> 164.11215 | R3: =P3 -> 308.35657 | S3: =IF(B3<=2019,"Y","N") -> Y | T3: =IFERROR(P3/O3,"NA") -> 1.878938 | U3: =IFERROR(R3/Q3,"NA") -> 1.878938
A4: 3121 | B4: 2010 | C4: Marine | D4: 1Marine | E4: Salmon | F4: 5 | G4: Area 5: W Juan de Fuca | H4: =G4 -> Area 5: W Juan de Fuca | I4: =IFERROR(VLOOKUP(H4,LUTs!$A$1:$C$73,2,FALSE),"NA") -> NA | J4: =IFERROR(VLOOKUP(H4,LUTs!$A$1:$C$73,3,FALSE),"NA") -> 0Strait of Juan de Fuca | K4: Jefferson | L4: =VLOOKUP(K4,LUTs!E$2:G$14,3,) -> 12Jefferson | M4: =VLOOKUP($K4,LUTs!$E$2:$H$14,2,) -> Strait of Juan de Fuca | N4: =VLOOKUP($K4,LUTs!$E$2:$H$14,4,) -> 03Strait of Juan de Fuca | O4: 651.62179 | P4: 1224.357 | Q4: =O4 -> 651.62179 | R4: =P4 -> 1224.357 | S4: =IF(B4<=2019,"Y","N") -> Y | T4: =IFERROR(P4/O4,"NA") -> 1.878938 | U4: =IFERROR(R4/Q4,"NA") -> 1.878938
A5: 3005 | B5: 2010 | C5: Marine | D5: 1Marine | E5: Salmon | F5: 5 | G5: Area 5: W Juan de Fuca | H5: =G5 -> Area 5: W Juan de Fuca | I5: =IFERROR(VLOOKUP(H5,LUTs!$A$1:$C$73,2,FALSE),"NA") -> NA | J5: =IFERROR(VLOOKUP(H5,LUTs!$A$1:$C$73,3,FALSE),"NA") -> 0Strait of Juan de Fuca | K5: King | L5: =VLOOKUP(K5,LUTs!E$2:G$14,3,) -> 06King | M5: =VLOOKUP($K5,LUTs!$E$2:$H$14,2,) -> South Puget Sound | N5: =VLOOKUP($K5,LUTs!$E$2:$H$14,4,) -> 02South Puget Sound | O5: 3610.4674 | P5: 6783.8445 | Q5: =O5 -> 3610.4674 | R5: =P5 -> 6783.8445 | S5: =IF(B5<=2019,"Y","N") -> Y | T5: =IFERROR(P5/O5,"NA") -> 1.878938 | U5: =IFERROR(R5/Q5,"NA") -> 1.878938
A6: 3119 | B6: 2010 | C6: Marine | D6: 1Marine | E6: Salmon | F6: 5 | G6: Area 5: W Juan de Fuca | H6: =G6 -> Area 5: W Juan de Fuca | I6: =IFERROR(VLOOKUP(H6,LUTs!$A$1:$C$73,2,FALSE),"NA") -> NA | J6: =IFERROR(VLOOKUP(H6,LUTs!$A$1:$C$73,3,FALSE),"NA") -> 0Strait of Juan de Fuca | K6: Kitsap | L6: =VLOOKUP(K6,LUTs!E$2:G$14,3,) -> 10Kitsap | M6: =VLOOKUP($K6,LUTs!$E$2:$H$14,2,) -> South Puget Sound | N6: =VLOOKUP($K6,LUTs!$E$2:$H$14,4,) -> 02South Puget Sound | O6: 1559.0655 | P6: 2929.3874 | Q6: =O6 -> 1559.0655 | R6: =P6 -> 2929.3874 | S6: =IF(B6<=2019,"Y","N") -> Y | T6: =IFERROR(P6/O6,"NA") -> 1.878938 | U6: =IFERROR(R6/Q6,"NA") -> 1.878938
A7: 3118 | B7: 2010 | C7: Marine | D7: 1Marine | E7: Salmon | F7: 5 | G7: Area 5: W Juan de Fuca | H7: =G7 -> Area 5: W Juan de Fuca | I7: =IFERROR(VLOOKUP(H7,LUTs!$A$1:$C$73,2,FALSE),"NA") -> NA | J7: =IFERROR(VLOOKUP(H7,LUTs!$A$1:$C$73,3,FALSE),"NA") -> 0Strait of Juan de Fuca | K7: Mason | L7: =VLOOKUP(K7,LUTs!E$2:G$14,3,) -> 09Mason | M7: =VLOOKUP($K7,LUTs!$E$2:$H$14,2,) -> South Puget Sound | N7: =VLOOKUP($K7,LUTs!$E$2:$H$14,4,) -> 02South Puget Sound | O7: 516.4706 | P7: 970.41625 | Q7: =O7 -> 516.4706 | R7: =P7 -> 970.41625 | S7: =IF(B7<=2019,"Y","N") -> Y | T7: =IFERROR(P7/O7,"NA") -> 1.878938 | U7: =IFERROR(R7/Q7,"NA") -> 1.878938
A8: 3122 | B8: 2010 | C8: Marine | D8: 1Marine | E8: Salmon | F8: 5 | G8: Area 5: W Juan de Fuca | H8: =G8 -> Area 5: W Juan de Fuca | I8: =IFERROR(VLOOKUP(H8,LUTs!$A$1:$C$73,2,FALSE),"NA") -> NA | J8: =IFERROR(VLOOKUP(H8,LUTs!$A$1:$C$73,3,FALSE),"NA") -> 0Strait of Juan de Fuca | K8: Other | L8: =VLOOKUP(K8,LUTs!E$2:G$14,3,) -> 20Other | M8: =VLOOKUP($K8,LUTs!$E$2:$H$14,2,) -> Non Puget Sound | N8: =VLOOKUP($K8,LUTs!$E$2:$H$14,4,) -> 07Non Puget Sound | O8: 4682.0232 | P8: 8797.2314 | Q8: =O8 -> 4682.0232 | R8: =P8 -> 8797.2314 | S8: =IF(B8<=2019,"Y","N") -> Y | T8: =IFERROR(P8/O8,"NA") -> 1.878938 | U8: =IFERROR(R8/Q8,"NA") -> 1.878938
A9: 3006 | B9: 2010 | C9: Marine | D9: 1Marine | E9: Salmon | F9: 5 | G9: Area 5: W Juan de Fuca | H9: =G9 -> Area 5: W Juan de Fuca | I9: =IFERROR(VLOOKUP(H9,LUTs!$A$1:$C$73,2,FALSE),"NA") -> NA | J9: =IFERROR(VLOOKUP(H9,LUTs!$A$1:$C$73,3,FALSE),"NA") -> 0Strait of Juan de Fuca | K9: Pierce | L9: =VLOOKUP(K9,LUTs!E$2:G$14,3,) -> 07Pierce | M9: =VLOOKUP($K9,LUTs!$E$2:$H$14,2,) -> South Puget Sound | N9: =VLOOKUP($K9,LUTs!$E$2:$H$14,4,) -> 02South Puget Sound | O9: 3393.2601 | P9: 6375.7255 | Q9: =O9 -> 3393.2601 | R9: =P9 -> 6375.7255 | S9: =IF(B9<=2019,"Y","N") -> Y | T9: =IFERROR(P9/O9,"NA") -> 1.878938 | U9: =IFERROR(R9/Q9,"NA") -> 1.878938
A10: 3002 | B10: 2010 | C10: Marine | D10: 1Marine | E10: Salmon | F10: 5 | G10: Area 5: W Juan de Fuca | H10: =G10 -> Area 5: W Juan de Fuca | I10: =IFERROR(VLOOKUP(H10,LUTs!$A$1:$C$73,2,FALSE),"NA") -> NA | J10: =IFERROR(VLOOKUP(H10,LUTs!$A$1:$C$73,3,FALSE),"NA") -> 0Strait of Juan de Fuca | K10: Skagit | L10: =VLOOKUP(K10,LUTs!E$2:G$14,3,) -> 02Skagit | M10: =VLOOKUP($K10,LUTs!$E$2:$H$14,2,) -> North Puget Sound | N10: =VLOOKUP($K10,LUTs!$E$2:$H$14,4,) -> 01North Puget Sound | O10: 77.229249 | P10: 145.10897 | Q10: =O10 -> 77.229249 | R10: =P10 -> 145.10897 | S10: =IF(B10<=2019,"Y","N") -> Y | T10: =IFERROR(P10/O10,"NA") -> 1.878938 | U10: =IFERROR(R10/Q10,"NA") -> 1.878938
A11: 3003 | B11: 2010 | C11: Marine | D11: 1Marine | E11: Salmon | F11: 5 | G11: Area 5: W Juan de Fuca | H11: =G11 -> Area 5: W Juan de Fuca | I11: =IFERROR(VLOOKUP(H11,LUTs!$A$1:$C$73,2,FALSE),"NA") -> NA | J11: =IFERROR(VLOOKUP(H11,LUTs!$A$1:$C$73,3,FALSE),"NA") -> 0Strait of Juan de Fuca | K11: Snohomish | L11: =VLOOKUP(K11,LUTs!E$2:G$14,3,) -> 03Snohomish | M11: =VLOOKUP($K11,LUTs!$E$2:$H$14,2,) -> North Puget Sound | N11: =VLOOKUP($K11,LUTs!$E$2:$H$14,4,) -> 01North Puget Sound | O11: 1423.9143 | P11: 2675.4467 | Q11: =O11 -> 1423.9143 | R11: =P11 -> 2675.4467 | S11: =IF(B11<=2019,"Y","N") -> Y | T11: =IFERROR(P11/O11,"NA") -> 1.878938 | U11: =IFERROR(R11/Q11,"NA") -> 1.878938
A12: 3007 | B12: 2010 | C12: Marine | D12: 1Marine | E12: Salmon | F12: 5 | G12: Area 5: W Juan de Fuca | H12: =G12 -> Area 5: W Juan de Fuca | I12: =IFERROR(VLOOKUP(H12,LUTs!$A$1:$C$73,2,FALSE),"NA") -> NA | J12: =IFERROR(VLOOKUP(H12,LUTs!$A$1:$C$73,3,FALSE),"NA") -> 0Strait of Juan de Fuca | K12: Thurston | L12: =VLOOKUP(K12,LUTs!E$2:G$14,3,) -> 08Thurston | M12: =VLOOKUP($K12,LUTs!$E$2:$H$14,2,) -> South Puget Sound | N12: =VLOOKUP($K12,LUTs!$E$2:$H$14,4,) -> 02South Puget Sound | O12: 675.75593 | P12: 1269.7035 | Q12: =O12 -> 675.75593 | R12: =P12 -> 1269.7035 | S12: =IF(B12<=2019,"Y","N") -> Y | T12: =IFERROR(P12/O12,"NA") -> 1.878938 | U12: =IFERROR(R12/Q12,"NA") -> 1.878938
A13: 1556 | B13: 2010 | C13: Marine | D13: 1Marine | E13: Salmon | F13: 5 | G13: Area 5: W Juan de Fuca | H13: =G13 -> Area 5: W Juan de Fuca | I13: =IFERROR(VLOOKUP(H13,LUTs!$A$1:$C$73,2,FALSE),"NA") -> NA | J13: =IFERROR(VLOOKUP(H13,LUTs!$A$1:$C$73,3,FALSE),"NA") -> 0Strait of Juan de Fuca | K13: Whatcom | L13: =VLOOKUP(K13,LUTs!E$2:G$14,3,) -> 01Whatcom | M13: =VLOOKUP($K13,LUTs!$E$2:$H$14,2,) -> North Puget Sound | N13: =VLOOKUP($K13,LUTs!$E$2:$H$14,4,) -> 01North Puget Sound | O13: 386.14625 | P13: 725.54486 | Q13: =O13 -> 386.14625 | R13: =P13 -> 725.54486 | S13: =IF(B13<=2019,"Y","N") -> Y | T13: =IFERROR(P13/O13,"NA") -> 1.878938 | U13: =IFERROR(R13/Q13,"NA") -> 1.878938
... A1051: 626 | B1051: 2021 | C1051: Marine | D1051: 1Marine | E1051: Salmon | F1051: 13 | G1051: Area 13: S Puget Sound | H1051: =G1051 -> Area 13: S Puget Sound | I1051: =IFERROR(VLOOKUP(H1051,LUTs!$A$1:$C$73,2,FALSE),"NA") -> NA | J1051: =IFERROR(VLOOKUP(H1051,LUTs!$A$1:$C$73,3,FALSE),"NA") -> 3South Puget Sound | K1051: Thurston | L1051: =VLOOKUP(K1051,LUTs!E$2:G$14,3,) -> 08Thurston | M1051: =VLOOKUP($K1051,LUTs!$E$2:$H$14,2,) -> South Puget Sound | N1051: =VLOOKUP($K1051,LUTs!$E$2:$H$14,4,) -> 02South Puget Sound | O1051: 1320.4153 | P1051: 1622.6559 | Q1051: =O1051 -> 1320.4153 | R1051: =P1051 -> 1622.6559 | S1051: =IF(B1051<=2019,"Y","N") -> N | T1051: =IFERROR(P1051/O1051,"NA") -> 1.2288981 | U1051: =IFERROR(R1051/Q1051,"NA") -> 1.2288981
A1052: 2591 | B1052: 2010 | C1052: Marine | D1052: 1Marine | E1052: Salmon | F1052: 8-1 | G1052: Area 8-1: Skagit Bay-Saratoga Psg. | H1052: =G1052 -> Area 8-1: Skagit Bay-Saratoga Psg. | I1052: =IFERROR(VLOOKUP(H1052,LUTs!$A$1:$C$73,2,FALSE),"NA") -> NA | J1052: =IFERROR(VLOOKUP(H1052,LUTs!$A$1:$C$73,3,FALSE),"NA") -> 2Central Puget Sound | K1052: Island | L1052: =VLOOKUP(K1052,LUTs!E$2:G$14,3,) -> 04Island | M1052: =VLOOKUP($K1052,LUTs!$E$2:$H$14,2,) -> North Puget Sound | N1052: =VLOOKUP($K1052,LUTs!$E$2:$H$14,4,) -> 01North Puget Sound | O1052: 128.93878 | P1052: 1744.5361 | Q1052: =O1052 -> 128.93878 | R1052: =P1052 -> 1744.5361 | S1052: =IF(B1052<=2019,"Y","N") -> Y | T1052: =IFERROR(P1052/O1052,"NA") -> 13.529957 | U1052: =IFERROR(R1052/Q1052,"NA") -> 13.529957
A1053: 2592 | B1053: 2010 | C1053: Marine | D1053: 1Marine | E1053: Salmon | F1053: 8-1 | G1053: Area 8-1: Skagit Bay-Saratoga Psg. | H1053: =G1053 -> Area 8-1: Skagit Bay-Saratoga Psg. | I1053: =IFERROR(VLOOKUP(H1053,LUTs!$A$1:$C$73,2,FALSE),"NA") -> NA | J1053: =IFERROR(VLOOKUP(H1053,LUTs!$A$1:$C$73,3,FALSE),"NA") -> 2Central Puget Sound | K1053: King | L1053: =VLOOKUP(K1053,LUTs!E$2:G$14,3,) -> 06King | M1053: =VLOOKUP($K1053,LUTs!$E$2:$H$14,2,) -> South Puget Sound | N1053: =VLOOKUP($K1053,LUTs!$E$2:$H$14,4,) -> 02South Puget Sound | O1053: 9.5510204 | P1053: 129.2249 | Q1053: =O1053 -> 9.5510204 | R1053: =P1053 -> 129.2249 | S1053: =IF(B1053<=2019,"Y","N") -> Y | T1053: =IFERROR(P1053/O1053,"NA") -> 13.529957 | U1053: =IFERROR(R1053/Q1053,"NA") -> 13.529957
A1054: 2595 | B1054: 2010 | C1054: Marine | D1054: 1Marine | E1054: Salmon | F1054: 8-1 | G1054: Area 8-1: Skagit Bay-Saratoga Psg. | H1054: =G1054 -> Area 8-1: Skagit Bay-Saratoga Psg. | I1054: =IFERROR(VLOOKUP(H1054,LUTs!$A$1:$C$73,2,FALSE),"NA") -> NA | J1054: =IFERROR(VLOOKUP(H1054,LUTs!$A$1:$C$73,3,FALSE),"NA") -> 2Central Puget Sound | K1054: Other | L1054: =VLOOKUP(K1054,LUTs!E$2:G$14,3,) -> 20Other | M1054: =VLOOKUP($K1054,LUTs!$E$2:$H$14,2,) -> Non Puget Sound | N1054: =VLOOKUP($K1054,LUTs!$E$2:$H$14,4,) -> 07Non Puget Sound | O1054: 9.5510204 | P1054: 129.2249 | Q1054: =O1054 -> 9.5510204 | R1054: =P1054 -> 129.2249 | S1054: =IF(B1054<=2019,"Y","N") -> Y | T1054: =IFERROR(P1054/O1054,"NA") -> 13.529957 | U1054: =IFERROR(R1054/Q1054,"NA") -> 13.529957
A1055: 2593 | B1055: 2010 | C1055: Marine | D1055: 1Marine | E1055: Salmon | F1055: 8-1 | G1055: Area 8-1: Skagit Bay-Saratoga Psg. | H1055: =G1055 -> Area 8-1: Skagit Bay-Saratoga Psg. | I1055: =IFERROR(VLOOKUP(H1055,LUTs!$A$1:$C$73,2,FALSE),"NA") -> NA | J1055: =IFERROR(VLOOKUP(H1055,LUTs!$A$1:$C$73,3,FALSE),"NA") -> 2Central Puget Sound | K1055: Pierce | L1055: =VLOOKUP(K1055,LUTs!E$2:G$14,3,) -> 07Pierce | M1055: =VLOOKUP($K1055,LUTs!$E$2:$H$14,2,) -> South Puget Sound | N1055: =VLOOKUP($K1055,LUTs!$E$2:$H$14,4,) -> 02South Puget Sound | O1055: 4.7755102 | P1055: 64.612449 | Q1055: =O1055 -> 4.7755102 | R1055: =P1055 -> 64.612449 | S1055: =IF(B1055<=2019,"Y","N") -> Y | T1055: =IFERROR(P1055/O1055,"NA") -> 13.529957 | U1055: =IFERROR(R1055/Q1055,"NA") -> 13.529957
A1056: 2589 | B1056: 2010 | C1056: Marine | D1056: 1Marine | E1056: Salmon | F1056: 8-1 | G1056: Area 8-1: Skagit Bay-Saratoga Psg. | H1056: =G1056 -> Area 8-1: Skagit Bay-Saratoga Psg. | I1056: =IFERROR(VLOOKUP(H1056,LUTs!$A$1:$C$73,2,FALSE),"NA") -> NA | J1056: =IFERROR(VLOOKUP(H1056,LUTs!$A$1:$C$73,3,FALSE),"NA") -> 2Central Puget Sound | K1056: Skagit | L1056: =VLOOKUP(K1056,LUTs!E$2:G$14,3,) -> 02Skagit | M1056: =VLOOKUP($K1056,LUTs!$E$2:$H$14,2,) -> North Puget Sound | N1056: =VLOOKUP($K1056,LUTs!$E$2:$H$14,4,) -> 01North Puget Sound | O1056: 33.428571 | P1056: 452.28714 | Q1056: =O1056 -> 33.428571 | R1056: =P1056 -> 452.28714 | S1056: =IF(B1056<=2019,"Y","N") -> Y | T1056: =IFERROR(P1056/O1056,"NA") -> 13.529957 | U1056: =IFERROR(R1056/Q1056,"NA") -> 13.529957
A1057: 2590 | B1057: 2010 | C1057: Marine | D1057: 1Marine | E1057: Salmon | F1057: 8-1 | G1057: Area 8-1: Skagit Bay-Saratoga Psg. | H1057: =G1057 -> Area 8-1: Skagit Bay-Saratoga Psg. | I1057: =IFERROR(VLOOKUP(H1057,LUTs!$A$1:$C$73,2,FALSE),"NA") -> NA | J1057: =IFERROR(VLOOKUP(H1057,LUTs!$A$1:$C$73,3,FALSE),"NA") -> 2Central Puget Sound | K1057: Snohomish | L1057: =VLOOKUP(K1057,LUTs!E$2:G$14,3,) -> 03Snohomish | M1057: =VLOOKUP($K1057,LUTs!$E$2:$H$14,2,) -> North Puget Sound | N1057: =VLOOKUP($K1057,LUTs!$E$2:$H$14,4,) -> 01North Puget Sound | O1057: 42.979592 | P1057: 581.51204 | Q1057: =O1057 -> 42.979592 | R1057: =P1057 -> 581.51204 | S1057: =IF(B1057<=2019,"Y","N") -> Y | T1057: =IFERROR(P1057/O1057,"NA") -> 13.529957 | U1057: =IFERROR(R1057/Q1057,"NA") -> 13.529957
A1058: 2594 | B1058: 2010 | C1058: Marine | D1058: 1Marine | E1058: Salmon | F1058: 8-1 | G1058: Area 8-1: Skagit Bay-Saratoga Psg. | H1058: =G1058 -> Area 8-1: Skagit Bay-Saratoga Psg. | I1058: =IFERROR(VLOOKUP(H1058,LUTs!$A$1:$C$73,2,FALSE),"NA") -> NA | J1058: =IFERROR(VLOOKUP(H1058,LUTs!$A$1:$C$73,3,FALSE),"NA") -> 2Central Puget Sound | K1058: Thurston | L1058: =VLOOKUP(K1058,LUTs!E$2:G$14,3,) -> 08Thurston | M1058: =VLOOKUP($K1058,LUTs!$E$2:$H$14,2,) -> South Puget Sound | N1058: =VLOOKUP($K1058,LUTs!$E$2:$H$14,4,) -> 02South Puget Sound | O1058: 4.7755102 | P1058: 64.612449 | Q1058: =O1058 -> 4.7755102 | R1058: =P1058 -> 64.612449 | S1058: =IF(B1058<=2019,"Y","N") -> Y | T1058: =IFERROR(P1058/O1058,"NA") -> 13.529957 | U1058: =IFERROR(R1058/Q1058,"NA") -> 13.529957
A1059: 2831 | B1059: 2011 | C1059: Marine | D1059: 1Marine | E1059: Salmon | F1059: 8-1 | G1059: Area 8-1: Skagit Bay-Saratoga Psg. | H1059: =G1059 -> Area 8-1: Skagit Bay-Saratoga Psg. | I1059: =IFERROR(VLOOKUP(H1059,LUTs!$A$1:$C$73,2,FALSE),"NA") -> NA | J1059: =IFERROR(VLOOKUP(H1059,LUTs!$A$1:$C$73,3,FALSE),"NA") -> 2Central Puget Sound | K1059: Island | L1059: =VLOOKUP(K1059,LUTs!E$2:G$14,3,) -> 04Island | M1059: =VLOOKUP($K1059,LUTs!$E$2:$H$14,2,) -> North Puget Sound | N1059: =VLOOKUP($K1059,LUTs!$E$2:$H$14,4,) -> 01North Puget Sound | O1059: 6674.7644 | P1059: 8632.1395 | Q1059: =O1059 -> 6674.7644 | R1059: =P1059 -> 8632.1395 | S1059: =IF(B1059<=2019,"Y","N") -> Y | T1059: =IFERROR(P1059/O1059,"NA") -> 1.2932501 | U1059: =IFERROR(R1059/Q1059,"NA") -> 1.2932501
A1060: 2832 | B1060: 2011 | C1060: Marine | D1060: 1Marine | E1060: Salmon | F1060: 8-1 | G1060: Area 8-1: Skagit Bay-Saratoga Psg. | H1060: =G1060 -> Area 8-1: Skagit Bay-Saratoga Psg. | I1060: =IFERROR(VLOOKUP(H1060,LUTs!$A$1:$C$73,2,FALSE),"NA") -> NA | J1060: =IFERROR(VLOOKUP(H1060,LUTs!$A$1:$C$73,3,FALSE),"NA") -> 2Central Puget Sound | K1060: King | L1060: =VLOOKUP(K1060,LUTs!E$2:G$14,3,) -> 06King | M1060: =VLOOKUP($K1060,LUTs!$E$2:$H$14,2,) -> South Puget Sound | N1060: =VLOOKUP($K1060,LUTs!$E$2:$H$14,4,) -> 02South Puget Sound | O1060: 611.26215 | P1060: 790.51482 | Q1060: =O1060 -> 611.26215 | R1060: =P1060 -> 790.51482 | S1060: =IF(B1060<=2019,"Y","N") -> Y | T1060: =IFERROR(P1060/O1060,"NA") -> 1.2932501 | U1060: =IFERROR(R1060/Q1060,"NA") -> 1.2932501
A1061: 2941 | B1061: 2011 | C1061: Marine | D1061: 1Marine | E1061: Salmon | F1061: 8-1 | G1061: Area 8-1: Skagit Bay-Saratoga Psg. | H1061: =G1061 -> Area 8-1: Skagit Bay-Saratoga Psg. | I1061: =IFERROR(VLOOKUP(H1061,LUTs!$A$1:$C$73,2,FALSE),"NA") -> NA | J1061: =IFERROR(VLOOKUP(H1061,LUTs!$A$1:$C$73,3,FALSE),"NA") -> 2Central Puget Sound | K1061: Kitsap | L1061: =VLOOKUP(K1061,LUTs!E$2:G$14,3,) -> 10Kitsap | M1061: =VLOOKUP($K1061,LUTs!$E$2:$H$14,2,) -> South Puget Sound | N1061: =VLOOKUP($K1061,LUTs!$E$2:$H$14,4,) -> 02South Puget Sound | O1061: 38.203885 | P1061: 49.407176 | Q1061: =O1061 -> 38.203885 | R1061: =P1061 -> 49.407176 | S1061: =IF(B1061<=2019,"Y","N") -> Y | T1061: =IFERROR(P1061/O1061,"NA") -> 1.2932501 | U1061: =IFERROR(R1061/Q1061,"NA") -> 1.2932501
A1062: 2942 | B1062: 2011 | C1062: Marine | D1062: 1Marine | E1062: Salmon | F1062: 8-1 | G1062: Area 8-1: Skagit Bay-Saratoga Psg. | H1062: =G1062 -> Area 8-1: Skagit Bay-Saratoga Psg. | I1062: =IFERROR(VLOOKUP(H1062,LUTs!$A$1:$C$73,2,FALSE),"NA") -> NA | J1062: =IFERROR(VLOOKUP(H1062,LUTs!$A$1:$C$73,3,FALSE),"NA") -> 2Central Puget Sound | K1062: Other | L1062: =VLOOKUP(K1062,LUTs!E$2:G$14,3,) -> 20Other | M1062: =VLOOKUP($K1062,LUTs!$E$2:$H$14,2,) -> Non Puget Sound | N1062: =VLOOKUP($K1062,LUTs!$E$2:$H$14,4,) -> 07Non Puget Sound | O1062: 1489.9515 | P1062: 1926.8799 | Q1062: =O1062 -> 1489.9515 | R1062: =P1062 -> 1926.8799 | S1062: =IF(B1062<=2019,"Y","N") -> Y | T1062: =IFERROR(P1062/O1062,"NA") -> 1.2932501 | U1062: =IFERROR(R1062/Q1062,"NA") -> 1.2932501
A1063: 2833 | B1063: 2011 | C1063: Marine | D1063: 1Marine | E1063: Salmon | F1063: 8-1 | G1063: Area 8-1: Skagit Bay-Saratoga Psg. | H1063: =G1063 -> Area 8-1: Skagit Bay-Saratoga Psg. | I1063: =IFERROR(VLOOKUP(H1063,LUTs!$A$1:$C$73,2,FALSE),"NA") -> NA | J1063: =IFERROR(VLOOKUP(H1063,LUTs!$A$1:$C$73,3,FALSE),"NA") -> 2Central Puget Sound | K1063: Pierce | L1063: =VLOOKUP(K1063,LUTs!E$2:G$14,3,) -> 07Pierce | M1063: =VLOOKUP($K1063,LUTs!$E$2:$H$14,2,) -> South Puget Sound | N1063: =VLOOKUP($K1063,LUTs!$E$2:$H$14,4,) -> 02South Puget Sound | O1063: 81.865467 | P1063: 105.87252 | Q1063: =O1063 -> 81.865467 | R1063: =P1063 -> 105.87252 | S1063: =IF(B1063<=2019,"Y","N") -> Y | T1063: =IFERROR(P1063/O1063,"NA") -> 1.2932501 | U1063: =IFERROR(R1063/Q1063,"NA") -> 1.2932501
... A1256: 2479 | B1256: 2021 | C1256: Marine | D1256: 1Marine | E1256: Salmon | F1256: 8-2 | G1256: Area 8-2: Port Susan-Port Gardner | H1256: =G1256 -> Area 8-2: Port Susan-Port Gardner | I1256: =IFERROR(VLOOKUP(H1256,LUTs!$A$1:$C$73,2,FALSE),"NA") -> NA | J1256: =IFERROR(VLOOKUP(H1256,LUTs!$A$1:$C$73,3,FALSE),"NA") -> 2Central Puget Sound | K1256: Whatcom | L1256: =VLOOKUP(K1256,LUTs!E$2:G$14,3,) -> 01Whatcom | M1256: =VLOOKUP($K1256,LUTs!$E$2:$H$14,2,) -> North Puget Sound | N1256: =VLOOKUP($K1256,LUTs!$E$2:$H$14,4,) -> 01North Puget Sound | O1256: 353.02107 | P1256: 367.9053 | Q1256: =O1256 -> 353.02107 | R1256: =P1256 -> 367.9053 | S1256: =IF(B1256<=2019,"Y","N") -> N | T1256: =IFERROR(P1256/O1256,"NA") -> 1.0421624 | U1256: =IFERROR(R1256/Q1256,"NA") -> 1.0421624
A1257: 1247 | B1257: 2012 | C1257: Freshwater | D1257: 2Freshwater | E1257: Salmon | F1257: 8 | G1257: Unknown | H1257: =G1257 -> Unknown | I1257: =IFERROR(VLOOKUP(H1257,LUTs!$A$1:$C$73,2,FALSE),"NA") -> NA | J1257: =IFERROR(VLOOKUP(H1257,LUTs!$A$1:$C$73,3,FALSE),"NA") -> NA | K1257: Skagit | L1257: =VLOOKUP(K1257,LUTs!E$2:G$14,3,) -> 02Skagit | M1257: =VLOOKUP($K1257,LUTs!$E$2:$H$14,2,) -> North Puget Sound | N1257: =VLOOKUP($K1257,LUTs!$E$2:$H$14,4,) -> 01North Puget Sound | O1257: 1 | P1257: 8.65 | Q1257: =SUMIFS('FW_Salmon_by_Month_2010-2021'!P$2:P$3810,'FW_Salmon_by_Month_2010-2021'!$B$2:$B$3810,'Rec_raw_catch_effort_2010-2021'!$B1257,'FW_Salmon_by_Month_2010-2021'!$H$2:$H$3810,'Rec_raw_catch_effort_2010-2021'!$F1257,'FW_Salmon_by_Month_2010-2021'!$M$2:$M$3810,'Rec_raw_catch_effort_2010-2021'!$K1257) -> 0 | R1257: =VLOOKUP(B1257,Readme!$A$62:$C$74,2,)*Q1257 -> 0 | S1257: =IF(B1257<=2019,"Y","N") -> Y | T1257: =IFERROR(P1257/O1257,"NA") -> 8.65 | U1257: =IFERROR(R1257/Q1257,"NA") -> NA
A1258: 1248 | B1258: 2013 | C1258: Freshwater | D1258: 2Freshwater | E1258: Salmon | F1258: 8 | G1258: Unknown | H1258: =G1258 -> Unknown | I1258: =IFERROR(VLOOKUP(H1258,LUTs!$A$1:$C$73,2,FALSE),"NA") -> NA | J1258: =IFERROR(VLOOKUP(H1258,LUTs!$A$1:$C$73,3,FALSE),"NA") -> NA | K1258: Other | L1258: =VLOOKUP(K1258,LUTs!E$2:G$14,3,) -> 20Other | M1258: =VLOOKUP($K1258,LUTs!$E$2:$H$14,2,) -> Non Puget Sound | N1258: =VLOOKUP($K1258,LUTs!$E$2:$H$14,4,) -> 07Non Puget Sound | O1258: 0 | P1258: 0 | Q1258: =SUMIFS('FW_Salmon_by_Month_2010-2021'!P$2:P$3810,'FW_Salmon_by_Month_2010-2021'!$B$2:$B$3810,'Rec_raw_catch_effort_2010-2021'!$B1258,'FW_Salmon_by_Month_2010-2021'!$H$2:$H$3810,'Rec_raw_catch_effort_2010-2021'!$F1258,'FW_Salmon_by_Month_2010-2021'!$M$2:$M$3810,'Rec_raw_catch_effort_2010-2021'!$K1258) -> 0 | R1258: =VLOOKUP(B1258,Readme!$A$62:$C$74,2,)*Q1258 -> 0 | S1258: =IF(B1258<=2019,"Y","N") -> Y | T1258: =IFERROR(P1258/O1258,"NA") -> NA | U1258: =IFERROR(R1258/Q1258,"NA") -> NA
A1259: 271 | B1259: 2013 | C1259: Freshwater | D1259: 2Freshwater | E1259: Salmon | F1259: 706 | G1259: Black River (Thurston Co) | H1259: =G1259 -> Black River (Thurston Co) | I1259: =IFERROR(VLOOKUP(H1259,LUTs!$A$1:$C$73,2,FALSE),"NA") -> Thurston | J1259: =IFERROR(VLOOKUP(H1259,LUTs!$A$1:$C$73,3,FALSE),"NA") -> 3South Puget Sound | K1259: Other | L1259: =VLOOKUP(K1259,LUTs!E$2:G$14,3,) -> 20Other | M1259: =VLOOKUP($K1259,LUTs!$E$2:$H$14,2,) -> Non Puget Sound | N1259: =VLOOKUP($K1259,LUTs!$E$2:$H$14,4,) -> 07Non Puget Sound | O1259: 15 | P1259: 51.6 | Q1259: =SUMIFS('FW_Salmon_by_Month_2010-2021'!P$2:P$3810,'FW_Salmon_by_Month_2010-2021'!$B$2:$B$3810,'Rec_raw_catch_effort_2010-2021'!$B1259,'FW_Salmon_by_Month_2010-2021'!$H$2:$H$3810,'Rec_raw_catch_effort_2010-2021'!$F1259,'FW_Salmon_by_Month_2010-2021'!$M$2:$M$3810,'Rec_raw_catch_effort_2010-2021'!$K1259) -> 15 | R1259: =VLOOKUP(B1259,Readme!$A$62:$C$74,2,)*Q1259 -> 53.085607 | S1259: =IF(B1259<=2019,"Y","N") -> Y | T1259: =IFERROR(P1259/O1259,"NA") -> 3.44 | U1259: =IFERROR(R1259/Q1259,"NA") -> 3.5390404
A1260: 272 | B1260: 2015 | C1260: Freshwater | D1260: 2Freshwater | E1260: Salmon | F1260: 706 | G1260: Black River (Thurston Co) | H1260: =G1260 -> Black River (Thurston Co) | I1260: =IFERROR(VLOOKUP(H1260,LUTs!$A$1:$C$73,2,FALSE),"NA") -> Thurston | J1260: =IFERROR(VLOOKUP(H1260,LUTs!$A$1:$C$73,3,FALSE),"NA") -> 3South Puget Sound | K1260: Other | L1260: =VLOOKUP(K1260,LUTs!E$2:G$14,3,) -> 20Other | M1260: =VLOOKUP($K1260,LUTs!$E$2:$H$14,2,) -> Non Puget Sound | N1260: =VLOOKUP($K1260,LUTs!$E$2:$H$14,4,) -> 07Non Puget Sound | O1260: 9 | P1260: 30.96 | Q1260: =SUMIFS('FW_Salmon_by_Month_2010-2021'!P$2:P$3810,'FW_Salmon_by_Month_2010-2021'!$B$2:$B$3810,'Rec_raw_catch_effort_2010-2021'!$B1260,'FW_Salmon_by_Month_2010-2021'!$H$2:$H$3810,'Rec_raw_catch_effort_2010-2021'!$F1260,'FW_Salmon_by_Month_2010-2021'!$M$2:$M$3810,'Rec_raw_catch_effort_2010-2021'!$K1260) -> 9 | R1260: =VLOOKUP(B1260,Readme!$A$62:$C$74,2,)*Q1260 -> 31.851364 | S1260: =IF(B1260<=2019,"Y","N") -> Y | T1260: =IFERROR(P1260/O1260,"NA") -> 3.44 | U1260: =IFERROR(R1260/Q1260,"NA") -> 3.5390404
A1261: 276 | B1261: 2019 | C1261: Freshwater | D1261: 2Freshwater | E1261: Salmon | F1261: 706 | G1261: Black River (Thurston Co) | H1261: =G1261 -> Black River (Thurston Co) | I1261: =IFERROR(VLOOKUP(H1261,LUTs!$A$1:$C$73,2,FALSE),"NA") -> Thurston | J1261: =IFERROR(VLOOKUP(H1261,LUTs!$A$1:$C$73,3,FALSE),"NA") -> 3South Puget Sound | K1261: King | L1261: =VLOOKUP(K1261,LUTs!E$2:G$14,3,) -> 06King | M1261: =VLOOKUP($K1261,LUTs!$E$2:$H$14,2,) -> South Puget Sound | N1261: =VLOOKUP($K1261,LUTs!$E$2:$H$14,4,) -> 02South Puget Sound | O1261: 22 | P1261: 75.68 | Q1261: =SUMIFS('FW_Salmon_by_Month_2010-2021'!P$2:P$3810,'FW_Salmon_by_Month_2010-2021'!$B$2:$B$3810,'Rec_raw_catch_effort_2010-2021'!$B1261,'FW_Salmon_by_Month_2010-2021'!$H$2:$H$3810,'Rec_raw_catch_effort_2010-2021'!$F1261,'FW_Salmon_by_Month_2010-2021'!$M$2:$M$3810,'Rec_raw_catch_effort_2010-2021'!$K1261) -> 22 | R1261: =VLOOKUP(B1261,Readme!$A$62:$C$74,2,)*Q1261 -> 77.85889 | S1261: =IF(B1261<=2019,"Y","N") -> Y | T1261: =IFERROR(P1261/O1261,"NA") -> 3.44 | U1261: =IFERROR(R1261/Q1261,"NA") -> 3.5390404
A1262: 3104 | B1262: 2019 | C1262: Freshwater | D1262: 2Freshwater | E1262: Salmon | F1262: 710 | G1262: California Creek | H1262: =G1262 -> California Creek | I1262: =IFERROR(VLOOKUP(H1262,LUTs!$A$1:$C$73,2,FALSE),"NA") -> Whatcom | J1262: =IFERROR(VLOOKUP(H1262,LUTs!$A$1:$C$73,3,FALSE),"NA") -> 1North Puget Sound | K1262: Whatcom | L1262: =VLOOKUP(K1262,LUTs!E$2:G$14,3,) -> 01Whatcom | M1262: =VLOOKUP($K1262,LUTs!$E$2:$H$14,2,) -> North Puget Sound | N1262: =VLOOKUP($K1262,LUTs!$E$2:$H$14,4,) -> 01North Puget Sound | O1262: 11 | P1262: 37.84 | Q1262: =SUMIFS('FW_Salmon_by_Month_2010-2021'!P$2:P$3810,'FW_Salmon_by_Month_2010-2021'!$B$2:$B$3810,'Rec_raw_catch_effort_2010-2021'!$B1262,'FW_Salmon_by_Month_2010-2021'!$H$2:$H$3810,'Rec_raw_catch_effort_2010-2021'!$F1262,'FW_Salmon_by_Month_2010-2021'!$M$2:$M$3810,'Rec_raw_catch_effort_2010-2021'!$K1262) -> 11 | R1262: =VLOOKUP(B1262,Readme!$A$62:$C$74,2,)*Q1262 -> 38.929445 | S1262: =IF(B1262<=2019,"Y","N") -> Y | T1262: =IFERROR(P1262/O1262,"NA") -> 3.44 | U1262: =IFERROR(R1262/Q1262,"NA") -> 3.5390404
A1263: 969 | B1263: 2010 | C1263: Freshwater | D1263: 2Freshwater | E1263: Salmon | F1263: 714 | G1263: Chambers Creek | H1263: =G1263 -> Chambers Creek | I1263: =IFERROR(VLOOKUP(H1263,LUTs!$A$1:$C$73,2,FALSE),"NA") -> Pierce | J1263: =IFERROR(VLOOKUP(H1263,LUTs!$A$1:$C$73,3,FALSE),"NA") -> 3South Puget Sound | K1263: Kitsap | L1263: =VLOOKUP(K1263,LUTs!E$2:G$14,3,) -> 10Kitsap | M1263: =VLOOKUP($K1263,LUTs!$E$2:$H$14,2,) -> South Puget Sound | N1263: =VLOOKUP($K1263,LUTs!$E$2:$H$14,4,) -> 02South Puget Sound | O1263: 13.727273 | P1263: 118.74091 | Q1263: =SUMIFS('FW_Salmon_by_Month_2010-2021'!P$2:P$3810,'FW_Salmon_by_Month_2010-2021'!$B$2:$B$3810,'Rec_raw_catch_effort_2010-2021'!$B1263,'FW_Salmon_by_Month_2010-2021'!$H$2:$H$3810,'Rec_raw_catch_effort_2010-2021'!$F1263,'FW_Salmon_by_Month_2010-2021'!$M$2:$M$3810,'Rec_raw_catch_effort_2010-2021'!$K1263) -> 13.681319 | R1263: =VLOOKUP(B1263,Readme!$A$62:$C$74,2,)*Q1263 -> 65.937867 | S1263: =IF(B1263<=2019,"Y","N") -> Y | T1263: =IFERROR(P1263/O1263,"NA") -> 8.65 | U1263: =IFERROR(R1263/Q1263,"NA") -> 4.8195549
A1264: 967 | B1264: 2010 | C1264: Freshwater | D1264: 2Freshwater | E1264: Salmon | F1264: 714 | G1264: Chambers Creek | H1264: =G1264 -> Chambers Creek | I1264: =IFERROR(VLOOKUP(H1264,LUTs!$A$1:$C$73,2,FALSE),"NA") -> Pierce | J1264: =IFERROR(VLOOKUP(H1264,LUTs!$A$1:$C$73,3,FALSE),"NA") -> 3South Puget Sound | K1264: Pierce | L1264: =VLOOKUP(K1264,LUTs!E$2:G$14,3,) -> 07Pierce | M1264: =VLOOKUP($K1264,LUTs!$E$2:$H$14,2,) -> South Puget Sound | N1264: =VLOOKUP($K1264,LUTs!$E$2:$H$14,4,) -> 02South Puget Sound | O1264: 132.69697 | P1264: 1147.8288 | Q1264: =SUMIFS('FW_Salmon_by_Month_2010-2021'!P$2:P$3810,'FW_Salmon_by_Month_2010-2021'!$B$2:$B$3810,'Rec_raw_catch_effort_2010-2021'!$B1264,'FW_Salmon_by_Month_2010-2021'!$H$2:$H$3810,'Rec_raw_catch_effort_2010-2021'!$F1264,'FW_Salmon_by_Month_2010-2021'!$M$2:$M$3810,'Rec_raw_catch_effort_2010-2021'!$K1264) -> 132.74725 | R1264: =VLOOKUP(B1264,Readme!$A$62:$C$74,2,)*Q1264 -> 639.78267 | S1264: =IF(B1264<=2019,"Y","N") -> Y | T1264: =IFERROR(P1264/O1264,"NA") -> 8.65 | U1264: =IFERROR(R1264/Q1264,"NA") -> 4.8195549
A1265: 968 | B1265: 2010 | C1265: Freshwater | D1265: 2Freshwater | E1265: Salmon | F1265: 714 | G1265: Chambers Creek | H1265: =G1265 -> Chambers Creek | I1265: =IFERROR(VLOOKUP(H1265,LUTs!$A$1:$C$73,2,FALSE),"NA") -> Pierce | J1265: =IFERROR(VLOOKUP(H1265,LUTs!$A$1:$C$73,3,FALSE),"NA") -> 3South Puget Sound | K1265: Thurston | L1265: =VLOOKUP(K1265,LUTs!E$2:G$14,3,) -> 08Thurston | M1265: =VLOOKUP($K1265,LUTs!$E$2:$H$14,2,) -> South Puget Sound | N1265: =VLOOKUP($K1265,LUTs!$E$2:$H$14,4,) -> 02South Puget Sound | O1265: 4.5757576 | P1265: 39.580303 | Q1265: =SUMIFS('FW_Salmon_by_Month_2010-2021'!P$2:P$3810,'FW_Salmon_by_Month_2010-2021'!$B$2:$B$3810,'Rec_raw_catch_effort_2010-2021'!$B1265,'FW_Salmon_by_Month_2010-2021'!$H$2:$H$3810,'Rec_raw_catch_effort_2010-2021'!$F1265,'FW_Salmon_by_Month_2010-2021'!$M$2:$M$3810,'Rec_raw_catch_effort_2010-2021'!$K1265) -> 4.5714286 | R1265: =VLOOKUP(B1265,Readme!$A$62:$C$74,2,)*Q1265 -> 22.032251 | S1265: =IF(B1265<=2019,"Y","N") -> Y | T1265: =IFERROR(P1265/O1265,"NA") -> 8.65 | U1265: =IFERROR(R1265/Q1265,"NA") -> 4.8195549
A1266: 978 | B1266: 2011 | C1266: Freshwater | D1266: 2Freshwater | E1266: Salmon | F1266: 714 | G1266: Chambers Creek | H1266: =G1266 -> Chambers Creek | I1266: =IFERROR(VLOOKUP(H1266,LUTs!$A$1:$C$73,2,FALSE),"NA") -> Pierce | J1266: =IFERROR(VLOOKUP(H1266,LUTs!$A$1:$C$73,3,FALSE),"NA") -> 3South Puget Sound | K1266: Pierce | L1266: =VLOOKUP(K1266,LUTs!E$2:G$14,3,) -> 07Pierce | M1266: =VLOOKUP($K1266,LUTs!$E$2:$H$14,2,) -> South Puget Sound | N1266: =VLOOKUP($K1266,LUTs!$E$2:$H$14,4,) -> 02South Puget Sound | O1266: 8.8571429 | P1266: 30.468571 | Q1266: =SUMIFS('FW_Salmon_by_Month_2010-2021'!P$2:P$3810,'FW_Salmon_by_Month_2010-2021'!$B$2:$B$3810,'Rec_raw_catch_effort_2010-2021'!$B1266,'FW_Salmon_by_Month_2010-2021'!$H$2:$H$3810,'Rec_raw_catch_effort_2010-2021'!$F1266,'FW_Salmon_by_Month_2010-2021'!$M$2:$M$3810,'Rec_raw_catch_effort_2010-2021'!$K1266) -> 8.8333333 | R1266: =VLOOKUP(B1266,Readme!$A$62:$C$74,2,)*Q1266 -> 31.261524 | S1266: =IF(B1266<=2019,"Y","N") -> Y | T1266: =IFERROR(P1266/O1266,"NA") -> 3.44 | U1266: =IFERROR(R1266/Q1266,"NA") -> 3.5390404
A1267: 979 | B1267: 2011 | C1267: Freshwater | D1267: 2Freshwater | E1267: Salmon | F1267: 714 | G1267: Chambers Creek | H1267: =G1267 -> Chambers Creek | I1267: =IFERROR(VLOOKUP(H1267,LUTs!$A$1:$C$73,2,FALSE),"NA") -> Pierce | J1267: =IFERROR(VLOOKUP(H1267,LUTs!$A$1:$C$73,3,FALSE),"NA") -> 3South Puget Sound | K1267: Thurston | L1267: =VLOOKUP(K1267,LUTs!E$2:G$14,3,) -> 08Thurston | M1267: =VLOOKUP($K1267,LUTs!$E$2:$H$14,2,) -> South Puget Sound | N1267: =VLOOKUP($K1267,LUTs!$E$2:$H$14,4,) -> 02South Puget Sound | O1267: 53.142857 | P1267: 182.81143 | Q1267: =SUMIFS('FW_Salmon_by_Month_2010-2021'!P$2:P$3810,'FW_Salmon_by_Month_2010-2021'!$B$2:$B$3810,'Rec_raw_catch_effort_2010-2021'!$B1267,'FW_Salmon_by_Month_2010-2021'!$H$2:$H$3810,'Rec_raw_catch_effort_2010-2021'!$F1267,'FW_Salmon_by_Month_2010-2021'!$M$2:$M$3810,'Rec_raw_catch_effort_2010-2021'!$K1267) -> 53.166667 | R1267: =VLOOKUP(B1267,Readme!$A$62:$C$74,2,)*Q1267 -> 188.15898 | S1267: =IF(B1267<=2019,"Y","N") -> Y | T1267: =IFERROR(P1267/O1267,"NA") -> 3.44 | U1267: =IFERROR(R1267/Q1267,"NA") -> 3.5390404
A1268: 1086 | B1268: 2012 | C1268: Freshwater | D1268: 2Freshwater | E1268: Salmon | F1268: 714 | G1268: Chambers Creek | H1268: =G1268 -> Chambers Creek | I1268: =IFERROR(VLOOKUP(H1268,LUTs!$A$1:$C$73,2,FALSE),"NA") -> Pierce | J1268: =IFERROR(VLOOKUP(H1268,LUTs!$A$1:$C$73,3,FALSE),"NA") -> 3South Puget Sound | K1268: King | L1268: =VLOOKUP(K1268,LUTs!E$2:G$14,3,) -> 06King | M1268: =VLOOKUP($K1268,LUTs!$E$2:$H$14,2,) -> South Puget Sound | N1268: =VLOOKUP($K1268,LUTs!$E$2:$H$14,4,) -> 02South Puget Sound | O1268: 22.846154 | P1268: 197.61923 | Q1268: =SUMIFS('FW_Salmon_by_Month_2010-2021'!P$2:P$3810,'FW_Salmon_by_Month_2010-2021'!$B$2:$B$3810,'Rec_raw_catch_effort_2010-2021'!$B1268,'FW_Salmon_by_Month_2010-2021'!$H$2:$H$3810,'Rec_raw_catch_effort_2010-2021'!$F1268,'FW_Salmon_by_Month_2010-2021'!$M$2:$M$3810,'Rec_raw_catch_effort_2010-2021'!$K1268) -> 22.933333 | R1268: =VLOOKUP(B1268,Readme!$A$62:$C$74,2,)*Q1268 -> 110.52846 | S1268: =IF(B1268<=2019,"Y","N") -> Y | T1268: =IFERROR(P1268/O1268,"NA") -> 8.65 | U1268: =IFERROR(R1268/Q1268,"NA") -> 4.8195549
... A1816: 2876 | B1816: 2019 | C1816: Freshwater | D1816: 2Freshwater | E1816: Salmon | F1816: 788 | G1816: Nooksack River | H1816: =G1816 -> Nooksack River | I1816: =IFERROR(VLOOKUP(H1816,LUTs!$A$1:$C$73,2,FALSE),"NA") -> Whatcom | J1816: =IFERROR(VLOOKUP(H1816,LUTs!$A$1:$C$73,3,FALSE),"NA") -> 1North Puget Sound | K1816: Whatcom | L1816: =VLOOKUP(K1816,LUTs!E$2:G$14,3,) -> 01Whatcom | M1816: =VLOOKUP($K1816,LUTs!$E$2:$H$14,2,) -> North Puget Sound | N1816: =VLOOKUP($K1816,LUTs!$E$2:$H$14,4,) -> 01North Puget Sound | O1816: 1499.1423 | P1816: 5157.0494 | Q1816: =SUMIFS('FW_Salmon_by_Month_2010-2021'!P$2:P$3810,'FW_Salmon_by_Month_2010-2021'!$B$2:$B$3810,'Rec_raw_catch_effort_2010-2021'!$B1816,'FW_Salmon_by_Month_2010-2021'!$H$2:$H$3810,'Rec_raw_catch_effort_2010-2021'!$F1816,'FW_Salmon_by_Month_2010-2021'!$M$2:$M$3810,'Rec_raw_catch_effort_2010-2021'!$K1816) -> 1536.7929 | R1816: =VLOOKUP(B1816,Readme!$A$62:$C$74,2,)*Q1816 -> 5438.7721 | S1816: =IF(B1816<=2019,"Y","N") -> Y | T1816: =IFERROR(P1816/O1816,"NA") -> 3.44 | U1816: =IFERROR(R1816/Q1816,"NA") -> 3.5390404
...

Sheet Pivot
A1: Species | B1: Salmon
A2: Year | B2: (Multiple Items) | C2: 2010-2019 | N2: Species | O2: Salmon
N3: Water_Type2 | O3: 1Marine
C4: Sum of Trips
A5: 0Strait of Juan de Fuca | B5: 01Whatcom | C5: 5453.5974 | O5: Year | P5: Values
B6: 02Skagit | C6: 9738.7007 | O6: 2010 | Q6: 2011 | S6: 2012 | U6: 2013 | W6: 2014 | Y6: 2015 | AA6: 2016 | AC6: 2017 | AE6: 2018 | AG6: 2019 | AI6: 2020 | AK6: 2021 | AM6: Total Sum of Catch | AN6: Total Sum of Trips
B7: 03Snohomish | C7: 30947.453 | N7: Subregion_CatchArea | O7: Sum of Catch | P7: Sum of Trips | Q7: Sum of Catch | R7: Sum of Trips | S7: Sum of Catch | T7: Sum of Trips | U7: Sum of Catch | V7: Sum of Trips | W7: Sum of Catch | X7: Sum of Trips | Y7: Sum of Catch | Z7: Sum of Trips | AA7: Sum of Catch | AB7: Sum of Trips | AC7: Sum of Catch | AD7: Sum of Trips | AE7: Sum of Catch | AF7: Sum of Trips | AG7: Sum of Catch | AH7: Sum of Trips | AI7: Sum of Catch | AJ7: Sum of Trips | AK7: Sum of Catch | AL7: Sum of Trips
B8: 04Island | C8: 16476.72 | N8: 0Strait of Juan de Fuca | O8: 22553 | P8: 50995.45 | Q8: 82260.468 | R8: 79163.167 | S8: 89890 | T8: 90080.17 | U8: 92379 | V8: 77823.97 | W8: 74613 | X8: 95012.42 | Y8: 116699 | Z8: 92065.73 | AA8: 11541 | AB8: 35457.68 | AC8: 19170 | AD8: 31715.603 | AE8: 43043 | AF8: 48517.802 | AG8: 36621 | AH8: 45396.21 | AI8: 49675 | AJ8: 54297.077 | AK8: 52650 | AL8: 60885.308 | AM8: 691094.47 | AN8: 761410.59
B9: 05San Juan | C9: 432.45754 | N9: 1North Puget Sound | O9: 4543 | P9: 33960.66 | Q9: 19304.927 | R9: 41446.764 | S9: 9228 | T9: 40414.85 | U9: 26506 | V9: 46149.72 | W9: 11221 | X9: 55828.4 | Y9: 40107 | Z9: 47238.63 | AA9: 6205 | AB9: 30663.02 | AC9: 13055 | AD9: 36195.094 | AE9: 13867 | AF9: 32271.992 | AG9: 11916 | AH9: 26541.473 | AI9: 12528 | AJ9: 25558.924 | AK9: 4614 | AL9: 9337.4702 | AM9: 173094.93 | AN9: 425607
B10: 06King | C10: 77403.288 | N10: 2Central Puget Sound | O10: 8980 | P10: 92794.59 | Q10: 72547.709 | R10: 133169.36 | S10: 70113 | T10: 150800.45 | U10: 122034 | V10: 177990.34 | W10: 49915 | X10: 167202.9 | Y10: 166130 | Z10: 254771.71 | AA10: 7413.8655 | AB10: 51830.79 | AC10: 16299 | AD10: 40854.333 | AE10: 29210 | AF10: 60118.257 | AG10: 46505 | AH10: 62858.103 | AI10: 11121 | AJ10: 52458.569 | AK10: 67743 | AL10: 74127.315 | AM10: 668011.57 | AN10: 1318976.7
B11: 07Pierce | C11: 80941.284 | N11: 3South Puget Sound | O11: 12195 | P11: 126383.1 | Q11: 49805.644 | R11: 137657.36 | S11: 40232 | T11: 138671.14 | U11: 49839 | V11: 156072.49 | W11: 20589 | X11: 117416.65 | Y11: 46437 | Z11: 113207.92 | AA11: 6498.9511 | AB11: 49480.46 | AC11: 40048 | AD11: 81182.608 | AE11: 49605 | AF11: 85568.76 | AG11: 51815 | AH11: 77819.636 | AI11: 41146 | AJ11: 93454.229 | AK11: 51680 | AL11: 104994.95 | AM11: 459890.6 | AN11: 1281909.3
B12: 08Thurston | C12: 23924.173 | N12: 4 Hood Canal | O12: 2415 | P12: 11298.4 | Q12: 5738 | R12: 32678.42 | S12: 6855 | T12: 27302.49 | U12: 5546 | V12: 23129.53 | W12: 3544 | X12: 16512.58 | Y12: 4331 | Z12: 28618.93 | AA12: 9675 | AB12: 26056.65 | AC12: 11397 | AD12: 6895.6172 | AE12: 8228 | AF12: 6959.2496 | AG12: 3626 | AH12: 3338.4856 | AI12: 4519 | AJ12: 4003.1902 | AK12: 8236 | AL12: 4022.7698 | AM12: 74110 | AN12: 190816.31
B13: 09Mason | C13: 15994.196 | N13: Grand Total | O13: 50686 | P13: 315432.2 | Q13: 229656.75 | R13: 424115.07 | S13: 216318 | T13: 447269.1 | U13: 296304 | V13: 481166.05 | W13: 159882 | X13: 451972.95 | Y13: 373704 | Z13: 535902.92 | AA13: 41333.817 | AB13: 193488.6 | AC13: 99969 | AD13: 196843.26 | AE13: 143953 | AF13: 233436.06 | AG13: 150483 | AH13: 215953.91 | AI13: 118989 | AJ13: 229771.99 | AK13: 184923 | AL13: 253367.81 | AM13: 2066201.6 | AN13: 3978719.9
B14: 10Kitsap | C14: 52205.264
B15: 11Clallam | C15: 232181.6
B16: 12Jefferson | C16: 18336.067
B17: 20Other | C17: 124916.68
A18: 0Strait of Juan de Fuca Total | C18: 688951.47
A19: 1North Puget Sound | B19: 01Whatcom | C19: 415694.79
B20: 02Skagit | C20: 345680.31
B21: 03Snohomish | C21: 393920.77
B22: 04Island | C22: 75332.675
B23: 05San Juan | C23: 49371.049
B24: 06King | C24: 144533.92
B25: 07Pierce | C25: 19890.083
B26: 08Thurston | C26: 6426.5206
B27: 09Mason | C27: 1267.0898
B28: 10Kitsap | C28: 2958.4388
B29: 11Clallam | C29: 5105.7361
B30: 12Jefferson | C30: 769.55694
B31: 20Other | C31: 105485.87
A32: 1North Puget Sound Total | C32: 1566436.8
A33: 2Central Puget Sound | B33: 01Whatcom | C33: 153635.66
B34: 02Skagit | C34: 529350.16
B35: 03Snohomish | C35: 1327669.8
B36: 04Island | C36: 264974.81
B37: 05San Juan | C37: 929.7414
B38: 06King | C38: 457217.87
B39: 07Pierce | C39: 36612.096
B40: 08Thurston | C40: 12024.317
...

Sheet Data_For_Appx_Table_C-4
A1: Data for Appx Table C-4 Corrected and Updated 05-15-2024
A3: Year: | B3: 2010-2019 | C3: Y | D3: Y | E3: Y | F3: Y
A4: Waters: | B4: Combined Marine and FW | C4: Salmon | D4: Salmon | E4: Steelhead | F4: Steelhead
A5: Subregion_CatchArea | B5: County_N-S_Order | C5: Total Trips2 | D5: Total Catch2 | E5: Total Trips2 | F5: Total Catch2
A6: 0Strait of Juan de Fuca | B6: 01Whatcom | C6: =SUMIFS('Rec_raw_catch_effort_2010-2021'!$R:$R,'Rec_raw_catch_effort_2010-2021'!$J:$J,'Data_For_Appx_Table_C-4'!$A6,'Rec_raw_catch_effort_2010-2021'!$L:$L,'Data_For_Appx_Table_C-4'!$B6,'Rec_raw_catch_effort_2010-2021'!$E:$E,'Data_For_Appx_Table_C-4'!$C$4,'Rec_raw_catch_effort_2010-2021'!$S:$S,'Data_For_Appx_Table_C-4'!C$3) -> 5453.5974 | D6: =SUMIFS('Rec_raw_catch_effort_2010-2021'!$Q:$Q,'Rec_raw_catch_effort_2010-2021'!$J:$J,'Data_For_Appx_Table_C-4'!$A6,'Rec_raw_catch_effort_2010-2021'!$L:$L,'Data_For_Appx_Table_C-4'!$B6,'Rec_raw_catch_effort_2010-2021'!$E:$E,'Data_For_Appx_Table_C-4'!$D$4,'Rec_raw_catch_effort_2010-2021'!$S:$S,'Data_For_Appx_Table_C-4'!D$3) -> 5028.4699 | E6: =SUMIFS('Rec_raw_catch_effort_2010-2021'!$R:$R,'Rec_raw_catch_effort_2010-2021'!$J:$J,'Data_For_Appx_Table_C-4'!$A6,'Rec_raw_catch_effort_2010-2021'!$L:$L,'Data_For_Appx_Table_C-4'!$B6,'Rec_raw_catch_effort_2010-2021'!$E:$E,'Data_For_Appx_Table_C-4'!$E$4,'Rec_raw_catch_effort_2010-2021'!$S:$S,'Data_For_Appx_Table_C-4'!E$3) -> 472.95556 | F6: =SUMIFS('Rec_raw_catch_effort_2010-2021'!$Q:$Q,'Rec_raw_catch_effort_2010-2021'!$J:$J,'Data_For_Appx_Table_C-4'!$A6,'Rec_raw_catch_effort_2010-2021'!$L:$L,'Data_For_Appx_Table_C-4'!$B6,'Rec_raw_catch_effort_2010-2021'!$E:$E,'Data_For_Appx_Table_C-4'!$F$4,'Rec_raw_catch_effort_2010-2021'!$S:$S,'Data_For_Appx_Table_C-4'!F$3) -> 22.6
A7: 0Strait of Juan de Fuca | B7: 02Skagit | C7: =SUMIFS('Rec_raw_catch_effort_2010-2021'!$R:$R,'Rec_raw_catch_effort_2010-2021'!$J:$J,'Data_For_Appx_Table_C-4'!$A7,'Rec_raw_catch_effort_2010-2021'!$L:$L,'Data_For_Appx_Table_C-4'!$B7,'Rec_raw_catch_effort_2010-2021'!$E:$E,'Data_For_Appx_Table_C-4'!$C$4,'Rec_raw_catch_effort_2010-2021'!$S:$S,'Data_For_Appx_Table_C-4'!C$3) -> 9743.7708 | D7: =SUMIFS('Rec_raw_catch_effort_2010-2021'!$Q:$Q,'Rec_raw_catch_effort_2010-2021'!$J:$J,'Data_For_Appx_Table_C-4'!$A7,'Rec_raw_catch_effort_2010-2021'!$L:$L,'Data_For_Appx_Table_C-4'!$B7,'Rec_raw_catch_effort_2010-2021'!$E:$E,'Data_For_Appx_Table_C-4'!$D$4,'Rec_raw_catch_effort_2010-2021'!$S:$S,'Data_For_Appx_Table_C-4'!D$3) -> 8667.2485 | E7: =SUMIFS('Rec_raw_catch_effort_2010-2021'!$R:$R,'Rec_raw_catch_effort_2010-2021'!$J:$J,'Data_For_Appx_Table_C-4'!$A7,'Rec_raw_catch_effort_2010-2021'!$L:$L,'Data_For_Appx_Table_C-4'!$B7,'Rec_raw_catch_effort_2010-2021'!$E:$E,'Data_For_Appx_Table_C-4'!$E$4,'Rec_raw_catch_effort_2010-2021'!$S:$S,'Data_For_Appx_Table_C-4'!E$3) -> 305.76376 | F7: =SUMIFS('Rec_raw_catch_effort_2010-2021'!$Q:$Q,'Rec_raw_catch_effort_2010-2021'!$J:$J,'Data_For_Appx_Table_C-4'!$A7,'Rec_raw_catch_effort_2010-2021'!$L:$L,'Data_For_Appx_Table_C-4'!$B7,'Rec_raw_catch_effort_2010-2021'!$E:$E,'Data_For_Appx_Table_C-4'!$F$4,'Rec_raw_catch_effort_2010-2021'!$S:$S,'Data_For_Appx_Table_C-4'!F$3) -> 14.610804
A8: 0Strait of Juan de Fuca | B8: 03Snohomish | C8: =SUMIFS('Rec_raw_catch_effort_2010-2021'!$R:$R,'Rec_raw_catch_effort_2010-2021'!$J:$J,'Data_For_Appx_Table_C-4'!$A8,'Rec_raw_catch_effort_2010-2021'!$L:$L,'Data_For_Appx_Table_C-4'!$B8,'Rec_raw_catch_effort_2010-2021'!$E:$E,'Data_For_Appx_Table_C-4'!$C$4,'Rec_raw_catch_effort_2010-2021'!$S:$S,'Data_For_Appx_Table_C-4'!C$3) -> 30804.992 | D8: =SUMIFS('Rec_raw_catch_effort_2010-2021'!$Q:$Q,'Rec_raw_catch_effort_2010-2021'!$J:$J,'Data_For_Appx_Table_C-4'!$A8,'Rec_raw_catch_effort_2010-2021'!$L:$L,'Data_For_Appx_Table_C-4'!$B8,'Rec_raw_catch_effort_2010-2021'!$E:$E,'Data_For_Appx_Table_C-4'!$D$4,'Rec_raw_catch_effort_2010-2021'!$S:$S,'Data_For_Appx_Table_C-4'!D$3) -> 28867.703 | E8: =SUMIFS('Rec_raw_catch_effort_2010-2021'!$R:$R,'Rec_raw_catch_effort_2010-2021'!$J:$J,'Data_For_Appx_Table_C-4'!$A8,'Rec_raw_catch_effort_2010-2021'!$L:$L,'Data_For_Appx_Table_C-4'!$B8,'Rec_raw_catch_effort_2010-2021'!$E:$E,'Data_For_Appx_Table_C-4'!$E$4,'Rec_raw_catch_effort_2010-2021'!$S:$S,'Data_For_Appx_Table_C-4'!E$3) -> 733.01471 | F8: =SUMIFS('Rec_raw_catch_effort_2010-2021'!$Q:$Q,'Rec_raw_catch_effort_2010-2021'!$J:$J,'Data_For_Appx_Table_C-4'!$A8,'Rec_raw_catch_effort_2010-2021'!$L:$L,'Data_For_Appx_Table_C-4'!$B8,'Rec_raw_catch_effort_2010-2021'!$E:$E,'Data_For_Appx_Table_C-4'!$F$4,'Rec_raw_catch_effort_2010-2021'!$S:$S,'Data_For_Appx_Table_C-4'!F$3) -> 35.026826
A9: 0Strait of Juan de Fuca | B9: 04Island | C9: =SUMIFS('Rec_raw_catch_effort_2010-2021'!$R:$R,'Rec_raw_catch_effort_2010-2021'!$J:$J,'Data_For_Appx_Table_C-4'!$A9,'Rec_raw_catch_effort_2010-2021'!$L:$L,'Data_For_Appx_Table_C-4'!$B9,'Rec_raw_catch_effort_2010-2021'!$E:$E,'Data_For_Appx_Table_C-4'!$C$4,'Rec_raw_catch_effort_2010-2021'!$S:$S,'Data_For_Appx_Table_C-4'!C$3) -> 16476.72 | D9: =SUMIFS('Rec_raw_catch_effort_2010-2021'!$Q:$Q,'Rec_raw_catch_effort_2010-2021'!$J:$J,'Data_For_Appx_Table_C-4'!$A9,'Rec_raw_catch_effort_2010-2021'!$L:$L,'Data_For_Appx_Table_C-4'!$B9,'Rec_raw_catch_effort_2010-2021'!$E:$E,'Data_For_Appx_Table_C-4'!$D$4,'Rec_raw_catch_effort_2010-2021'!$S:$S,'Data_For_Appx_Table_C-4'!D$3) -> 15469.594 | E9: =SUMIFS('Rec_raw_catch_effort_2010-2021'!$R:$R,'Rec_raw_catch_effort_2010-2021'!$J:$J,'Data_For_Appx_Table_C-4'!$A9,'Rec_raw_catch_effort_2010-2021'!$L:$L,'Data_For_Appx_Table_C-4'!$B9,'Rec_raw_catch_effort_2010-2021'!$E:$E,'Data_For_Appx_Table_C-4'!$E$4,'Rec_raw_catch_effort_2010-2021'!$S:$S,'Data_For_Appx_Table_C-4'!E$3) -> 1300.0457 | F9: =SUMIFS('Rec_raw_catch_effort_2010-2021'!$Q:$Q,'Rec_raw_catch_effort_2010-2021'!$J:$J,'Data_For_Appx_Table_C-4'!$A9,'Rec_raw_catch_effort_2010-2021'!$L:$L,'Data_For_Appx_Table_C-4'!$B9,'Rec_raw_catch_effort_2010-2021'!$E:$E,'Data_For_Appx_Table_C-4'!$F$4,'Rec_raw_catch_effort_2010-2021'!$S:$S,'Data_For_Appx_Table_C-4'!F$3) -> 62.122184
A10: 0Strait of Juan de Fuca | B10: 05San Juan | C10: =SUMIFS('Rec_raw_catch_effort_2010-2021'!$R:$R,'Rec_raw_catch_effort_2010-2021'!$J:$J,'Data_For_Appx_Table_C-4'!$A10,'Rec_raw_catch_effort_2010-2021'!$L:$L,'Data_For_Appx_Table_C-4'!$B10,'Rec_raw_catch_effort_2010-2021'!$E:$E,'Data_For_Appx_Table_C-4'!$C$4,'Rec_raw_catch_effort_2010-2021'!$S:$S,'Data_For_Appx_Table_C-4'!C$3) -> 432.45754 | D10: =SUMIFS('Rec_raw_catch_effort_2010-2021'!$Q:$Q,'Rec_raw_catch_effort_2010-2021'!$J:$J,'Data_For_Appx_Table_C-4'!$A10,'Rec_raw_catch_effort_2010-2021'!$L:$L,'Data_For_Appx_Table_C-4'!$B10,'Rec_raw_catch_effort_2010-2021'!$E:$E,'Data_For_Appx_Table_C-4'!$D$4,'Rec_raw_catch_effort_2010-2021'!$S:$S,'Data_For_Appx_Table_C-4'!D$3) -> 374.12183 | E10: =SUMIFS('Rec_raw_catch_effort_2010-2021'!$R:$R,'Rec_raw_catch_effort_2010-2021'!$J:$J,'Data_For_Appx_Table_C-4'!$A10,'Rec_raw_catch_effort_2010-2021'!$L:$L,'Data_For_Appx_Table_C-4'!$B10,'Rec_raw_catch_effort_2010-2021'!$E:$E,'Data_For_Appx_Table_C-4'!$E$4,'Rec_raw_catch_effort_2010-2021'!$S:$S,'Data_For_Appx_Table_C-4'!E$3) -> 0 | F10: =SUMIFS('Rec_raw_catch_effort_2010-2021'!$Q:$Q,'Rec_raw_catch_effort_2010-2021'!$J:$J,'Data_For_Appx_Table_C-4'!$A10,'Rec_raw_catch_effort_2010-2021'!$L:$L,'Data_For_Appx_Table_C-4'!$B10,'Rec_raw_catch_effort_2010-2021'!$E:$E,'Data_For_Appx_Table_C-4'!$F$4,'Rec_raw_catch_effort_2010-2021'!$S:$S,'Data_For_Appx_Table_C-4'!F$3) -> 0
A11: 0Strait of Juan de Fuca | B11: 06King | C11: =SUMIFS('Rec_raw_catch_effort_2010-2021'!$R:$R,'Rec_raw_catch_effort_2010-2021'!$J:$J,'Data_For_Appx_Table_C-4'!$A11,'Rec_raw_catch_effort_2010-2021'!$L:$L,'Data_For_Appx_Table_C-4'!$B11,'Rec_raw_catch_effort_2010-2021'!$E:$E,'Data_For_Appx_Table_C-4'!$C$4,'Rec_raw_catch_effort_2010-2021'!$S:$S,'Data_For_Appx_Table_C-4'!C$3) -> 77361.237 | D11: =SUMIFS('Rec_raw_catch_effort_2010-2021'!$Q:$Q,'Rec_raw_catch_effort_2010-2021'!$J:$J,'Data_For_Appx_Table_C-4'!$A11,'Rec_raw_catch_effort_2010-2021'!$L:$L,'Data_For_Appx_Table_C-4'!$B11,'Rec_raw_catch_effort_2010-2021'!$E:$E,'Data_For_Appx_Table_C-4'!$D$4,'Rec_raw_catch_effort_2010-2021'!$S:$S,'Data_For_Appx_Table_C-4'!D$3) -> 74833.851 | E11: =SUMIFS('Rec_raw_catch_effort_2010-2021'!$R:$R,'Rec_raw_catch_effort_2010-2021'!$J:$J,'Data_For_Appx_Table_C-4'!$A11,'Rec_raw_catch_effort_2010-2021'!$L:$L,'Data_For_Appx_Table_C-4'!$B11,'Rec_raw_catch_effort_2010-2021'!$E:$E,'Data_For_Appx_Table_C-4'!$E$4,'Rec_raw_catch_effort_2010-2021'!$S:$S,'Data_For_Appx_Table_C-4'!E$3) -> 2273.6447 | F11: =SUMIFS('Rec_raw_catch_effort_2010-2021'!$Q:$Q,'Rec_raw_catch_effort_2010-2021'!$J:$J,'Data_For_Appx_Table_C-4'!$A11,'Rec_raw_catch_effort_2010-2021'!$L:$L,'Data_For_Appx_Table_C-4'!$B11,'Rec_raw_catch_effort_2010-2021'!$E:$E,'Data_For_Appx_Table_C-4'!$F$4,'Rec_raw_catch_effort_2010-2021'!$S:$S,'Data_For_Appx_Table_C-4'!F$3) -> 108.64524
A12: 0Strait of Juan de Fuca | B12: 07Pierce | C12: =SUMIFS('Rec_raw_catch_effort_2010-2021'!$R:$R,'Rec_raw_catch_effort_2010-2021'!$J:$J,'Data_For_Appx_Table_C-4'!$A12,'Rec_raw_catch_effort_2010-2021'!$L:$L,'Data_For_Appx_Table_C-4'!$B12,'Rec_raw_catch_effort_2010-2021'!$E:$E,'Data_For_Appx_Table_C-4'!$C$4,'Rec_raw_catch_effort_2010-2021'!$S:$S,'Data_For_Appx_Table_C-4'!C$3) -> 80761.96 | D12: =SUMIFS('Rec_raw_catch_effort_2010-2021'!$Q:$Q,'Rec_raw_catch_effort_2010-2021'!$J:$J,'Data_For_Appx_Table_C-4'!$A12,'Rec_raw_catch_effort_2010-2021'!$L:$L,'Data_For_Appx_Table_C-4'!$B12,'Rec_raw_catch_effort_2010-2021'!$E:$E,'Data_For_Appx_Table_C-4'!$D$4,'Rec_raw_catch_effort_2010-2021'!$S:$S,'Data_For_Appx_Table_C-4'!D$3) -> 77043.788 | E12: =SUMIFS('Rec_raw_catch_effort_2010-2021'!$R:$R,'Rec_raw_catch_effort_2010-2021'!$J:$J,'Data_For_Appx_Table_C-4'!$A12,'Rec_raw_catch_effort_2010-2021'!$L:$L,'Data_For_Appx_Table_C-4'!$B12,'Rec_raw_catch_effort_2010-2021'!$E:$E,'Data_For_Appx_Table_C-4'!$E$4,'Rec_raw_catch_effort_2010-2021'!$S:$S,'Data_For_Appx_Table_C-4'!E$3) -> 4144.2759 | F12: =SUMIFS('Rec_raw_catch_effort_2010-2021'!$Q:$Q,'Rec_raw_catch_effort_2010-2021'!$J:$J,'Data_For_Appx_Table_C-4'!$A12,'Rec_raw_catch_effort_2010-2021'!$L:$L,'Data_For_Appx_Table_C-4'!$B12,'Rec_raw_catch_effort_2010-2021'!$E:$E,'Data_For_Appx_Table_C-4'!$F$4,'Rec_raw_catch_effort_2010-2021'!$S:$S,'Data_For_Appx_Table_C-4'!F$3) -> 198.03263
A13: 0Strait of Juan de Fuca | B13: 08Thurston | C13: =SUMIFS('Rec_raw_catch_effort_2010-2021'!$R:$R,'Rec_raw_catch_effort_2010-2021'!$J:$J,'Data_For_Appx_Table_C-4'!$A13,'Rec_raw_catch_effort_2010-2021'!$L:$L,'Data_For_Appx_Table_C-4'!$B13,'Rec_raw_catch_effort_2010-2021'!$E:$E,'Data_For_Appx_Table_C-4'!$C$4,'Rec_raw_catch_effort_2010-2021'!$S:$S,'Data_For_Appx_Table_C-4'!C$3) -> 23846.07 | D13: =SUMIFS('Rec_raw_catch_effort_2010-2021'!$Q:$Q,'Rec_raw_catch_effort_2010-2021'!$J:$J,'Data_For_Appx_Table_C-4'!$A13,'Rec_raw_catch_effort_2010-2021'!$L:$L,'Data_For_Appx_Table_C-4'!$B13,'Rec_raw_catch_effort_2010-2021'!$E:$E,'Data_For_Appx_Table_C-4'!$D$4,'Rec_raw_catch_effort_2010-2021'!$S:$S,'Data_For_Appx_Table_C-4'!D$3) -> 23277.759 | E13: =SUMIFS('Rec_raw_catch_effort_2010-2021'!$R:$R,'Rec_raw_catch_effort_2010-2021'!$J:$J,'Data_For_Appx_Table_C-4'!$A13,'Rec_raw_catch_effort_2010-2021'!$L:$L,'Data_For_Appx_Table_C-4'!$B13,'Rec_raw_catch_effort_2010-2021'!$E:$E,'Data_For_Appx_Table_C-4'!$E$4,'Rec_raw_catch_effort_2010-2021'!$S:$S,'Data_For_Appx_Table_C-4'!E$3) -> 256.31527 | F13: =SUMIFS('Rec_raw_catch_effort_2010-2021'!$Q:$Q,'Rec_raw_catch_effort_2010-2021'!$J:$J,'Data_For_Appx_Table_C-4'!$A13,'Rec_raw_catch_effort_2010-2021'!$L:$L,'Data_For_Appx_Table_C-4'!$B13,'Rec_raw_catch_effort_2010-2021'!$E:$E,'Data_For_Appx_Table_C-4'!$F$4,'Rec_raw_catch_effort_2010-2021'!$S:$S,'Data_For_Appx_Table_C-4'!F$3) -> 12.247927
A14: 0Strait of Juan de Fuca | B14: 09Mason | C14: =SUMIFS('Rec_raw_catch_effort_2010-2021'!$R:$R,'Rec_raw_catch_effort_2010-2021'!$J:$J,'Data_For_Appx_Table_C-4'!$A14,'Rec_raw_catch_effort_2010-2021'!$L:$L,'Data_For_Appx_Table_C-4'!$B14,'Rec_raw_catch_effort_2010-2021'!$E:$E,'Data_For_Appx_Table_C-4'!$C$4,'Rec_raw_catch_effort_2010-2021'!$S:$S,'Data_For_Appx_Table_C-4'!C$3) -> 15922.198 | D14: =SUMIFS('Rec_raw_catch_effort_2010-2021'!$Q:$Q,'Rec_raw_catch_effort_2010-2021'!$J:$J,'Data_For_Appx_Table_C-4'!$A14,'Rec_raw_catch_effort_2010-2021'!$L:$L,'Data_For_Appx_Table_C-4'!$B14,'Rec_raw_catch_effort_2010-2021'!$E:$E,'Data_For_Appx_Table_C-4'!$D$4,'Rec_raw_catch_effort_2010-2021'!$S:$S,'Data_For_Appx_Table_C-4'!D$3) -> 16352.972 | E14: =SUMIFS('Rec_raw_catch_effort_2010-2021'!$R:$R,'Rec_raw_catch_effort_2010-2021'!$J:$J,'Data_For_Appx_Table_C-4'!$A14,'Rec_raw_catch_effort_2010-2021'!$L:$L,'Data_For_Appx_Table_C-4'!$B14,'Rec_raw_catch_effort_2010-2021'!$E:$E,'Data_For_Appx_Table_C-4'!$E$4,'Rec_raw_catch_effort_2010-2021'!$S:$S,'Data_For_Appx_Table_C-4'!E$3) -> 564.19832 | F14: =SUMIFS('Rec_raw_catch_effort_2010-2021'!$Q:$Q,'Rec_raw_catch_effort_2010-2021'!$J:$J,'Data_For_Appx_Table_C-4'!$A14,'Rec_raw_catch_effort_2010-2021'!$L:$L,'Data_For_Appx_Table_C-4'!$B14,'Rec_raw_catch_effort_2010-2021'!$E:$E,'Data_For_Appx_Table_C-4'!$F$4,'Rec_raw_catch_effort_2010-2021'!$S:$S,'Data_For_Appx_Table_C-4'!F$3) -> 26.96
