Workbook
Name _Toc485765816: 'T35'!#REF!
Name _Toc8058813: 'T35'!#REF!
Name _Toc8058814: 'T36'!$L$2
Name _Toc8058815: 'T35'!#REF!

Sheet Due Dates
A1: Group 1 due date: | C1: 45975
A2: Group 2 due date: | C2: 46003
A4: Table # | B4: Lead | C4: Group 1 | D4: Group 2
A5: 1 | B5: ODFW (Moore) | D5: X
A6: 2 | B6: ODFW (Moore) | D6: X
A7: 3 | B7: ODFW (Ollerenshaw) | D7: X
A8: 4 | B8: ODFW (Ollerenshaw) | C8: X
A9: 5 | B9: ODFW (Moore) | D9: X
A10: 5add | B10: ODFW (Moore) | D10: X
A11: 6 | B11: ODFW (Moore) | D11: X
A12: 7 | B12: ODFW (Moore) | D12: X
A13: 8 | B13: WDFW (Lothrop) | D13: X
A14: 9 | B14: ODFW (Moore) | D14: X
A15: 10 | B15: ODFW (Moore) | D15: X
A16: 11a&b | B16: ODFW (Moore) | D16: X
A17: 12 | B17: WDFW (Sorel) | D17: X
A18: 13 | B18: WDFW (Sorel) | D18: X | E18: JW: prior run year final reconstruction should be available from A. Byrne IDFG by mid-Dec, prelim estimate for current run year in January.
A19: 14 | B19: WDFW/ODFW (Daugherty/Moore) | C19: X
A20: 15 | B20: WDFW (Sorel) | D20: X
A21: 16 | B21: ODFW (Reagan) | C21: X
A22: 17 | B22: ODFW (Morgan) | C22: X | E22: JW: timeseries (start in '05) needs to be double checked for consistency with landings posted on web; web should represent final, most accurate estimates. If any of these these table numbers are the best estimate, they should be flagged to indicate they should stay in.
A23: 18 | B23: ODFW (Morgan) | C23: X
A24: 19 | B24: ODFW (Morgan) | D24: X
A25: 20 | B25: ODFW (Morgan) | D25: X
A26: 21 | B26: ODFW (Moore) | D26: X
A27: 22 | B27: ODFW (Watts) | C27: X
A28: 23 | B28: ODFW (Watts) | C28: X
A29: 24 | B29: ODFW (Watts) | C29: X
A30: 25 | B30: WDFW (Lothrop/Trump) | C30: X
A31: 26 | B31: ODFW (Watts) | C31: X
A32: 27 | B32: ODFW (Reagan) | D32: X
A33: 28 | B33: WDFW (Deacy) | C33: X
A34: 29 | B34: ODFW (Duff) | C34: X
A35: 30 | B35: ODFW (Duff) | D35: X
A36: 31 | B36: ODFW (Duff) | D36: X
A37: 32 | B37: CRITFC (Ellis) | C37: X | E37: links to T35
A38: 33 | B38: CRITFC (Ellis) | C38: X
A39: 34 | B39: CRITFC (Ellis) | C39: X
A40: 35 | B40: CRITFC (Ellis) | C40: X
A41: 36 | B41: CRITFC (Ellis) | C41: X | E41: JW: question for CRITFC has not been addressed

Sheet New Figures

Sheet T1Manip
A1: Table 1. Minimum Adult Spring Chinook Run Entering the Columbia River, 1980- | K1: CRC estimate status | AA1: RANK
A2: Year | B2: Select Areas2 | C2: Cowlitz River | D2: Kalama River | E2: Lewis River | F2: Sandy River | G2: Willamette River3 | H2: Upriver Run4 | I2: Total | K2: C | L2: K | M2: L | N2: S | P2: Prop Upriver | Q2: CKLS | R2: CKLS | S2: CKLS | T2: CKLS+Safe | U2: CKL Only | AA2: year | AB2: TTL | AC2: Rank
A4: 1980 | B4: -- | C4: 23749 | D4: 2477 | E4: 2265 | F4: 1822 | G4: 42378 | H4: 57691.638 | I4: =SUM(B4:H4) -> 130382.64 | K4: F | L4: F | M4: F | AA4: 1980 | AB4: =VLOOKUP(AA4,$A$4:$I$48,8,FALSE) -> 57691.638 | AC4: =RANK(AB4,$AB$4:$AB$48,0) -> 37
A5: 1981 | B5: -- | C5: 27921 | D5: 3265 | E5: 2964 | F5: 2841 | G5: 54338 | H5: 67400.662 | I5: =SUM(B5:H5) -> 158729.66 | K5: F | L5: F | M5: F | AA5: 1981 | AB5: =VLOOKUP(AA5,$A$4:$I$48,8,FALSE) -> 67400.662 | AC5: =RANK(AB5,$AB$4:$AB$48,0) -> 34
A6: 1982 | B6: -- | C6: 19337 | D6: 8420 | E6: 3889 | F6: 1382 | G6: 75941 | H6: 77246.321 | I6: =SUM(B6:H6) -> 186215.32 | K6: F | L6: F | M6: F | AA6: 1982 | AB6: =VLOOKUP(AA6,$A$4:$I$48,8,FALSE) -> 77246.321 | AC6: =RANK(AB6,$AB$4:$AB$48,0) -> 32
A7: 1983 | B7: -- | C7: 21350 | D7: 4857 | E7: 3669 | F7: 1864 | G7: 59395 | H7: 62911.566 | I7: =SUM(B7:H7) -> 154046.57 | K7: F | L7: F | M7: F | AA7: 1983 | AB7: =VLOOKUP(AA7,$A$4:$I$48,8,FALSE) -> 62911.566 | AC7: =RANK(AB7,$AB$4:$AB$48,0) -> 36
A8: 1984 | B8: -- | C8: 21327 | D8: 1807 | E8: 6381 | F8: 2374 | G8: 82621 | H8: 52357.285 | I8: =SUM(B8:H8) -> 166867.29 | K8: F | L8: F | M8: F | AA8: 1984 | AB8: =VLOOKUP(AA8,$A$4:$I$48,8,FALSE) -> 52357.285 | AC8: =RANK(AB8,$AB$4:$AB$48,0) -> 39
A9: 1980-84 Ave. | B9: -- | C9: =AVERAGE(C4:C8) -> 22736.8 | D9: =AVERAGE(D4:D8) -> 4165.2 | E9: =AVERAGE(E4:E8) -> 3833.6 | F9: =AVERAGE(F4:F8) -> 2056.6 | G9: =AVERAGE(G4:G8) -> 62934.6 | H9: =AVERAGE(H4:H8) -> 63521.494 | I9: =SUM(B9:H9) -> 159248.29 | P9: =H9/I9 -> 0.39888336 | Q9: =SUM(C9:F9) -> 32792.2 | R9: =(C9+D9+E9)/1000 -> 30.7356 | T9: =Q9 -> 32792.2 | U9: =Q9-F9 -> 30735.6 | W9: RANK | AD9: Year | AF9: Select Area Origin CHS in SAFE Commercial | AG9: SAFE Recreational Catch | AJ9: total lower river stocks (w/o Select Area fish)
A10: 1985 | B10: -- | C10: 9911 | D10: 338 | E10: 4116 | F10: 1449 | G10: 65994 | H10: 92284 | I10: =SUM(B10:H10) -> 174092 | K10: F | L10: F | M10: F | AA10: 1985 | AB10: =VLOOKUP(AA10,$A$4:$I$48,8,FALSE) -> 92284 | AC10: =RANK(AB10,$AB$4:$AB$48,0) -> 27
A11: 1986 | B11: -- | C11: 7325 | D11: 1077 | E11: 8259 | F11: 1286 | G11: 70498 | H11: 128413.05 | I11: =SUM(B11:H11) -> 216858.05 | K11: F | L11: F | M11: F | AA11: 1986 | AB11: =VLOOKUP(AA11,$A$4:$I$48,8,FALSE) -> 128413.05 | AC11: =RANK(AB11,$AB$4:$AB$48,0) -> 16
A12: 1987 | B12: -- | C12: 17983 | D12: 2421 | E12: 16547 | F12: 2353 | G12: 90917 | H12: 110771.71 | I12: =SUM(B12:H12) -> 240992.71 | K12: F | L12: F | M12: F | AA12: 1987 | AB12: =VLOOKUP(AA12,$A$4:$I$48,8,FALSE) -> 110771.71 | AC12: =RANK(AB12,$AB$4:$AB$48,0) -> 22
A13: 1988 | B13: -- | C13: 12337 | D13: 1937 | E13: 10618 | F13: 2931 | G13: 115994 | H13: 106003.12 | I13: =SUM(B13:H13) -> 249820.12 | K13: F | L13: F | M13: F | AA13: 1988 | AB13: =VLOOKUP(AA13,$A$4:$I$48,8,FALSE) -> 106003.12 | AC13: =RANK(AB13,$AB$4:$AB$48,0) -> 24
A14: 1989 | B14: -- | C14: 8324 | D14: 1986 | E14: 12019 | F14: 2004 | G14: 110613 | H14: 90031.089 | I14: =SUM(B14:H14) -> 224977.09 | K14: F | L14: F | M14: F | AA14: 1989 | AB14: =VLOOKUP(AA14,$A$4:$I$48,8,FALSE) -> 90031.089 | AC14: =RANK(AB14,$AB$4:$AB$48,0) -> 29
A15: 1985-89 Ave. | B15: -- | C15: =AVERAGE(C10:C14) -> 11176 | D15: =AVERAGE(D10:D14) -> 1551.8 | E15: =AVERAGE(E10:E14) -> 10311.8 | F15: =AVERAGE(F10:F14) -> 2004.6 | G15: =AVERAGE(G10:G14) -> 90803.2 | H15: =AVERAGE(H10:H14) -> 105500.59 | I15: =SUM(B15:H15) -> 221347.99 | P15: =H15/I15 -> 0.47662774 | Q15: =SUM(C15:F15) -> 25044.2 | R15: =(C15+D15+E15)/1000 -> 23.0396 | T15: =Q15 -> 25044.2 | U15: =Q15-F15 -> 23039.6 | W15: year | X15: TTL | Y15: Rank
A16: 1990 | B16: -- | C16: 7555 | D16: 1987 | E16: 9299 | F16: 3527 | G16: 127900 | H16: 105715.28 | I16: =SUM(B16:H16) -> 255983.28 | K16: F | L16: F | M16: F | P16: =H16/I16 -> 0.41297729 | Q16: =SUM(C16:F16) -> 22368 | R16: =(C16+D16+E16)/1000 -> 18.841 | T16: =Q16 -> 22368 | U16: =Q16-F16 -> 18841 | W16: 1990 | X16: =VLOOKUP(W16,$A$16:$I$48,9,FALSE) -> 255983.28 | Y16: =RANK(X16,$X$16:$X$48,0) -> 13 | AA16: 1990 | AB16: =VLOOKUP(AA16,$A$4:$I$48,8,FALSE) -> 105715.28 | AC16: =RANK(AB16,$AB$4:$AB$48,0) -> 25 | AD16: 1990
A17: 1991 | B17: -- | C17: 8945 | D17: 2613 | E17: 8334 | F17: 3652 | G17: 105530 | H17: 64478.652 | I17: =SUM(B17:H17) -> 193552.65 | K17: F | L17: F | M17: F | P17: =H17/I17 -> 0.33313236 | Q17: =SUM(C17:F17) -> 23544 | R17: =(C17+D17+E17)/1000 -> 19.892 | T17: =Q17 -> 23544 | U17: =Q17-F17 -> 19892 | W17: 1991 | X17: =VLOOKUP(W17,$A$16:$I$48,9,FALSE) -> 193552.65 | Y17: =RANK(X17,$X$16:$X$48,0) -> 20 | AA17: 1991 | AB17: =VLOOKUP(AA17,$A$4:$I$48,8,FALSE) -> 64478.652 | AC17: =RANK(AB17,$AB$4:$AB$48,0) -> 35 | AD17: 1991
A18: 1992 | B18: =AF18+AG18 -> 211 | C18: 10353 | D18: 2430 | E18: 6025 | F18: 8551 | G18: 72197 | H18: 95691.439 | I18: =SUM(B18:H18) -> 195458.44 | K18: F | L18: F | M18: F | P18: =H18/I18 -> 0.48957435 | Q18: =SUM(C18:F18) -> 27359 | R18: =(C18+D18+E18)/1000 -> 18.808 | T18: =Q18+B18 -> 27570 | U18: =Q18-F18 -> 18808 | W18: 1992 | X18: =VLOOKUP(W18,$A$16:$I$48,9,FALSE) -> 195458.44 | Y18: =RANK(X18,$X$16:$X$48,0) -> 19 | AA18: 1992 | AB18: =VLOOKUP(AA18,$A$4:$I$48,8,FALSE) -> 95691.439 | AC18: =RANK(AB18,$AB$4:$AB$48,0) -> 26 | AD18: 1992 | AF18: ='T31 SAFE Comp Manip'!B3 -> 211
A19: 1993 | B19: =AF19+AG19 -> 629 | C19: 9458 | D19: 2874 | E19: 8195 | F19: 6369 | G19: 62778 | H19: 119962.96 | I19: =SUM(B19:H19) -> 210265.96 | K19: F | L19: F | M19: F | P19: =H19/I19 -> 0.57052963 | Q19: =SUM(C19:F19) -> 26896 | R19: =(C19+D19+E19)/1000 -> 20.527 | T19: =Q19+B19 -> 27525 | U19: =Q19-F19 -> 20527 | W19: 1993 | X19: =VLOOKUP(W19,$A$16:$I$48,9,FALSE) -> 210265.96 | Y19: =RANK(X19,$X$16:$X$48,0) -> 18 | AA19: 1993 | AB19: =VLOOKUP(AA19,$A$4:$I$48,8,FALSE) -> 119962.96 | AC19: =RANK(AB19,$AB$4:$AB$48,0) -> 19 | AD19: 1993 | AF19: ='T31 SAFE Comp Manip'!B4 -> 629 | AG19: =T30Manip!H5 -> 0
A20: 1994 | B20: =AF20+AG20 -> 126 | C20: 3149 | D20: 1265 | E20: 3068 | F20: 3498 | G20: 48804 | H20: 24095.182 | I20: =SUM(B20:H20) -> 84005.182 | K20: F | L20: F | M20: F | P20: =H20/I20 -> 0.28682971 | Q20: =SUM(C20:F20) -> 10980 | R20: =(C20+D20+E20)/1000 -> 7.482 | T20: =Q20+B20 -> 11106 | U20: =Q20-F20 -> 7482 | W20: 1994 | X20: =VLOOKUP(W20,$A$16:$I$48,9,FALSE) -> 84005.182 | Y20: =RANK(X20,$X$16:$X$48,0) -> 32 | AA20: 1994 | AB20: =VLOOKUP(AA20,$A$4:$I$48,8,FALSE) -> 24095.182 | AC20: =RANK(AB20,$AB$4:$AB$48,0) -> 42 | AD20: 1994 | AF20: ='T31 SAFE Comp Manip'!B5 -> 126 | AG20: =T30Manip!H6 -> 0
A21: 1995 | B21: =AF21+AG21 -> 169 | C21: 2102 | D21: 697 | E21: 3726 | F21: 2529 | G21: 40854 | H21: 12792 | I21: =SUM(B21:H21) -> 62869 | K21: F | L21: F | M21: F | N21: F | P21: =H21/I21 -> 0.20347071 | Q21: =SUM(C21:F21) -> 9054 | R21: =(C21+D21+E21)/1000 -> 6.525 | T21: =Q21+B21 -> 9223 | U21: =Q21-F21 -> 6525 | W21: 1995 | X21: =VLOOKUP(W21,$A$16:$I$48,9,FALSE) -> 62869 | Y21: =RANK(X21,$X$16:$X$48,0) -> 33 | AA21: 1995 | AB21: =VLOOKUP(AA21,$A$4:$I$48,8,FALSE) -> 12792 | AC21: =RANK(AB21,$AB$4:$AB$48,0) -> 43 | AD21: 1995 | AF21: ='T31 SAFE Comp Manip'!B6 -> 169 | AG21: =T30Manip!H7 -> 0
A22: 1996 | B22: =AF22+AG22 -> 689 | C22: 1787 | D22: 627 | E22: 1730 | F22: 3801 | G22: 33358 | H22: 55551 | I22: =SUM(B22:H22) -> 97543 | K22: F | L22: F | M22: F | N22: F | P22: =H22/I22 -> 0.56950268 | Q22: =SUM(C22:F22) -> 7945 | R22: =(C22+D22+E22)/1000 -> 4.144 | T22: =Q22+B22 -> 8634 | U22: =Q22-F22 -> 4144 | W22: 1996 | X22: =VLOOKUP(W22,$A$16:$I$48,9,FALSE) -> 97543 | Y22: =RANK(X22,$X$16:$X$48,0) -> 30 | AA22: 1996 | AB22: =VLOOKUP(AA22,$A$4:$I$48,8,FALSE) -> 55551 | AC22: =RANK(AB22,$AB$4:$AB$48,0) -> 38 | AD22: 1996 | AF22: ='T31 SAFE Comp Manip'!B7 -> 689 | AG22: =T30Manip!H8 -> 0
A23: 1997 | B23: =AF23+AG23 -> 1583 | C23: 1877 | D23: 505 | E23: 2196 | F23: 4410 | G23: 34540 | H23: 124321 | I23: =SUM(B23:H23) -> 169432 | K23: F | L23: F | M23: F | N23: F | P23: =H23/I23 -> 0.73375159 | Q23: =SUM(C23:F23) -> 8988 | R23: =(C23+D23+E23)/1000 -> 4.578 | T23: =Q23+B23 -> 10571 | U23: =Q23-F23 -> 4578 | W23: 1997 | X23: =VLOOKUP(W23,$A$16:$I$48,9,FALSE) -> 169432 | Y23: =RANK(X23,$X$16:$X$48,0) -> 24 | AA23: 1997 | AB23: =VLOOKUP(AA23,$A$4:$I$48,8,FALSE) -> 124321 | AC23: =RANK(AB23,$AB$4:$AB$48,0) -> 17 | AD23: 1997 | AF23: ='T31 SAFE Comp Manip'!B8 -> 1583 | AG23: =T30Manip!H9 -> 0
A24: 1998 | B24: =AF24+AG24 -> 2034 | C24: 1055 | D24: 407 | E24: 1611 | F24: 3577 | G24: 43497 | H24: 44308 | I24: =SUM(B24:H24) -> 96489 | K24: F | L24: F | M24: F | N24: F | P24: =H24/I24 -> 0.4592026 | Q24: =SUM(C24:F24) -> 6650 | R24: =(C24+D24+E24)/1000 -> 3.073 | T24: =Q24+B24 -> 8684 | U24: =Q24-F24 -> 3073 | W24: 1998 | X24: =VLOOKUP(W24,$A$16:$I$48,9,FALSE) -> 96489 | Y24: =RANK(X24,$X$16:$X$48,0) -> 31 | AA24: 1998 | AB24: =VLOOKUP(AA24,$A$4:$I$48,8,FALSE) -> 44308 | AC24: =RANK(AB24,$AB$4:$AB$48,0) -> 40 | AD24: 1998 | AF24: ='T31 SAFE Comp Manip'!B9 -> 1979 | AG24: =T30Manip!H10 -> 55
A25: 1999 | B25: =AF25+AG25 -> 1337 | C25: 2069 | D25: 977 | E25: 1753 | F25: 3585 | G25: 52584 | H25: 43067.18 | I25: =SUM(B25:H25) -> 105372.18 | K25: F | L25: F | M25: F | N25: F | P25: =H25/I25 -> 0.4087149 | Q25: =SUM(C25:F25) -> 8384 | R25: =(C25+D25+E25)/1000 -> 4.799 | T25: =Q25+B25 -> 9721 | U25: =Q25-F25 -> 4799 | W25: 1999 | X25: =VLOOKUP(W25,$A$16:$I$48,9,FALSE) -> 105372.18 | Y25: =RANK(X25,$X$16:$X$48,0) -> 29 | AA25: 1999 | AB25: =VLOOKUP(AA25,$A$4:$I$48,8,FALSE) -> 43067.18 | AC25: =RANK(AB25,$AB$4:$AB$48,0) -> 41 | AD25: 1999 | AF25: ='T31 SAFE Comp Manip'!B10 -> 1312 | AG25: =T30Manip!H11 -> 25
A26: 2000 | B26: =AF26+AG26 -> 5585 | C26: 2199 | D26: 1418 | E26: 2515 | F26: 3641 | G26: 55740 | H26: 186715.2 | I26: =SUM(B26:H26) -> 257813.2 | K26: F | L26: F | M26: F | N26: F | P26: =H26/I26 -> 0.72422669 | Q26: =SUM(C26:F26) -> 9773 | R26: =(C26+D26+E26)/1000 -> 6.132 | T26: =Q26+B26 -> 15358 | U26: =Q26-F26 -> 6132 | W26: 2000 | X26: =VLOOKUP(W26,$A$16:$I$48,9,FALSE) -> 257813.2 | Y26: =RANK(X26,$X$16:$X$48,0) -> 12 | AA26: 2000 | AB26: =VLOOKUP(AA26,$A$4:$I$48,8,FALSE) -> 186715.2 | AC26: =RANK(AB26,$AB$4:$AB$48,0) -> 11 | AD26: 2000 | AF26: ='T31 SAFE Comp Manip'!B11 -> 5330 | AG26: =T30Manip!H12 -> 255
A27: 2001 | B27: =AF27+AG27 -> 8089 | C27: 1609 | D27: 1796 | E27: 3777 | F27: 5329 | G27: 78502 | H27: 439885 | I27: =SUM(B27:H27) -> 538987 | K27: F | L27: F | M27: F | N27: F | P27: =H27/I27 -> 0.81613286 | Q27: =SUM(C27:F27) -> 12511 | R27: =(C27+D27+E27)/1000 -> 7.182 | T27: =Q27+B27 -> 20600 | U27: =Q27-F27 -> 7182 | W27: 2001 | X27: =VLOOKUP(W27,$A$16:$I$48,9,FALSE) -> 538987 | Y27: =RANK(X27,$X$16:$X$48,0) -> 1 | AA27: 2001 | AB27: =VLOOKUP(AA27,$A$4:$I$48,8,FALSE) -> 439885 | AC27: =RANK(AB27,$AB$4:$AB$48,0) -> 1 | AD27: 2001 | AF27: ='T31 SAFE Comp Manip'!B12 -> 7589 | AG27: =T30Manip!H13 -> 500 | AJ27: =I27-H27-B27 -> 91013
A28: 2002 | B28: =AF28+AG28 -> 8661 | C28: 5129 | D28: 2912 | E28: 3514 | F28: 5905 | G28: 120161 | H28: 335306 | I28: =SUM(B28:H28) -> 481588 | K28: F | L28: F | M28: F | N28: F | P28: =H28/I28 -> 0.69625074 | Q28: =SUM(C28:F28) -> 17460 | R28: =(C28+D28+E28)/1000 -> 11.555 | T28: =Q28+B28 -> 26121 | U28: =Q28-F28 -> 11555 | W28: 2002 | X28: =VLOOKUP(W28,$A$16:$I$48,9,FALSE) -> 481588 | Y28: =RANK(X28,$X$16:$X$48,0) -> 2 | AA28: 2002 | AB28: =VLOOKUP(AA28,$A$4:$I$48,8,FALSE) -> 335306 | AC28: =RANK(AB28,$AB$4:$AB$48,0) -> 2 | AD28: 2002 | AF28: ='T31 SAFE Comp Manip'!B13 -> 8109 | AG28: =T30Manip!H14 -> 552 | AJ28: =I28-H28-B28 -> 137621
A29: 2003 | B29: =AF29+AG29 -> 6827 | C29: 15954 | D29: 4556 | E29: 5040 | F29: 5472 | G29: 123355 | H29: 242605.3 | I29: =SUM(B29:H29) -> 403809.3 | K29: F | L29: F | M29: F | N29: F | P29: =H29/I29 -> 0.60079176 | Q29: =SUM(C29:F29) -> 31022 | R29: =(C29+D29+E29)/1000 -> 25.55 | T29: =Q29+B29 -> 37849 | U29: =Q29-F29 -> 25550 | W29: 2003 | X29: =VLOOKUP(W29,$A$16:$I$48,9,FALSE) -> 403809.3 | Y29: =RANK(X29,$X$16:$X$48,0) -> 6 | AA29: 2003 | AB29: =VLOOKUP(AA29,$A$4:$I$48,8,FALSE) -> 242605.3 | AC29: =RANK(AB29,$AB$4:$AB$48,0) -> 6 | AD29: 2003 | AF29: ='T31 SAFE Comp Manip'!B14 -> 5833 | AG29: =T30Manip!H15 -> 994 | AJ29: =I29-H29-B29 -> 154377
A30: 2004 | B30: =AF30+AG30 -> 10162 | C30: 16530 | D30: 4286 | E30: 7475 | F30: 12680 | G30: 143240 | H30: 221675.28 | I30: =SUM(B30:H30) -> 416048.28 | K30: F | L30: F | M30: F | N30: F | P30: =H30/I30 -> 0.53281143 | Q30: =SUM(C30:F30) -> 40971 | R30: =(C30+D30+E30)/1000 -> 28.291 | T30: =Q30+B30 -> 51133 | U30: =Q30-F30 -> 28291 | W30: 2004 | X30: =VLOOKUP(W30,$A$16:$I$48,9,FALSE) -> 416048.28 | Y30: =RANK(X30,$X$16:$X$48,0) -> 5 | AA30: 2004 | AB30: =VLOOKUP(AA30,$A$4:$I$48,8,FALSE) -> 221675.28 | AC30: =RANK(AB30,$AB$4:$AB$48,0) -> 7 | AD30: 2004 | AF30: ='T31 SAFE Comp Manip'!B15 -> 9081 | AG30: =T30Manip!H16 -> 1081 | AJ30: =I30-H30-B30 -> 184211
A31: 2005 | B31: =AF31+AG31 -> 2366 | C31: 9398 | D31: 3367 | E31: 3512 | F31: 7665 | G31: 59471 | H31: 106909.65 | I31: =SUM(B31:H31) -> 192688.65 | K31: F | L31: F | M31: F | N31: F | P31: =H31/I31 -> 0.55483108 | Q31: =SUM(C31:F31) -> 23942 | R31: =(C31+D31+E31)/1000 -> 16.277 | T31: =Q31+B31 -> 26308 | U31: =Q31-F31 -> 16277 | W31: 2005 | X31: =VLOOKUP(W31,$A$16:$I$48,9,FALSE) -> 192688.65 | Y31: =RANK(X31,$X$16:$X$48,0) -> 21 | AA31: 2005 | AB31: =VLOOKUP(AA31,$A$4:$I$48,8,FALSE) -> 106909.65 | AC31: =RANK(AB31,$AB$4:$AB$48,0) -> 23 | AD31: 2005 | AF31: ='T31 SAFE Comp Manip'!B16 -> 2209 | AG31: =T30Manip!H17 -> 157 | AJ31: =I31-H31-B31 -> 83413
A32: 2006 | B32: =AF32+AG32 -> 6998 | C32: 7001 | D32: 5458 | E32: 7301 | F32: 4382 | G32: 59311 | H32: 132583.34 | I32: =SUM(B32:H32) -> 223034.34 | K32: F | L32: F | M32: F | N32: F | P32: =H32/I32 -> 0.59445259 | Q32: =SUM(C32:F32) -> 24142 | R32: =(C32+D32+E32)/1000 -> 19.76 | T32: =Q32+B32 -> 31140 | U32: =Q32-F32 -> 19760 | W32: 2006 | X32: =VLOOKUP(W32,$A$16:$I$48,9,FALSE) -> 223034.34 | Y32: =RANK(X32,$X$16:$X$48,0) -> 14 | AA32: 2006 | AB32: =VLOOKUP(AA32,$A$4:$I$48,8,FALSE) -> 132583.34 | AC32: =RANK(AB32,$AB$4:$AB$48,0) -> 15 | AD32: 2006 | AF32: ='T31 SAFE Comp Manip'!B17 -> 6662 | AG32: =T30Manip!H18 -> 336 | AJ32: =I32-H32-B32 -> 83453
A33: 2007 | B33: =AF33+AG33 -> 6356 | C33: 3961 | D33: 8030 | E33: 7596 | F33: 2841 | G33: 39963 | H33: 86246.565 | I33: =SUM(B33:H33) -> 154993.57 | K33: F | L33: F | M33: F | N33: F | P33: =H33/I33 -> 0.55645255 | Q33: =SUM(C33:F33) -> 22428 | R33: =(C33+D33+E33)/1000 -> 19.587 | T33: =Q33+B33 -> 28784 | U33: =Q33-F33 -> 19587 | W33: 2007 | X33: =VLOOKUP(W33,$A$16:$I$48,9,FALSE) -> 154993.57 | Y33: =RANK(X33,$X$16:$X$48,0) -> 25 | AA33: 2007 | AB33: =VLOOKUP(AA33,$A$4:$I$48,8,FALSE) -> 86246.565 | AC33: =RANK(AB33,$AB$4:$AB$48,0) -> 30 | AD33: 2007 | AF33: ='T31 SAFE Comp Manip'!B18 -> 6162 | AG33: =T30Manip!H19 -> 194 | AJ33: =I33-H33-B33 -> 62391
A34: 2008 | B34: =AF34+AG34 -> 3289 | C34: 2978 | D34: 1623 | E34: 2215 | F34: 5848 | G34: 26615 | H34: 178626.96 | I34: =SUM(B34:H34) -> 221194.96 | K34: F | L34: F | M34: F | N34: F | P34: =H34/I34 -> 0.80755438 | Q34: =SUM(C34:F34) -> 12664 | R34: =(C34+D34+E34)/1000 -> 6.816 | T34: =Q34+B34 -> 15953 | U34: =Q34-F34 -> 6816 | W34: 2008 | X34: =VLOOKUP(W34,$A$16:$I$48,9,FALSE) -> 221194.96 | Y34: =RANK(X34,$X$16:$X$48,0) -> 15 | AA34: 2008 | AB34: =VLOOKUP(AA34,$A$4:$I$48,8,FALSE) -> 178626.96 | AC34: =RANK(AB34,$AB$4:$AB$48,0) -> 13 | AD34: 2008 | AF34: ='T31 SAFE Comp Manip'!B19 -> 3057 | AG34: =T30Manip!H20 -> 232 | AJ34: =I34-H34-B34 -> 39279
A35: 2009 | B35: =AF35+AG35 -> 2830 | C35: 6054 | D35: 404 | E35: 1493 | F35: 2347 | G35: 35432 | H35: 169295.9 | I35: =SUM(B35:H35) -> 217855.9 | K35: F | L35: F | M35: F | N35: F | P35: =H35/I35 -> 0.77710037 | Q35: =SUM(C35:F35) -> 10298 | R35: =(C35+D35+E35)/1000 -> 7.951 | T35: =Q35+B35 -> 13128 | U35: =Q35-F35 -> 7951 | W35: 2009 | X35: =VLOOKUP(W35,$A$16:$I$48,9,FALSE) -> 217855.9 | Y35: =RANK(X35,$X$16:$X$48,0) -> 16 | AA35: 2009 | AB35: =VLOOKUP(AA35,$A$4:$I$48,8,FALSE) -> 169295.9 | AC35: =RANK(AB35,$AB$4:$AB$48,0) -> 14 | AD35: 2009 | AF35: ='T31 SAFE Comp Manip'!B20 -> 2556 | AG35: =T30Manip!H21 -> 274 | AJ35: =I35-H35-B35 -> 45730
A36: 2010 | B36: =AF36+AG36 -> 22955 | C36: 8615 | D36: 977 | E36: 2347 | F36: 7343 | G36: 107675 | H36: 315345.82 | I36: =SUM(B36:H36) -> 465257.82 | K36: F | L36: F | M36: F | N36: F | P36: =H36/I36 -> 0.67778726 | Q36: =SUM(C36:F36) -> 19282 | R36: =(C36+D36+E36)/1000 -> 11.939 | T36: =Q36+B36 -> 42237 | U36: =Q36-F36 -> 11939 | W36: 2010 | X36: =VLOOKUP(W36,$A$16:$I$48,9,FALSE) -> 465257.82 | Y36: =RANK(X36,$X$16:$X$48,0) -> 3 | AA36: 2010 | AB36: =VLOOKUP(AA36,$A$4:$I$48,8,FALSE) -> 315345.82 | AC36: =RANK(AB36,$AB$4:$AB$48,0) -> 3 | AD36: 2010 | AF36: ='T31 SAFE Comp Manip'!B21 -> 20956 | AG36: =T30Manip!H22 -> 1999 | AJ36: =I36-H36-B36 -> 126957
A37: 2011 | B37: =AF37+AG37 -> 8850 | C37: 5379 | D37: 776 | E37: 1310 | F37: 4702 | G37: 76549 | H37: 221157.83 | I37: =SUM(B37:H37) -> 318723.83 | K37: F | L37: F | M37: F | N37: F | P37: =H37/I37 -> 0.69388546 | Q37: =SUM(C37:F37) -> 12167 | R37: =(C37+D37+E37)/1000 -> 7.465 | T37: =Q37+B37 -> 21017 | U37: =Q37-F37 -> 7465 | W37: 2011 | X37: =VLOOKUP(W37,$A$16:$I$48,9,FALSE) -> 318723.83 | Y37: =RANK(X37,$X$16:$X$48,0) -> 7 | AA37: 2011 | AB37: =VLOOKUP(AA37,$A$4:$I$48,8,FALSE) -> 221157.83 | AC37: =RANK(AB37,$AB$4:$AB$48,0) -> 8 | AD37: 2011 | AF37: ='T31 SAFE Comp Manip'!B22 -> 8432 | AG37: =T30Manip!H23 -> 418 | AJ37: =I37-H37-B37 -> 88716
A38: 2012 | B38: =AF38+AG38 -> 8984 | C38: 12212.852 | D38: 889.0263 | E38: 1895 | F38: 4568 | G38: 63037 | H38: 203089.6 | I38: =SUM(B38:H38) -> 294675.48 | K38: F | L38: F | M38: F | N38: F | P38: =H38/I38 -> 0.68919749 | Q38: =SUM(C38:F38) -> 19564.878 | R38: =(C38+D38+E38)/1000 -> 14.996878 | T38: =Q38+B38 -> 28548.878 | U38: =Q38-F38 -> 14996.878 | W38: 2012 | X38: =VLOOKUP(W38,$A$16:$I$48,9,FALSE) -> 294675.48 | Y38: =RANK(X38,$X$16:$X$48,0) -> 9 | AA38: 2012 | AB38: =VLOOKUP(AA38,$A$4:$I$48,8,FALSE) -> 203089.6 | AC38: =RANK(AB38,$AB$4:$AB$48,0) -> 9 | AD38: 2012 | AF38: ='T31 SAFE Comp Manip'!B23 -> 8338 | AG38: =T30Manip!H24 -> 646 | AJ38: =I38-H38-B38 -> 82601.878
... A46: 2020 | B46: =AF46+AG46 -> 4003 | C46: 908 | D46: 1158 | E46: 1900 | F46: 7782 | G46: 45965 | H46: 81301 | I46: =SUM(B46:H46) -> 143017 | K46: NA | L46: NA | M46: NA | N46: NA | P46: =H46/I46 -> 0.56847088 | Q46: =SUM(C46:F46) -> 11748 | R46: =(C46+D46+E46)/1000 -> 3.966 | T46: =Q46+B46 -> 15751 | U46: =Q46-F46 -> 3966 | W46: 2020 | X46: =VLOOKUP(W46,$A$16:$I$48,9,FALSE) -> 143017 | Y46: =RANK(X46,$X$16:$X$48,0) -> 27 | AA46: 2020 | AB46: =VLOOKUP(AA46,$A$4:$I$48,8,FALSE) -> 81301 | AC46: =RANK(AB46,$AB$4:$AB$48,0) -> 31 | AD46: 2020 | AF46: ='T31 SAFE Comp Manip'!B31 -> 3714 | AG46: =T30Manip!H32 -> 289 | AJ46: =I46-H46-B46 -> 57713
A47: 2021 | B47: =AF47+AG47 -> 6897 | C47: 3700 | D47: 1857 | E47: 2938 | F47: 5676 | G47: 41308 | H47: 91756 | I47: =SUM(B47:H47) -> 154132 | K47: NA | L47: NA | M47: NA | N47: NA | P47: =H47/I47 -> 0.59530792 | Q47: =SUM(C47:F47) -> 14171 | T47: =Q47+B47 -> 21068 | U47: =Q47-F47 -> 8495 | W47: 2021 | X47: =VLOOKUP(W47,$A$16:$I$48,9,FALSE) -> 154132 | Y47: =RANK(X47,$X$16:$X$48,0) -> 26 | AA47: 2021 | AB47: =VLOOKUP(AA47,$A$4:$I$48,8,FALSE) -> 91756 | AC47: =RANK(AB47,$AB$4:$AB$48,0) -> 28 | AD47: 2021 | AF47: ='T31 SAFE Comp Manip'!B32 -> 5754 | AG47: =T30Manip!H33 -> 1143 | AJ47: =I47-H47-B47 -> 55479
A48: 2022 | B48: =AF48+AG48 -> 19186 | C48: 7146 | D48: 3148 | E48: 6875 | F48: 10289 | G48: 55391 | H48: 185379 | I48: =SUM(B48:H48) -> 287414 | K48: NA | L48: NA | M48: NA | N48: NA | P48: =H48/I48 -> 0.64498946 | Q48: =SUM(C48:F48) -> 27458 | T48: =Q48+B48 -> 46644 | U48: =Q48-F48 -> 17169 | W48: 2022 | X48: =VLOOKUP(W48,$A$16:$I$48,9,FALSE) -> 287414 | Y48: =RANK(X48,$X$16:$X$48,0) -> 10 | AA48: 2022 | AB48: =VLOOKUP(AA48,$A$4:$I$48,8,FALSE) -> 185379 | AC48: =RANK(AB48,$AB$4:$AB$48,0) -> 12 | AD48: 2022 | AF48: ='T31 SAFE Comp Manip'!B33 -> 16726 | AG48: =T30Manip!H34 -> 2460 | AJ48: =I48-H48-B48 -> 82849
...

Sheet T1Static
A1: Table 1. Minimum adult spring Chinook run entering the Columbia River, 1990–2025.1
A3: Year | B3: Select Areas2 | C3: Cowlitz River | D3: Kalama River | E3: Lewis River | F3: Sandy River | G3: Willamette River3 | H3: Upriver Run4 | I3: Total
A4: 1980-84 Avg. | B4: =IF(T1Manip!B9="","",T1Manip!B9) -> -- | C4: =IF(T1Manip!C9="","",T1Manip!C9) -> 22736.8 | D4: =IF(T1Manip!D9="","",T1Manip!D9) -> 4165.2 | E4: =IF(T1Manip!E9="","",T1Manip!E9) -> 3833.6 | F4: =IF(T1Manip!F9="","",T1Manip!F9) -> 2056.6 | G4: =IF(T1Manip!G9="","",T1Manip!G9) -> 62934.6 | H4: =IF(T1Manip!H9="","",T1Manip!H9) -> 63521.494 | I4: =IF(T1Manip!I9="","",T1Manip!I9) -> 159248.29
A5: 1985-89 Avg. | B5: =IF(T1Manip!B15="","",T1Manip!B15) -> -- | C5: =IF(T1Manip!C15="","",T1Manip!C15) -> 11176 | D5: =IF(T1Manip!D15="","",T1Manip!D15) -> 1551.8 | E5: =IF(T1Manip!E15="","",T1Manip!E15) -> 10311.8 | F5: =IF(T1Manip!F15="","",T1Manip!F15) -> 2004.6 | G5: =IF(T1Manip!G15="","",T1Manip!G15) -> 90803.2 | H5: =IF(T1Manip!H15="","",T1Manip!H15) -> 105500.59 | I5: =IF(T1Manip!I15="","",T1Manip!I15) -> 221347.99
A6: 1990 | B6: =IF(T1Manip!B16="","",T1Manip!B16) -> -- | C6: =IF(T1Manip!C16="","",T1Manip!C16) -> 7555 | D6: =IF(T1Manip!D16="","",T1Manip!D16) -> 1987 | E6: =IF(T1Manip!E16="","",T1Manip!E16) -> 9299 | F6: =IF(T1Manip!F16="","",T1Manip!F16) -> 3527 | G6: =IF(T1Manip!G16="","",T1Manip!G16) -> 127900 | H6: =IF(T1Manip!H16="","",T1Manip!H16) -> 105715.28 | I6: =IF(T1Manip!I16="","",T1Manip!I16) -> 255983.28
A7: 1991 | B7: =IF(T1Manip!B17="","",T1Manip!B17) -> -- | C7: =IF(T1Manip!C17="","",T1Manip!C17) -> 8945 | D7: =IF(T1Manip!D17="","",T1Manip!D17) -> 2613 | E7: =IF(T1Manip!E17="","",T1Manip!E17) -> 8334 | F7: =IF(T1Manip!F17="","",T1Manip!F17) -> 3652 | G7: =IF(T1Manip!G17="","",T1Manip!G17) -> 105530 | H7: =IF(T1Manip!H17="","",T1Manip!H17) -> 64478.652 | I7: =IF(T1Manip!I17="","",T1Manip!I17) -> 193552.65
A8: 1992 | B8: =IF(T1Manip!B18="","",T1Manip!B18) -> 211 | C8: =IF(T1Manip!C18="","",T1Manip!C18) -> 10353 | D8: =IF(T1Manip!D18="","",T1Manip!D18) -> 2430 | E8: =IF(T1Manip!E18="","",T1Manip!E18) -> 6025 | F8: =IF(T1Manip!F18="","",T1Manip!F18) -> 8551 | G8: =IF(T1Manip!G18="","",T1Manip!G18) -> 72197 | H8: =IF(T1Manip!H18="","",T1Manip!H18) -> 95691.439 | I8: =IF(T1Manip!I18="","",T1Manip!I18) -> 195458.44
A9: 1993 | B9: =IF(T1Manip!B19="","",T1Manip!B19) -> 629 | C9: =IF(T1Manip!C19="","",T1Manip!C19) -> 9458 | D9: =IF(T1Manip!D19="","",T1Manip!D19) -> 2874 | E9: =IF(T1Manip!E19="","",T1Manip!E19) -> 8195 | F9: =IF(T1Manip!F19="","",T1Manip!F19) -> 6369 | G9: =IF(T1Manip!G19="","",T1Manip!G19) -> 62778 | H9: =IF(T1Manip!H19="","",T1Manip!H19) -> 119962.96 | I9: =IF(T1Manip!I19="","",T1Manip!I19) -> 210265.96
A10: 1994 | B10: =IF(T1Manip!B20="","",T1Manip!B20) -> 126 | C10: =IF(T1Manip!C20="","",T1Manip!C20) -> 3149 | D10: =IF(T1Manip!D20="","",T1Manip!D20) -> 1265 | E10: =IF(T1Manip!E20="","",T1Manip!E20) -> 3068 | F10: =IF(T1Manip!F20="","",T1Manip!F20) -> 3498 | G10: =IF(T1Manip!G20="","",T1Manip!G20) -> 48804 | H10: =IF(T1Manip!H20="","",T1Manip!H20) -> 24095.182 | I10: =IF(T1Manip!I20="","",T1Manip!I20) -> 84005.182
A11: 1990-94 Avg. | B11: =AVERAGE(B6:B10) -> 322 | C11: =AVERAGE(C6:C10) -> 7892 | D11: =AVERAGE(D6:D10) -> 2233.8 | E11: =AVERAGE(E6:E10) -> 6984.2 | F11: =AVERAGE(F6:F10) -> 5119.4 | G11: =AVERAGE(G6:G10) -> 83441.8 | H11: =AVERAGE(H6:H10) -> 81988.704 | I11: =AVERAGE(I6:I10) -> 187853.1
A12: 1995 | B12: =IF(T1Manip!B21="","",T1Manip!B21) -> 169 | C12: =IF(T1Manip!C21="","",T1Manip!C21) -> 2102 | D12: =IF(T1Manip!D21="","",T1Manip!D21) -> 697 | E12: =IF(T1Manip!E21="","",T1Manip!E21) -> 3726 | F12: =IF(T1Manip!F21="","",T1Manip!F21) -> 2529 | G12: =IF(T1Manip!G21="","",T1Manip!G21) -> 40854 | H12: =IF(T1Manip!H21="","",T1Manip!H21) -> 12792 | I12: =IF(T1Manip!I21="","",T1Manip!I21) -> 62869
A13: 1996 | B13: =IF(T1Manip!B22="","",T1Manip!B22) -> 689 | C13: =IF(T1Manip!C22="","",T1Manip!C22) -> 1787 | D13: =IF(T1Manip!D22="","",T1Manip!D22) -> 627 | E13: =IF(T1Manip!E22="","",T1Manip!E22) -> 1730 | F13: =IF(T1Manip!F22="","",T1Manip!F22) -> 3801 | G13: =IF(T1Manip!G22="","",T1Manip!G22) -> 33358 | H13: =IF(T1Manip!H22="","",T1Manip!H22) -> 55551 | I13: =IF(T1Manip!I22="","",T1Manip!I22) -> 97543
A14: 1997 | B14: =IF(T1Manip!B23="","",T1Manip!B23) -> 1583 | C14: =IF(T1Manip!C23="","",T1Manip!C23) -> 1877 | D14: =IF(T1Manip!D23="","",T1Manip!D23) -> 505 | E14: =IF(T1Manip!E23="","",T1Manip!E23) -> 2196 | F14: =IF(T1Manip!F23="","",T1Manip!F23) -> 4410 | G14: =IF(T1Manip!G23="","",T1Manip!G23) -> 34540 | H14: =IF(T1Manip!H23="","",T1Manip!H23) -> 124321 | I14: =IF(T1Manip!I23="","",T1Manip!I23) -> 169432
A15: 1998 | B15: =IF(T1Manip!B24="","",T1Manip!B24) -> 2034 | C15: =IF(T1Manip!C24="","",T1Manip!C24) -> 1055 | D15: =IF(T1Manip!D24="","",T1Manip!D24) -> 407 | E15: =IF(T1Manip!E24="","",T1Manip!E24) -> 1611 | F15: =IF(T1Manip!F24="","",T1Manip!F24) -> 3577 | G15: =IF(T1Manip!G24="","",T1Manip!G24) -> 43497 | H15: =IF(T1Manip!H24="","",T1Manip!H24) -> 44308 | I15: =IF(T1Manip!I24="","",T1Manip!I24) -> 96489
A16: 1999 | B16: =IF(T1Manip!B25="","",T1Manip!B25) -> 1337 | C16: =IF(T1Manip!C25="","",T1Manip!C25) -> 2069 | D16: =IF(T1Manip!D25="","",T1Manip!D25) -> 977 | E16: =IF(T1Manip!E25="","",T1Manip!E25) -> 1753 | F16: =IF(T1Manip!F25="","",T1Manip!F25) -> 3585 | G16: =IF(T1Manip!G25="","",T1Manip!G25) -> 52584 | H16: =IF(T1Manip!H25="","",T1Manip!H25) -> 43067.18 | I16: =IF(T1Manip!I25="","",T1Manip!I25) -> 105372.18
A17: 1995-99 Avg. | B17: =AVERAGE(B12:B16) -> 1162.4 | C17: =AVERAGE(C12:C16) -> 1778 | D17: =AVERAGE(D12:D16) -> 642.6 | E17: =AVERAGE(E12:E16) -> 2203.2 | F17: =AVERAGE(F12:F16) -> 3580.4 | G17: =AVERAGE(G12:G16) -> 40966.6 | H17: =AVERAGE(H12:H16) -> 56007.836 | I17: =AVERAGE(I12:I16) -> 106341.04
A18: 2000 | B18: =IF(T1Manip!B26="","",T1Manip!B26) -> 5585 | C18: =IF(T1Manip!C26="","",T1Manip!C26) -> 2199 | D18: =IF(T1Manip!D26="","",T1Manip!D26) -> 1418 | E18: =IF(T1Manip!E26="","",T1Manip!E26) -> 2515 | F18: =IF(T1Manip!F26="","",T1Manip!F26) -> 3641 | G18: =IF(T1Manip!G26="","",T1Manip!G26) -> 55740 | H18: =IF(T1Manip!H26="","",T1Manip!H26) -> 186715.2 | I18: =IF(T1Manip!I26="","",T1Manip!I26) -> 257813.2
A19: 2001 | B19: =IF(T1Manip!B27="","",T1Manip!B27) -> 8089 | C19: =IF(T1Manip!C27="","",T1Manip!C27) -> 1609 | D19: =IF(T1Manip!D27="","",T1Manip!D27) -> 1796 | E19: =IF(T1Manip!E27="","",T1Manip!E27) -> 3777 | F19: =IF(T1Manip!F27="","",T1Manip!F27) -> 5329 | G19: =IF(T1Manip!G27="","",T1Manip!G27) -> 78502 | H19: =IF(T1Manip!H27="","",T1Manip!H27) -> 439885 | I19: =IF(T1Manip!I27="","",T1Manip!I27) -> 538987
A20: 2002 | B20: =IF(T1Manip!B28="","",T1Manip!B28) -> 8661 | C20: =IF(T1Manip!C28="","",T1Manip!C28) -> 5129 | D20: =IF(T1Manip!D28="","",T1Manip!D28) -> 2912 | E20: =IF(T1Manip!E28="","",T1Manip!E28) -> 3514 | F20: =IF(T1Manip!F28="","",T1Manip!F28) -> 5905 | G20: =IF(T1Manip!G28="","",T1Manip!G28) -> 120161 | H20: =IF(T1Manip!H28="","",T1Manip!H28) -> 335306 | I20: =IF(T1Manip!I28="","",T1Manip!I28) -> 481588
A21: 2003 | B21: =IF(T1Manip!B29="","",T1Manip!B29) -> 6827 | C21: =IF(T1Manip!C29="","",T1Manip!C29) -> 15954 | D21: =IF(T1Manip!D29="","",T1Manip!D29) -> 4556 | E21: =IF(T1Manip!E29="","",T1Manip!E29) -> 5040 | F21: =IF(T1Manip!F29="","",T1Manip!F29) -> 5472 | G21: =IF(T1Manip!G29="","",T1Manip!G29) -> 123355 | H21: =IF(T1Manip!H29="","",T1Manip!H29) -> 242605.3 | I21: =IF(T1Manip!I29="","",T1Manip!I29) -> 403809.3
A22: 2004 | B22: =IF(T1Manip!B30="","",T1Manip!B30) -> 10162 | C22: =IF(T1Manip!C30="","",T1Manip!C30) -> 16530 | D22: =IF(T1Manip!D30="","",T1Manip!D30) -> 4286 | E22: =IF(T1Manip!E30="","",T1Manip!E30) -> 7475 | F22: =IF(T1Manip!F30="","",T1Manip!F30) -> 12680 | G22: =IF(T1Manip!G30="","",T1Manip!G30) -> 143240 | H22: =IF(T1Manip!H30="","",T1Manip!H30) -> 221675.28 | I22: =IF(T1Manip!I30="","",T1Manip!I30) -> 416048.28
A23: 2000-04 Avg. | B23: =AVERAGE(B18:B22) -> 7864.8 | C23: =AVERAGE(C18:C22) -> 8284.2 | D23: =AVERAGE(D18:D22) -> 2993.6 | E23: =AVERAGE(E18:E22) -> 4464.2 | F23: =AVERAGE(F18:F22) -> 6605.4 | G23: =AVERAGE(G18:G22) -> 104199.6 | H23: =AVERAGE(H18:H22) -> 285237.36 | I23: =AVERAGE(I18:I22) -> 419649.16
A24: 2005 | B24: =IF(T1Manip!B31="","",T1Manip!B31) -> 2366 | C24: =IF(T1Manip!C31="","",T1Manip!C31) -> 9398 | D24: =IF(T1Manip!D31="","",T1Manip!D31) -> 3367 | E24: =IF(T1Manip!E31="","",T1Manip!E31) -> 3512 | F24: =IF(T1Manip!F31="","",T1Manip!F31) -> 7665 | G24: =IF(T1Manip!G31="","",T1Manip!G31) -> 59471 | H24: =IF(T1Manip!H31="","",T1Manip!H31) -> 106909.65 | I24: =IF(T1Manip!I31="","",T1Manip!I31) -> 192688.65
A25: 2006 | B25: =IF(T1Manip!B32="","",T1Manip!B32) -> 6998 | C25: =IF(T1Manip!C32="","",T1Manip!C32) -> 7001 | D25: =IF(T1Manip!D32="","",T1Manip!D32) -> 5458 | E25: =IF(T1Manip!E32="","",T1Manip!E32) -> 7301 | F25: =IF(T1Manip!F32="","",T1Manip!F32) -> 4382 | G25: =IF(T1Manip!G32="","",T1Manip!G32) -> 59311 | H25: =IF(T1Manip!H32="","",T1Manip!H32) -> 132583.34 | I25: =IF(T1Manip!I32="","",T1Manip!I32) -> 223034.34
A26: 2007 | B26: =IF(T1Manip!B33="","",T1Manip!B33) -> 6356 | C26: =IF(T1Manip!C33="","",T1Manip!C33) -> 3961 | D26: =IF(T1Manip!D33="","",T1Manip!D33) -> 8030 | E26: =IF(T1Manip!E33="","",T1Manip!E33) -> 7596 | F26: =IF(T1Manip!F33="","",T1Manip!F33) -> 2841 | G26: =IF(T1Manip!G33="","",T1Manip!G33) -> 39963 | H26: =IF(T1Manip!H33="","",T1Manip!H33) -> 86246.565 | I26: =IF(T1Manip!I33="","",T1Manip!I33) -> 154993.57
A27: 2008 | B27: =IF(T1Manip!B34="","",T1Manip!B34) -> 3289 | C27: =IF(T1Manip!C34="","",T1Manip!C34) -> 2978 | D27: =IF(T1Manip!D34="","",T1Manip!D34) -> 1623 | E27: =IF(T1Manip!E34="","",T1Manip!E34) -> 2215 | F27: =IF(T1Manip!F34="","",T1Manip!F34) -> 5848 | G27: =IF(T1Manip!G34="","",T1Manip!G34) -> 26615 | H27: =IF(T1Manip!H34="","",T1Manip!H34) -> 178626.96 | I27: =IF(T1Manip!I34="","",T1Manip!I34) -> 221194.96
A28: 2009 | B28: =IF(T1Manip!B35="","",T1Manip!B35) -> 2830 | C28: =IF(T1Manip!C35="","",T1Manip!C35) -> 6054 | D28: =IF(T1Manip!D35="","",T1Manip!D35) -> 404 | E28: =IF(T1Manip!E35="","",T1Manip!E35) -> 1493 | F28: =IF(T1Manip!F35="","",T1Manip!F35) -> 2347 | G28: =IF(T1Manip!G35="","",T1Manip!G35) -> 35432 | H28: =IF(T1Manip!H35="","",T1Manip!H35) -> 169295.9 | I28: =IF(T1Manip!I35="","",T1Manip!I35) -> 217855.9
A29: 2005-09 Avg. | B29: =AVERAGE(B24:B28) -> 4367.8 | C29: =AVERAGE(C24:C28) -> 5878.4 | D29: =AVERAGE(D24:D28) -> 3776.4 | E29: =AVERAGE(E24:E28) -> 4423.4 | F29: =AVERAGE(F24:F28) -> 4616.6 | G29: =AVERAGE(G24:G28) -> 44158.4 | H29: =AVERAGE(H24:H28) -> 134732.48 | I29: =AVERAGE(I24:I28) -> 201953.48
A30: 2010 | B30: =IF(T1Manip!B36="","",T1Manip!B36) -> 22955 | C30: =IF(T1Manip!C36="","",T1Manip!C36) -> 8615 | D30: =IF(T1Manip!D36="","",T1Manip!D36) -> 977 | E30: =IF(T1Manip!E36="","",T1Manip!E36) -> 2347 | F30: =IF(T1Manip!F36="","",T1Manip!F36) -> 7343 | G30: =IF(T1Manip!G36="","",T1Manip!G36) -> 107675 | H30: =IF(T1Manip!H36="","",T1Manip!H36) -> 315345.82 | I30: =IF(T1Manip!I36="","",T1Manip!I36) -> 465257.82
A31: 2011 | B31: =IF(T1Manip!B37="","",T1Manip!B37) -> 8850 | C31: =IF(T1Manip!C37="","",T1Manip!C37) -> 5379 | D31: =IF(T1Manip!D37="","",T1Manip!D37) -> 776 | E31: =IF(T1Manip!E37="","",T1Manip!E37) -> 1310 | F31: =IF(T1Manip!F37="","",T1Manip!F37) -> 4702 | G31: =IF(T1Manip!G37="","",T1Manip!G37) -> 76549 | H31: =IF(T1Manip!H37="","",T1Manip!H37) -> 221157.83 | I31: =IF(T1Manip!I37="","",T1Manip!I37) -> 318723.83
A32: 2012 | B32: =IF(T1Manip!B38="","",T1Manip!B38) -> 8984 | C32: =IF(T1Manip!C38="","",T1Manip!C38) -> 12212.852 | D32: =IF(T1Manip!D38="","",T1Manip!D38) -> 889.0263 | E32: =IF(T1Manip!E38="","",T1Manip!E38) -> 1895 | F32: =IF(T1Manip!F38="","",T1Manip!F38) -> 4568 | G32: =IF(T1Manip!G38="","",T1Manip!G38) -> 63037 | H32: =IF(T1Manip!H38="","",T1Manip!H38) -> 203089.6 | I32: =IF(T1Manip!I38="","",T1Manip!I38) -> 294675.48
A33: 2013 | B33: =IF(T1Manip!B39="","",T1Manip!B39) -> 5383 | C33: =IF(T1Manip!C39="","",T1Manip!C39) -> 8132 | D33: =IF(T1Manip!D39="","",T1Manip!D39) -> 1014 | E33: =IF(T1Manip!E39="","",T1Manip!E39) -> 1570 | F33: =IF(T1Manip!F39="","",T1Manip!F39) -> 3723 | G33: =IF(T1Manip!G39="","",T1Manip!G39) -> 44880 | H33: =IF(T1Manip!H39="","",T1Manip!H39) -> 123136.15 | I33: =IF(T1Manip!I39="","",T1Manip!I39) -> 187838.15
A34: 2014 | B34: =IF(T1Manip!B40="","",T1Manip!B40) -> 2479 | C34: =IF(T1Manip!C40="","",T1Manip!C40) -> 8294 | D34: =IF(T1Manip!D40="","",T1Manip!D40) -> 1013 | E34: =IF(T1Manip!E40="","",T1Manip!E40) -> 1396 | F34: =IF(T1Manip!F40="","",T1Manip!F40) -> 3106 | G34: =IF(T1Manip!G40="","",T1Manip!G40) -> 49765 | H34: =IF(T1Manip!H40="","",T1Manip!H40) -> 242634.83 | I34: =IF(T1Manip!I40="","",T1Manip!I40) -> 308687.83
A35: 2010-14 Avg. | B35: =AVERAGE(B30:B34) -> 9730.2 | C35: =AVERAGE(C30:C34) -> 8526.5704 | D35: =AVERAGE(D30:D34) -> 933.80526 | E35: =AVERAGE(E30:E34) -> 1703.6 | F35: =AVERAGE(F30:F34) -> 4688.4 | G35: =AVERAGE(G30:G34) -> 68381.2 | H35: =AVERAGE(H30:H34) -> 221072.85 | I35: =AVERAGE(I30:I34) -> 315036.62
A36: 2015 | B36: =IF(T1Manip!B41="","",T1Manip!B41) -> 13562 | C36: =IF(T1Manip!C41="","",T1Manip!C41) -> 26504 | D36: =IF(T1Manip!D41="","",T1Manip!D41) -> 3237 | E36: =IF(T1Manip!E41="","",T1Manip!E41) -> 1108 | F36: =IF(T1Manip!F41="","",T1Manip!F41) -> 3474 | G36: =IF(T1Manip!G41="","",T1Manip!G41) -> 84532 | H36: =IF(T1Manip!H41="","",T1Manip!H41) -> 288993 | I36: =IF(T1Manip!I41="","",T1Manip!I41) -> 421410
A37: 2016 | B37: =IF(T1Manip!B42="","",T1Manip!B42) -> 9920 | C37: =IF(T1Manip!C42="","",T1Manip!C42) -> 24554 | D37: =IF(T1Manip!D42="","",T1Manip!D42) -> 4462 | E37: =IF(T1Manip!E42="","",T1Manip!E42) -> 597 | F37: =IF(T1Manip!F42="","",T1Manip!F42) -> 3964 | G37: =IF(T1Manip!G42="","",T1Manip!G42) -> 47225 | H37: =IF(T1Manip!H42="","",T1Manip!H42) -> 187815.8 | I37: =IF(T1Manip!I42="","",T1Manip!I42) -> 278537.8
A38: 2017 | B38: =IF(T1Manip!B43="","",T1Manip!B43) -> 16818 | C38: =IF(T1Manip!C43="","",T1Manip!C43) -> 14618 | D38: =IF(T1Manip!D43="","",T1Manip!D43) -> 3505 | E38: =IF(T1Manip!E43="","",T1Manip!E43) -> 2338 | F38: =IF(T1Manip!F43="","",T1Manip!F43) -> 7607 | G38: =IF(T1Manip!G43="","",T1Manip!G43) -> 50774 | H38: =IF(T1Manip!H43="","",T1Manip!H43) -> 115820.9 | I38: =IF(T1Manip!I43="","",T1Manip!I43) -> 211480.9
A39: 2018 | B39: =IF(T1Manip!B44="","",T1Manip!B44) -> 10569 | C39: =IF(T1Manip!C44="","",T1Manip!C44) -> 4196 | D39: =IF(T1Manip!D44="","",T1Manip!D44) -> 1889 | E39: =IF(T1Manip!E44="","",T1Manip!E44) -> 3138 | F39: =IF(T1Manip!F44="","",T1Manip!F44) -> 4838 | G39: =IF(T1Manip!G44="","",T1Manip!G44) -> 37441 | H39: =IF(T1Manip!H44="","",T1Manip!H44) -> 115080.8 | I39: =IF(T1Manip!I44="","",T1Manip!I44) -> 177151.8
A40: 2019 | B40: =IF(T1Manip!B45="","",T1Manip!B45) -> 2717 | C40: =IF(T1Manip!C45="","",T1Manip!C45) -> 1573 | D40: =IF(T1Manip!D45="","",T1Manip!D45) -> 809 | E40: =IF(T1Manip!E45="","",T1Manip!E45) -> 997 | F40: =IF(T1Manip!F45="","",T1Manip!F45) -> 3424 | G40: =IF(T1Manip!G45="","",T1Manip!G45) -> 27292 | H40: =IF(T1Manip!H45="","",T1Manip!H45) -> 73105 | I40: =IF(T1Manip!I45="","",T1Manip!I45) -> 109917
A41: 2015-19 Avg. | B41: =AVERAGE(B36:B40) -> 10717.2 | C41: =AVERAGE(C36:C40) -> 14289 | D41: =AVERAGE(D36:D40) -> 2780.4 | E41: =AVERAGE(E36:E40) -> 1635.6 | F41: =AVERAGE(F36:F40) -> 4661.4 | G41: =AVERAGE(G36:G40) -> 49452.8 | H41: =AVERAGE(H36:H40) -> 156163.1 | I41: =AVERAGE(I36:I40) -> 239699.5
...

Sheet T2Manip
A1: Table 2. Predicted and Actual Spring Chinook Entering the Columbia River, and Projections.
B2: Willamette River (All Age Classes) | E2: Sandy River (Adults) | H2: Cowlitz, Kalama, & Lewis Rivers Combined (Adults) | K2: Upriver (Adults)
A3: Year | B3: PreseasonForecast | C3: Actual Return | D3: PercOfPredicted | E3: PreseasonForecast | F3: Actual Return | G3: PercOfPredicted | H3: Preseason Forecast | I3: Actual Return | J3: PercOfPredicted | K3: Preseason Forecast | L3: Actual Return | M3: PercOfPredicted
A4: 1985 | B4: =70*1000 -> 70000 | C4: 68090 | D4: =C4/B4*100 -> 97.271429 | E4: — | F4: =T1Manip!F10 -> 1449 | G4: — | H4: — | I4: 14400 | J4: — | K4: 52600 | L4: =84.7*1000 -> 84700 | M4: =L4/K4*100 -> 161.02662
A5: 1986 | B5: =65*1000 -> 65000 | C5: 73552 | D5: =C5/B5*100 -> 113.15692 | E5: — | F5: =T1Manip!F11 -> 1286 | G5: — | H5: — | I5: 16700 | J5: — | K5: 115000 | L5: =120.6*1000 -> 120600 | M5: =L5/K5*100 -> 104.86957
A6: 1987 | B6: =78*1000 -> 78000 | C6: 93593 | D6: =C6/B6*100 -> 119.99103 | E6: — | F6: =T1Manip!F12 -> 2353 | G6: — | H6: — | I6: 37000 | J6: — | K6: 79700 | L6: =99.8*1000 -> 99800 | M6: =L6/K6*100 -> 125.21957
A7: 1988 | B7: =97*1000 -> 97000 | C7: 118112 | D7: =C7/B7*100 -> 121.76495 | E7: — | F7: =T1Manip!F13 -> 2931 | G7: — | H7: 32000 | I7: 24900 | J7: =I7/H7*100 -> 77.8125 | K7: 53400 | L7: =97*1000 -> 97000 | M7: =L7/K7*100 -> 181.64794
A8: 1989 | B8: =102*1000 -> 102000 | C8: 114929 | D8: =C8/B8*100 -> 112.67549 | E8: — | F8: =T1Manip!F14 -> 2004 | G8: — | H8: 16100 | I8: 22300 | J8: =I8/H8*100 -> 138.50932 | K8: 92700 | L8: =82.6*1000 -> 82600 | M8: =L8/K8*100 -> 89.104639
A9: 1990 | B9: =128*1000 -> 128000 | C9: 130588 | D9: =C9/B9*100 -> 102.02187 | E9: — | F9: =T1Manip!F16 -> 3527 | G9: — | H9: 18600 | I9: =T1Manip!C16+T1Manip!D16+T1Manip!E16 -> 18841 | J9: =I9/H9*100 -> 101.2957 | K9: 120800 | L9: =99.1*1000 -> 99100 | M9: =L9/K9*100 -> 82.036424
A10: 1991 | B10: =110*1000 -> 110000 | C10: 109929 | D10: =C10/B10*100 -> 99.935455 | E10: — | F10: =T1Manip!F17 -> 3652 | G10: — | H10: 19700 | I10: =T1Manip!C17+T1Manip!D17+T1Manip!E17 -> 19892 | J10: =I10/H10*100 -> 100.97462 | K10: 61900 | L10: =59.2*1000 -> 59200 | M10: =L10/K10*100 -> 95.638126
A11: 1992 | B11: =106*1000 -> 106000 | C11: 75008 | D11: =C11/B11*100 -> 70.762264 | E11: — | F11: =T1Manip!F18 -> 8551 | G11: — | H11: 26600 | I11: =T1Manip!C18+T1Manip!D18+T1Manip!E18 -> 18808 | J11: =I11/H11*100 -> 70.706767 | K11: 71400 | L11: =89.8*1000 -> 89800 | M11: =L11/K11*100 -> 125.77031
A12: 1993 | B12: =70*1000 -> 70000 | C12: 65934 | D12: =C12/B12*100 -> 94.191429 | E12: — | F12: =T1Manip!F19 -> 6369 | G12: — | H12: 21300 | I12: =T1Manip!C19+T1Manip!D19+T1Manip!E19 -> 20527 | J12: =I12/H12*100 -> 96.370892 | K12: 76200 | L12: =111*1000 -> 111000 | M12: =L12/K12*100 -> 145.66929
A13: 1994 | B13: =75*1000 -> 75000 | C13: 49580 | D13: =C13/B13*100 -> 66.106667 | E13: — | F13: =T1Manip!F20 -> 3498 | G13: — | H13: 12300 | I13: =T1Manip!C20+T1Manip!D20+T1Manip!E20 -> 7482 | J13: =I13/H13*100 -> 60.829268 | K13: 49000 | L13: =20.8*1000 -> 20800 | M13: =L13/K13*100 -> 42.44898
A14: 1995 | B14: =49*1000 -> 49000 | C14: 42563 | D14: =C14/B14*100 -> 86.863265 | E14: — | F14: =T1Manip!F21 -> 2529 | G14: — | H14: 4600 | I14: =T1Manip!C21+T1Manip!D21+T1Manip!E21 -> 6525 | J14: =I14/H14*100 -> 141.84783 | K14: 12000 | L14: =9.8*1000 -> 9800 | M14: =L14/K14*100 -> 81.666667
A15: 1996 | B15: =41*1000 -> 41000 | C15: 34765 | D15: =C15/B15*100 -> 84.792683 | E15: — | F15: =T1Manip!F22 -> 3801 | G15: — | H15: 4400 | I15: =T1Manip!C22+T1Manip!D22+T1Manip!E22 -> 4144 | J15: =I15/H15*100 -> 94.181818 | K15: 37200 | L15: =51.5*1000 -> 51500 | M15: =L15/K15*100 -> 138.44086
A16: 1997 | B16: =30*1000 -> 30000 | C16: 35303 | D16: =C16/B16*100 -> 117.67667 | E16: — | F16: =T1Manip!F23 -> 4410 | G16: — | H16: 4500 | I16: =T1Manip!C23+T1Manip!D23+T1Manip!E23 -> 4578 | J16: =I16/H16*100 -> 101.73333 | K16: 67800 | L16: =114*1000 -> 114000 | M16: =L16/K16*100 -> 168.14159
A17: 1998 | B17: =33.7*1000 -> 33700 | C17: 45139 | D17: =C17/B17*100 -> 133.94362 | E17: — | F17: =T1Manip!F24 -> 3577 | G17: — | H17: 2900 | I17: =T1Manip!C24+T1Manip!D24+T1Manip!E24 -> 3073 | J17: =I17/H17*100 -> 105.96552 | K17: 36200 | L17: =38.3*1000 -> 38300 | M17: =L17/K17*100 -> 105.8011
A18: 1999 | B18: 46500 | C18: 54202 | D18: =C18/B18*100 -> 116.56344 | E18: 4300 | F18: =T1Manip!F25 -> 3585 | G18: =F18/E18*100 -> 83.372093 | H18: 3900 | I18: =T1Manip!C25+T1Manip!D25+T1Manip!E25 -> 4799 | J18: =I18/H18*100 -> 123.05128 | K18: 24600 | L18: =38.7*1000 -> 38700 | M18: =L18/K18*100 -> 157.31707
A19: 2000 | B19: 59900 | C19: 57454 | D19: =C19/B19*100 -> 95.916528 | E19: 3800 | F19: =T1Manip!F26 -> 3641 | G19: =F19/E19*100 -> 95.815789 | H19: 6000 | I19: =T1Manip!C26+T1Manip!D26+T1Manip!E26 -> 6132 | J19: =I19/H19*100 -> 102.2 | K19: 134000 | L19: =178.6*1000 -> 178600 | M19: =L19/K19*100 -> 133.28358
A20: 2001 | B20: 61000 | C20: 80366 | D20: =C20/B20*100 -> 131.74754 | E20: 4000 | F20: =T1Manip!F27 -> 5329 | G20: =F20/E20*100 -> 133.225 | H20: 4800 | I20: =T1Manip!C27+T1Manip!D27+T1Manip!E27 -> 7182 | J20: =I20/H20*100 -> 149.625 | K20: 364600 | L20: =416.5*1000 -> 416500 | M20: =L20/K20*100 -> 114.23478
A21: 2002 | B21: 73800 | C21: 121711 | D21: =C21/B21*100 -> 164.92005 | E21: 4300 | F21: =T1Manip!F28 -> 5905 | G21: =F21/E21*100 -> 137.32558 | H21: 6700 | I21: =T1Manip!C28+T1Manip!D28+T1Manip!E28 -> 11555 | J21: =I21/H21*100 -> 172.46269 | K21: 333700 | L21: =295.1*1000 -> 295100 | M21: =L21/K21*100 -> 88.432724
A22: 2003 | B22: 109800 | C22: 126580 | D22: =C22/B22*100 -> 115.28233 | E22: 4800 | F22: =T1Manip!F29 -> 5472 | G22: =F22/E22*100 -> 114 | H22: 11600 | I22: =T1Manip!C29+T1Manip!D29+T1Manip!E29 -> 25550 | J22: =I22/H22*100 -> 220.25862 | K22: 145400 | L22: =208.9*1000 -> 208900 | M22: =L22/K22*100 -> 143.67263
A23: 2004 | B23: 109400 | C23: 144448 | D23: =C23/B23*100 -> 132.03656 | E23: 5200 | F23: =T1Manip!F30 -> 12680 | G23: =F23/E23*100 -> 243.84615 | H23: 27300 | I23: =T1Manip!C30+T1Manip!D30+T1Manip!E30 -> 28291 | J23: =I23/H23*100 -> 103.63004 | K23: 360700 | L23: =193.4*1000 -> 193400 | M23: =L23/K23*100 -> 53.617965
A24: 2005 | B24: 116900 | C24: 60976 | D24: =C24/B24*100 -> 52.160821 | E24: 7400 | F24: =T1Manip!F31 -> 7665 | G24: =F24/E24*100 -> 103.58108 | H24: 24800 | I24: =T1Manip!C31+T1Manip!D31+T1Manip!E31 -> 16277 | J24: =I24/H24*100 -> 65.633065 | K24: 254100 | L24: =T1Manip!H31 -> 106909.65 | M24: =L24/K24*100 -> 42.073851
A25: 2006 | B25: 46500 | C25: 59662 | D25: =C25/B25*100 -> 128.30538 | E25: 8200 | F25: =T1Manip!F32 -> 4382 | G25: =F25/E25*100 -> 53.439024 | H25: 15200 | I25: =T1Manip!C32+T1Manip!D32+T1Manip!E32 -> 19760 | J25: =I25/H25*100 -> 130 | K25: 88400 | L25: =T1Manip!H32 -> 132583.34 | M25: =L25/K25*100 -> 149.98115
A26: 2007 | B26: 52000 | C26: 40489 | D26: =C26/B26*100 -> 77.863462 | E26: 7900 | F26: =T1Manip!F33 -> 2841 | G26: =F26/E26*100 -> 35.962025 | H26: 15900 | I26: =T1Manip!C33+T1Manip!D33+T1Manip!E33 -> 19587 | J26: =I26/H26*100 -> 123.18868 | K26: 78500 | L26: =T1Manip!H33 -> 86246.565 | M26: =L26/K26*100 -> 109.86824
A27: 2008 | B27: 34050 | C27: 27356 | D27: =C27/B27*100 -> 80.340675 | E27: 6800 | F27: =T1Manip!F34 -> 5848 | G27: =F27/E27*100 -> 86 | H27: 12400 | I27: =T1Manip!C34+T1Manip!D34+T1Manip!E34 -> 6816 | J27: =I27/H27*100 -> 54.967742 | K27: 269300 | L27: =T1Manip!H34 -> 178626.96 | M27: =L27/K27*100 -> 66.330099
A28: 2009 | B28: 37614 | C28: 39410 | D28: =C28/B28*100 -> 104.77482 | E28: 5200 | F28: =T1Manip!F35 -> 2347 | G28: =F28/E28*100 -> 45.134615 | H28: 7200 | I28: =T1Manip!C35+T1Manip!D35+T1Manip!E35 -> 7951 | J28: =I28/H28*100 -> 110.43056 | K28: 298900 | L28: =T1Manip!H35 -> 169295.9 | M28: =L28/K28*100 -> 56.639645
A29: 2010 | B29: 62662 | C29: 110536 | D29: =C29/B29*100 -> 176.40037 | E29: 3700 | F29: =T1Manip!F36 -> 7343 | G29: =F29/E29*100 -> 198.45946 | H29: 19400 | I29: =T1Manip!C36+T1Manip!D36+T1Manip!E36 -> 11939 | J29: =I29/H29*100 -> 61.541237 | K29: 470000 | L29: =T1Manip!H36 -> 315345.82 | M29: =L29/K29*100 -> 67.094856
A30: 2011 | B30: 104067 | C30: 80254 | D30: =C30/B30*100 -> 77.117626 | E30: 5500 | F30: =T1Manip!F37 -> 4702 | G30: =F30/E30*100 -> 85.490909 | H30: 10600 | I30: =T1Manip!C37+T1Manip!D37+T1Manip!E37 -> 7465 | J30: =I30/H30*100 -> 70.424528 | K30: 198400 | L30: =T1Manip!H37 -> 221157.83 | M30: =L30/K30*100 -> 111.47068
A31: 2012 | B31: 83402 | C31: 65115 | D31: =C31/B31*100 -> 78.073667 | E31: 4800 | F31: =T1Manip!F38 -> 4568 | G31: =F31/E31*100 -> 95.166667 | H31: 12100 | I31: =T1Manip!C38+T1Manip!D38+T1Manip!E38 -> 14996.878 | J31: =I31/H31*100 -> 123.94114 | K31: 314200 | L31: =T1Manip!H38 -> 203089.6 | M31: =L31/K31*100 -> 64.637046
A32: 2013 | B32: 59845 | C32: 47311 | D32: =C32/B32*100 -> 79.055894 | E32: 6100 | F32: =T1Manip!F39 -> 3723 | G32: =F32/E32*100 -> 61.032787 | H32: 7800 | I32: =T1Manip!C39+T1Manip!D39+T1Manip!E39 -> 10716 | J32: =I32/H32*100 -> 137.38462 | K32: 141400 | L32: =T1Manip!H39 -> 123136.15 | M32: =L32/K32*100 -> 87.083554
A33: 2014 | B33: 58690 | C33: 51794 | D33: =C33/B33*100 -> 88.250128 | E33: 5500 | F33: =T1Manip!F40 -> 3106 | G33: =F33/E33*100 -> 56.472727 | H33: 13800 | I33: =T1Manip!C40+T1Manip!D40+T1Manip!E40 -> 10703 | J33: =I33/H33*100 -> 77.557971 | K33: 227000 | L33: =T1Manip!H40 -> 242634.83 | M33: =L33/K33*100 -> 106.88759
A34: 2015 | B34: 55440 | C34: 87071 | D34: =C34/B34*100 -> 157.05447 | E34: 5500 | F34: =T1Manip!F41 -> 3474 | G34: =F34/E34*100 -> 63.163636 | H34: 14200 | I34: =T1Manip!C41+T1Manip!D41+T1Manip!E41 -> 30849 | J34: =I34/H34*100 -> 217.24648 | K34: 232500 | L34: =T1Manip!H41 -> 288993 | M34: =L34/K34*100 -> 124.29806
A35: 2016 | B35: 70100 | C35: 49768 | D35: =C35/B35*100 -> 70.99572 | E35: — | F35: =T1Manip!F42 -> 3964 | G35: — | H35: 31100 | I35: =T1Manip!C42+T1Manip!D42+T1Manip!E42 -> 29613 | J35: =I35/H35*100 -> 95.21865 | K35: 188800 | L35: =T1Manip!H42 -> 187815.8 | M35: =L35/K35*100 -> 99.478706
A36: 2017 | B36: 40190 | C36: 53653 | D36: =C36/B36*100 -> 133.49838 | E36: 3600 | F36: =T1Manip!F43 -> 7607 | G36: =F36/E36*100 -> 211.30556 | H36: 20900 | I36: =T1Manip!C43+T1Manip!D43+T1Manip!E43 -> 20461 | J36: =I36/H36*100 -> 97.899522 | K36: 160400 | L36: =T1Manip!H43 -> 115820.9 | M36: =L36/K36*100 -> 72.207544
A37: 2018 | B37: 55950 | C37: 39660 | D37: =C37/B37*100 -> 70.884718 | E37: 5400 | F37: =T1Manip!F44 -> 4838 | G37: =F37/E37*100 -> 89.592593 | H37: =5150+1450+3700 -> 10300 | I37: =T1Manip!C44+T1Manip!D44+T1Manip!E44 -> 9223 | J37: =I37/H37*100 -> 89.543689 | K37: 166700 | L37: =T1Manip!H44 -> 115080.8 | M37: =L37/K37*100 -> 69.034673
A38: 2019 | B38: 42490 | C38: 29314 | D38: =C38/B38*100 -> 68.990351 | E38: 5500 | F38: =T1Manip!F45 -> 3424 | G38: =F38/E38*100 -> 62.254545 | H38: =1300+1400+1600 -> 4300 | I38: =T1Manip!C45+T1Manip!D45+T1Manip!E45 -> 3379 | J38: =I38/H38*100 -> 78.581395 | K38: 99300 | L38: =T1Manip!H45 -> 73105 | M38: =L38/K38*100 -> 73.620342
A39: 2020 | B39: 43430 | C39: 47327 | D39: =C39/B39*100 -> 108.97306 | E39: 5200 | F39: =T1Manip!F46 -> 7782 | G39: =F39/E39*100 -> 149.65385 | H39: 3840 | I39: =T1Manip!C46+T1Manip!D46+T1Manip!E46 -> 3966 | J39: =I39/H39*100 -> 103.28125 | K39: 81700 | L39: =T1Manip!H46 -> 81301 | M39: =L39/K39*100 -> 99.511628
A40: 2021 | B40: 52400 | C40: 43148 | D40: =C40/B40*100 -> 82.343511 | E40: 5300 | F40: =T1Manip!F47 -> 5676 | G40: =F40/E40*100 -> 107.09434 | H40: =1800+2200+2400 -> 6400 | I40: =T1Manip!C47+T1Manip!D47+T1Manip!E47 -> 8495 | J40: =I40/H40*100 -> 132.73438 | K40: 75200 | L40: =T1Manip!H47 -> 91756 | M40: =L40/K40*100 -> 122.01596
...

Sheet T2Static
A1: Table 2. Forecasted and actual abundance of spring Chinook entering the Columbia River, 1985–2025 and 2026 forecasts.
B3: Willamette River (All Age Classes) | F3: Sandy River (Adults) | J3: Cowlitz, Kalama, & Lewis Rivers Combined (Adults)1 | N3: Upriver (Adults)2
A5: Year | B5: Preseason Forecast | C5: Actual Return | D5: % of Forecast | F5: Preseason Forecast | G5: Actual Return | H5: % of Forecast | J5: Preseason Forecast | K5: Actual Return | L5: % of Forecast | N5: Preseason Forecast | O5: Actual Return | P5: % of Forecast
A8: 1985 | B8: =IF(T2Manip!B4="","",T2Manip!B4/1000) -> 70 | C8: =IF(T2Manip!C4="","",T2Manip!C4/1000) -> 68.09 | D8: =IF(T2Manip!D4="","",T2Manip!D4) -> 97.271429 | F8: =IF(T2Manip!E4="","",T2Manip!E4) -> — | G8: =IF(T2Manip!F4="","",T2Manip!F4/1000) -> 1.449 | H8: =IF(T2Manip!G4="","",T2Manip!G4) -> — | J8: =IF(T2Manip!H4="","",T2Manip!H4) -> — | K8: =IF(T2Manip!I4="","",T2Manip!I4/1000) -> 14.4 | L8: =IF(T2Manip!J4="","",T2Manip!J4) -> — | N8: =IF(T2Manip!K4="","",T2Manip!K4/1000) -> 52.6 | O8: =IF(T2Manip!L4="","",T2Manip!L4/1000) -> 84.7 | P8: =IF(T2Manip!M4="","",T2Manip!M4) -> 161.02662
A9: 1986 | B9: =IF(T2Manip!B5="","",T2Manip!B5/1000) -> 65 | C9: =IF(T2Manip!C5="","",T2Manip!C5/1000) -> 73.552 | D9: =IF(T2Manip!D5="","",T2Manip!D5) -> 113.15692 | F9: =IF(T2Manip!E5="","",T2Manip!E5) -> — | G9: =IF(T2Manip!F5="","",T2Manip!F5/1000) -> 1.286 | H9: =IF(T2Manip!G5="","",T2Manip!G5) -> — | J9: =IF(T2Manip!H5="","",T2Manip!H5) -> — | K9: =IF(T2Manip!I5="","",T2Manip!I5/1000) -> 16.7 | L9: =IF(T2Manip!J5="","",T2Manip!J5) -> — | N9: =IF(T2Manip!K5="","",T2Manip!K5/1000) -> 115 | O9: =IF(T2Manip!L5="","",T2Manip!L5/1000) -> 120.6 | P9: =IF(T2Manip!M5="","",T2Manip!M5) -> 104.86957
A10: 1987 | B10: =IF(T2Manip!B6="","",T2Manip!B6/1000) -> 78 | C10: =IF(T2Manip!C6="","",T2Manip!C6/1000) -> 93.593 | D10: =IF(T2Manip!D6="","",T2Manip!D6) -> 119.99103 | F10: =IF(T2Manip!E6="","",T2Manip!E6) -> — | G10: =IF(T2Manip!F6="","",T2Manip!F6/1000) -> 2.353 | H10: =IF(T2Manip!G6="","",T2Manip!G6) -> — | J10: =IF(T2Manip!H6="","",T2Manip!H6) -> — | K10: =IF(T2Manip!I6="","",T2Manip!I6/1000) -> 37 | L10: =IF(T2Manip!J6="","",T2Manip!J6) -> — | N10: =IF(T2Manip!K6="","",T2Manip!K6/1000) -> 79.7 | O10: =IF(T2Manip!L6="","",T2Manip!L6/1000) -> 99.8 | P10: =IF(T2Manip!M6="","",T2Manip!M6) -> 125.21957
A11: 1988 | B11: =IF(T2Manip!B7="","",T2Manip!B7/1000) -> 97 | C11: =IF(T2Manip!C7="","",T2Manip!C7/1000) -> 118.112 | D11: =IF(T2Manip!D7="","",T2Manip!D7) -> 121.76495 | F11: =IF(T2Manip!E7="","",T2Manip!E7) -> — | G11: =IF(T2Manip!F7="","",T2Manip!F7/1000) -> 2.931 | H11: =IF(T2Manip!G7="","",T2Manip!G7) -> — | J11: =IF(T2Manip!H7="","",T2Manip!H7/1000) -> 32 | K11: =IF(T2Manip!I7="","",T2Manip!I7/1000) -> 24.9 | L11: =IF(T2Manip!J7="","",T2Manip!J7) -> 77.8125 | N11: =IF(T2Manip!K7="","",T2Manip!K7/1000) -> 53.4 | O11: =IF(T2Manip!L7="","",T2Manip!L7/1000) -> 97 | P11: =IF(T2Manip!M7="","",T2Manip!M7) -> 181.64794
A12: 1989 | B12: =IF(T2Manip!B8="","",T2Manip!B8/1000) -> 102 | C12: =IF(T2Manip!C8="","",T2Manip!C8/1000) -> 114.929 | D12: =IF(T2Manip!D8="","",T2Manip!D8) -> 112.67549 | F12: =IF(T2Manip!E8="","",T2Manip!E8) -> — | G12: =IF(T2Manip!F8="","",T2Manip!F8/1000) -> 2.004 | H12: =IF(T2Manip!G8="","",T2Manip!G8) -> — | J12: =IF(T2Manip!H8="","",T2Manip!H8/1000) -> 16.1 | K12: =IF(T2Manip!I8="","",T2Manip!I8/1000) -> 22.3 | L12: =IF(T2Manip!J8="","",T2Manip!J8) -> 138.50932 | N12: =IF(T2Manip!K8="","",T2Manip!K8/1000) -> 92.7 | O12: =IF(T2Manip!L8="","",T2Manip!L8/1000) -> 82.6 | P12: =IF(T2Manip!M8="","",T2Manip!M8) -> 89.104639
A13: 1990 | B13: =IF(T2Manip!B9="","",T2Manip!B9/1000) -> 128 | C13: =IF(T2Manip!C9="","",T2Manip!C9/1000) -> 130.588 | D13: =IF(T2Manip!D9="","",T2Manip!D9) -> 102.02187 | F13: =IF(T2Manip!E9="","",T2Manip!E9) -> — | G13: =IF(T2Manip!F9="","",T2Manip!F9/1000) -> 3.527 | H13: =IF(T2Manip!G9="","",T2Manip!G9) -> — | J13: =IF(T2Manip!H9="","",T2Manip!H9/1000) -> 18.6 | K13: =IF(T2Manip!I9="","",T2Manip!I9/1000) -> 18.841 | L13: =IF(T2Manip!J9="","",T2Manip!J9) -> 101.2957 | N13: =IF(T2Manip!K9="","",T2Manip!K9/1000) -> 120.8 | O13: =IF(T2Manip!L9="","",T2Manip!L9/1000) -> 99.1 | P13: =IF(T2Manip!M9="","",T2Manip!M9) -> 82.036424
A14: 1991 | B14: =IF(T2Manip!B10="","",T2Manip!B10/1000) -> 110 | C14: =IF(T2Manip!C10="","",T2Manip!C10/1000) -> 109.929 | D14: =IF(T2Manip!D10="","",T2Manip!D10) -> 99.935455 | F14: =IF(T2Manip!E10="","",T2Manip!E10) -> — | G14: =IF(T2Manip!F10="","",T2Manip!F10/1000) -> 3.652 | H14: =IF(T2Manip!G10="","",T2Manip!G10) -> — | J14: =IF(T2Manip!H10="","",T2Manip!H10/1000) -> 19.7 | K14: =IF(T2Manip!I10="","",T2Manip!I10/1000) -> 19.892 | L14: =IF(T2Manip!J10="","",T2Manip!J10) -> 100.97462 | N14: =IF(T2Manip!K10="","",T2Manip!K10/1000) -> 61.9 | O14: =IF(T2Manip!L10="","",T2Manip!L10/1000) -> 59.2 | P14: =IF(T2Manip!M10="","",T2Manip!M10) -> 95.638126
A15: 1992 | B15: =IF(T2Manip!B11="","",T2Manip!B11/1000) -> 106 | C15: =IF(T2Manip!C11="","",T2Manip!C11/1000) -> 75.008 | D15: =IF(T2Manip!D11="","",T2Manip!D11) -> 70.762264 | F15: =IF(T2Manip!E11="","",T2Manip!E11) -> — | G15: =IF(T2Manip!F11="","",T2Manip!F11/1000) -> 8.551 | H15: =IF(T2Manip!G11="","",T2Manip!G11) -> — | J15: =IF(T2Manip!H11="","",T2Manip!H11/1000) -> 26.6 | K15: =IF(T2Manip!I11="","",T2Manip!I11/1000) -> 18.808 | L15: =IF(T2Manip!J11="","",T2Manip!J11) -> 70.706767 | N15: =IF(T2Manip!K11="","",T2Manip!K11/1000) -> 71.4 | O15: =IF(T2Manip!L11="","",T2Manip!L11/1000) -> 89.8 | P15: =IF(T2Manip!M11="","",T2Manip!M11) -> 125.77031
A16: 1993 | B16: =IF(T2Manip!B12="","",T2Manip!B12/1000) -> 70 | C16: =IF(T2Manip!C12="","",T2Manip!C12/1000) -> 65.934 | D16: =IF(T2Manip!D12="","",T2Manip!D12) -> 94.191429 | F16: =IF(T2Manip!E12="","",T2Manip!E12) -> — | G16: =IF(T2Manip!F12="","",T2Manip!F12/1000) -> 6.369 | H16: =IF(T2Manip!G12="","",T2Manip!G12) -> — | J16: =IF(T2Manip!H12="","",T2Manip!H12/1000) -> 21.3 | K16: =IF(T2Manip!I12="","",T2Manip!I12/1000) -> 20.527 | L16: =IF(T2Manip!J12="","",T2Manip!J12) -> 96.370892 | N16: =IF(T2Manip!K12="","",T2Manip!K12/1000) -> 76.2 | O16: =IF(T2Manip!L12="","",T2Manip!L12/1000) -> 111 | P16: =IF(T2Manip!M12="","",T2Manip!M12) -> 145.66929
A17: 1994 | B17: =IF(T2Manip!B13="","",T2Manip!B13/1000) -> 75 | C17: =IF(T2Manip!C13="","",T2Manip!C13/1000) -> 49.58 | D17: =IF(T2Manip!D13="","",T2Manip!D13) -> 66.106667 | F17: =IF(T2Manip!E13="","",T2Manip!E13) -> — | G17: =IF(T2Manip!F13="","",T2Manip!F13/1000) -> 3.498 | H17: =IF(T2Manip!G13="","",T2Manip!G13) -> — | J17: =IF(T2Manip!H13="","",T2Manip!H13/1000) -> 12.3 | K17: =IF(T2Manip!I13="","",T2Manip!I13/1000) -> 7.482 | L17: =IF(T2Manip!J13="","",T2Manip!J13) -> 60.829268 | N17: =IF(T2Manip!K13="","",T2Manip!K13/1000) -> 49 | O17: =IF(T2Manip!L13="","",T2Manip!L13/1000) -> 20.8 | P17: =IF(T2Manip!M13="","",T2Manip!M13) -> 42.44898
A18: 1995 | B18: =IF(T2Manip!B14="","",T2Manip!B14/1000) -> 49 | C18: =IF(T2Manip!C14="","",T2Manip!C14/1000) -> 42.563 | D18: =IF(T2Manip!D14="","",T2Manip!D14) -> 86.863265 | F18: =IF(T2Manip!E14="","",T2Manip!E14) -> — | G18: =IF(T2Manip!F14="","",T2Manip!F14/1000) -> 2.529 | H18: =IF(T2Manip!G14="","",T2Manip!G14) -> — | J18: =IF(T2Manip!H14="","",T2Manip!H14/1000) -> 4.6 | K18: =IF(T2Manip!I14="","",T2Manip!I14/1000) -> 6.525 | L18: =IF(T2Manip!J14="","",T2Manip!J14) -> 141.84783 | N18: =IF(T2Manip!K14="","",T2Manip!K14/1000) -> 12 | O18: =IF(T2Manip!L14="","",T2Manip!L14/1000) -> 9.8 | P18: =IF(T2Manip!M14="","",T2Manip!M14) -> 81.666667
A19: 1996 | B19: =IF(T2Manip!B15="","",T2Manip!B15/1000) -> 41 | C19: =IF(T2Manip!C15="","",T2Manip!C15/1000) -> 34.765 | D19: =IF(T2Manip!D15="","",T2Manip!D15) -> 84.792683 | F19: =IF(T2Manip!E15="","",T2Manip!E15) -> — | G19: =IF(T2Manip!F15="","",T2Manip!F15/1000) -> 3.801 | H19: =IF(T2Manip!G15="","",T2Manip!G15) -> — | J19: =IF(T2Manip!H15="","",T2Manip!H15/1000) -> 4.4 | K19: =IF(T2Manip!I15="","",T2Manip!I15/1000) -> 4.144 | L19: =IF(T2Manip!J15="","",T2Manip!J15) -> 94.181818 | N19: =IF(T2Manip!K15="","",T2Manip!K15/1000) -> 37.2 | O19: =IF(T2Manip!L15="","",T2Manip!L15/1000) -> 51.5 | P19: =IF(T2Manip!M15="","",T2Manip!M15) -> 138.44086
A20: 1997 | B20: =IF(T2Manip!B16="","",T2Manip!B16/1000) -> 30 | C20: =IF(T2Manip!C16="","",T2Manip!C16/1000) -> 35.303 | D20: =IF(T2Manip!D16="","",T2Manip!D16) -> 117.67667 | F20: =IF(T2Manip!E16="","",T2Manip!E16) -> — | G20: =IF(T2Manip!F16="","",T2Manip!F16/1000) -> 4.41 | H20: =IF(T2Manip!G16="","",T2Manip!G16) -> — | J20: =IF(T2Manip!H16="","",T2Manip!H16/1000) -> 4.5 | K20: =IF(T2Manip!I16="","",T2Manip!I16/1000) -> 4.578 | L20: =IF(T2Manip!J16="","",T2Manip!J16) -> 101.73333 | N20: =IF(T2Manip!K16="","",T2Manip!K16/1000) -> 67.8 | O20: =IF(T2Manip!L16="","",T2Manip!L16/1000) -> 114 | P20: =IF(T2Manip!M16="","",T2Manip!M16) -> 168.14159
A21: 1998 | B21: =IF(T2Manip!B17="","",T2Manip!B17/1000) -> 33.7 | C21: =IF(T2Manip!C17="","",T2Manip!C17/1000) -> 45.139 | D21: =IF(T2Manip!D17="","",T2Manip!D17) -> 133.94362 | F21: =IF(T2Manip!E17="","",T2Manip!E17) -> — | G21: =IF(T2Manip!F17="","",T2Manip!F17/1000) -> 3.577 | H21: =IF(T2Manip!G17="","",T2Manip!G17) -> — | J21: =IF(T2Manip!H17="","",T2Manip!H17/1000) -> 2.9 | K21: =IF(T2Manip!I17="","",T2Manip!I17/1000) -> 3.073 | L21: =IF(T2Manip!J17="","",T2Manip!J17) -> 105.96552 | N21: =IF(T2Manip!K17="","",T2Manip!K17/1000) -> 36.2 | O21: =IF(T2Manip!L17="","",T2Manip!L17/1000) -> 38.3 | P21: =IF(T2Manip!M17="","",T2Manip!M17) -> 105.8011
A22: 1999 | B22: =IF(T2Manip!B18="","",T2Manip!B18/1000) -> 46.5 | C22: =IF(T2Manip!C18="","",T2Manip!C18/1000) -> 54.202 | D22: =IF(T2Manip!D18="","",T2Manip!D18) -> 116.56344 | F22: =IF(T2Manip!E18="","",T2Manip!E18/1000) -> 4.3 | G22: =IF(T2Manip!F18="","",T2Manip!F18/1000) -> 3.585 | H22: =IF(T2Manip!G18="","",T2Manip!G18) -> 83.372093 | J22: =IF(T2Manip!H18="","",T2Manip!H18/1000) -> 3.9 | K22: =IF(T2Manip!I18="","",T2Manip!I18/1000) -> 4.799 | L22: =IF(T2Manip!J18="","",T2Manip!J18) -> 123.05128 | N22: =IF(T2Manip!K18="","",T2Manip!K18/1000) -> 24.6 | O22: =IF(T2Manip!L18="","",T2Manip!L18/1000) -> 38.7 | P22: =IF(T2Manip!M18="","",T2Manip!M18) -> 157.31707
